Workbook

Sheet Summary
A1: May '26 Monthly Summary
B3: Avg Price | C3: Avg Price MoM | D3: Avg Price YoY | E3: Quantity/Mo | F3: Qty by % | G3: Qty MoM | H3: Qty YoY | I3: Revenue/Mo | J3: Revenue by % | K3: Revenue MoM | L3: Revenue YoY
A4: Tablet $800+ | B4: 1513.9489 | C4: -0.014324707 | D4: -0.031861649 | E4: 2297 | F4: 0.0077160805 | G4: -0.007346586 | H4: 0.026821636 | I4: 3477540.7 | J4: 0.10701921 | K4: -0.021566055 | L4: -0.0058945944
A5: Tablet $400-$800 | B5: 545.18097 | C5: 0.001683684 | D5: 0.045315859 | E5: 11903 | F5: 0.039984548 | G5: -0.091651404 | H5: 0.1983288 | I5: 6489289.1 | J5: 0.19970395 | K5: -0.090122032 | L5: 0.2526321
A6: Tablet $400- | B6: 209.91847 | C6: 0.013128357 | D6: 0.029067689 | E6: 26153 | F6: 0.087853136 | G6: -0.035158268 | H6: 0.40668029 | I6: 5489997.8 | J6: 0.16895137 | K6: -0.022491481 | L6: 0.44756924
A7: Total Tablet | B7: 383.04036 | C7: -0.0008675193 | D7: -0.055179676 | E7: 40353 | F7: 0.13555376 | G7: -0.051053523 | H7: 0.31178077 | I7: 15456828 | J7: 0.47567453 | K7: -0.051876752 | L7: 0.23939713
A8: Handheld $75+ | B8: 179.1437 | C8: -0.025501343 | D8: 0.10534129 | E8: 17752 | F8: 0.059632504 | G8: -0.085655421 | H8: 0.19236969 | I8: 3180159 | J8: 0.097867472 | K8: -0.10897244 | L8: 0.31797546
A9: Handheld $75- | B9: 31.387422 | C9: 0.018806128 | D9: 0.0093193017 | E9: 101308 | F9: 0.34031375 | G9: -0.033910589 | H9: 0.0021961498 | I9: 3179796.9 | J9: 0.097856328 | K9: -0.015742188 | L9: 0.011535918
A10: Total Handheld | B10: 53.418074 | C10: -0.023677538 | D10: 0.11494079 | E10: 119060 | F10: 0.39994625 | G10: -0.041994223 | H10: 0.026609412 | I10: 6359955.9 | J10: 0.1957238 | K10: -0.064677441 | L10: 0.14460871
A11: Total Dongle | B11: 87.920125 | C11: 0.03771862 | D11: 0.191942 | E11: 67679 | F11: 0.22734724 | G11: 0.17479908 | H11: -0.0047352245 | I11: 5950346.1 | J11: 0.18311831 | K11: 0.21911088 | L11: 0.18629788
A12: Total Other Tools | B12: 69.21433 | C12: -0.049746839 | D12: 0.045786567 | E12: 66495 | F12: 0.22336995 | G12: 0.08628886 | H12: 0.44322177 | I12: 4602406.9 | J12: 0.14163629 | K12: 0.032249423 | L12: 0.50930194
A13: Total | B13: 110.25535 | C13: -0.029286984 | D13: 0.10205279 | E13: 293587 | F13: 0.98621721 | G13: 0.027875711 | H13: 0.12566955 | I13: 32369537 | J13: 0.99615293 | K13: -0.0022276688 | L13: 0.24054726
A45: May '26 Monthly Summary - Revenue
A46: Brand | B46: # of Listings | C46: Monthly Rev | D46: Estimated 12mo Revenue | E46: Monthly Units | F46: Monthly Rev Market Share % | G46: Price Per Unit | H46: Total Reviews | I46: Avg Rating
A47: autel | B47: 547 | C47: 4990834 | D47: 64472355 | E47: 18656 | F47: 0.1536 | G47: 267.52 | H47: 132487 | I47: 4.6
A48: ancel | B48: 79 | C48: 2748377 | D48: 33286994 | E48: 40920 | F48: 0.0846 | G48: 67.16 | H48: 130538 | I48: 4.2
A49: topdon | B49: 51 | C49: 2698187.6 | D49: 35169754 | E49: 11224 | F49: 0.083 | G49: 240.39 | H49: 26138 | I49: 4.3
A50: launch | B50: 286 | C50: 2569052.5 | D50: 32114238 | E50: 7779 | F50: 0.0791 | G50: 330.25 | H50: 73485 | I50: 4.2
A51: foxwell | B51: 49 | C51: 2004459.1 | D51: 21848414 | E51: 14808 | F51: 0.0617 | G51: 135.36 | H51: 72130 | I51: 4.3
A52: innova | B52: 42 | C52: 1793626.5 | D52: 17823864 | E52: 11876 | F52: 0.0552 | G52: 151.03 | H52: 32448 | I52: 4.3
A53: obdlink | B53: 4 | C53: 1538190.5 | D53: 15013735 | E53: 16012 | F53: 0.0473 | G53: 96.06 | H53: 37252 | I53: 4.6
A54: xtool | B54: 69 | C54: 1537851.7 | D54: 17241589 | E54: 6065 | F54: 0.0473 | G54: 253.56 | H54: 12032 | I54: 4.4
A55: bluedriver | B55: 3 | C55: 1093129.2 | D55: 12240545 | E55: 10265 | F55: 0.0336 | G55: 106.49 | H55: 124836 | I55: 4.5
A56: thinkcar | B56: 25 | C56: 839971.06 | D56: 9681257.5 | E56: 3250 | F56: 0.0258 | G56: 258.45 | H56: 13856 | I56: 4.3
A57: diesel laptops | B57: 21 | C57: 771053.38 | D57: 7722648.9 | E57: 1141 | F57: 0.0237 | G57: 675.77 | H57: 700 | I57: 4.1
A58: generic | B58: 197 | C58: 718749.55 | D58: 4782532.8 | E58: 3130 | F58: 0.0221 | G58: 229.63 | H58: 1392 | I58: 4
... A71: z automotive | B71: 14 | C71: 228306.07 | D71: 2929076.6 | E71: 854 | F71: 0.007 | G71: 267.34 | H71: 1932 | I71: 4.4
A73: Total | B73: =SUM(B46:B71) | C73: =SUM(C47:C71) | D73: =SUM(D47:D71) | E73: =SUM(E47:E71) | F73: =SUM(F47:F71) | G73: =AVERAGE(G47:G71) | H73: =SUM(H47:H71) | I73: =AVERAGE(I47:I71)
A76: May '26 Summary - Units
A77: Brand | B77: # of Listings | C77: Monthly Rev | D77: Estimated 12mo Units | E77: Monthly Units | F77: Monthly Unit Market Share % | G77: Price Per Unit | H77: Reviews | I77: Avg Rating
A78: ancel | B78: 79 | C78: 2748377 | D78: 583145.54 | E78: 40920 | F78: 0.1375 | G78: 67.16 | H78: 130538 | I78: 4.2
A79: autel | B79: 547 | C79: 4990834 | D79: 224601.23 | E79: 18656 | F79: 0.0627 | G79: 267.52 | H79: 132487 | I79: 4.6
A80: obdlink | B80: 4 | C80: 1538190.5 | D80: 155118.46 | E80: 16012 | F80: 0.0538 | G80: 96.06 | H80: 37252 | I80: 4.6
A81: foxwell | B81: 49 | C81: 2004459.1 | D81: 171792 | E81: 14808 | F81: 0.0497 | G81: 135.36 | H81: 72130 | I81: 4.3
A82: motopower | B82: 7 | C82: 307614.7 | D82: 127448.31 | E82: 12057 | F82: 0.0405 | G82: 25.51 | H82: 59491 | I82: 4.5
A83: innova | B83: 42 | C83: 1793626.5 | D83: 96864.923 | E83: 11876 | F83: 0.0399 | G83: 151.03 | H83: 32448 | I83: 4.3
A84: topdon | B84: 51 | C84: 2698187.6 | D84: 148226.77 | E84: 11224 | F84: 0.0377 | G84: 240.39 | H84: 26138 | I84: 4.3
A85: bluedriver | B85: 3 | C85: 1093129.2 | D85: 143465.54 | E85: 10265 | F85: 0.0345 | G85: 106.49 | H85: 124836 | I85: 4.5
A86: veepeak | B86: 4 | C86: 290264.25 | D86: 87092.308 | E86: 9029 | F86: 0.0303 | G86: 32.15 | H86: 53304 | I86: 4.5
A87: launch | B87: 286 | C87: 2569052.5 | D87: 104687.08 | E87: 7779 | F87: 0.0261 | G87: 330.25 | H87: 73485 | I87: 4.2
...

Sheet Top 50
A1: Top 50 Products - May '26 ONLY
B3: Avg Price | C3: Avg Price MoM | D3: Avg Price YoY | E3: Quantity/Mo | F3: Qty by % | G3: Qty MoM | H3: Qty YoY | I3: Revenue/Mo | J3: Revenue by % | L3: Revenue MoM | M3: Revenue YoY
A4: Total Tablet | B4: 401.6994 | C4: 0.049128055 | D4: 0.04553251 | E4: 15151 | F4: 0.13626103 | G4: -0.2000528 | H4: 0.13320868 | I4: 6086147.6 | J4: 0.43419987 | L4: -0.16075295 | M4: 0.18480651
A5: Total Handheld | B5: 54.932093 | C5: -0.047394216 | D5: 0.24575025 | E5: 53243 | F5: 0.47884271 | G5: -0.072162972 | H5: -0.075289173 | I5: 2924749.4 | J5: 0.2086584 | L5: -0.11613708 | M5: 0.15195875
A6: Total Dongle | B6: 110.19434 | C6: -0.023288911 | D6: 0.31051401 | E6: 34856 | F6: 0.31347861 | G6: 0.38840868 | H6: -0.083845871 | I6: 3840934 | J6: 0.27402113 | L6: 0.35607416 | M6: 0.20063282
A7: Total Other Tools | B7: 146.71895 | C7: -0.049776608 | D7: -0.038733798 | E7: 7941 | F7: 0.071417651 | G7: 0.1337807 | H7: 0.36045914 | I7: 1165095.2 | J7: 0.08312059 | L7: 0.077344939 | M7: 0.30776339
A8: Total | B8: 126.0617 | C8: -0.055652688 | D8: 0.23033175 | E8: 111191 | F8: 1 | G8: 0.025435061 | H8: -0.031698757 | I8: 14016926 | J8: 1 | L8: -0.031633157 | M8: 0.19133176
A40: Rank By Monthly Revenue - May '26 ONLY
A41: Ranking | B41: ASIN | C41: Product Name | D41: Brand | E41: Type | F41: Price | G41: Est. Monthly Retail Rev | H41: Est. Monthly Units Sold | I41: # of Reviews | J41: Avg. Rating | K41: Column2 | L41: Link
A42: 1 | B42: B07Z481NJM | C42: Innova 5610 OBD2 Bidirectional Scan Tool - Understand Your Vehicle, Pinpoint What's Wrong, and Complete Your Repairs with Less Headache, Updates Included, US-Based Technical Support | D42: innova | E42: Handheld | F42: 313.9311 | G42: 1084945.9 | H42: 3456 | I42: 3548 | J42: 4.4 | K42: https://amazon.com/dp/B07Z481NJM | L42: =IF(K42="","",HYPERLINK(K42,K42))
A43: 2 | B43: B07JFRFJG6 | C43: OBDLink MX+ OBD2 Bluetooth Scanner for iPhone, Android, and Windows | D43: obdlink | E43: Dongle | F43: 139.93305 | G43: 747242.47 | H43: 5340 | I43: 15235 | J43: 4.6 | K43: https://amazon.com/dp/B07JFRFJG6 | L43: =IF(K43="","",HYPERLINK(K43,K43))
A44: 3 | B44: B01G5EA74I | C44: ANCEL AD310 Classic Enhanced Universal OBD II Scanner Car Engine Fault Code Reader CAN Diagnostic Scan Tool, Read and Clear Error Codes for 1996 or Newer OBD2 Protocol Vehicle (Black) | D44: ancel | E44: Handheld | F44: 27.758715 | G44: 668152.27 | H44: 24070 | I44: 64423 | J44: 4.6 | K44: https://amazon.com/dp/B01G5EA74I | L44: =IF(K44="","",HYPERLINK(K44,K44))
A45: 4 | B45: B0GL9RL3XS | C45: BlueDriver Pro Next Gen OBD2 Scanner – No Subscription, Bluetooth Car Code Reader for iPhone & Android – Diagnose 8000+ Issues, ABS SRS TPMS, Repair Reports, Vehicles 1996+ | D45: bluedriver | E45: Dongle | F45: 97.454834 | G45: 634430.97 | H45: 6510 | I45: 62416 | J45: 4.5 | K45: https://amazon.com/dp/B0GL9RL3XS | L45: =IF(K45="","",HYPERLINK(K45,K45))
A46: 5 | B46: B098PYB8XG | C46: Autel Scanner MaxiCOM MK900BT, 2026 MK900-BT V2.0 Bidirectional Diagnostic Tool, 8in Up of MK900 MX900 MK808S MK808BT MX808S MK808Z, 3000+ Active Tests, 40+ Service, CAN-FD&DOIP, All System, FCA 11 OS | D46: autel | E46: Tablet | F46: 658.58882 | G46: 503161.86 | H46: 764 | I46: 723 | J46: 4.6 | K46: https://amazon.com/dp/B098PYB8XG | L46: =IF(K46="","",HYPERLINK(K46,K46))
A47: 6 | B47: B081VQVD3F | C47: OBDLink EX FORScan OBD Adapter | D47: obdlink | E47: Cable/Adapter | F47: 69.944527 | G47: 475692.73 | H47: 6801 | I47: 10006 | J47: 4.8 | K47: https://amazon.com/dp/B081VQVD3F | L47: =IF(K47="","",HYPERLINK(K47,K47))
A48: 7 | B48: B00652G4TS | C48: BlueDriver Bluetooth Pro OBDII Scan Tool for iPhone & Android - No Subscription Fee - OBD2 Car Scanner and Code Reader - Diagnose Check Engine, ABS, SRS, Airbag & 7000+ Issues on Vehicles 1996+ | D48: bluedriver | E48: Dongle | F48: 122.15666 | G48: 458698.26 | H48: 3755 | I48: 62420 | J48: 4.5 | K48: https://amazon.com/dp/B00652G4TS | L48: =IF(K48="","",HYPERLINK(K48,K48))
A49: 8 | B49: B0BPYPNDVP | C49: Diesel Laptops Nexiq USB Link 3 Wired Edition with Repair Information & Diagnostic Software | D49: diesel laptops | E49: VCI | F49: 749.55194 | G49: 454978.03 | H49: 607 | I49: 257 | J49: 4.5 | K49: https://amazon.com/dp/B0BPYPNDVP | L49: =IF(K49="","",HYPERLINK(K49,K49))
A50: 9 | B50: B00UJV3E12 | C50: FOXWELL NT301 OBD2 Scanner Live Data Professional Mechanic OBDII Diagnostic Code Reader Tool for Check Engine Light | D50: foxwell | E50: Handheld | F50: 65.640497 | G50: 390823.52 | H50: 5954 | I50: 29789 | J50: 4.5 | K50: https://amazon.com/dp/B00UJV3E12 | L50: =IF(K50="","",HYPERLINK(K50,K50))
A51: 10 | B51: B0C33Y285Y | C51: TOPDON Bidirectional Scan Tool, 2026 New ArtiDiag900 Lite Automotive Diagnostic Tool for Full System, Scanner for Car with Active Test, 8 Reset, Wireless OBD2 Scanner Diagnostic Tool for All Vehicles | D51: topdon | E51: Tablet | F51: 315.0536 | G51: 384680.45 | H51: 1221 | I51: 1273 | J51: 4.2 | K51: https://amazon.com/dp/B0C33Y285Y | L51: =IF(K51="","",HYPERLINK(K51,K51))
A52: 11 | B52: B0DV2N2FND | C52: BLCKTEC 460T OBD2 Scanner Car Code Reader Engine ABS SRS Transmission Diagnostic Tool, 12 Reset Services, Oil/TPMS/EPB/BMS/SAS/DPF/Throttle Reset, ABS Bleeding, Battery Test, Auto VIN, Free Update | D52: blcktec | E52: Tablet | F52: 196.13548 | G52: 356182.04 | H52: 1816 | I52: 656 | J52: 4.4 | K52: https://amazon.com/dp/B0DV2N2FND | L52: =IF(K52="","",HYPERLINK(K52,K52))
A53: 12 | B53: B08PFJMTY3 | C53: FOXWELL Car Scanner NT604 Elite OBD2 Scanner ABS SRS Transmission, Check Engine Code Reader for Cars and Trucks, Diagnostic Scan Tool with SRS Airbag, Automotive Diagnostic Tool with Live Data | D53: foxwell | E53: Tablet | F53: 153.79738 | G53: 353118.78 | H53: 2296 | I53: 4914 | J53: 4.4 | K53: https://amazon.com/dp/B08PFJMTY3 | L53: =IF(K53="","",HYPERLINK(K53,K53))
... A91: 50 | B91: B0DZC1M7MZ | C91: Autel MaxiSys Ultra S2 Scanner, 2026 Top Intelligen Scan Diagnostic with AI, 6-in-1 VCMI2, Up of MSUltra MS919, Topology 3.0, Multi-Point DVI, Motor Truspeed Repair, EV Test, 48+ Service, ECU Program | D91: autel | E91: Tablet | F91: 5788.9904 | G91: 133146.78 | H91: 23 | I91: 22 | J91: 4.8 | K91: https://amazon.com/dp/B0DZC1M7MZ | L91: =IF(K91="","",HYPERLINK(K91,K91))
A94: Rank By Monthly Units - May '26 ONLY
A95: Ranking | B95: ASIN | C95: Product Name | D95: Brand | E95: Type | F95: Price | G95: Est. Monthly Retail Rev | H95: Est. Monthly Units Sold | I95: # of Reviews | J95: Avg. Rating | K95: Column2 | L95: Link
A96: 1 | B96: B01G5EA74I | C96: ANCEL AD310 Classic Enhanced Universal OBD II Scanner Car Engine Fault Code Reader CAN Diagnostic Scan Tool, Read and Clear Error Codes for 1996 or Newer OBD2 Protocol Vehicle (Black) | D96: ancel | E96: Handheld | F96: 27.758715 | G96: 668152.27 | H96: 24070 | I96: 64423 | J96: 4.6 | K96: https://amazon.com/dp/B01G5EA74I | L96: =IF(K96="","",HYPERLINK(K96,K96))
A97: 2 | B97: B07Z3HB7DR | C97: MOTOPOWER MP69033 Car OBD2 Scanner Code Reader Engine Fault Scanner CAN Diagnostic Scan Tool for All OBD II Protocol Cars Since 1996, Yellow | D97: motopower | E97: Handheld | F97: 24.501724 | G97: 264030.58 | H97: 10776 | I97: 51034 | J97: 4.6 | K97: https://amazon.com/dp/B07Z3HB7DR | L97: =IF(K97="","",HYPERLINK(K97,K97))
A98: 3 | B98: B081VQVD3F | C98: OBDLink EX FORScan OBD Adapter | D98: obdlink | E98: Cable/Adapter | F98: 69.944527 | G98: 475692.73 | H98: 6801 | I98: 10006 | J98: 4.8 | K98: https://amazon.com/dp/B081VQVD3F | L98: =IF(K98="","",HYPERLINK(K98,K98))
A99: 4 | B99: B071FSNL73 | C99: ANCEL AD410 Enhanced OBD2 Scanner, Vehicle Code Reader for Check Engine Light, Automotive OBD II Scanner Fault Diagnosis, OBDII Scan Tool for All OBDII Cars 1996+, Black/Yellow | D99: ancel | E99: Handheld | F99: 45.525505 | G99: 301515.42 | H99: 6623 | I99: 15175 | J99: 4.5 | K99: https://amazon.com/dp/B071FSNL73 | L99: =IF(K99="","",HYPERLINK(K99,K99))
A100: 5 | B100: B0BY1TS725 | C100: VDIAGTOOL VD10 OBD2 Scanner Code Reader Car Diagnostic Tool Engine Fault Code Reader for Turn Off CEL with Freeze Frame/I/M Readiness for All OBDII Protocol Cars, OBD2 Scanner Diagnostic Tool | D100: vdiagtool | E100: Handheld | F100: 19.980454 | G100: 131251.6 | H100: 6569 | I100: 2686 | J100: 4.6 | K100: https://amazon.com/dp/B0BY1TS725 | L100: =IF(K100="","",HYPERLINK(K100,K100))
A101: 6 | B101: B0GL9RL3XS | C101: BlueDriver Pro Next Gen OBD2 Scanner – No Subscription, Bluetooth Car Code Reader for iPhone & Android – Diagnose 8000+ Issues, ABS SRS TPMS, Repair Reports, Vehicles 1996+ | D101: bluedriver | E101: Dongle | F101: 97.454834 | G101: 634430.97 | H101: 6510 | I101: 62416 | J101: 4.5 | K101: https://amazon.com/dp/B0GL9RL3XS | L101: =IF(K101="","",HYPERLINK(K101,K101))
A102: 7 | B102: B00UJV3E12 | C102: FOXWELL NT301 OBD2 Scanner Live Data Professional Mechanic OBDII Diagnostic Code Reader Tool for Check Engine Light | D102: foxwell | E102: Handheld | F102: 65.640497 | G102: 390823.52 | H102: 5954 | I102: 29789 | J102: 4.5 | K102: https://amazon.com/dp/B00UJV3E12 | L102: =IF(K102="","",HYPERLINK(K102,K102))
A103: 8 | B103: B073XKQQQW | C103: Veepeak OBDCheck BLE Bluetooth OBD II Scanner for iOS & Android, Car Wireless Check Engine Light Code Reader Diagnostic Tool | D103: veepeak | E103: Dongle | F103: 31.298403 | G103: 180842.17 | H103: 5778 | I103: 23568 | J103: 4.5 | K103: https://amazon.com/dp/B073XKQQQW | L103: =IF(K103="","",HYPERLINK(K103,K103))
A104: 9 | B104: B07JFRFJG6 | C104: OBDLink MX+ OBD2 Bluetooth Scanner for iPhone, Android, and Windows | D104: obdlink | E104: Dongle | F104: 139.93305 | G104: 747242.47 | H104: 5340 | I104: 15235 | J104: 4.6 | K104: https://amazon.com/dp/B07JFRFJG6 | L104: =IF(K104="","",HYPERLINK(K104,K104))
A105: 10 | B105: B013RIQMEO | C105: FIXD Bluetooth OBD2 Scanner for iPhone & Android - Diagnostic Scan Tool for Repairs and Car Buying - Check Engine Code Reader & Enhanced Codes - (1 Pack w/Free 14-Day FIXD Premium Bundle) | D105: fixd | E105: Dongle | F105: 39.988087 | G105: 150915.04 | H105: 3774 | I105: 35178 | J105: 4.2 | K105: https://amazon.com/dp/B013RIQMEO | L105: =IF(K105="","",HYPERLINK(K105,K105))
A106: 11 | B106: B00652G4TS | C106: BlueDriver Bluetooth Pro OBDII Scan Tool for iPhone & Android - No Subscription Fee - OBD2 Car Scanner and Code Reader - Diagnose Check Engine, ABS, SRS, Airbag & 7000+ Issues on Vehicles 1996+ | D106: bluedriver | E106: Dongle | F106: 122.15666 | G106: 458698.26 | H106: 3755 | I106: 62420 | J106: 4.5 | K106: https://amazon.com/dp/B00652G4TS | L106: =IF(K106="","",HYPERLINK(K106,K106))
A107: 12 | B107: B07Z481NJM | C107: Innova 5610 OBD2 Bidirectional Scan Tool - Understand Your Vehicle, Pinpoint What's Wrong, and Complete Your Repairs with Less Headache, Updates Included, US-Based Technical Support | D107: innova | E107: Handheld | F107: 313.9311 | G107: 1084945.9 | H107: 3456 | I107: 3548 | J107: 4.4 | K107: https://amazon.com/dp/B07Z481NJM | L107: =IF(K107="","",HYPERLINK(K107,K107))
... A125: 30 | B125: B09KZTYD18 | C125: OBD2 Scanner TOPDON AD600S Scan Tool, Code Reader, Diagnostics Scanner for ABS/SRS/AT/Engine, 9 Reset Services, Oil/Brake/BMS/SAS/DPF/TPMS/ETS Reset/ABS Bleeding/Injector Coding, Free Lifetime Upgrade | D125: topdon | E125: Tablet | F125: 201.80111 | G125: 222990.23 | H125: 1105 | I125: 1864 | J125: 4.4 | K125: https://amazon.com/dp/B09KZTYD18 | L125: =IF(K125="","",HYPERLINK(K125,K125))
A126: 31 | B126: B000EVYGV4 | C126: Innova 3568 Digital Timing Light | D126: innova | E126: Other | F126: 77.445181 | G126: 83253.57 | H126: 1075 | K126: https://amazon.com/dp/B000EVYGV4 | L126: =IF(K126="","",HYPERLINK(K126,K126))
A127: 32 | B127: B0DPHCBL89 | C127: 12+8 Pin Connector to OBD2 Adapter, Secutiry Gateway Bypass Cable, 12+8 Cable for Chrysler SGW Equipped FCA Vehicles for Diagnostic, Fit for Scanners MK808 MK808S MX808 MS906 Pro MS908S | D127: ecocstm | E127: Cable/Adapter | F127: 12.980797 | G127: 13850.51 | H127: 1067 | I127: 148 | J127: 4.6 | K127: https://amazon.com/dp/B0DPHCBL89 | L127: =IF(K127="","",HYPERLINK(K127,K127))
A128: 33 | B128: B0DFY6CCSV | C128: pinflaw 2 PCS Automobile Power Upgrade Fuel Saving, OBD2 ECOOBD2 Automotive Plug and Driver Single Plate, Automotive Energy Saver Accessories, Universal for Most Cars (Green) | D128: pinflaw | E128: Other | F128: 13.258625 | G128: 14080.66 | H128: 1062 | I128: 429 | J128: 3.6 | K128: https://amazon.com/dp/B0DFY6CCSV | L128: =IF(K128="","",HYPERLINK(K128,K128))
...

Sheet Tablet Total
A1: Tablet Monthly Summary
A3: Tablet Overall
B4: Avg Price | C4: Avg Price MoM | D4: Avg Price YoY | E4: Quantity/Mo | F4: Qty by % | G4: Qty MoM | H4: Qty YoY | I4: Revenue/Mo | J4: Revenue by % | L4: Revenue MoM | M4: Revenue YoY
A5: autel | B5: 758.21987 | C5: 0.036543181 | D5: -0.021240031 | E5: 5591 | F5: 0.13855228 | G5: -0.15760133 | H5: 0.049755914 | I5: 4239207.3 | J5: 0.27426115 | L5: -0.1268174 | M5: 0.027459066
A6: launch | B6: 439.35212 | C6: 0.081884841 | D6: 0.14597188 | E6: 5442 | F6: 0.13485986 | G6: -0.096163428 | H6: -0.20554745 | I6: 2390954.2 | J6: 0.15468596 | L6: -0.022152914 | M6: -0.089579713
A7: topdon | B7: 327.91994 | C7: -0.025270915 | D7: 0.031862684 | E7: 6761 | F7: 0.1675464 | G7: -0.18971716 | H7: 0.13211654 | I7: 2217066.7 | J7: 0.14343608 | L7: -0.21019375 | M7: 0.16818882
A8: xtool | B8: 333.66305 | C8: -0.010373718 | D8: -0.12982713 | E8: 3840 | F8: 0.095160211 | G8: 0.016410799 | H8: 0.69014085 | I8: 1281266.1 | J8: 0.082893213 | L8: 0.0058668404 | M8: 0.47071471
A9: ancel | B9: 480.03556 | C9: 0.03865599 | D9: 0.42560697 | E9: 2480 | F9: 0.061457636 | G9: 0.17036338 | H9: 0.34929271 | I9: 1190488.2 | J9: 0.077020215 | L9: 0.21560493 | M9: 0.92356109
A10: blcktec | B10: 196.13548 | C10: 0.034452976 | D10: 0.059213373 | E10: 1816 | F10: 0.04500285 | G10: 0.135 | H10: 2.5193798 | I10: 356182.04 | J10: 0.02304367 | L10: 0.17410413 | M10: 2.7277742
A11: innova | B11: 159.12765 | C11: -0.0077981129 | D11: -0.22299144 | E11: 557 | F11: 0.013803187 | G11: -0.11305732 | H11: 3.2846154 | I11: 88634.1 | J11: 0.0057343009 | L11: -0.1199738 | M11: 2.3291828
A12: Other | B12: 266.33701 | C12: 0.0084489572 | D12: -0.052569202 | E12: 13866 | F12: 0.34361757 | G12: 0.035007838 | H12: 0.76457114 | I12: 3693029 | J12: 0.23892542 | L12: 0.043752574 | M12: 0.67180904
A13: Total Tablet | B13: 383.04036 | C13: -0.0008675193 | D13: -0.055179676 | E13: 40353 | F13: 1 | G13: -0.051053523 | H13: 0.31178077 | I13: 15456828 | J13: 1 | L13: -0.051876752 | M13: 0.23939713
A45: Rank By Monthly Revenue - May '26 ONLY
A46: Ranking | B46: ASIN | C46: Product Name | D46: Brand | E46: Type | F46: Price | G46: Est. Monthly Retail Rev | H46: Est. Monthly Units Sold | I46: # of Reviews | J46: Avg. Rating | K46: Column2 | L46: Link
A47: 1 | B47: B098PYB8XG | C47: Autel Scanner MaxiCOM MK900BT, 2026 MK900-BT V2.0 Bidirectional Diagnostic Tool, 8in Up of MK900 MX900 MK808S MK808BT MX808S MK808Z, 3000+ Active Tests, 40+ Service, CAN-FD&DOIP, All System, FCA 11 OS | D47: autel | E47: Tablet | F47: 658.58882 | G47: 503161.86 | H47: 764 | I47: 723 | J47: 4.6 | K47: https://amazon.com/dp/B098PYB8XG | L47: =IF(K47="","",HYPERLINK(K47,K47))
A48: 2 | B48: B0C33Y285Y | C48: TOPDON Bidirectional Scan Tool, 2026 New ArtiDiag900 Lite Automotive Diagnostic Tool for Full System, Scanner for Car with Active Test, 8 Reset, Wireless OBD2 Scanner Diagnostic Tool for All Vehicles | D48: topdon | E48: Tablet | F48: 315.0536 | G48: 384680.45 | H48: 1221 | I48: 1273 | J48: 4.2 | K48: https://amazon.com/dp/B0C33Y285Y | L48: =IF(K48="","",HYPERLINK(K48,K48))
A49: 3 | B49: B0DV2N2FND | C49: BLCKTEC 460T OBD2 Scanner Car Code Reader Engine ABS SRS Transmission Diagnostic Tool, 12 Reset Services, Oil/TPMS/EPB/BMS/SAS/DPF/Throttle Reset, ABS Bleeding, Battery Test, Auto VIN, Free Update | D49: blcktec | E49: Tablet | F49: 196.13548 | G49: 356182.04 | H49: 1816 | I49: 656 | J49: 4.4 | K49: https://amazon.com/dp/B0DV2N2FND | L49: =IF(K49="","",HYPERLINK(K49,K49))
A50: 4 | B50: B08PFJMTY3 | C50: FOXWELL Car Scanner NT604 Elite OBD2 Scanner ABS SRS Transmission, Check Engine Code Reader for Cars and Trucks, Diagnostic Scan Tool with SRS Airbag, Automotive Diagnostic Tool with Live Data | D50: foxwell | E50: Tablet | F50: 153.79738 | G50: 353118.78 | H50: 2296 | I50: 4914 | J50: 4.4 | K50: https://amazon.com/dp/B08PFJMTY3 | L50: =IF(K50="","",HYPERLINK(K50,K50))
A51: 5 | B51: B0DTK24XKB | C51: MUCAR 892BT AI-Assisted Bidirectional Scan Tool, Full System OBD2 Scanner, Bi-Directional OBD2 Scanner Diagnostic Tool,ECU Coding, 35 Services, FCA Autoauth, CANFD and DOIP, Free Lifetime Upgrade | D51: mucar | E51: Tablet | F51: 639.61776 | G51: 345393.59 | H51: 540 | I51: 421 | J51: 4.3 | K51: https://amazon.com/dp/B0DTK24XKB | L51: =IF(K51="","",HYPERLINK(K51,K51))
A52: 6 | B52: B0BZ82WQ4Q | C52: ANCEL X7HD 10.1'' Heavy Duty Truck Scanner, Semi Trucks Full System Diagnostic Tool, Bidirectional Diesel Scan Tool with DPF, ECU Coding, 40+ Reset for Cummins, Detroit, Caterpillar, Volvo, Paccar etc | D52: ancel | E52: Tablet | F52: 765.33645 | G52: 267102.42 | H52: 349 | I52: 796 | J52: 3.7 | K52: https://amazon.com/dp/B0BZ82WQ4Q | L52: =IF(K52="","",HYPERLINK(K52,K52))
A53: 7 | B53: B0DCFRF2TF | C53: THINKCAR Bidirectional Scan Tool, THINKSCAN 689BT All System Automotive Diagnostic Tool, Bi Directional OBD2 Scanner with ECU Coding, 34 Services, FCA Autoauth, CANFD and DoIP, Wireless Update | D53: thinkcar | E53: Tablet | F53: 555.84548 | G53: 239569.4 | H53: 431 | I53: 603 | J53: 4.4 | K53: https://amazon.com/dp/B0DCFRF2TF | L53: =IF(K53="","",HYPERLINK(K53,K53))
A54: 8 | B54: B091BQNR3S | C54: TOPDON Phoenix Plus 2, OE-Level TOPDON Scanner, Advanced Online ECU Coding & Configuration Flashing, Bidirectional Scan Tool with Topology Map, CANFD, 42+ Services, FCA AutoAuth, 2 Years Free Update | D54: topdon | E54: Tablet | F54: 1017.3352 | G54: 231952.42 | H54: 228 | I54: 502 | J54: 4.5 | K54: https://amazon.com/dp/B091BQNR3S | L54: =IF(K54="","",HYPERLINK(K54,K54))
A55: 9 | B55: B08ML7T7KZ | C55: Autel Scanner MaxiCheck MX808S, 2026 US Ver. of MaxiCOM MK808S MK808Z, Bidirectional 3000+ Active Test 11OS as MK900 MK900BT MX900, 28+ Service, OE All Systems OBD2 Diagnostic Tool, FCA, 10X Faster | D55: autel | E55: Tablet | F55: 427.35611 | G55: 230772.3 | H55: 540 | I55: 722 | J55: 4.7 | K55: https://amazon.com/dp/B08ML7T7KZ | L55: =IF(K55="","",HYPERLINK(K55,K55))
A56: 10 | B56: B09KZTYD18 | C56: OBD2 Scanner TOPDON AD600S Scan Tool, Code Reader, Diagnostics Scanner for ABS/SRS/AT/Engine, 9 Reset Services, Oil/Brake/BMS/SAS/DPF/TPMS/ETS Reset/ABS Bleeding/Injector Coding, Free Lifetime Upgrade | D56: topdon | E56: Tablet | F56: 201.80111 | G56: 222990.23 | H56: 1105 | I56: 1864 | J56: 4.4 | K56: https://amazon.com/dp/B09KZTYD18 | L56: =IF(K56="","",HYPERLINK(K56,K56))
A58: Rank By Monthly Units - May '26 ONLY
A59: Ranking | B59: ASIN | C59: Product Name | D59: Brand | E59: Type | F59: Price | G59: Est. Monthly Retail Rev | H59: Est. Monthly Units Sold | I59: # of Reviews | J59: Avg. Rating | K59: Column2 | L59: Link
A60: 1 | B60: B08PFJMTY3 | C60: FOXWELL Car Scanner NT604 Elite OBD2 Scanner ABS SRS Transmission, Check Engine Code Reader for Cars and Trucks, Diagnostic Scan Tool with SRS Airbag, Automotive Diagnostic Tool with Live Data | D60: foxwell | E60: Tablet | F60: 153.79738 | G60: 353118.78 | H60: 2296 | I60: 4914 | J60: 4.4 | K60: https://amazon.com/dp/B08PFJMTY3 | L60: =IF(K60="","",HYPERLINK(K60,K60))
A61: 2 | B61: B0DV2N2FND | C61: BLCKTEC 460T OBD2 Scanner Car Code Reader Engine ABS SRS Transmission Diagnostic Tool, 12 Reset Services, Oil/TPMS/EPB/BMS/SAS/DPF/Throttle Reset, ABS Bleeding, Battery Test, Auto VIN, Free Update | D61: blcktec | E61: Tablet | F61: 196.13548 | G61: 356182.04 | H61: 1816 | I61: 656 | J61: 4.4 | K61: https://amazon.com/dp/B0DV2N2FND | L61: =IF(K61="","",HYPERLINK(K61,K61))
A62: 3 | B62: B0C33Y285Y | C62: TOPDON Bidirectional Scan Tool, 2026 New ArtiDiag900 Lite Automotive Diagnostic Tool for Full System, Scanner for Car with Active Test, 8 Reset, Wireless OBD2 Scanner Diagnostic Tool for All Vehicles | D62: topdon | E62: Tablet | F62: 315.0536 | G62: 384680.45 | H62: 1221 | I62: 1273 | J62: 4.2 | K62: https://amazon.com/dp/B0C33Y285Y | L62: =IF(K62="","",HYPERLINK(K62,K62))
A63: 4 | B63: B09KZTYD18 | C63: OBD2 Scanner TOPDON AD600S Scan Tool, Code Reader, Diagnostics Scanner for ABS/SRS/AT/Engine, 9 Reset Services, Oil/Brake/BMS/SAS/DPF/TPMS/ETS Reset/ABS Bleeding/Injector Coding, Free Lifetime Upgrade | D63: topdon | E63: Tablet | F63: 201.80111 | G63: 222990.23 | H63: 1105 | I63: 1864 | J63: 4.4 | K63: https://amazon.com/dp/B09KZTYD18 | L63: =IF(K63="","",HYPERLINK(K63,K63))
A64: 5 | B64: B08XK3DJ42 | C64: TOPDON AD500 OBD2 Scanner, Oil SAS Throttle TPMS BMS EPB Reset, Engine ABS SRS Transmission, Diagnostic Scan Tool, AutoVIN, Car Check Engine Code Reader with Battery Test, Lifetime Wi-Fi Free Update | D64: topdon | E64: Tablet | F64: 159.11793 | G64: 150366.44 | H64: 945 | I64: 1766 | J64: 4.4 | K64: https://amazon.com/dp/B08XK3DJ42 | L64: =IF(K64="","",HYPERLINK(K64,K64))
A65: 6 | B65: B098PYB8XG | C65: Autel Scanner MaxiCOM MK900BT, 2026 MK900-BT V2.0 Bidirectional Diagnostic Tool, 8in Up of MK900 MX900 MK808S MK808BT MX808S MK808Z, 3000+ Active Tests, 40+ Service, CAN-FD&DOIP, All System, FCA 11 OS | D65: autel | E65: Tablet | F65: 658.58882 | G65: 503161.86 | H65: 764 | I65: 723 | J65: 4.6 | K65: https://amazon.com/dp/B098PYB8XG | L65: =IF(K65="","",HYPERLINK(K65,K65))
A66: 7 | B66: B08DCNDFVK | C66: FOXWELL NT614 Elite OBD2 Scanner for DIY Mechanics, Upgrade of NT604, 4 System Diagnostic Tool with 5 Resets (ABS Bleeding, EPB, Oil, SAS, Throttle), Read/Clear Engine/ABS/SRS/Transmission Fault Codes | D66: foxwell | E66: Tablet | F66: 177.04205 | G66: 117201.84 | H66: 662 | I66: 745 | J66: 4.3 | K66: https://amazon.com/dp/B08DCNDFVK | L66: =IF(K66="","",HYPERLINK(K66,K66))
A67: 8 | B67: B0DFCMT416 | C67: XTOOL D5S OBD2 Scanner with Touchscreen, Code Reader for Cars & Trucks with 16 Resets, Crank Sensor Relearn, Throttle Relearn, EPB, FCA, CAN FD for GM, Engine ABS SRS Transmission Car Diagnostic Tool | D67: xtool | E67: Tablet | F67: 175.72467 | G67: 105786.25 | H67: 602 | I67: 455 | J67: 4.3 | K67: https://amazon.com/dp/B0DFCMT416 | L67: =IF(K67="","",HYPERLINK(K67,K67))
A68: 9 | B68: B07RLF8FBC | C68: Launch OBD2 Scanner CRP123X V3.0 Elite, 2026 Lifetime Free WiFi Update Scan Tool, FCA SGW, CANFD&DoIP, SAS/Throttle/Brake/BMS/D-P-F/Oil/ABS Service Multi Systems Car Scanner, Battery Test, Auto VIN | D68: launch | E68: Tablet | F68: 209.1466 | G68: 122978.2 | H68: 588 | I68: 3489 | J68: 4.4 | K68: https://amazon.com/dp/B07RLF8FBC | L68: =IF(K68="","",HYPERLINK(K68,K68))
A69: 10 | B69: B073GW5MTS | C69: LAUNCH CRP123 V2.0 OBD2 Scanner-2026 New Model Engine/ABS/SRS/Transmission Diagnostic Scan Tool SRS Airbag Code Reader,3 Reset Oil Service/Throttle Relearn/SAS Reset,Lifetime Free Update | D69: launch | E69: Tablet | F69: 124.90528 | G69: 68323.19 | H69: 547 | I69: 4066 | J69: 4.3 | K69: https://amazon.com/dp/B073GW5MTS | L69: =IF(K69="","",HYPERLINK(K69,K69))
A71: Tablet $800+
B72: Avg Price | C72: Avg Price MoM | D72: Avg Price YoY | E72: Quantity/Mo | F72: Qty by % | G72: Qty MoM | H72: Qty YoY | I72: Revenue/Mo | J72: Revenue by % | L72: Revenue MoM | M72: Revenue YoY
A73: autel | B73: 1904.8305 | C73: 0.033080843 | D73: -0.047155361 | E73: 893 | F73: 0.38876796 | G73: -0.11932939 | H73: -0.018681319 | I73: 1701013.6 | J73: 0.4891427 | L73: -0.090196062 | M73: -0.064955755
A74: launch | B74: 1394.6057 | C74: 0.0093515194 | D74: 0.028908938 | E74: 617 | F74: 0.26861123 | G74: -0.097953216 | H74: -0.15710383 | I74: 860471.73 | J74: 0.24743685 | L74: -0.089517708 | M74: -0.13273659
...

Sheet Tablet $800+
A1: Tablet $800+ Monthly Summary
A3: ='Tablet Total'!A71
B4: Avg Price | C4: Avg Price MoM | D4: Avg Price YoY | E4: Quantity/Mo | F4: Qty by % | G4: Qty MoM | H4: Qty YoY | I4: Revenue/Mo | J4: Revenue by % | L4: Revenue MoM | M4: Revenue YoY
A5: ='Tablet Total'!A73 | B5: ='Tablet Total'!B73 | C5: ='Tablet Total'!C73 | D5: ='Tablet Total'!D73 | E5: ='Tablet Total'!E73 | F5: ='Tablet Total'!F73 | G5: ='Tablet Total'!G73 | H5: ='Tablet Total'!H73 | ... M5: ='Tablet Total'!M73
A6: ='Tablet Total'!A74 | B6: ='Tablet Total'!B74 | C6: ='Tablet Total'!C74 | D6: ='Tablet Total'!D74 | E6: ='Tablet Total'!E74 | F6: ='Tablet Total'!F74 | G6: ='Tablet Total'!G74 | H6: ='Tablet Total'!H74 | ... M6: ='Tablet Total'!M74
A7: ='Tablet Total'!A75 | B7: ='Tablet Total'!B75 | C7: ='Tablet Total'!C75 | D7: ='Tablet Total'!D75 | E7: ='Tablet Total'!E75 | F7: ='Tablet Total'!F75 | G7: ='Tablet Total'!G75 | H7: ='Tablet Total'!H75 | ... M7: ='Tablet Total'!M75
A8: ='Tablet Total'!A76 | B8: ='Tablet Total'!B76 | C8: ='Tablet Total'!C76 | D8: ='Tablet Total'!D76 | E8: ='Tablet Total'!E76 | F8: ='Tablet Total'!F76 | G8: ='Tablet Total'!G76 | H8: ='Tablet Total'!H76 | ... M8: ='Tablet Total'!M76
A9: ='Tablet Total'!A77 | B9: ='Tablet Total'!B77 | C9: ='Tablet Total'!C77 | D9: ='Tablet Total'!D77 | E9: ='Tablet Total'!E77 | F9: ='Tablet Total'!F77 | G9: ='Tablet Total'!G77 | H9: ='Tablet Total'!H77 | ... M9: ='Tablet Total'!M77
A10: ='Tablet Total'!A78 | B10: ='Tablet Total'!B78 | C10: ='Tablet Total'!C78 | D10: ='Tablet Total'!D78 | E10: ='Tablet Total'!E78 | F10: ='Tablet Total'!F78 | G10: ='Tablet Total'!G78 | H10: ='Tablet Total'!H78 | ... M10: ='Tablet Total'!M78
A11: ='Tablet Total'!A79 | B11: ='Tablet Total'!B79 | C11: ='Tablet Total'!C79 | D11: ='Tablet Total'!D79 | E11: ='Tablet Total'!E79 | F11: ='Tablet Total'!F79 | G11: ='Tablet Total'!G79 | H11: ='Tablet Total'!H79 | ... M11: ='Tablet Total'!M79
A43: Rank By Monthly Revenue - May '26 ONLY
A44: Ranking | B44: ASIN | C44: Product Name | D44: Brand | E44: Type | F44: Price | G44: Est. Monthly Retail Rev | H44: Est. Monthly Units Sold | I44: # of Reviews | J44: Avg. Rating | K44: Column2 | L44: Link
A45: 1 | B45: B091BQNR3S | C45: TOPDON Phoenix Plus 2, OE-Level TOPDON Scanner, Advanced Online ECU Coding & Configuration Flashing, Bidirectional Scan Tool with Topology Map, CANFD, 42+ Services, FCA AutoAuth, 2 Years Free Update | D45: topdon | E45: Tablet | F45: 1017.3352 | G45: 231952.42 | H45: 228 | I45: 502 | J45: 4.5 | K45: https://amazon.com/dp/B091BQNR3S | L45: =IF(K45="","",HYPERLINK(K45,K45))
A46: 2 | B46: B0DTTTJWYH | C46: Launch X431 PRO3 V+ Elite, 2026 SmartlinkC 2.0 Bidirectional Scan Tool with J2534 Portocol, HD Trucks Scanner, 10.1 inch, Topology Map, 60+Service, Online Code, CANFD/DoIP/D-PDU, FCA, 2 Yrs Update | D46: launch | E46: Tablet | F46: 1352.3306 | G46: 167689 | H46: 124 | I46: 96 | J46: 4.6 | K46: https://amazon.com/dp/B0DTTTJWYH | L46: =IF(K46="","",HYPERLINK(K46,K46))
A47: 3 | B47: B0D7VS8SHS | C47: LAUNCH X431 PRO3S+ Elite, 2026 All-in-One Bidirectional Scan Tool with J2534 Protocols, HD Trucks Scanner, Topology Map, 60+Service, ECU Code Full Function Scanner, CANFD/DoIP/D-PDU/FCA, 2 Yrs Update | D47: launch | E47: Tablet | F47: 1237.3999 | G47: 165811.58 | H47: 134 | I47: 157 | J47: 4.3 | K47: https://amazon.com/dp/B0D7VS8SHS | L47: =IF(K47="","",HYPERLINK(K47,K47))
A48: 4 | B48: B08V59JNYP | C48: LAUNCH X431 PRO3S+ Smartlink HD Heavy Duty Truck Scanner,2026 Diesel&Gasoline Bidirectional Diagnostic Scan Tool with J2534 Protocols,Topology Map,60+Service,ECU Code,CANFD &DOIP,2 Yrs Free Update | D48: launch | E48: Tablet | F48: 1714.2888 | G48: 140571.68 | H48: 82 | I48: 183 | J48: 4.3 | K48: https://amazon.com/dp/B08V59JNYP | L48: =IF(K48="","",HYPERLINK(K48,K48))
A49: 5 | B49: B0DZC1M7MZ | C49: Autel MaxiSys Ultra S2 Scanner, 2026 Top Intelligen Scan Diagnostic with AI, 6-in-1 VCMI2, Up of MSUltra MS919, Topology 3.0, Multi-Point DVI, Motor Truspeed Repair, EV Test, 48+ Service, ECU Program | D49: autel | E49: Tablet | F49: 5788.9904 | G49: 133146.78 | H49: 23 | I49: 22 | J49: 4.8 | K49: https://amazon.com/dp/B0DZC1M7MZ | L49: =IF(K49="","",HYPERLINK(K49,K49))
A50: 6 | B50: B0BMZW65LJ | C50: ANCEL MT700 Motorcycle OBD2 Scanner Full Systems, ABS Engine Meter TPMS Diagnostic Tool with 35+ Reset Functions for Harley Indian Yamaha Polaris Piaggio Ducati Honda BMW, AutoVIN, 7”Touch Screen,16G | D50: ancel | E50: Tablet | F50: 936.38185 | G50: 111429.44 | H50: 119 | I50: 883 | J50: 4.5 | K50: https://amazon.com/dp/B0BMZW65LJ | L50: =IF(K50="","",HYPERLINK(K50,K50))
A51: 7 | B51: B0GLFSPMZ4 | C51: ANCEL X7HD PRO 10.1'' Heavy Duty Truck Scanner, Full-System Diesel Diagnostic Tool with DPF Regen, 42+ Reset, Bi-Directional and Active Test, ECU Coding, HDOBD/OBD2 Scanner for Diesel Trucks - Grey | D51: ancel | E51: Tablet | F51: 940.765 | G51: 88431.91 | H51: 94 | K51: https://amazon.com/dp/B0GLFSPMZ4 | L51: =IF(K51="","",HYPERLINK(K51,K51))
A52: 8 | B52: B0751G1W5C | C52: Autel MaxiPRO MP900-BT KIT Scanner: 2026 Same as MS906 Pro MS906 MAX MK908 w/OE C0ding, 3000+ Test, 40+ Service, 150+ Makes, Up of MP900-BT MP900BT w/ 200 Bucks 11 PCS OBD Cables, CAN FD & FCA SGW | D52: autel | E52: Tablet | F52: 965.19723 | G52: 62737.82 | H52: 65 | I52: 149 | J52: 4.6 | K52: https://amazon.com/dp/B0751G1W5C | L52: =IF(K52="","",HYPERLINK(K52,K52))
A53: 9 | B53: B0DBLQXQ6W | C53: XTOOL IP919 PRO V2.0 ECU Programming Scan Tool, Topology Mapping OBD2 Scanner, 4000+ Bidirectional Test, 51+ Reset, Upgrade of D9S PRO, Automotive ADAS Scanner for Car, FCA/CAN FD/DoIP | D53: xtool | E53: Tablet | F53: 1483.7785 | G53: 60834.92 | H53: 41 | I53: 76 | J53: 4.4 | K53: https://amazon.com/dp/B0DBLQXQ6W | L53: =IF(K53="","",HYPERLINK(K53,K53))
A54: 10 | B54: B0B1HT1J23 | C54: Launch X431 PAD VII Elite, 2026 Top Intelligent Diagnostic Scanner, J2534 Protocol, Topology Map, Remote Diagnosis with Smartlink C, 2-Year Free Update, Bi-Directional Scan,60+ Service | D54: launch | E54: Tablet | F54: 2697.3575 | G54: 53947.15 | H54: 20 | I54: 136 | J54: 4.1 | K54: https://amazon.com/dp/B0B1HT1J23 | L54: =IF(K54="","",HYPERLINK(K54,K54))
A56: Rank By Monthly Units - May '26 ONLY
A57: Ranking | B57: ASIN | C57: Product Name | D57: Brand | E57: Type | F57: Price | G57: Est. Monthly Retail Rev | H57: Est. Monthly Units Sold | I57: # of Reviews | J57: Avg. Rating | K57: Column2 | L57: Link
A58: 1 | B58: B091BQNR3S | C58: TOPDON Phoenix Plus 2, OE-Level TOPDON Scanner, Advanced Online ECU Coding & Configuration Flashing, Bidirectional Scan Tool with Topology Map, CANFD, 42+ Services, FCA AutoAuth, 2 Years Free Update | D58: topdon | E58: Tablet | F58: 1017.3352 | G58: 231952.42 | H58: 228 | I58: 502 | J58: 4.5 | K58: https://amazon.com/dp/B091BQNR3S | L58: =IF(K58="","",HYPERLINK(K58,K58))
A59: 2 | B59: B0D7VS8SHS | C59: LAUNCH X431 PRO3S+ Elite, 2026 All-in-One Bidirectional Scan Tool with J2534 Protocols, HD Trucks Scanner, Topology Map, 60+Service, ECU Code Full Function Scanner, CANFD/DoIP/D-PDU/FCA, 2 Yrs Update | D59: launch | E59: Tablet | F59: 1237.3999 | G59: 165811.58 | H59: 134 | I59: 157 | J59: 4.3 | K59: https://amazon.com/dp/B0D7VS8SHS | L59: =IF(K59="","",HYPERLINK(K59,K59))
A60: 3 | B60: B0DTTTJWYH | C60: Launch X431 PRO3 V+ Elite, 2026 SmartlinkC 2.0 Bidirectional Scan Tool with J2534 Portocol, HD Trucks Scanner, 10.1 inch, Topology Map, 60+Service, Online Code, CANFD/DoIP/D-PDU, FCA, 2 Yrs Update | D60: launch | E60: Tablet | F60: 1352.3306 | G60: 167689 | H60: 124 | I60: 96 | J60: 4.6 | K60: https://amazon.com/dp/B0DTTTJWYH | L60: =IF(K60="","",HYPERLINK(K60,K60))
A61: 4 | B61: B0BMZW65LJ | C61: ANCEL MT700 Motorcycle OBD2 Scanner Full Systems, ABS Engine Meter TPMS Diagnostic Tool with 35+ Reset Functions for Harley Indian Yamaha Polaris Piaggio Ducati Honda BMW, AutoVIN, 7”Touch Screen,16G | D61: ancel | E61: Tablet | F61: 936.38185 | G61: 111429.44 | H61: 119 | I61: 883 | J61: 4.5 | K61: https://amazon.com/dp/B0BMZW65LJ | L61: =IF(K61="","",HYPERLINK(K61,K61))
A62: 5 | B62: B0GLFSPMZ4 | C62: ANCEL X7HD PRO 10.1'' Heavy Duty Truck Scanner, Full-System Diesel Diagnostic Tool with DPF Regen, 42+ Reset, Bi-Directional and Active Test, ECU Coding, HDOBD/OBD2 Scanner for Diesel Trucks - Grey | D62: ancel | E62: Tablet | F62: 940.765 | G62: 88431.91 | H62: 94 | K62: https://amazon.com/dp/B0GLFSPMZ4 | L62: =IF(K62="","",HYPERLINK(K62,K62))
A63: 6 | B63: B08V59JNYP | C63: LAUNCH X431 PRO3S+ Smartlink HD Heavy Duty Truck Scanner,2026 Diesel&Gasoline Bidirectional Diagnostic Scan Tool with J2534 Protocols,Topology Map,60+Service,ECU Code,CANFD &DOIP,2 Yrs Free Update | D63: launch | E63: Tablet | F63: 1714.2888 | G63: 140571.68 | H63: 82 | I63: 183 | J63: 4.3 | K63: https://amazon.com/dp/B08V59JNYP | L63: =IF(K63="","",HYPERLINK(K63,K63))
A64: 7 | B64: B0751G1W5C | C64: Autel MaxiPRO MP900-BT KIT Scanner: 2026 Same as MS906 Pro MS906 MAX MK908 w/OE C0ding, 3000+ Test, 40+ Service, 150+ Makes, Up of MP900-BT MP900BT w/ 200 Bucks 11 PCS OBD Cables, CAN FD & FCA SGW | D64: autel | E64: Tablet | F64: 965.19723 | G64: 62737.82 | H64: 65 | I64: 149 | J64: 4.6 | K64: https://amazon.com/dp/B0751G1W5C | L64: =IF(K64="","",HYPERLINK(K64,K64))
A65: 8 | B65: B08PB6DHBS | C65: 2026 Autel MaxiCOM MK900TS Scanner, MK900-TS Up of MK808S-TS MK900BT MK900 MX900, Bidirectional Scan Tool w/Top TPMS Function, All System, CAN FD & DoIP, 3000+ Active Test, 40+ Service, FCA, OS 11.0 | D65: autel | E65: Tablet | F65: 874.2331 | G65: 50705.52 | H65: 58 | I65: 93 | J65: 4.8 | K65: https://amazon.com/dp/B08PB6DHBS | L65: =IF(K65="","",HYPERLINK(K65,K65))
A66: 9 | B66: B0DFLWDPK2 | C66: TOPDON Phoenix Lite 3 OBD2 Scanner, Upgraded Scanner of Lite 2, Bidirectional Scan Tool with CAN-FD, Car Scanner Diagnostic Tool, 35+ Maintenance Resets, Topology Mapping, ECU Coding, FCA Autoauth | D66: topdon | E66: Tablet | F66: 803.15765 | G66: 40961.04 | H66: 51 | I66: 19 | J66: 4.7 | K66: https://amazon.com/dp/B0DFLWDPK2 | L66: =IF(K66="","",HYPERLINK(K66,K66))
A67: 10 | B67: B092894STV | C67: Launch X431 PRO3S+ V5.0,2026 Upgrade All-in-One Bidirectional Scan Tool,HD Trucks Scan,Topology Map,ECU Code,55+ Service,Full System,CANFD&DOIP,DBSCar VII VCI 2-Year Update | D67: launch | E67: Tablet | F67: 1169.0831 | G67: 49101.49 | H67: 42 | I67: 682 | J67: 4.2 | K67: https://amazon.com/dp/B092894STV | L67: =IF(K67="","",HYPERLINK(K67,K67))

Sheet Tablet $400-$800
A1: Tablet $400-$800 Monthly Summary
A3: ='Tablet Total'!A81
B4: Avg Price | C4: Avg Price MoM | D4: Avg Price YoY | E4: Quantity/Mo | F4: Qty by % | G4: Qty MoM | H4: Qty YoY | I4: Revenue/Mo | J4: Revenue by % | L4: Revenue MoM | M4: Revenue YoY
A5: ='Tablet Total'!A83 | B5: ='Tablet Total'!B83 | C5: ='Tablet Total'!C83 | D5: ='Tablet Total'!D83 | E5: ='Tablet Total'!E83 | F5: ='Tablet Total'!F83 | G5: ='Tablet Total'!G83 | H5: ='Tablet Total'!H83 | ... M5: ='Tablet Total'!M83
A6: ='Tablet Total'!A84 | B6: ='Tablet Total'!B84 | C6: ='Tablet Total'!C84 | D6: ='Tablet Total'!D84 | E6: ='Tablet Total'!E84 | F6: ='Tablet Total'!F84 | G6: ='Tablet Total'!G84 | H6: ='Tablet Total'!H84 | ... M6: ='Tablet Total'!M84
A7: ='Tablet Total'!A85 | B7: ='Tablet Total'!B85 | C7: ='Tablet Total'!C85 | D7: ='Tablet Total'!D85 | E7: ='Tablet Total'!E85 | F7: ='Tablet Total'!F85 | G7: ='Tablet Total'!G85 | H7: ='Tablet Total'!H85 | ... M7: ='Tablet Total'!M85
A8: ='Tablet Total'!A86 | B8: ='Tablet Total'!B86 | C8: ='Tablet Total'!C86 | D8: ='Tablet Total'!D86 | E8: ='Tablet Total'!E86 | F8: ='Tablet Total'!F86 | G8: ='Tablet Total'!G86 | H8: ='Tablet Total'!H86 | ... M8: ='Tablet Total'!M86
A9: ='Tablet Total'!A87 | B9: ='Tablet Total'!B87 | C9: ='Tablet Total'!C87 | D9: ='Tablet Total'!D87 | E9: ='Tablet Total'!E87 | F9: ='Tablet Total'!F87 | G9: ='Tablet Total'!G87 | H9: ='Tablet Total'!H87 | ... M9: ='Tablet Total'!M87
A10: ='Tablet Total'!A88 | B10: ='Tablet Total'!B88 | C10: ='Tablet Total'!C88 | D10: ='Tablet Total'!D88 | E10: ='Tablet Total'!E88 | F10: ='Tablet Total'!F88 | G10: ='Tablet Total'!G88 | H10: ='Tablet Total'!H88 | ... M10: ='Tablet Total'!M88
A11: ='Tablet Total'!A89 | B11: ='Tablet Total'!B89 | C11: ='Tablet Total'!C89 | D11: ='Tablet Total'!D89 | E11: ='Tablet Total'!E89 | F11: ='Tablet Total'!F89 | G11: ='Tablet Total'!G89 | H11: ='Tablet Total'!H89 | ... M11: ='Tablet Total'!M89
A43: Rank By Monthly Revenue - May '26 ONLY
A44: Ranking | B44: ASIN | C44: Product Name | D44: Brand | E44: Type | F44: Price | G44: Est. Monthly Retail Rev | H44: Est. Monthly Units Sold | I44: # of Reviews | J44: Avg. Rating | K44: Column2 | L44: Link
A45: 1 | B45: B098PYB8XG | C45: Autel Scanner MaxiCOM MK900BT, 2026 MK900-BT V2.0 Bidirectional Diagnostic Tool, 8in Up of MK900 MX900 MK808S MK808BT MX808S MK808Z, 3000+ Active Tests, 40+ Service, CAN-FD&DOIP, All System, FCA 11 OS | D45: autel | E45: Tablet | F45: 658.58882 | G45: 503161.86 | H45: 764 | I45: 723 | J45: 4.6 | K45: https://amazon.com/dp/B098PYB8XG | L45: =IF(K45="","",HYPERLINK(K45,K45))
A46: 2 | B46: B0DTK24XKB | C46: MUCAR 892BT AI-Assisted Bidirectional Scan Tool, Full System OBD2 Scanner, Bi-Directional OBD2 Scanner Diagnostic Tool,ECU Coding, 35 Services, FCA Autoauth, CANFD and DOIP, Free Lifetime Upgrade | D46: mucar | E46: Tablet | F46: 639.61776 | G46: 345393.59 | H46: 540 | I46: 421 | J46: 4.3 | K46: https://amazon.com/dp/B0DTK24XKB | L46: =IF(K46="","",HYPERLINK(K46,K46))
A47: 3 | B47: B0BZ82WQ4Q | C47: ANCEL X7HD 10.1'' Heavy Duty Truck Scanner, Semi Trucks Full System Diagnostic Tool, Bidirectional Diesel Scan Tool with DPF, ECU Coding, 40+ Reset for Cummins, Detroit, Caterpillar, Volvo, Paccar etc | D47: ancel | E47: Tablet | F47: 765.33645 | G47: 267102.42 | H47: 349 | I47: 796 | J47: 3.7 | K47: https://amazon.com/dp/B0BZ82WQ4Q | L47: =IF(K47="","",HYPERLINK(K47,K47))
A48: 4 | B48: B0DCFRF2TF | C48: THINKCAR Bidirectional Scan Tool, THINKSCAN 689BT All System Automotive Diagnostic Tool, Bi Directional OBD2 Scanner with ECU Coding, 34 Services, FCA Autoauth, CANFD and DoIP, Wireless Update | D48: thinkcar | E48: Tablet | F48: 555.84548 | G48: 239569.4 | H48: 431 | I48: 603 | J48: 4.4 | K48: https://amazon.com/dp/B0DCFRF2TF | L48: =IF(K48="","",HYPERLINK(K48,K48))
A49: 5 | B49: B08ML7T7KZ | C49: Autel Scanner MaxiCheck MX808S, 2026 US Ver. of MaxiCOM MK808S MK808Z, Bidirectional 3000+ Active Test 11OS as MK900 MK900BT MX900, 28+ Service, OE All Systems OBD2 Diagnostic Tool, FCA, 10X Faster | D49: autel | E49: Tablet | F49: 427.35611 | G49: 230772.3 | H49: 540 | I49: 722 | J49: 4.7 | K49: https://amazon.com/dp/B08ML7T7KZ | L49: =IF(K49="","",HYPERLINK(K49,K49))
A50: 6 | B50: B0GDY7WJB7 | C50: Autel MaxiCOM MK900 Bidirectional Scanner: 2026 Up of MaxiCheck MX808S MK808S, Work as MK900-BT MK900BT MX900 OBD2 Diagnostic Tool w/ 3000+ Active Test, 40+ Service, CAN-FD&DOIP, All System, FCA 11 OS | D50: autel | E50: Tablet | F50: 589.08904 | G50: 196755.74 | H50: 334 | I50: 34 | J50: 4.9 | K50: https://amazon.com/dp/B0GDY7WJB7 | L50: =IF(K50="","",HYPERLINK(K50,K50))
A51: 7 | B51: B09712X5CW | C51: Autel Scanner MaxiCOM MK900BT, 2026 MK900-BT Bidirectional Diagnostic Scan Tool, 2.0 BT Ver. of MK900 MX900, 8in Up of MK808S MK808BT PRO MX808S MK808Z, 40+ Reset, 3K+ Active Tests, CAN FD & DoIP, FCA | D51: autel | E51: Tablet | F51: 659.53915 | G51: 186649.58 | H51: 283 | I51: 224 | J51: 4.5 | K51: https://amazon.com/dp/B09712X5CW | L51: =IF(K51="","",HYPERLINK(K51,K51))
A52: 8 | B52: B0BNKHCXVC | C52: TOPDON ArtiDiag Pro OBD2 Scanner Diagnostic Tool, Bidirectional Scan Tool with ECU Coding, 35+ Services, V.A.G Guided, FCA SGW, Can FD DoIP/All System Diagnosis | D52: topdon | E52: Tablet | F52: 456.01918 | G52: 183775.73 | H52: 403 | I52: 780 | J52: 4.3 | K52: https://amazon.com/dp/B0BNKHCXVC | L52: =IF(K52="","",HYPERLINK(K52,K52))
A53: 9 | B53: B0DCFF7VGF | C53: THINKCAR THINKSCAN 689 OBD2 Scanner, Bidirectional Scan Tool with 34+ Reset, 3000+ Active Test, ECU Coding, PMI, Wired Full System Diagnostic Scanner for Cars, CANFD/DOIP, FCA SGW AutoAuth | D53: thinkcar | E53: Tablet | F53: 458.18879 | G53: 181442.76 | H53: 396 | I53: 301 | J53: 4.4 | K53: https://amazon.com/dp/B0DCFF7VGF | L53: =IF(K53="","",HYPERLINK(K53,K53))
A54: 10 | B54: B073CQMF25 | C54: Autel Scanner MaxiCOM MK900: 2026 Updated as MK900BT MK900-BT MX900 Bidirectional Diagnostic Tool, 8in Up of MK808S MK808BT Pro MX808S 808Z, 3K+ Active Tests, 40+ Service, CAN-FD&DOIP, All System, FCA | D54: autel | E54: Tablet | F54: 570.78419 | G54: 168952.12 | H54: 296 | I54: 598 | J54: 4.4 | K54: https://amazon.com/dp/B073CQMF25 | L54: =IF(K54="","",HYPERLINK(K54,K54))
A56: Rank By Monthly Units - May '26 ONLY
A57: Ranking | B57: ASIN | C57: Product Name | D57: Brand | E57: Type | F57: Price | G57: Est. Monthly Retail Rev | H57: Est. Monthly Units Sold | I57: # of Reviews | J57: Avg. Rating | K57: Column2 | L57: Link
A58: 1 | B58: B098PYB8XG | C58: Autel Scanner MaxiCOM MK900BT, 2026 MK900-BT V2.0 Bidirectional Diagnostic Tool, 8in Up of MK900 MX900 MK808S MK808BT MX808S MK808Z, 3000+ Active Tests, 40+ Service, CAN-FD&DOIP, All System, FCA 11 OS | D58: autel | E58: Tablet | F58: 658.58882 | G58: 503161.86 | H58: 764 | I58: 723 | J58: 4.6 | K58: https://amazon.com/dp/B098PYB8XG | L58: =IF(K58="","",HYPERLINK(K58,K58))
A59: 2 | B59: B0DTK24XKB | C59: MUCAR 892BT AI-Assisted Bidirectional Scan Tool, Full System OBD2 Scanner, Bi-Directional OBD2 Scanner Diagnostic Tool,ECU Coding, 35 Services, FCA Autoauth, CANFD and DOIP, Free Lifetime Upgrade | D59: mucar | E59: Tablet | F59: 639.61776 | G59: 345393.59 | H59: 540 | I59: 421 | J59: 4.3 | K59: https://amazon.com/dp/B0DTK24XKB | L59: =IF(K59="","",HYPERLINK(K59,K59))
A60: 3 | B60: B08ML7T7KZ | C60: Autel Scanner MaxiCheck MX808S, 2026 US Ver. of MaxiCOM MK808S MK808Z, Bidirectional 3000+ Active Test 11OS as MK900 MK900BT MX900, 28+ Service, OE All Systems OBD2 Diagnostic Tool, FCA, 10X Faster | D60: autel | E60: Tablet | F60: 427.35611 | G60: 230772.3 | H60: 540 | I60: 722 | J60: 4.7 | K60: https://amazon.com/dp/B08ML7T7KZ | L60: =IF(K60="","",HYPERLINK(K60,K60))
A61: 4 | B61: B0DCFRF2TF | C61: THINKCAR Bidirectional Scan Tool, THINKSCAN 689BT All System Automotive Diagnostic Tool, Bi Directional OBD2 Scanner with ECU Coding, 34 Services, FCA Autoauth, CANFD and DoIP, Wireless Update | D61: thinkcar | E61: Tablet | F61: 555.84548 | G61: 239569.4 | H61: 431 | I61: 603 | J61: 4.4 | K61: https://amazon.com/dp/B0DCFRF2TF | L61: =IF(K61="","",HYPERLINK(K61,K61))
A62: 5 | B62: B098LF38DS | C62: XTOOL D7 Bidirectional Scan Tool: 2026 Ai-Assisted OBD2 Scanner Diagnostic Tool with 36+ Resets, Full System Car Scanner with EPB, Injector Test, Throttle, Crank Sensor Relearn, FCA, CANFD & DoIP | D62: xtool | E62: Tablet | F62: 401.21926 | G62: 168512.09 | H62: 420 | I62: 1661 | J62: 4.4 | K62: https://amazon.com/dp/B098LF38DS | L62: =IF(K62="","",HYPERLINK(K62,K62))
A63: 6 | B63: B0BNKHCXVC | C63: TOPDON ArtiDiag Pro OBD2 Scanner Diagnostic Tool, Bidirectional Scan Tool with ECU Coding, 35+ Services, V.A.G Guided, FCA SGW, Can FD DoIP/All System Diagnosis | D63: topdon | E63: Tablet | F63: 456.01918 | G63: 183775.73 | H63: 403 | I63: 780 | J63: 4.3 | K63: https://amazon.com/dp/B0BNKHCXVC | L63: =IF(K63="","",HYPERLINK(K63,K63))
A64: 7 | B64: B0DCFF7VGF | C64: THINKCAR THINKSCAN 689 OBD2 Scanner, Bidirectional Scan Tool with 34+ Reset, 3000+ Active Test, ECU Coding, PMI, Wired Full System Diagnostic Scanner for Cars, CANFD/DOIP, FCA SGW AutoAuth | D64: thinkcar | E64: Tablet | F64: 458.18879 | G64: 181442.76 | H64: 396 | I64: 301 | J64: 4.4 | K64: https://amazon.com/dp/B0DCFF7VGF | L64: =IF(K64="","",HYPERLINK(K64,K64))
A65: 8 | B65: B0BZ82WQ4Q | C65: ANCEL X7HD 10.1'' Heavy Duty Truck Scanner, Semi Trucks Full System Diagnostic Tool, Bidirectional Diesel Scan Tool with DPF, ECU Coding, 40+ Reset for Cummins, Detroit, Caterpillar, Volvo, Paccar etc | D65: ancel | E65: Tablet | F65: 765.33645 | G65: 267102.42 | H65: 349 | I65: 796 | J65: 3.7 | K65: https://amazon.com/dp/B0BZ82WQ4Q | L65: =IF(K65="","",HYPERLINK(K65,K65))
A66: 9 | B66: B0FN4JHLY7 | C66: ANCEL DS500BT Bidirectional Scan Tool, Full-System Automotive Diagnostic Scanner with 28+ Services, Injector Coding, DPF/Brake/BMS/Oil/Gear/Throttle Functions, CAN FD Support, Lifetime Free Updates | D66: ancel | E66: Tablet | F66: 493.77205 | G66: 168376.27 | H66: 341 | I66: 1080 | J66: 4.6 | K66: https://amazon.com/dp/B0FN4JHLY7 | L66: =IF(K66="","",HYPERLINK(K66,K66))
A67: 10 | B67: B0GDY7WJB7 | C67: Autel MaxiCOM MK900 Bidirectional Scanner: 2026 Up of MaxiCheck MX808S MK808S, Work as MK900-BT MK900BT MX900 OBD2 Diagnostic Tool w/ 3000+ Active Test, 40+ Service, CAN-FD&DOIP, All System, FCA 11 OS | D67: autel | E67: Tablet | F67: 589.08904 | G67: 196755.74 | H67: 334 | I67: 34 | J67: 4.9 | K67: https://amazon.com/dp/B0GDY7WJB7 | L67: =IF(K67="","",HYPERLINK(K67,K67))

Sheet Tablet $400-
A1: Tablet $400- Monthly Summary
A3: ='Tablet Total'!A91
B4: Avg Price | C4: Avg Price MoM | D4: Avg Price YoY | E4: Quantity/Mo | F4: Qty by % | G4: Qty MoM | H4: Qty YoY | I4: Revenue/Mo | J4: Revenue by % | L4: Revenue MoM | M4: Revenue YoY
A5: ='Tablet Total'!A93 | B5: ='Tablet Total'!B93 | C5: ='Tablet Total'!C93 | D5: ='Tablet Total'!D93 | E5: ='Tablet Total'!E93 | F5: ='Tablet Total'!F93 | G5: ='Tablet Total'!G93 | H5: ='Tablet Total'!H93 | ... M5: ='Tablet Total'!M93
A6: ='Tablet Total'!A94 | B6: ='Tablet Total'!B94 | C6: ='Tablet Total'!C94 | D6: ='Tablet Total'!D94 | E6: ='Tablet Total'!E94 | F6: ='Tablet Total'!F94 | G6: ='Tablet Total'!G94 | H6: ='Tablet Total'!H94 | ... M6: ='Tablet Total'!M94
A7: ='Tablet Total'!A95 | B7: ='Tablet Total'!B95 | C7: ='Tablet Total'!C95 | D7: ='Tablet Total'!D95 | E7: ='Tablet Total'!E95 | F7: ='Tablet Total'!F95 | G7: ='Tablet Total'!G95 | H7: ='Tablet Total'!H95 | ... M7: ='Tablet Total'!M95
A8: ='Tablet Total'!A96 | B8: ='Tablet Total'!B96 | C8: ='Tablet Total'!C96 | D8: ='Tablet Total'!D96 | E8: ='Tablet Total'!E96 | F8: ='Tablet Total'!F96 | G8: ='Tablet Total'!G96 | H8: ='Tablet Total'!H96 | ... M8: ='Tablet Total'!M96
A9: ='Tablet Total'!A97 | B9: ='Tablet Total'!B97 | C9: ='Tablet Total'!C97 | D9: ='Tablet Total'!D97 | E9: ='Tablet Total'!E97 | F9: ='Tablet Total'!F97 | G9: ='Tablet Total'!G97 | H9: ='Tablet Total'!H97 | ... M9: ='Tablet Total'!M97
A10: ='Tablet Total'!A98 | B10: ='Tablet Total'!B98 | C10: ='Tablet Total'!C98 | D10: ='Tablet Total'!D98 | E10: ='Tablet Total'!E98 | F10: ='Tablet Total'!F98 | G10: ='Tablet Total'!G98 | H10: ='Tablet Total'!H98 | ... M10: ='Tablet Total'!M98
A11: ='Tablet Total'!A99 | B11: ='Tablet Total'!B99 | C11: ='Tablet Total'!C99 | D11: ='Tablet Total'!D99 | E11: ='Tablet Total'!E99 | F11: ='Tablet Total'!F99 | G11: ='Tablet Total'!G99 | H11: ='Tablet Total'!H99 | ... M11: ='Tablet Total'!M99
A12: ='Tablet Total'!A100 | B12: ='Tablet Total'!B100 | C12: ='Tablet Total'!C100 | D12: ='Tablet Total'!D100 | E12: ='Tablet Total'!E100 | F12: ='Tablet Total'!F100 | G12: ='Tablet Total'!G100 | H12: ='Tablet Total'!H100 | ... M12: ='Tablet Total'!M100
A13: ='Tablet Total'!A101 | B13: ='Tablet Total'!B101 | C13: ='Tablet Total'!C101 | D13: ='Tablet Total'!D101 | E13: ='Tablet Total'!E101 | F13: ='Tablet Total'!F101 | G13: ='Tablet Total'!G101 | H13: ='Tablet Total'!H101 | ... M13: ='Tablet Total'!M101
A45: Rank By Monthly Revenue - May '26 ONLY
A46: Ranking | B46: ASIN | C46: Product Name | D46: Brand | E46: Type | F46: Price | G46: Est. Monthly Retail Rev | H46: Est. Monthly Units Sold | I46: # of Reviews | J46: Avg. Rating | K46: Column2 | L46: Link
A47: 1 | B47: B0C33Y285Y | C47: TOPDON Bidirectional Scan Tool, 2026 New ArtiDiag900 Lite Automotive Diagnostic Tool for Full System, Scanner for Car with Active Test, 8 Reset, Wireless OBD2 Scanner Diagnostic Tool for All Vehicles | D47: topdon | E47: Tablet | F47: 315.0536 | G47: 384680.45 | H47: 1221 | I47: 1273 | J47: 4.2 | K47: https://amazon.com/dp/B0C33Y285Y | L47: =IF(K47="","",HYPERLINK(K47,K47))
A48: 2 | B48: B0DV2N2FND | C48: BLCKTEC 460T OBD2 Scanner Car Code Reader Engine ABS SRS Transmission Diagnostic Tool, 12 Reset Services, Oil/TPMS/EPB/BMS/SAS/DPF/Throttle Reset, ABS Bleeding, Battery Test, Auto VIN, Free Update | D48: blcktec | E48: Tablet | F48: 196.13548 | G48: 356182.04 | H48: 1816 | I48: 656 | J48: 4.4 | K48: https://amazon.com/dp/B0DV2N2FND | L48: =IF(K48="","",HYPERLINK(K48,K48))
A49: 3 | B49: B08PFJMTY3 | C49: FOXWELL Car Scanner NT604 Elite OBD2 Scanner ABS SRS Transmission, Check Engine Code Reader for Cars and Trucks, Diagnostic Scan Tool with SRS Airbag, Automotive Diagnostic Tool with Live Data | D49: foxwell | E49: Tablet | F49: 153.79738 | G49: 353118.78 | H49: 2296 | I49: 4914 | J49: 4.4 | K49: https://amazon.com/dp/B08PFJMTY3 | L49: =IF(K49="","",HYPERLINK(K49,K49))
A50: 4 | B50: B09KZTYD18 | C50: OBD2 Scanner TOPDON AD600S Scan Tool, Code Reader, Diagnostics Scanner for ABS/SRS/AT/Engine, 9 Reset Services, Oil/Brake/BMS/SAS/DPF/TPMS/ETS Reset/ABS Bleeding/Injector Coding, Free Lifetime Upgrade | D50: topdon | E50: Tablet | F50: 201.80111 | G50: 222990.23 | H50: 1105 | I50: 1864 | J50: 4.4 | K50: https://amazon.com/dp/B09KZTYD18 | L50: =IF(K50="","",HYPERLINK(K50,K50))
A51: 5 | B51: B08TR5PS5V | C51: TOPDON AD800BT 2 OBD2 Scanner, 2026 Bidirectional Scan Tool, Function as AD900 Lite AD Pro, All System Automotive Diagnostic Scanner, Active Test, 28+ Reset Service, FCA Autoauth, 2 Years Free Update | D51: topdon | E51: Tablet | F51: 379.01247 | G51: 206940.81 | H51: 546 | I51: 842 | J51: 4.4 | K51: https://amazon.com/dp/B08TR5PS5V | L51: =IF(K51="","",HYPERLINK(K51,K51))
A52: 6 | B52: B08TBRDH7W | C52: TOPDON Scanner AD800BT V2.0, Bidirectional Scan Tool, Full Systems Diagnostic Tool for All Vehicles, Automotive Diagnostic Scanner for Car, 28+ Services, FCA AutoAuth, CANFD, 2 Years Free Update | D52: topdon | E52: Tablet | F52: 320.66287 | G52: 151994.2 | H52: 474 | I52: 692 | J52: 4.4 | K52: https://amazon.com/dp/B08TBRDH7W | L52: =IF(K52="","",HYPERLINK(K52,K52))
A53: 7 | B53: B08XK3DJ42 | C53: TOPDON AD500 OBD2 Scanner, Oil SAS Throttle TPMS BMS EPB Reset, Engine ABS SRS Transmission, Diagnostic Scan Tool, AutoVIN, Car Check Engine Code Reader with Battery Test, Lifetime Wi-Fi Free Update | D53: topdon | E53: Tablet | F53: 159.11793 | G53: 150366.44 | H53: 945 | I53: 1766 | J53: 4.4 | K53: https://amazon.com/dp/B08XK3DJ42 | L53: =IF(K53="","",HYPERLINK(K53,K53))
A54: 8 | B54: B07RLF8FBC | C54: Launch OBD2 Scanner CRP123X V3.0 Elite, 2026 Lifetime Free WiFi Update Scan Tool, FCA SGW, CANFD&DoIP, SAS/Throttle/Brake/BMS/D-P-F/Oil/ABS Service Multi Systems Car Scanner, Battery Test, Auto VIN | D54: launch | E54: Tablet | F54: 209.1466 | G54: 122978.2 | H54: 588 | I54: 3489 | J54: 4.4 | K54: https://amazon.com/dp/B07RLF8FBC | L54: =IF(K54="","",HYPERLINK(K54,K54))
A55: 9 | B55: B0FGC7K873 | C55: OBD2 Scanner, MUCAR 632 Elite AI-Assisted Bidirectional Scan Tool, 15 Reset Services Oil/TPMS/EPB/BMS/SAS/Brake/Throttle Car Scanner Diagnostic Tool, AutoAuth FCA, CANFD, AutoVIN, Lifetime Free Update | D55: mucar | E55: Tablet | F55: 232.63806 | G55: 122367.62 | H55: 526 | I55: 264 | J55: 4 | K55: https://amazon.com/dp/B0FGC7K873 | L55: =IF(K55="","",HYPERLINK(K55,K55))
A56: 10 | B56: B08DCNDFVK | C56: FOXWELL NT614 Elite OBD2 Scanner for DIY Mechanics, Upgrade of NT604, 4 System Diagnostic Tool with 5 Resets (ABS Bleeding, EPB, Oil, SAS, Throttle), Read/Clear Engine/ABS/SRS/Transmission Fault Codes | D56: foxwell | E56: Tablet | F56: 177.04205 | G56: 117201.84 | H56: 662 | I56: 745 | J56: 4.3 | K56: https://amazon.com/dp/B08DCNDFVK | L56: =IF(K56="","",HYPERLINK(K56,K56))
A58: Rank By Monthly Units - May '26 ONLY
A59: Ranking | B59: ASIN | C59: Product Name | D59: Brand | E59: Type | F59: Price | G59: Est. Monthly Retail Rev | H59: Est. Monthly Units Sold | I59: # of Reviews | J59: Avg. Rating | K59: Column2 | L59: Link
A60: 1 | B60: B08PFJMTY3 | C60: FOXWELL Car Scanner NT604 Elite OBD2 Scanner ABS SRS Transmission, Check Engine Code Reader for Cars and Trucks, Diagnostic Scan Tool with SRS Airbag, Automotive Diagnostic Tool with Live Data | D60: foxwell | E60: Tablet | F60: 153.79738 | G60: 353118.78 | H60: 2296 | I60: 4914 | J60: 4.4 | K60: https://amazon.com/dp/B08PFJMTY3 | L60: =IF(K60="","",HYPERLINK(K60,K60))
A61: 2 | B61: B0DV2N2FND | C61: BLCKTEC 460T OBD2 Scanner Car Code Reader Engine ABS SRS Transmission Diagnostic Tool, 12 Reset Services, Oil/TPMS/EPB/BMS/SAS/DPF/Throttle Reset, ABS Bleeding, Battery Test, Auto VIN, Free Update | D61: blcktec | E61: Tablet | F61: 196.13548 | G61: 356182.04 | H61: 1816 | I61: 656 | J61: 4.4 | K61: https://amazon.com/dp/B0DV2N2FND | L61: =IF(K61="","",HYPERLINK(K61,K61))
A62: 3 | B62: B0C33Y285Y | C62: TOPDON Bidirectional Scan Tool, 2026 New ArtiDiag900 Lite Automotive Diagnostic Tool for Full System, Scanner for Car with Active Test, 8 Reset, Wireless OBD2 Scanner Diagnostic Tool for All Vehicles | D62: topdon | E62: Tablet | F62: 315.0536 | G62: 384680.45 | H62: 1221 | I62: 1273 | J62: 4.2 | K62: https://amazon.com/dp/B0C33Y285Y | L62: =IF(K62="","",HYPERLINK(K62,K62))
A63: 4 | B63: B09KZTYD18 | C63: OBD2 Scanner TOPDON AD600S Scan Tool, Code Reader, Diagnostics Scanner for ABS/SRS/AT/Engine, 9 Reset Services, Oil/Brake/BMS/SAS/DPF/TPMS/ETS Reset/ABS Bleeding/Injector Coding, Free Lifetime Upgrade | D63: topdon | E63: Tablet | F63: 201.80111 | G63: 222990.23 | H63: 1105 | I63: 1864 | J63: 4.4 | K63: https://amazon.com/dp/B09KZTYD18 | L63: =IF(K63="","",HYPERLINK(K63,K63))
A64: 5 | B64: B08XK3DJ42 | C64: TOPDON AD500 OBD2 Scanner, Oil SAS Throttle TPMS BMS EPB Reset, Engine ABS SRS Transmission, Diagnostic Scan Tool, AutoVIN, Car Check Engine Code Reader with Battery Test, Lifetime Wi-Fi Free Update | D64: topdon | E64: Tablet | F64: 159.11793 | G64: 150366.44 | H64: 945 | I64: 1766 | J64: 4.4 | K64: https://amazon.com/dp/B08XK3DJ42 | L64: =IF(K64="","",HYPERLINK(K64,K64))
A65: 6 | B65: B08DCNDFVK | C65: FOXWELL NT614 Elite OBD2 Scanner for DIY Mechanics, Upgrade of NT604, 4 System Diagnostic Tool with 5 Resets (ABS Bleeding, EPB, Oil, SAS, Throttle), Read/Clear Engine/ABS/SRS/Transmission Fault Codes | D65: foxwell | E65: Tablet | F65: 177.04205 | G65: 117201.84 | H65: 662 | I65: 745 | J65: 4.3 | K65: https://amazon.com/dp/B08DCNDFVK | L65: =IF(K65="","",HYPERLINK(K65,K65))
