Workbook

Sheet Summary
A1: Monthly Summaries- Revenue
A2: Brand | B2: # of Listings | C2: Monthly Rev | D2: Estimated 12mo Revenue | E2: Monthly Units | F2: Monthly Rev Market Share % | G2: Price Per Unit | H2: Reviews | I2: Avg Rating
A3: Teslong | B3: 61 | C3: 1749770.4 | D3: 20997245 | E3: 15076 | F3: 0.26213266 | G3: 116.0633 | H3: 31091 | I3: 4.469763
A4: DEPSTECH | B4: 33 | C4: 642464.19 | D4: 7709570.3 | E4: 6863 | F4: 0.096247398 | G4: 93.612733 | H4: 38523 | I4: 4.4607325
A5: DXZtoz | B5: 5 | C5: 498047.53 | D5: 5976570.4 | E5: 3505 | F5: 0.074612375 | G5: 142.0963 | H5: 2174 | I5: 4.5358326
A6: Kinpthy | B6: 6 | C6: 312629.19 | D6: 3751550.3 | E6: 8975 | F6: 0.0468349 | G6: 34.833336 | H6: 26446 | I6: 4.4
A7: anysun | B7: 97 | C7: 287877.11 | D7: 3454525.3 | E7: 500 | F7: 0.043126797 | G7: 575.75422 | H7: 6168 | I7: 4.1966764
A8: VEVOR | B8: 35 | C8: 254859.43 | D8: 3058313.2 | E8: 1561 | F8: 0.038180427 | G8: 163.26677 | H8: 4194 | I8: 4.3067
A9: Sanyipace | B9: 46 | C9: 172015.92 | D9: 2064191 | E9: 375 | F9: 0.025769661 | G9: 458.70912 | H9: 2565 | I9: 4.1500195
A10: Daxiongmao | B10: 8 | C10: 159821.55 | D10: 1917858.6 | E10: 4365 | F10: 0.023942826 | G10: 36.61433 | H10: 11375 | I10: 4.4001055
A11: Ralcam | B11: 21 | C11: 144605.07 | D11: 1735260.8 | E11: 762 | F11: 0.021663249 | G11: 189.77043 | H11: 2734 | I11: 4.4377103
A12: Acoath | B12: 6 | C12: 104632.67 | D12: 1255592 | E12: 3480 | F12: 0.015674994 | G12: 30.066859 | H12: 4073 | I12: 4.4338817
A14: Market Total | B14: 1558 | C14: 6675133.1 | D14: 80101597 | E14: 92155 | F14: 1 | G14: 72.433759 | H14: 268046 | I14: 4.3556087
A16: Monthly Summary - Units
A17: Brand | B17: # of Listings | C17: Monthly Rev | D17: Estimated 12mo Units | E17: Monthly Units | F17: Monthly Unit Market Share % | G17: Price Per Unit | H17: Reviews | I17: Avg Rating
A18: Teslong | B18: 61 | C18: 1749770.4 | D18: 180912 | E18: 15076 | F18: 0.16359394 | G18: 116.0633 | H18: 31091 | I18: 4.469763
A19: Kinpthy | B19: 6 | C19: 312629.19 | D19: 107700 | E19: 8975 | F19: 0.097390266 | G19: 34.833336 | H19: 26446 | I19: 4.4
A20: DEPSTECH | B20: 33 | C20: 642464.19 | D20: 82356 | E20: 6863 | F20: 0.074472356 | G20: 93.612733 | H20: 38523 | I20: 4.4607325
A21: Daxiongmao | B21: 8 | C21: 159821.55 | D21: 52380 | E21: 4365 | F21: 0.047365851 | G21: 36.61433 | H21: 11375 | I21: 4.4001055
A22: DXZtoz | B22: 5 | C22: 498047.53 | D22: 42060 | E22: 3505 | F22: 0.038033747 | G22: 142.0963 | H22: 2174 | I22: 4.5358326
A23: Acoath | B23: 6 | C23: 104632.67 | D23: 41760 | E23: 3480 | F23: 0.037762465 | G23: 30.066859 | H23: 4073 | I23: 4.4338817
A24: AukonVee | B24: 7 | C24: 97904.13 | D24: 38892 | E24: 3241 | F24: 0.035169009 | G24: 30.208001 | H24: 579 | I24: 4.4839378
A25: Elecshion | B25: 4 | C25: 102178.58 | D25: 36456 | E25: 3038 | F25: 0.032966198 | G25: 33.633502 | H25: 3847 | I25: 4.3434104
A26: PAPIBLU | B26: 2 | C26: 51510.91 | D26: 31932 | E26: 2661 | F26: 0.028875265 | G26: 19.357726 | H26: 274 | I26: 4.3
A27: WINWEND | B27: 5 | C27: 87761.93 | D27: 31188 | E27: 2599 | F27: 0.028202485 | G27: 33.767576 | H27: 1548 | I27: 4.4925065
A29: Market Total | B29: 1558 | C29: 6675133.1 | D29: 1105860 | E29: 92155 | F29: 1 | G29: 72.433759 | H29: 268046 | I29: 4.3556087

Sheet Top 50
A1: Rank By Monthly Revenue - ONLY
A2: Ranking | B2: ASIN | C2: Product Name | D2: Brand | E2: Type | F2: 2/4-way | G2: Display | H2: Lens diameter | I2: Lens count | J2: Cable length | K2: Price | L2: Est. Monthly Retail Rev | M2: Est. Monthly Units Sold | N2: # of Reviews | O2: Avg. Rating | P2: Column2 | Q2: Link
A3: 1 | B3: B0CJY5C9QX | C3: Teslong Two-Way Articulating Borescope with Light, Industrial Endoscope Inspection Camera with Articulated Probe, Flexible Mechanic Fiber Optic Snake Scope Cam for Wall Automotive Engine Inspect-5FT | D3: teslong | E3: Articulation | F3: 2-way | G3: 4.5" | H3: 8mm | I3: Single | J3: 5ft | K3: 129.99 | L3: 699032.88 | M3: 5378 | N3: 1078 | O3: 4.7 | P3: https://amazon.com/dp/B0CJY5C9QX | Q3: https://amazon.com/dp/B0CJY5C9QX
A4: 2 | B4: B0B28HRSBP | C4: DXZtoz Two-Way Articulating Borescope, Industrial Endoscope with 0.33in Articulated Snake Camera, Video Inspection Scope with Light for Automotive Aircraft Mechanics- 5.5FT | D4: dxztoz | E4: Articulation | F4: 2-way | G4: 4.3" | H4: 8.5mm | I4: Single | J4: 5.5ft | K4: 139.39 | L4: 300981.94 | M4: 2210 | N4: 1468 | O4: 4.6 | P4: https://amazon.com/dp/B0B28HRSBP | Q4: https://amazon.com/dp/B0B28HRSBP
A5: 3 | B5: B0C9JR3N4W | C5: Endoscope Camera with Light,1920P HD Borescope Tools with 8 Adjustable LED Lights, Endoscope with Semi-Rigid Snake Camera, IP67 Waterproof Inspection Borescope for iOS and Android-16.4ft Dual-Lens | D5: kinpthy | E5: USB | G5: App | H5: 8mm | I5: Dual | J5: 16.5ft | K5: 42.99 | L5: 180193.2 | M5: 4708 | N5: 5288 | O5: 4.4 | P5: https://amazon.com/dp/B0C9JR3N4W | Q5: https://amazon.com/dp/B0C9JR3N4W
A6: 4 | B6: B0DT4H7QQM | C6: Teslong Two-Way Articulating Borescope, 5.5mm Slim Probe, 5.0'' Industrial Endoscope with Light, 5FT Flexible Snake Scope for Automotive, HVAC & Mechanics | D6: teslong | E6: Articulation | F6: 2-way | G6: 5.0" | H6: 5.5mm | I6: Single | J6: 5ft | K6: 106.39 | L6: 128609.35 | M6: 924 | N6: 177 | O6: 4.6 | P6: https://amazon.com/dp/B0DT4H7QQM | Q6: https://amazon.com/dp/B0DT4H7QQM
A7: 5 | B7: B0C3B32Q9Z | C7: DXZtoz Dual-Lens Articulating Borescope, Engine Endoscope with 0.33in Two-Way Articulated Snake Camera, 5'' Dual Screen, 1080P Inspection Camera with Light for Automotive Home Mechanics-5FT | D7: dxztoz | E7: Articulation | F7: 2-way | G7: 5.0" | H7: 8mm | I7: Dual | J7: 5ft | K7: 159.99 | L7: 127974.16 | M7: 910 | N7: 428 | O7: 4.5 | P7: https://amazon.com/dp/B0C3B32Q9Z | Q7: https://amazon.com/dp/B0C3B32Q9Z
A8: 6 | B8: B0BS1CFFH8 | C8: Triple Lens Endoscope Camera with Light with 50FT Semi-Rigid Cable, DEPSTECH 5" IPS Screen Sewer Inspection Camera, 1080P Industrial Borescope, Split Screen, Waterproof Drain Pipe Tool, Carrying Case | D8: depstech | E8: Landscape | G8: 5.0" | H8: 8mm | I8: Triple | J8: 50ft | K8: 129.99 | L8: 125621.04 | M8: 1058 | N8: 1394 | O8: 4.3 | P8: https://amazon.com/dp/B0BS1CFFH8 | Q8: https://amazon.com/dp/B0BS1CFFH8
A9: 7 | B9: B0CJY6SWBN | C9: Articulating Borescope with Dual Lens Endoscope Camera, Teslong Two-Way Articulated Industrial Inspection Camera with LED Light, Flexible Mechanic Fiber Optic Snake Scope Cam for Wall Automotive-5FT | D9: teslong | E9: Articulation | F9: 2-way | G9: 4.5" | H9: 8mm | I9: Dual | J9: 5ft | K9: 149.99 | L9: 115523.95 | M9: 839 | N9: 318 | O9: 4.4 | P9: https://amazon.com/dp/B0CJY6SWBN | Q9: https://amazon.com/dp/B0CJY6SWBN
A10: 8 | B10: B07TV2BFVR | C10: Teslong Inspection Camera, Dual Lens Borescope Camera with Light, NTS300 5" IPS Industrial Endoscope, 1080P Waterproof Flexible Mechanic Fiber Optic Snake Scope Cam for Wall Automotive Engine (16.5FT) | D10: teslong | E10: Handheld | G10: 5.0" | H10: 5.5mm | I10: Dual | J10: 16.5ft | K10: 159.99 | L10: 104232.74 | M10: 651 | N10: 3542 | O10: 4.6 | P10: https://amazon.com/dp/B07TV2BFVR | Q10: https://amazon.com/dp/B07TV2BFVR
A11: 9 | B11: B0928Q3T42 | C11: DEPSTECH Dual Lens Industrial Endoscope, 1080P Digital Borescope Inspection Camera, 7.9mm IP67 Waterproof Sewer Camera with 4.3" LCD Screen, 7 LED Lights, 16.5FT Semi-Rigid Cable, 32GB Card-Black | D11: depstech | E11: Landscape | G11: 4.3" | H11: 8mm | I11: Dual | J11: 16.5ft | K11: 69.99 | L11: 99914.55 | M11: 1428 | N11: 6721 | O11: 4.5 | P11: https://amazon.com/dp/B0928Q3T42 | Q11: https://amazon.com/dp/B0928Q3T42
A12: 10 | B12: B0CMCSGPJC | C12: [Dual-Lens] Endoscope Camera with Light, 1920P HD Borescope with 8+1 Adjustable LED Lights, IP67 Waterproof 16.5FT Semi-Rigid Snake Cord Inspection Camera for iPhone, iPad and Android Phone (Type C) | D12: elecshion | E12: USB | G12: App | H12: 8mm | I12: Dual | J12: 16.5ft | K12: 35.99 | L12: 87777.71 | M12: 2507 | N12: 1085 | O12: 4.3 | P12: https://amazon.com/dp/B0CMCSGPJC | Q12: https://amazon.com/dp/B0CMCSGPJC
A13: 11 | B13: B0DD6YVBHD | C13: DEPSTECH 50ft Sewer Camera, 1080P HD Triple Lens Borescope, 5" IPS Screen Endoscope with Light, IP67 Waterproof Plumbing Drain Pipe Snake Inspection Camera with 32G Card, Carry Case | D13: depstech | E13: Landscape | G13: 5.0" | H13: 8mm | I13: Triple | J13: 50ft | K13: 137.79 | L13: 85121.94 | M13: 718 | N13: 253 | O13: 4.3 | P13: https://amazon.com/dp/B0DD6YVBHD | Q13: https://amazon.com/dp/B0DD6YVBHD
A14: 12 | B14: B0CHW4FLS7 | C14: Articulating Borescope with Dual Lens Endoscope, Teslong 5-inch IPS Automotive Inspection Camera with Two-Way Articulation Tip, 6+1 LED Lights, Mechanics Fiber Optic Scope-Dia. 0.25 inch & L 5.0 feet | D14: teslong | E14: Articulation | F14: 2-way | G14: 5.0" | H14: 6.5mm | I14: Dual | J14: 5ft | K14: 299.99 | L14: 75799.26 | M14: 253 | N14: 184 | O14: 4.2 | P14: https://amazon.com/dp/B0CHW4FLS7 | Q14: https://amazon.com/dp/B0CHW4FLS7
A15: 13 | B15: B0BXSMSS7M | C15: Endoscope Camera with Light, 1080P HD Borescope with 8 Adjustable Lights, 4.3" Endoscope with 16.4ft Semi-Rigid Snake Camera, IP67 Waterproof Borescopese for Sewer, Cool Gadgets & Tools for Men | D15: daxiongmao | E15: Handheld | F15: No camera | G15: 4.3" | H15: 8mm | I15: Single | J15: 16.5ft | K15: 39.99 | L15: 72545.94 | M15: 2107 | N15: 1810 | O15: 4.4 | P15: https://amazon.com/dp/B0BXSMSS7M | Q15: https://amazon.com/dp/B0BXSMSS7M
A16: 14 | B16: B0F1CXQ3YS | C16: Endoscope Borescope Camera with Light, 4.3" IPS 1920P HD Inspection Camera, 7.9mm IP67 Waterproof with 8 Adjustable LEDs, 16.5FT Semi-Rigid Snake Cable for Sewer, Automotive Engine, Pipe, HVAC | D16: aukonvee | E16: Landscape | F16: No camera | G16: 4.3" | H16: 8mm | I16: Single | J16: 16.5ft | K16: 28.49 | L16: 69483.37 | M16: 2390 | N16: 233 | O16: 4.5 | P16: https://amazon.com/dp/B0F1CXQ3YS | Q16: https://amazon.com/dp/B0F1CXQ3YS
A17: 15 | B17: B0CP538LN1 | C17: WINWEND Endoscope Camera with Light - IP67 Waterproof Borescope Camera with 8 Adjustable LED Lights | 4.3" LCD Screen Borescope | HD 1080P Inspection Cameras with 16.5ft Semi-Rigid Cord Tools for Men | D17: winwend | E17: Handheld | F17: No camera | G17: 4.3" | H17: 8mm | I17: Single | J17: 16.5ft | K17: 37.95 | L17: 64529.13 | M17: 1956 | N17: 1082 | O17: 4.5 | P17: https://amazon.com/dp/B0CP538LN1 | Q17: https://amazon.com/dp/B0CP538LN1
A18: 16 | B18: B0C4V5LWWL | C18: Endoscope Camera with Light,1920P HD Borescope Tools with 8 Adjustable LED Lights, Endoscope with Semi-Rigid Snake Camera, Inspection Borescope for iOS and Android-16.4ft Single Lens | D18: kinpthy | E18: USB | G18: App | H18: 8mm | I18: Single | J18: 16.5ft | K18: 23.99 | L18: 62751.69 | M18: 2273 | N18: 5278 | O18: 4.4 | P18: https://amazon.com/dp/B0C4V5LWWL | Q18: https://amazon.com/dp/B0C4V5LWWL
A19: 17 | B19: B0DFHL8YN5 | C19: Two-Way Articulating Borescope with Light, UJOYOK Industrial Endoscope with Snake Scope Camera, Borescope Inspection Camera with Light for Automotive & Aircraft Mechanics, 5.5FT | D19: ujoyok | E19: Articulation | F19: 2-way | G19: 4.3" | H19: 8mm | I19: Single | J19: 5.5ft | K19: 105.99 | L19: 59592.67 | M19: 627 | N19: 300 | O19: 4.6 | P19: https://amazon.com/dp/B0DFHL8YN5 | Q19: https://amazon.com/dp/B0DFHL8YN5
A20: 18 | B20: B0DT16R78W | C20: DEPSTECH Dual Lens Two-Way Articulating Borescope Camera with Light, 4.5" Screen and 5FT Flexible Snake Scope Industrial Endoscope, Inspection Video Camera Tool for Wall, Engine, Auto, Mechanics | D20: depstech | E20: Articulation | F20: 2-way | G20: 4.5" | H20: 8mm | I20: Dual | J20: 5ft | K20: 129.99 | L20: 57984.25 | M20: 510 | N20: 245 | O20: 4.6 | P20: https://amazon.com/dp/B0DT16R78W | Q20: https://amazon.com/dp/B0DT16R78W
A21: 19 | B21: B0C3R381FC | C21: Endoscope Camera with Light, Borescope Camera with 4.3" IPS Screen, 1920P HD with 8 LED Lights, 16.4FT Semi-Rigid Cord Bore Scope, Gadgets for Men & Tools for Men | D21: daxiongmao | E21: Landscape | F21: No camera | G21: 4.3" | H21: 8mm | I21: Single | J21: 16.5ft | K21: 32.98 | L21: 57070.35 | M21: 1595 | N21: 3741 | O21: 4.4 | P21: https://amazon.com/dp/B0C3R381FC | Q21: https://amazon.com/dp/B0C3R381FC
A22: 20 | B22: B0DGFBCH38 | C22: Acoath Endoscope Camera with Light, Dual-Lens 1920P HD Borescope with 8 Adjustable LED Lights, IP67 Waterproof Boroscope Inspection Tools, 16.4ft Semi-Rigid Snake Camera for iOS & Android | D22: acoath | E22: USB | G22: App | H22: 8mm | I22: Dual | J22: 16.5ft | K22: 35.99 | L22: 56990.09 | M22: 2048 | N22: 1132 | O22: 4.4 | P22: https://amazon.com/dp/B0DGFBCH38 | Q22: https://amazon.com/dp/B0DGFBCH38
A23: 21 | B23: B0F62WJY8N | C23: DEPSTECH Dual Lens Articulating Endoscope Camera with Lights, 4.5" Screen Two-Way Industrial Borescope, Flexible Snake Scope, Video Inspection Camera Tool for Wall Engine Auto Mechanics - 10FT | D23: depstech | E23: Articulation | F23: 2-way | G23: 4.5" | H23: 8mm | I23: Dual | J23: 10ft | K23: 159.99 | L23: 55154.49 | M23: 386 | N23: 252 | O23: 4.6 | P23: https://amazon.com/dp/B0F62WJY8N | Q23: https://amazon.com/dp/B0F62WJY8N
A24: 22 | B24: B0FC2HS5GZ | C24: Endoscope with Light, 1920P HD Borescope with 8 Adjustable LED Lights, 16.4FT Semi-Rigid Snake Camera, IP67 Waterproof Inspection Tool for iPhone & Android - Dual Lens | D24: papiblu | E24: USB | G24: App | H24: 8mm | I24: Dual | J24: 16.5ft | K24: 22.99 | L24: 50110.88 | M24: 2575 | N24: 137 | O24: 4.3 | P24: https://amazon.com/dp/B0FC2HS5GZ | Q24: https://amazon.com/dp/B0FC2HS5GZ
A25: 23 | B25: B0DT98YB3X | C25: Two-Way Articulating Borescope Camera with Light: Industrial Endoscope Inspection Snake Camera - Flexible Bore Scope Cam with 0.33in Articulated Probe for Mechanic Automotive Engine Wall - 5.5FT | D25: wanawong k | E25: Articulation | F25: 2-way | G25: 4.3" | H25: 8mm | I25: Single | J25: 5.5ft | K25: 79.99 | L25: 46412.67 | M25: 616 | N25: 164 | O25: 4.5 | P25: https://amazon.com/dp/B0DT98YB3X | Q25: https://amazon.com/dp/B0DT98YB3X
A26: 24 | B26: B09ZV7KJHL | C26: Two-Way Articulating Borescope with Light, Teslong 5-inch IPS Endoscope Inspection Camera with Articulation Head, Automotive Mechanics Fiber Optic Scope-0.33inch | D26: teslong | E26: Articulation | F26: 2-way | G26: 5.0" | H26: 8mm | I26: Single | J26: 5ft | K26: 279.99 | L26: 43464.52 | M26: 179 | N26: 549 | O26: 4.7 | P26: https://amazon.com/dp/B09ZV7KJHL | Q26: https://amazon.com/dp/B09ZV7KJHL
A27: 25 | B27: B0D7PYRRKD | C27: Teslong 3.9mm 4-Way Articulating Borescope with Light, 6'' IPS Endoscope Inspection Camera with 360 Articulated Probe, Flexible Automotive Mechanics Gadgets Fiber Optic Scope Cam (0.15inch-5FT) | D27: teslong | E27: Articulation | F27: 4-way | G27: 6.0" | H27: 3.9mm | I27: Single | J27: 5ft | K27: 699.99 | L27: 40745.77 | M27: 58 | N27: 21 | O27: 4.6 | P27: https://amazon.com/dp/B0D7PYRRKD | Q27: https://amazon.com/dp/B0D7PYRRKD
A28: 26 | B28: B0DK965BZP | C28: Teslong Endoscope Borescope with Light, Snake Inspection Camera for Automotive Engine, Waterproof Fiber Optic Camera for Mechanics - Ideal for Wall, Vent, Wire Video Scope (16.5FT) | D28: teslong | E28: Landscape | G28: 4.3" | H28: 8mm | I28: Single | J28: 16.5ft | K28: 37.99 | L28: 39438.44 | M28: 803 | N28: 234 | O28: 4.5 | P28: https://amazon.com/dp/B0DK965BZP | Q28: https://amazon.com/dp/B0DK965BZP
A29: 27 | B29: B0B71PT47Q | C29: DXZtoz 10FT Articulating Borescope, Inspection Camera with 0.33in Two-Way Steering Snake Camera, Waterproof 1080P Endoscope with Light for Mechanics Electriction Wall Pipe Inspection | D29: dxztoz | E29: Articulation | F29: 2-way | G29: 4.3" | H29: 8mm | I29: Single | J29: 10ft | K29: 172.89 | L29: 38511.09 | M29: 212 | N29: 180 | O29: 4.3 | P29: https://amazon.com/dp/B0B71PT47Q | Q29: https://amazon.com/dp/B0B71PT47Q
A30: 28 | B30: B08NJ8627V | C30: DEPSTECH Dual Lens Wireless Endoscope, 1080P Scope Snake Camera with 7 LED Lights,0.31In Lens Video HD Inspection Camera,IP67 Waterproof Borescope,16.5FT Cable for Android & iOS Phone or Tablet-Yellow | D30: depstech | E30: Wireless | H30: 8mm | I30: Dual | J30: 16.5ft | K30: 54.99 | L30: 36197.11 | M30: 658 | N30: 2461 | O30: 4.3 | P30: https://amazon.com/dp/B08NJ8627V | Q30: https://amazon.com/dp/B08NJ8627V
A31: 29 | B31: B0DPHJSPBY | C31: FOXWELL 2-Way Articulating Borescope Camera with Light, 0.24in Industrial Endoscope Inspection Camera with Articulated Snake Cameras, HD Video Scope for Automotive Engine HVAC Inspection - 5.25FT | D31: foxwell | E31: Articulation | F31: 2-way | G31: 4.3" | H31: 6.2mm | I31: Single | J31: 5.25ft | K31: 199.99 | L31: 36138.18 | M31: 232 | N31: 97 | O31: 4.8 | P31: https://amazon.com/dp/B0DPHJSPBY | Q31: https://amazon.com/dp/B0DPHJSPBY
A32: 30 | B32: B0DWSKVF5H | C32: Endoscope Camera with Light: 5" Dual-Lens Inspection Borescope Camera for Sewer - 16.4ft Waterproof Industrial Endoscope - Flexible Snake Bore Scope for Plumbing Automotive | D32: tgjor | E32: Handheld | F32: No camera | G32: 5.0" | H32: 8mm | I32: Dual | J32: 16.5ft | K32: 49.99 | L32: 36045.72 | M32: 899 | N32: 191 | O32: 4.6 | P32: https://amazon.com/dp/B0DWSKVF5H | Q32: https://amazon.com/dp/B0DWSKVF5H
A33: 31 | B33: B0BF64PP4F | C33: Endoscope Camera with Light,1920P HD Borescope Tools with 8 Adjustable LED Lights, Endoscope with Semi-Rigid Snake Camera, IP67 Waterproof Inspection Borescope for iOS and Android-32.8ft Single Lens | D33: kinpthy | E33: USB | G33: App | H33: 8mm | I33: Single | J33: 32.8ft | K33: 40.99 | L33: 33366.73 | M33: 915 | N33: 5287 | O33: 4.4 | P33: https://amazon.com/dp/B0BF64PP4F | Q33: https://amazon.com/dp/B0BF64PP4F
A34: 32 | B34: B0D9M3Q7FK | C34: Two-Way Articulating Borescope Camera with Light, KAIWEETS 0.33in Industrial Endoscope Camera with Light, 5FT Flexible Snake Inspection Scope for Automotive and Aircraft Mechanics | D34: kaiweets | E34: Articulation | F34: 2-way | G34: 4.3" | H34: 8mm | I34: Single | J34: 5ft | K34: 119.99 | L34: 33220.95 | M34: 343 | N34: 464 | O34: 4.4 | P34: https://amazon.com/dp/B0D9M3Q7FK | Q34: https://amazon.com/dp/B0D9M3Q7FK
A35: 33 | B35: B07Q86XGN2 | C35: Triple Lens Borescope Inspection Camera, Teslong Professional Endoscope with Light, Digital Video Scope Camera, 5" IPS Screen, Waterproof Flexible Cable for Automotive/Home/Wall/Pipe/Car (16.5FT) | D35: teslong | E35: Handheld | G35: 5.0" | H35: 8mm | I35: Triple | J35: 16.5ft | K35: 179.99 | L35: 33131.59 | M35: 200 | N35: 339 | O35: 4.5 | P35: https://amazon.com/dp/B07Q86XGN2 | Q35: https://amazon.com/dp/B07Q86XGN2
A36: 34 | B36: B0CM3FBXJT | C36: VEVOR Sewer Inspection Camera, 300 ft/91.5 m, 9" Pipeline Camera w/DVR & 512Hz Locator, IP68 Waterproof, 12 LEDs, 16 GB SD Card for Sewer, Drain & Duct Pipe Plumbing | D36: vevor | E36: Sewer camera | G36: 9.0" | H36: 23mm | I36: Single | J36: 300ft | K36: 659.99 | L36: 33096.25 | M36: 48 | N36: 22 | O36: 4.1 | P36: https://amazon.com/dp/B0CM3FBXJT | Q36: https://amazon.com/dp/B0CM3FBXJT
A37: 35 | B37: B0C1GFBTDC | C37: USB C Endoscope Camera with Light, Teslong Type-C Snake Borescope Camera with 8 LED Lights, 10FT Flexible Waterproof Inspection Cam, Fiber Optic Scope Compatible with iPhone 15/16, Android Phone | D37: teslong | E37: USB | G37: App | H37: 8mm | I37: Single | J37: 10ft | K37: 29.99 | L37: 32368.85 | M37: 1080 | N37: 911 | O37: 4.4 | P37: https://amazon.com/dp/B0C1GFBTDC | Q37: https://amazon.com/dp/B0C1GFBTDC
A38: 36 | B38: B0DTHZDGYD | C38: Teslong 360 Articulating Borescope with Light, 5'' Monitor Industrial Inspection Camera with 4-Way Joystick Articulation, HD Endoscope Camera for Automotive, Pipes, and Mechanics (0.24inch-5FT) | D38: teslong | E38: Articulation | F38: 4-way | G38: 5.0" | H38: 6mm | I38: Single | J38: 5ft | K38: 449.99 | L38: 31681.51 | M38: 71 | N38: 28 | O38: 4.7 | P38: https://amazon.com/dp/B0DTHZDGYD | Q38: https://amazon.com/dp/B0DTHZDGYD
A39: 37 | B39: B0D54NQWZH | C39: Klein Tools ET17 Utility Borescope with 5.5 mm 9.8-Foot Waterproof Gooseneck Snake, LEDs, 4.3-Inch LCD, Attachments, Endoscope Inspection Camera | D39: klein tools | E39: Landscape | G39: 4.3" | H39: 5.5mm | I39: Single | J39: 9.8ft | K39: 102.99 | L39: 31444.16 | M39: 305 | N39: 101 | O39: 4.4 | P39: https://amazon.com/dp/B0D54NQWZH | Q39: https://amazon.com/dp/B0D54NQWZH
A40: 38 | B40: B0DT45G8F3 | C40: Epicmate Triple Lens Sewer Inspection Camera-Endoscope Camera with Light 50 ft, 5" IPS Sewer Snake Camera with Lights 1080P Industrial Borescope, IP67 Waterproof Plumbing Pipe Snake Camera(32G Card) | D40: bestisan | E40: Portrait | G40: 5.0" | H40: 8mm | I40: Triple | J40: 50ft | K40: 120.89 | L40: 30628.24 | M40: 252 | N40: 94 | O40: 4.7 | P40: https://amazon.com/dp/B0DT45G8F3 | Q40: https://amazon.com/dp/B0DT45G8F3
...

Sheet Top 50 Type Summary
A1: Top 50 By Revenue Summary
A2: Type | B2: Avg Price | C2: Quantity/Mo | D2: Qty by % | E2: Revenue/Mo | F2: Revenue by %
A3: Articulation | B3: 203.65316 | C3: 14504 | D3: 0.28859661 | E3: 1976226.9 | F3: 0.54328326
A4: Handheld | B4: 94.65 | C4: 6099 | D4: 0.12135623 | E4: 335863.59 | F4: 0.092332041
A5: Landscape | B5: 81.019 | C5: 9783 | D5: 0.19465945 | E5: 591804.72 | F5: 0.16269265
A6: Portrait | B6: 120.89 | C6: 252 | D6: 0.0050142269 | E6: 30628.24 | F6: 0.0084199895
A7: Sewer camera | B7: 659.99 | C7: 48 | D7: 0.00095509083 | E7: 33096.25 | F7: 0.0090984686
A8: USB | B8: 31.261111 | C8: 18476 | D8: 0.36763038 | E8: 560123.98 | F8: 0.15398332
A9: Wireless | B9: 54.99 | C9: 658 | D9: 0.013092704 | E9: 36197.11 | F9: 0.009950924
B10: 181.98667 | C10: 437 | D10: 0.0086953061 | E10: 73621.88 | F10: 0.020239343
A11: Total | B11: 178.55499 | C11: 50257 | D11: 1 | E11: 3637562.7 | F11: 1
A29: Top 50 By Unit Summary
A30: Type | B30: Avg Price | C30: Quantity/Mo | D30: Qty by % | E30: Revenue/Mo | F30: Revenue by %
A31: Articulation | B31: 125.215 | C31: 12014 | D31: 0.20775403 | E31: 1536111.9 | F31: 0.46797832
A32: Handheld | B32: 53.1725 | C32: 7952 | D32: 0.13751124 | E32: 356616.27 | F32: 0.10864357
A33: Landscape | B33: 50.395714 | C33: 13030 | D33: 0.22532337 | E33: 642702.91 | F33: 0.19580021
A34: USB | B34: 28.917895 | C34: 24174 | D34: 0.41803279 | E34: 710814.25 | F34: 0.21655041
A35: Wireless | B35: 54.99 | C35: 658 | D35: 0.011378571 | E35: 36197.11 | F35: 0.011027493
A36: Total | B36: 62.538222 | C36: 57828 | D36: 1 | E36: 3282442.4 | F36: 1

Sheet Top50 2or4way Summary 
A1: Top 50 By Revenue Summary
A2: 2/4-way | B2: Avg Price | C2: Quantity/Mo | D2: Qty by % | E2: Revenue/Mo | F2: Revenue by %
A3: 2-way | B3: 151.215 | C3: 14280 | D3: 0.28413952 | E3: 1876739.6 | F3: 0.51593327
A4: 4-way | B4: 483.32333 | C4: 224 | D4: 0.0044570906 | E4: 99487.32 | F4: 0.027349994
A5: No camera | B5: 38.231667 | C5: 9741 | D5: 0.19382375 | E5: 327595.06 | F5: 0.090058945
B6: 112.4752 | C6: 26012 | D6: 0.51757964 | E6: 1333740.7 | F6: 0.36665779
A7: Total | B7: 196.3113 | C7: 50257 | D7: 1 | E7: 3637562.7 | F7: 1
A25: Top 50 By Unit Summary
A26: 2/4-way | B26: Avg Price | C26: Quantity/Mo | D26: Qty by % | E26: Revenue/Mo | F26: Revenue by %
A27: 2-way | B27: 125.215 | C27: 12014 | D27: 0.20775403 | E27: 1536111.9 | F27: 0.46797832
A28: No camera | B28: 33.44875 | C28: 15781 | D28: 0.27289548 | E28: 514452.73 | F28: 0.15672864
B29: 46.160385 | C29: 30033 | D29: 0.51935049 | E29: 1231877.8 | F29: 0.37529305
A30: Total | B30: 68.274712 | C30: 57828 | D30: 1 | E30: 3282442.4 | F30: 1

Sheet Top 50 Display Summary 
A1: Top 50 By Revenue Summary
A2: Display | B2: Avg Price | C2: Quantity/Mo | D2: Qty by % | E2: Revenue/Mo | F2: Revenue by %
A3: 4.3" | B3: 90.504706 | C3: 16596 | D3: 0.33022266 | E3: 1058372.8 | F3: 0.29095657
A4: 4.5" | B4: 142.49 | C4: 7113 | D4: 0.14153252 | E4: 927695.57 | F4: 0.25503219
A5: 5.0" | B5: 189.22077 | C5: 6508 | D5: 0.1294944 | E5: 877990.86 | F5: 0.2413679
A6: 6.0" | B6: 699.99 | C6: 58 | D6: 0.0011540681 | E6: 40745.77 | F6: 0.011201393
A7: 9.0" | B7: 659.99 | C7: 48 | D7: 0.00095509083 | E7: 33096.25 | F7: 0.0090984686
A8: App | B8: 38.134 | C8: 18839 | D8: 0.37485325 | E8: 589842.49 | F8: 0.16215322
B9: 150.2375 | C9: 1095 | D9: 0.02178801 | E9: 109818.99 | F9: 0.030190267
A10: Total | B10: 281.50957 | C10: 50257 | D10: 1 | E10: 3637562.7 | F10: 1
A28: Top 50 By Unit Summary
A29: Display | B29: Avg Price | C29: Quantity/Mo | D29: Qty by % | E29: Revenue/Mo | F29: Revenue by %
A30: 2.4" | B30: 29.9 | C30: 599 | D30: 0.010358304 | E30: 17916.11 | F30: 0.0054581643
A31: 4.3" | B31: 47.4315 | C31: 20510 | D31: 0.35467248 | E31: 1037368.9 | F31: 0.31603568
A32: 4.5" | B32: 136.65667 | C32: 6727 | D32: 0.11632773 | E32: 872541.08 | F32: 0.26582068
A33: 5.0" | B33: 124.02333 | C33: 5160 | D33: 0.089230131 | E33: 607604.95 | F33: 0.18510757
A34: App | B34: 28.917895 | C34: 24174 | D34: 0.41803279 | E34: 710814.25 | F34: 0.21655041
B35: 54.99 | C35: 658 | D35: 0.011378571 | E35: 36197.11 | F35: 0.011027493
A36: Total | B36: 70.319899 | C36: 57828 | D36: 1 | E36: 3282442.4 | F36: 1

Sheet Top50 Lensdiameter Summary  
A1: Top 50 By Revenue Summary
A2: Lens diameter | B2: Avg Price | C2: Quantity/Mo | D2: Qty by % | E2: Revenue/Mo | F2: Revenue by %
A3: 23mm | B3: 659.99 | C3: 48 | D3: 0.00095509083 | E3: 33096.25 | F3: 0.0090984686
A4: 3.9mm | B4: 699.99 | C4: 58 | D4: 0.0011540681 | E4: 40745.77 | F4: 0.011201393
A5: 5.5mm | B5: 134.84 | C5: 2029 | D5: 0.040372485 | E5: 289538.83 | F5: 0.079596932
A6: 6.2mm | B6: 149.99 | C6: 595 | D6: 0.011839147 | E6: 65856.69 | F6: 0.01810462
A7: 6.4mm | B7: 84.89 | C7: 298 | D7: 0.0059295223 | E7: 28620.75 | F7: 0.0078681118
A8: 6.5mm | B8: 299.99 | C8: 348 | D8: 0.0069244085 | E8: 102859.3 | F8: 0.028276983
A9: 6mm | B9: 449.99 | C9: 71 | D9: 0.0014127385 | E9: 31681.51 | F9: 0.0087095433
A10: 8.5mm | B10: 139.39 | C10: 2210 | D10: 0.043973974 | E10: 300981.94 | F10: 0.082742749
A11: 8mm | B11: 85.033824 | C11: 44163 | D11: 0.87874326 | E11: 2670559.8 | F11: 0.73416186
B12: 181.98667 | C12: 437 | D12: 0.0086953061 | E12: 73621.88 | F12: 0.020239343
A13: Total | B13: 288.60905 | C13: 50257 | D13: 1 | E13: 3637562.7 | F13: 1
A31: Top 50 By Unit Summary
A32: Lens diameter | B32: Avg Price | C32: Quantity/Mo | D32: Qty by % | E32: Revenue/Mo | F32: Revenue by %
A33: 3.9mm | B33: 39.98 | C33: 533 | D33: 0.0092169883 | E33: 21020.51 | F33: 0.0064039235
A34: 5.5mm | B34: 133.19 | C34: 1575 | D34: 0.027235941 | E34: 232842.09 | F34: 0.070935621
A35: 8.5mm | B35: 89.69 | C35: 2800 | D35: 0.048419451 | E35: 321694.51 | F35: 0.098004617
A36: 8mm | B36: 50.029556 | C36: 52920 | D36: 0.91512762 | E36: 2706885.3 | F36: 0.82465584
A37: Total | B37: 78.222389 | C37: 57828 | D37: 1 | E37: 3282442.4 | F37: 1

Sheet Top50 Lens count Summary 
A1: Top 50 By Revenue Summary
A2: Lens count | B2: Avg Price | C2: Quantity/Mo | D2: Qty by % | E2: Revenue/Mo | F2: Revenue by %
A3: Dual | B3: 113.49 | C3: 20239 | D3: 0.40271007 | E3: 1220047.5 | F3: 0.33540246
A4: Single | B4: 150.1296 | C4: 27353 | D4: 0.54426249 | E4: 2069390.5 | F4: 0.56889481
A5: Triple | B5: 142.165 | C5: 2228 | D5: 0.044332133 | E5: 274502.81 | F5: 0.075463389
B6: 181.98667 | C6: 437 | D6: 0.0086953061 | E6: 73621.88 | F6: 0.020239343
A7: Total | B7: 146.94282 | C7: 50257 | D7: 1 | E7: 3637562.7 | F7: 1
A25: Top 50 By Unit Summary
A26: Lens count | B26: Avg Price | C26: Quantity/Mo | D26: Qty by % | E26: Revenue/Mo | F26: Revenue by %
A27: Dual | B27: 65.282222 | C27: 22164 | D27: 0.38327454 | E27: 1102923.2 | F27: 0.33600687
A28: Single | B28: 43.140333 | C28: 33888 | D28: 0.5860137 | E28: 1968776.2 | F28: 0.59979003
A29: Triple | B29: 133.89 | C29: 1776 | D29: 0.030711766 | E29: 210742.98 | F29: 0.064203101
A30: Total | B30: 80.770852 | C30: 57828 | D30: 1 | E30: 3282442.4 | F30: 1

Sheet Top50 Cable length Summary  
A1: Top 50 By Revenue Summary
A2: Cable length | B2: Avg Price | C2: Quantity/Mo | D2: Qty by % | E2: Revenue/Mo | F2: Revenue by %
A3: 10ft | B3: 120.95667 | C3: 1678 | D3: 0.033388384 | E3: 126034.43 | F3: 0.034648043
A4: 16.5ft | B4: 52.773684 | C4: 30505 | D4: 0.60698012 | E4: 1165435.6 | F4: 0.32038915
A5: 300ft | B5: 659.99 | C5: 48 | D5: 0.00095509083 | E5: 33096.25 | F5: 0.0090984686
A6: 32.8ft | B6: 40.99 | C6: 915 | D6: 0.018206419 | E6: 33366.73 | F6: 0.0091728261
A7: 5.25ft | B7: 199.99 | C7: 232 | D7: 0.0046162724 | E7: 36138.18 | F7: 0.0099347236
A8: 5.5ft | B8: 108.45667 | C8: 3453 | D8: 0.068706847 | E8: 406987.28 | F8: 0.11188461
A9: 5.6ft | B9: 99.99 | C9: 363 | D9: 0.0072228744 | E9: 29718.51 | F9: 0.0081698963
A10: 50ft | B10: 122.165 | C10: 2314 | D10: 0.046043337 | E10: 266749.69 | F10: 0.073331984
A11: 5ft | B11: 242.59833 | C11: 9858 | D11: 0.19615178 | E11: 1409717.4 | F11: 0.38754449
A12: 9.8ft | B12: 136.49 | C12: 454 | D12: 0.0090335675 | E12: 56696.74 | F12: 0.015586464
B13: 181.98667 | C13: 437 | D13: 0.0086953061 | E13: 73621.88 | F13: 0.020239343
A14: Total | B14: 178.76246 | C14: 50257 | D14: 1 | E14: 3637562.7 | F14: 1
A32: Top 50 By Unit Summary
A33: Cable length | B33: Avg Price | C33: Quantity/Mo | D33: Qty by % | E33: Revenue/Mo | F33: Revenue by %
A34: 10ft | B34: 22.73 | C34: 1675 | D34: 0.028965207 | E34: 42400.6 | F34: 0.012917393
A35: 16.5ft | B35: 37.308182 | C35: 39098 | D35: 0.67610846 | E35: 1382202.1 | F35: 0.42108951
A36: 32.8ft | B36: 40.99 | C36: 915 | D36: 0.015822785 | E36: 33366.73 | F36: 0.010165214
A37: 33ft | B37: 39.99 | C37: 581 | D37: 0.010047036 | E37: 19298.9 | F37: 0.0058794329
A38: 5.5ft | B38: 108.45667 | C38: 3453 | D38: 0.059711558 | E38: 406987.28 | F38: 0.12398916
A39: 50ft | B39: 102.59 | C39: 2366 | D39: 0.040914436 | E39: 231455.55 | F39: 0.07051321
A40: 5ft | B40: 119.38833 | C40: 9094 | D40: 0.15725946 | E40: 1150145.1 | F40: 0.35039308
A41: 9.8ft | B41: 29.99 | C41: 646 | D41: 0.011171059 | E41: 16586.2 | F41: 0.0050530056
A42: Total | B42: 62.680398 | C42: 57828 | D42: 1 | E42: 3282442.4 | F42: 1

Sheet Teslong
A1: #VALUE!
A7: Rank by Revenue
A8: Product Name | B8: ASIN | C8: Avg Price | D8: Estimated 12mo Revenue | E8: Monthly Rev | F8: Estimated 12mo Units | G8: Monthly Units | H8: # of Reviews | I8: Tool Rating | J8: Column1 | K8: Link
A9: Teslong Two-Way Articulating Borescope with Light, Industrial Endoscope Inspection Camera with Articulated Probe, Flexible Mechanic Fiber Optic Snake Scope Cam for Wall Automotive Engine Inspect-5FT | B9: B0CJY5C9QX | C9: 129.99 | D9: 8388394.6 | E9: 699032.88 | F9: 64536 | G9: 5378 | H9: 1078 | I9: 4.7 | J9: https://amazon.com/dp/B0CJY5C9QX | K9: =HYPERLINK(J9) -> https://amazon.com/dp/B0CJY5C9QX
A10: Teslong Two-Way Articulating Borescope, 5.5mm Slim Probe, 5.0'' Industrial Endoscope with Light, 5FT Flexible Snake Scope for Automotive, HVAC & Mechanics | B10: B0DT4H7QQM | C10: 106.39 | D10: 1543312.2 | E10: 128609.35 | F10: 11088 | G10: 924 | H10: 177 | I10: 4.6 | J10: https://amazon.com/dp/B0DT4H7QQM | K10: =HYPERLINK(J10) -> https://amazon.com/dp/B0DT4H7QQM
A11: Articulating Borescope with Dual Lens Endoscope Camera, Teslong Two-Way Articulated Industrial Inspection Camera with LED Light, Flexible Mechanic Fiber Optic Snake Scope Cam for Wall Automotive-5FT | B11: B0CJY6SWBN | C11: 149.99 | D11: 1386287.4 | E11: 115523.95 | F11: 10068 | G11: 839 | H11: 318 | I11: 4.4 | J11: https://amazon.com/dp/B0CJY6SWBN | K11: =HYPERLINK(J11) -> https://amazon.com/dp/B0CJY6SWBN
A12: Teslong Inspection Camera, Dual Lens Borescope Camera with Light, NTS300 5" IPS Industrial Endoscope, 1080P Waterproof Flexible Mechanic Fiber Optic Snake Scope Cam for Wall Automotive Engine (16.5FT) | B12: B07TV2BFVR | C12: 159.99 | D12: 1250792.9 | E12: 104232.74 | F12: 7812 | G12: 651 | H12: 3542 | I12: 4.6 | J12: https://amazon.com/dp/B07TV2BFVR | K12: =HYPERLINK(J12) -> https://amazon.com/dp/B07TV2BFVR
A13: Articulating Borescope with Dual Lens Endoscope, Teslong 5-inch IPS Automotive Inspection Camera with Two-Way Articulation Tip, 6+1 LED Lights, Mechanics Fiber Optic Scope-Dia. 0.25 inch & L 5.0 feet | B13: B0CHW4FLS7 | C13: 299.99 | D13: 909591.12 | E13: 75799.26 | F13: 3036 | G13: 253 | H13: 184 | I13: 4.2 | J13: https://amazon.com/dp/B0CHW4FLS7 | K13: =HYPERLINK(J13) -> https://amazon.com/dp/B0CHW4FLS7
A14: Two-Way Articulating Borescope with Light, Teslong 5-inch IPS Endoscope Inspection Camera with Articulation Head, Automotive Mechanics Fiber Optic Scope-0.33inch | B14: B09ZV7KJHL | C14: 279.99 | D14: 521574.24 | E14: 43464.52 | F14: 2148 | G14: 179 | H14: 549 | I14: 4.7 | J14: https://amazon.com/dp/B09ZV7KJHL | K14: =HYPERLINK(J14) -> https://amazon.com/dp/B09ZV7KJHL
A15: Teslong 3.9mm 4-Way Articulating Borescope with Light, 6'' IPS Endoscope Inspection Camera with 360 Articulated Probe, Flexible Automotive Mechanics Gadgets Fiber Optic Scope Cam (0.15inch-5FT) | B15: B0D7PYRRKD | C15: 699.99 | D15: 488949.24 | E15: 40745.77 | F15: 696 | G15: 58 | H15: 21 | I15: 4.6 | J15: https://amazon.com/dp/B0D7PYRRKD | K15: =HYPERLINK(J15) -> https://amazon.com/dp/B0D7PYRRKD
A16: Teslong Endoscope Borescope with Light, Snake Inspection Camera for Automotive Engine, Waterproof Fiber Optic Camera for Mechanics - Ideal for Wall, Vent, Wire Video Scope (16.5FT) | B16: B0DK965BZP | C16: 37.99 | D16: 473261.28 | E16: 39438.44 | F16: 9636 | G16: 803 | H16: 234 | I16: 4.5 | J16: https://amazon.com/dp/B0DK965BZP | K16: =HYPERLINK(J16) -> https://amazon.com/dp/B0DK965BZP
A17: Triple Lens Borescope Inspection Camera, Teslong Professional Endoscope with Light, Digital Video Scope Camera, 5" IPS Screen, Waterproof Flexible Cable for Automotive/Home/Wall/Pipe/Car (16.5FT) | B17: B07Q86XGN2 | C17: 179.99 | D17: 397579.08 | E17: 33131.59 | F17: 2400 | G17: 200 | H17: 339 | I17: 4.5 | J17: https://amazon.com/dp/B07Q86XGN2 | K17: =HYPERLINK(J17) -> https://amazon.com/dp/B07Q86XGN2
A18: USB C Endoscope Camera with Light, Teslong Type-C Snake Borescope Camera with 8 LED Lights, 10FT Flexible Waterproof Inspection Cam, Fiber Optic Scope Compatible with iPhone 15/16, Android Phone | B18: B0C1GFBTDC | C18: 29.99 | D18: 388426.2 | E18: 32368.85 | F18: 12960 | G18: 1080 | H18: 911 | I18: 4.4 | J18: https://amazon.com/dp/B0C1GFBTDC | K18: =HYPERLINK(J18) -> https://amazon.com/dp/B0C1GFBTDC
A19: Teslong 360 Articulating Borescope with Light, 5'' Monitor Industrial Inspection Camera with 4-Way Joystick Articulation, HD Endoscope Camera for Automotive, Pipes, and Mechanics (0.24inch-5FT) | B19: B0DTHZDGYD | C19: 449.99 | D19: 380178.12 | E19: 31681.51 | F19: 852 | G19: 71 | H19: 28 | I19: 4.7 | J19: https://amazon.com/dp/B0DTHZDGYD | K19: =HYPERLINK(J19) -> https://amazon.com/dp/B0DTHZDGYD
A20: Teslong Dual Lens Endoscope with Light, Mechanic Borescope Inspection Camera, Fiber Optic Scope, Flexible Snake Probe for Automotive, HVAC, Wall & Home Inspections (16.5FT) | B20: B0DYDXH1NQ | C20: 59.99 | D20: 366452.88 | E20: 30537.74 | F20: 6516 | G20: 543 | H20: 57 | I20: 4.8 | J20: https://amazon.com/dp/B0DYDXH1NQ | K20: =HYPERLINK(J20) -> https://amazon.com/dp/B0DYDXH1NQ
... A68: Teslong Endoscope Replacement Cable with Light, Single Lens Inspection Camera 5.5mm/0.21inch Waterproof Probe Compatible with NTS500, NTS300(10FT) | B68: B08QCZQMJ4 | C68: 69.99 | D68: 2012.16 | E68: 167.68 | F68: 24 | G68: 2 | H68: 3 | I68: 4.7 | J68: https://amazon.com/dp/B08QCZQMJ4 | K68: =HYPERLINK(J68) -> https://amazon.com/dp/B08QCZQMJ4
A69: 10FT Single Lens Probe, 3.9mm/0.15inch Diameter Semi-Rigid Cable Compatible with MS450 Inspection Camera | B69: B0D9JGJG5R | C69: 59.99 | F69: 0 | G69: 0 | J69: https://amazon.com/dp/B0D9JGJG5R | K69: =HYPERLINK(J69) -> https://amazon.com/dp/B0D9JGJG5R
A70: Total | D70: =SUM(D9:D69) -> 20997245 | E70: =SUM(E9:E69) -> 1749770.4
A73: Rank by Units
A74: Product Name | B74: ASIN | C74: Avg Price | D74: Estimated 12mo Revenue | E74: Monthly Rev | F74: Estimated 12mo Units | G74: Monthly Units | H74: # of Reviews | I74: Tool Rating | J74: Column1 | K74: Link
A75: Teslong Two-Way Articulating Borescope with Light, Industrial Endoscope Inspection Camera with Articulated Probe, Flexible Mechanic Fiber Optic Snake Scope Cam for Wall Automotive Engine Inspect-5FT | B75: B0CJY5C9QX | C75: 129.99 | D75: 8388394.6 | E75: 699032.88 | F75: 64536 | G75: 5378 | H75: 1078 | I75: 4.7 | J75: https://amazon.com/dp/B0CJY5C9QX | K75: =HYPERLINK(J75) -> https://amazon.com/dp/B0CJY5C9QX
A76: USB C Endoscope Camera with Light, Teslong Type-C Snake Borescope Camera with 8 LED Lights, 10FT Flexible Waterproof Inspection Cam, Fiber Optic Scope Compatible with iPhone 15/16, Android Phone | B76: B0C1GFBTDC | C76: 29.99 | D76: 388426.2 | E76: 32368.85 | F76: 12960 | G76: 1080 | H76: 911 | I76: 4.4 | J76: https://amazon.com/dp/B0C1GFBTDC | K76: =HYPERLINK(J76) -> https://amazon.com/dp/B0C1GFBTDC
A77: Teslong Two-Way Articulating Borescope, 5.5mm Slim Probe, 5.0'' Industrial Endoscope with Light, 5FT Flexible Snake Scope for Automotive, HVAC & Mechanics | B77: B0DT4H7QQM | C77: 106.39 | D77: 1543312.2 | E77: 128609.35 | F77: 11088 | G77: 924 | H77: 177 | I77: 4.6 | J77: https://amazon.com/dp/B0DT4H7QQM | K77: =HYPERLINK(J77) -> https://amazon.com/dp/B0DT4H7QQM
A78: Articulating Borescope with Dual Lens Endoscope Camera, Teslong Two-Way Articulated Industrial Inspection Camera with LED Light, Flexible Mechanic Fiber Optic Snake Scope Cam for Wall Automotive-5FT | B78: B0CJY6SWBN | C78: 149.99 | D78: 1386287.4 | E78: 115523.95 | F78: 10068 | G78: 839 | H78: 318 | I78: 4.4 | J78: https://amazon.com/dp/B0CJY6SWBN | K78: =HYPERLINK(J78) -> https://amazon.com/dp/B0CJY6SWBN
A79: Teslong Endoscope Borescope with Light, Snake Inspection Camera for Automotive Engine, Waterproof Fiber Optic Camera for Mechanics - Ideal for Wall, Vent, Wire Video Scope (16.5FT) | B79: B0DK965BZP | C79: 37.99 | D79: 473261.28 | E79: 39438.44 | F79: 9636 | G79: 803 | H79: 234 | I79: 4.5 | J79: https://amazon.com/dp/B0DK965BZP | K79: =HYPERLINK(J79) -> https://amazon.com/dp/B0DK965BZP
A80: Teslong Inspection Camera, Dual Lens Borescope Camera with Light, NTS300 5" IPS Industrial Endoscope, 1080P Waterproof Flexible Mechanic Fiber Optic Snake Scope Cam for Wall Automotive Engine (16.5FT) | B80: B07TV2BFVR | C80: 159.99 | D80: 1250792.9 | E80: 104232.74 | F80: 7812 | G80: 651 | H80: 3542 | I80: 4.6 | J80: https://amazon.com/dp/B07TV2BFVR | K80: =HYPERLINK(J80) -> https://amazon.com/dp/B07TV2BFVR
A81: Teslong 50FT USB-C Borescope Camera with Light, Only Compatible with iPhone 15/16 Android Phones, 50 ft Flexible Waterproof Endoscope for DIY Pipe Inspection with Drain Snake | B81: B0CL4KT182 | C81: 39.99 | D81: 248550.84 | E81: 20712.57 | F81: 7080 | G81: 590 | H81: 717 | I81: 4.1 | J81: https://amazon.com/dp/B0CL4KT182 | K81: =HYPERLINK(J81) -> https://amazon.com/dp/B0CL4KT182
A82: Teslong Dual Lens Endoscope with Light, Mechanic Borescope Inspection Camera, Fiber Optic Scope, Flexible Snake Probe for Automotive, HVAC, Wall & Home Inspections (16.5FT) | B82: B0DYDXH1NQ | C82: 59.99 | D82: 366452.88 | E82: 30537.74 | F82: 6516 | G82: 543 | H82: 57 | I82: 4.8 | J82: https://amazon.com/dp/B0DYDXH1NQ | K82: =HYPERLINK(J82) -> https://amazon.com/dp/B0DYDXH1NQ
A83: Teslong Rifle Borescope, Bore Camera Gun Cleaning Camera - Fits .20 Caliber & Larger-Hunting Shooting Firearms Visual Barrel Inspection Tool w/3 Right-Angle Mirrors and Carrying Case(45inch-Flexible) | B83: B07TTQF24F | C83: 55.99 | D83: 256079.4 | E83: 21339.95 | F83: 4572 | G83: 381 | H83: 2098 | I83: 4.4 | J83: https://amazon.com/dp/B07TTQF24F | K83: =HYPERLINK(J83) -> https://amazon.com/dp/B07TTQF24F
A84: Teslong Rifle Borescope for Phone & PC, USB C Bore Scope Camera with Lights & Mirror Set, Fits .20 Caliber & Larger, Flexible Gun Cleaning Camera, Compatible with iPhone 15/16 & USB-C Android Devices | B84: B0DRP8LPF8 | C84: 65.99 | D84: 268233.36 | E84: 22352.78 | F84: 4068 | G84: 339 | H84: 114 | I84: 4.3 | J84: https://amazon.com/dp/B0DRP8LPF8 | K84: =HYPERLINK(J84) -> https://amazon.com/dp/B0DRP8LPF8
A85: Teslong 50FT Sewer Camera, Dual Lens Borescope with Light, 4.3" HD Drain Plumbing Endoscope Inspection Camera, Home Waterproof Flexible in Wall Cam Pipe Tools, Snake Scope for Air Duct HVAC | B85: B0DH24P6NY | C85: 99.99 | D85: 304541.64 | E85: 25378.47 | F85: 3432 | G85: 286 | H85: 106 | I85: 4.4 | J85: https://amazon.com/dp/B0DH24P6NY | K85: =HYPERLINK(J85) -> https://amazon.com/dp/B0DH24P6NY
A86: Articulating Borescope with Dual Lens Endoscope, Teslong 5-inch IPS Automotive Inspection Camera with Two-Way Articulation Tip, 6+1 LED Lights, Mechanics Fiber Optic Scope-Dia. 0.25 inch & L 5.0 feet | B86: B0CHW4FLS7 | C86: 299.99 | D86: 909591.12 | E86: 75799.26 | F86: 3036 | G86: 253 | H86: 184 | I86: 4.2 | J86: https://amazon.com/dp/B0CHW4FLS7 | K86: =HYPERLINK(J86) -> https://amazon.com/dp/B0CHW4FLS7
... A134: Teslong Endoscope Replacement Cable with Light, Single Lens Inspection Camera 5.5mm/0.21inch Waterproof Probe Compatible with NTS500, NTS300(10FT) | B134: B08QCZQMJ4 | C134: 69.99 | D134: 2012.16 | E134: 167.68 | F134: 24 | G134: 2 | H134: 3 | I134: 4.7 | J134: https://amazon.com/dp/B08QCZQMJ4 | K134: =HYPERLINK(J134) -> https://amazon.com/dp/B08QCZQMJ4
A135: 10FT Single Lens Probe, 3.9mm/0.15inch Diameter Semi-Rigid Cable Compatible with MS450 Inspection Camera | B135: B0D9JGJG5R | C135: 59.99 | F135: 0 | G135: 0 | J135: https://amazon.com/dp/B0D9JGJG5R | K135: =HYPERLINK(J135) -> https://amazon.com/dp/B0D9JGJG5R
A136: Total | F136: =SUM(Table43161821[Estimated 12mo Units]) -> 180912 | G136: =SUM(Table43161821[Monthly Units]) -> 15076

Sheet DEPSTECH
A1: #VALUE!
A7: Rank by Revenue
A8: Product Name | B8: ASIN | C8: Avg Price | D8: Estimated 12mo Revenue | E8: Monthly Rev | F8: Estimated 12mo Units | G8: Monthly Units | H8: # of Reviews | I8: Tool Rating | J8: Column1 | K8: Link
A9: Triple Lens Endoscope Camera with Light with 50FT Semi-Rigid Cable, DEPSTECH 5" IPS Screen Sewer Inspection Camera, 1080P Industrial Borescope, Split Screen, Waterproof Drain Pipe Tool, Carrying Case | B9: B0BS1CFFH8 | C9: 129.99 | D9: 1507452.5 | E9: 125621.04 | F9: 12696 | G9: 1058 | H9: 1394 | I9: 4.3 | J9: https://amazon.com/dp/B0BS1CFFH8 | K9: =HYPERLINK(J9) -> https://amazon.com/dp/B0BS1CFFH8
A10: DEPSTECH Dual Lens Industrial Endoscope, 1080P Digital Borescope Inspection Camera, 7.9mm IP67 Waterproof Sewer Camera with 4.3" LCD Screen, 7 LED Lights, 16.5FT Semi-Rigid Cable, 32GB Card-Black | B10: B0928Q3T42 | C10: 69.99 | D10: 1198974.6 | E10: 99914.55 | F10: 17136 | G10: 1428 | H10: 6721 | I10: 4.5 | J10: https://amazon.com/dp/B0928Q3T42 | K10: =HYPERLINK(J10) -> https://amazon.com/dp/B0928Q3T42
A11: DEPSTECH 50ft Sewer Camera, 1080P HD Triple Lens Borescope, 5" IPS Screen Endoscope with Light, IP67 Waterproof Plumbing Drain Pipe Snake Inspection Camera with 32G Card, Carry Case | B11: B0DD6YVBHD | C11: 137.79 | D11: 1021463.3 | E11: 85121.94 | F11: 8616 | G11: 718 | H11: 253 | I11: 4.3 | J11: https://amazon.com/dp/B0DD6YVBHD | K11: =HYPERLINK(J11) -> https://amazon.com/dp/B0DD6YVBHD
A12: DEPSTECH Dual Lens Two-Way Articulating Borescope Camera with Light, 4.5" Screen and 5FT Flexible Snake Scope Industrial Endoscope, Inspection Video Camera Tool for Wall, Engine, Auto, Mechanics | B12: B0DT16R78W | C12: 129.99 | D12: 695811 | E12: 57984.25 | F12: 6120 | G12: 510 | H12: 245 | I12: 4.6 | J12: https://amazon.com/dp/B0DT16R78W | K12: =HYPERLINK(J12) -> https://amazon.com/dp/B0DT16R78W
A13: DEPSTECH Dual Lens Articulating Endoscope Camera with Lights, 4.5" Screen Two-Way Industrial Borescope, Flexible Snake Scope, Video Inspection Camera Tool for Wall Engine Auto Mechanics - 10FT | B13: B0F62WJY8N | C13: 159.99 | D13: 661853.88 | E13: 55154.49 | F13: 4632 | G13: 386 | H13: 252 | I13: 4.6 | J13: https://amazon.com/dp/B0F62WJY8N | K13: =HYPERLINK(J13) -> https://amazon.com/dp/B0F62WJY8N
A14: DEPSTECH Dual Lens Wireless Endoscope, 1080P Scope Snake Camera with 7 LED Lights,0.31In Lens Video HD Inspection Camera,IP67 Waterproof Borescope,16.5FT Cable for Android & iOS Phone or Tablet-Yellow | B14: B08NJ8627V | C14: 54.99 | D14: 434365.32 | E14: 36197.11 | F14: 7896 | G14: 658 | H14: 2461 | I14: 4.3 | J14: https://amazon.com/dp/B08NJ8627V | K14: =HYPERLINK(J14) -> https://amazon.com/dp/B08NJ8627V
A15: DEPSTECH Articulating Borescope Camera with Light, 5" IPS HD Screen, Industrial Endoscope Inspection Camera with Two-Way Articulated Probe, 0.24'' Flexible Snake Scope for Wall Automotive Engine - 5FT | B15: B0FD3NRZ5S | C15: 139.99 | D15: 293259.72 | E15: 24438.31 | F15: 2136 | G15: 178 | H15: 84 | I15: 4.7 | J15: https://amazon.com/dp/B0FD3NRZ5S | K15: =HYPERLINK(J15) -> https://amazon.com/dp/B0FD3NRZ5S
A16: Dual-Lens Endoscope Camera with Light, DEPSTECH 1080P HD Borescope with 5" IPS Screen, 16.5FT Flexible Sewer Plumbing Snake Camera, Cool Gadgets for Men, Women | B16: B0CT2CX59S | C16: 69.99 | D16: 290535.12 | E16: 24211.26 | F16: 4272 | G16: 356 | H16: 1273 | I16: 4.6 | J16: https://amazon.com/dp/B0CT2CX59S | K16: =HYPERLINK(J16) -> https://amazon.com/dp/B0CT2CX59S
A17: DEPSTECH Inspection Endoscope Camera with Lights: 1080P Triple Lens Snake Camera with 5" Screen and 16.5FT Flexible Cable, Waterproof Industrial Borescope Tool for Auto, Wall, Sewer, Pipe, Mechanics | B17: B0FKM8K5QX | C17: 74.99 | D17: 206101.08 | E17: 17175.09 | F17: 3204 | G17: 267 | H17: 85 | I17: 4.7 | J17: https://amazon.com/dp/B0FKM8K5QX | K17: =HYPERLINK(J17) -> https://amazon.com/dp/B0FKM8K5QX
A18: DEPSTECH 210° Two-Way Articulating Borescope, 0.24in Ultra-Slim Endoscope Camera with Lights, 4.5” IPS Screen, 5ft Waterproof Flexible Snake Tube, Industrial Inspection Camera for Automotive Mechanics | B18: B0DBZ6Q4YH | C18: 124.99 | D18: 146783.4 | E18: 12231.95 | F18: 1260 | G18: 105 | H18: 299 | I18: 4.6 | J18: https://amazon.com/dp/B0DBZ6Q4YH | K18: =HYPERLINK(J18) -> https://amazon.com/dp/B0DBZ6Q4YH
A19: DEPSTECH 7'' IPS Endoscope Camera with Lights, 1080P Triple-Lens Digital Borescope Tool, Inspection Camera with Split Screen, Sound Recording, 16.5ft IP67 Waterproof Snake Cable, 180° Rotation View | B19: B0CT5L1H9B | C19: 139.99 | D19: 143746.8 | E19: 11978.9 | F19: 1176 | G19: 98 | H19: 184 | I19: 4.6 | J19: https://amazon.com/dp/B0CT5L1H9B | K19: =HYPERLINK(J19) -> https://amazon.com/dp/B0CT5L1H9B
A20: DEPSTECH Endoscope, 7'' IPS Screen Borescope Camera with Light, Triple-Lens Inspection Camera with Sound Recording, 1080P HD 7.9 mm Snake Camera, 16.5ft Gooseneck Camera for Automotive Wall Pipe HVAC | B20: B0BVML78W1 | C20: 194.97 | D20: 135734.52 | E20: 11311.21 | F20: 780 | G20: 65 | H20: 184 | I20: 4.6 | J20: https://amazon.com/dp/B0BVML78W1 | K20: =HYPERLINK(J20) -> https://amazon.com/dp/B0BVML78W1
... A38: DEPSTECH Endoscope Camera with Light, 1080P HD Borescope Inspection Camera with 2X Zoom, IP67 Waterproof Plumbing Snake Camera, 16.5ft Semi-Rigid Cable, 2.4'' IPS Screen Scope Camera Gadgets for Men | B38: B0CJM3HDR1 | C38: 39.99 | D38: 7824.12 | E38: 652.01 | F38: 192 | G38: 16 | H38: 224 | I38: 4.5 | J38: https://amazon.com/dp/B0CJM3HDR1 | K38: =HYPERLINK(J38) -> https://amazon.com/dp/B0CJM3HDR1
A39: DEPSTECH Dual Lens Borescope Camera with Light, Two-Way Articulating Borescope, 5" IPS Dual View Endoscope with 0.33in Slim Probe, 1080P Waterproof Inspection Camera for Wall Auto Engine Inspect-5FT | B39: B0FQC32XV7 | C39: 159.99 | F39: 0 | G39: 0 | H39: 15 | I39: 4.6 | J39: https://amazon.com/dp/B0FQC32XV7 | K39: =HYPERLINK(J39) -> https://amazon.com/dp/B0FQC32XV7
A40: DEPSTECH DS700SE Triple Lens Endoscope Camera with Lights: 7'' IPS Screen and 16.5FT Flexible Cable Inspection Snake Camera, Industrial Borescope with Video and Sound Recording for Auto, Sewer, Pipe | B40: B0FS68V4ZV | C40: 129.99 | F40: 0 | G40: 0 | H40: 2 | I40: 5 | J40: https://amazon.com/dp/B0FS68V4ZV | K40: =HYPERLINK(J40) -> https://amazon.com/dp/B0FS68V4ZV
A41: DEPSTECH Endoscope With Light, FHD Borescope Inspection Camera, Bluart 3.0 Tech, 7mm Slim Probe, 16.4ft Semi-Rigid Cable, IP67 Waterproof Snake Camera for IOS Smartphone, Cool Gadget for Men | B41: B0CT8MDJQD | C41: 25.49 | F41: 0 | G41: 0 | H41: 170 | I41: 4.3 | J41: https://amazon.com/dp/B0CT8MDJQD | K41: =HYPERLINK(J41) -> https://amazon.com/dp/B0CT8MDJQD
A42: Total | D42: =SUM(D9:D41) -> 7709570.3 | E42: =SUM(E9:E41) -> 642464.19
A45: Rank by Units
A46: Product Name | B46: ASIN | C46: Avg Price | D46: Estimated 12mo Revenue | E46: Monthly Rev | F46: Estimated 12mo Units | G46: Monthly Units | H46: # of Reviews | I46: Tool Rating | J46: Column1 | K46: Link
A47: DEPSTECH Dual Lens Industrial Endoscope, 1080P Digital Borescope Inspection Camera, 7.9mm IP67 Waterproof Sewer Camera with 4.3" LCD Screen, 7 LED Lights, 16.5FT Semi-Rigid Cable, 32GB Card-Black | B47: B0928Q3T42 | C47: 69.99 | D47: 1198974.6 | E47: 99914.55 | F47: 17136 | G47: 1428 | H47: 6721 | I47: 4.5 | J47: https://amazon.com/dp/B0928Q3T42 | K47: =HYPERLINK(J47) -> https://amazon.com/dp/B0928Q3T42
A48: Triple Lens Endoscope Camera with Light with 50FT Semi-Rigid Cable, DEPSTECH 5" IPS Screen Sewer Inspection Camera, 1080P Industrial Borescope, Split Screen, Waterproof Drain Pipe Tool, Carrying Case | B48: B0BS1CFFH8 | C48: 129.99 | D48: 1507452.5 | E48: 125621.04 | F48: 12696 | G48: 1058 | H48: 1394 | I48: 4.3 | J48: https://amazon.com/dp/B0BS1CFFH8 | K48: =HYPERLINK(J48) -> https://amazon.com/dp/B0BS1CFFH8
A49: DEPSTECH 50ft Sewer Camera, 1080P HD Triple Lens Borescope, 5" IPS Screen Endoscope with Light, IP67 Waterproof Plumbing Drain Pipe Snake Inspection Camera with 32G Card, Carry Case | B49: B0DD6YVBHD | C49: 137.79 | D49: 1021463.3 | E49: 85121.94 | F49: 8616 | G49: 718 | H49: 253 | I49: 4.3 | J49: https://amazon.com/dp/B0DD6YVBHD | K49: =HYPERLINK(J49) -> https://amazon.com/dp/B0DD6YVBHD
A50: DEPSTECH Dual Lens Wireless Endoscope, 1080P Scope Snake Camera with 7 LED Lights,0.31In Lens Video HD Inspection Camera,IP67 Waterproof Borescope,16.5FT Cable for Android & iOS Phone or Tablet-Yellow | B50: B08NJ8627V | C50: 54.99 | D50: 434365.32 | E50: 36197.11 | F50: 7896 | G50: 658 | H50: 2461 | I50: 4.3 | J50: https://amazon.com/dp/B08NJ8627V | K50: =HYPERLINK(J50) -> https://amazon.com/dp/B08NJ8627V
A51: DEPSTECH Dual Lens Two-Way Articulating Borescope Camera with Light, 4.5" Screen and 5FT Flexible Snake Scope Industrial Endoscope, Inspection Video Camera Tool for Wall, Engine, Auto, Mechanics | B51: B0DT16R78W | C51: 129.99 | D51: 695811 | E51: 57984.25 | F51: 6120 | G51: 510 | H51: 245 | I51: 4.6 | J51: https://amazon.com/dp/B0DT16R78W | K51: =HYPERLINK(J51) -> https://amazon.com/dp/B0DT16R78W
A52: DEPSTECH Dual Lens Articulating Endoscope Camera with Lights, 4.5" Screen Two-Way Industrial Borescope, Flexible Snake Scope, Video Inspection Camera Tool for Wall Engine Auto Mechanics - 10FT | B52: B0F62WJY8N | C52: 159.99 | D52: 661853.88 | E52: 55154.49 | F52: 4632 | G52: 386 | H52: 252 | I52: 4.6 | J52: https://amazon.com/dp/B0F62WJY8N | K52: =HYPERLINK(J52) -> https://amazon.com/dp/B0F62WJY8N
A53: Dual-Lens Endoscope Camera with Light, DEPSTECH 1080P HD Borescope with 5" IPS Screen, 16.5FT Flexible Sewer Plumbing Snake Camera, Cool Gadgets for Men, Women | B53: B0CT2CX59S | C53: 69.99 | D53: 290535.12 | E53: 24211.26 | F53: 4272 | G53: 356 | H53: 1273 | I53: 4.6 | J53: https://amazon.com/dp/B0CT2CX59S | K53: =HYPERLINK(J53) -> https://amazon.com/dp/B0CT2CX59S
A54: DEPSTECH Inspection Endoscope Camera with Lights: 1080P Triple Lens Snake Camera with 5" Screen and 16.5FT Flexible Cable, Waterproof Industrial Borescope Tool for Auto, Wall, Sewer, Pipe, Mechanics | B54: B0FKM8K5QX | C54: 74.99 | D54: 206101.08 | E54: 17175.09 | F54: 3204 | G54: 267 | H54: 85 | I54: 4.7 | J54: https://amazon.com/dp/B0FKM8K5QX | K54: =HYPERLINK(J54) -> https://amazon.com/dp/B0FKM8K5QX
A55: DEPSTECH Articulating Borescope Camera with Light, 5" IPS HD Screen, Industrial Endoscope Inspection Camera with Two-Way Articulated Probe, 0.24'' Flexible Snake Scope for Wall Automotive Engine - 5FT | B55: B0FD3NRZ5S | C55: 139.99 | D55: 293259.72 | E55: 24438.31 | F55: 2136 | G55: 178 | H55: 84 | I55: 4.7 | J55: https://amazon.com/dp/B0FD3NRZ5S | K55: =HYPERLINK(J55) -> https://amazon.com/dp/B0FD3NRZ5S
A56: DEPSTECH 5.5mm Industrial Endoscope, 1080P Digital Borescope Inspection Camera with 4.3" Screen, IP67 Waterproof Snake Camera with Lights,16.5FT Semi-Rigid Cable, 32GB Card &Photo Capture,Helpful Tool | B56: B094XGX6GQ | C56: 49.99 | D56: 103971.12 | E56: 8664.26 | F56: 2076 | G56: 173 | H56: 4253 | I56: 4.4 | J56: https://amazon.com/dp/B094XGX6GQ | K56: =HYPERLINK(J56) -> https://amazon.com/dp/B094XGX6GQ
A57: DEPSTECH 210° Two-Way Articulating Borescope, 0.24in Ultra-Slim Endoscope Camera with Lights, 4.5” IPS Screen, 5ft Waterproof Flexible Snake Tube, Industrial Inspection Camera for Automotive Mechanics | B57: B0DBZ6Q4YH | C57: 124.99 | D57: 146783.4 | E57: 12231.95 | F57: 1260 | G57: 105 | H57: 299 | I57: 4.6 | J57: https://amazon.com/dp/B0DBZ6Q4YH | K57: =HYPERLINK(J57) -> https://amazon.com/dp/B0DBZ6Q4YH
A58: DEPSTECH 7'' IPS Endoscope Camera with Lights, 1080P Triple-Lens Digital Borescope Tool, Inspection Camera with Split Screen, Sound Recording, 16.5ft IP67 Waterproof Snake Cable, 180° Rotation View | B58: B0CT5L1H9B | C58: 139.99 | D58: 143746.8 | E58: 11978.9 | F58: 1176 | G58: 98 | H58: 184 | I58: 4.6 | J58: https://amazon.com/dp/B0CT5L1H9B | K58: =HYPERLINK(J58) -> https://amazon.com/dp/B0CT5L1H9B
... A76: Dual Lens Articulating Borescope, DEPSTECH Endoscope Camera with Light, Articulated Probe, Flexible Snake Inspection Camera for Wall, Automotive Engine Inspect-4.92FT | B76: B0CXSTNWTW | C76: 271.69 | D76: 19101.36 | E76: 1591.78 | F76: 84 | G76: 7 | H76: 144 | I76: 4.3 | J76: https://amazon.com/dp/B0CXSTNWTW | K76: =HYPERLINK(J76) -> https://amazon.com/dp/B0CXSTNWTW
A77: DEPSTECH DS700SE Triple Lens Endoscope Camera with Lights: 7'' IPS Screen and 16.5FT Flexible Cable Inspection Snake Camera, Industrial Borescope with Video and Sound Recording for Auto, Sewer, Pipe | B77: B0FS68V4ZV | C77: 129.99 | F77: 0 | G77: 0 | H77: 2 | I77: 5 | J77: https://amazon.com/dp/B0FS68V4ZV | K77: =HYPERLINK(J77) -> https://amazon.com/dp/B0FS68V4ZV
A78: DEPSTECH Dual Lens Borescope Camera with Light, Two-Way Articulating Borescope, 5" IPS Dual View Endoscope with 0.33in Slim Probe, 1080P Waterproof Inspection Camera for Wall Auto Engine Inspect-5FT | B78: B0FQC32XV7 | C78: 159.99 | F78: 0 | G78: 0 | H78: 15 | I78: 4.6 | J78: https://amazon.com/dp/B0FQC32XV7 | K78: =HYPERLINK(J78) -> https://amazon.com/dp/B0FQC32XV7
A79: DEPSTECH Endoscope With Light, FHD Borescope Inspection Camera, Bluart 3.0 Tech, 7mm Slim Probe, 16.4ft Semi-Rigid Cable, IP67 Waterproof Snake Camera for IOS Smartphone, Cool Gadget for Men | B79: B0CT8MDJQD | C79: 25.49 | F79: 0 | G79: 0 | H79: 170 | I79: 4.3 | J79: https://amazon.com/dp/B0CT8MDJQD | K79: =HYPERLINK(J79) -> https://amazon.com/dp/B0CT8MDJQD
A80: Total | F80: =SUM(Table4316[Estimated 12mo Units]) -> 82356 | G80: =SUM(Table4316[Monthly Units]) -> 6863

Sheet KINPTHY
A1: #VALUE!
A7: Rank by Revenue
A8: Product Name | B8: ASIN | C8: Avg Price | D8: Estimated 12mo Revenue | E8: Monthly Rev | F8: Estimated 12mo Units | G8: Monthly Units | H8: # of Reviews | I8: Tool Rating | J8: Column1 | K8: Link
A9: Endoscope Camera with Light,1920P HD Borescope Tools with 8 Adjustable LED Lights, Endoscope with Semi-Rigid Snake Camera, IP67 Waterproof Inspection Borescope for iOS and Android-16.4ft Dual-Lens | B9: B0C9JR3N4W | C9: 42.99 | D9: 2162318.4 | E9: 180193.2 | F9: 56496 | G9: 4708 | H9: 5288 | I9: 4.4 | J9: https://amazon.com/dp/B0C9JR3N4W | K9: =HYPERLINK(J9) -> https://amazon.com/dp/B0C9JR3N4W
A10: Endoscope Camera with Light,1920P HD Borescope Tools with 8 Adjustable LED Lights, Endoscope with Semi-Rigid Snake Camera, Inspection Borescope for iOS and Android-16.4ft Single Lens | B10: B0C4V5LWWL | C10: 23.99 | D10: 753020.28 | E10: 62751.69 | F10: 27276 | G10: 2273 | H10: 5278 | I10: 4.4 | J10: https://amazon.com/dp/B0C4V5LWWL | K10: =HYPERLINK(J10) -> https://amazon.com/dp/B0C4V5LWWL
A11: Endoscope Camera with Light,1920P HD Borescope Tools with 8 Adjustable LED Lights, Endoscope with Semi-Rigid Snake Camera, IP67 Waterproof Inspection Borescope for iOS and Android-32.8ft Single Lens | B11: B0BF64PP4F | C11: 40.99 | D11: 400400.76 | E11: 33366.73 | F11: 10980 | G11: 915 | H11: 5287 | I11: 4.4 | J11: https://amazon.com/dp/B0BF64PP4F | K11: =HYPERLINK(J11) -> https://amazon.com/dp/B0BF64PP4F
A12: Endoscope Camera with Light,1920P HD Borescope Tools with 8 Adjustable LED Lights, Endoscope with Semi-Rigid Snake Camera, Inspection Borescope for iOS and Android-16.4ft Single Lens(Yellow) | B12: B0FJ2CFSHR | C12: 25.99 | D12: 215625.24 | E12: 17968.77 | F12: 6204 | G12: 517 | H12: 5288 | I12: 4.4 | J12: https://amazon.com/dp/B0FJ2CFSHR | K12: =HYPERLINK(J12) -> https://amazon.com/dp/B0FJ2CFSHR
A13: Endoscope Camera with Light,1920P HD Borescope Tools with 8 Adjustable LED Lights, Endoscope with Semi-Rigid Snake Camera, Inspection Borescope for iOS and Android-16.4ft Single Lens(Blue) | B13: B0FJ29BJZ7 | C13: 25.99 | D13: 214551.24 | E13: 17879.27 | F13: 6180 | G13: 515 | H13: 5288 | I13: 4.4 | J13: https://amazon.com/dp/B0FJ29BJZ7 | K13: =HYPERLINK(J13) -> https://amazon.com/dp/B0FJ29BJZ7
A14: Endoscope 4-Piece Accessories Hook Magnet Side View Mirror Set, 8-Piece Accessories, Suitable for Kinpthy W400 W400-B Series | B14: B0DBDJ3FK2 | C14: 9.99 | D14: 5634.36 | E14: 469.53 | F14: 564 | G14: 47 | H14: 17 | I14: 4.4 | J14: https://amazon.com/dp/B0DBDJ3FK2 | K14: =HYPERLINK(J14) -> https://amazon.com/dp/B0DBDJ3FK2
A15: Total | D15: =SUM(D9:D14) -> 3751550.3 | E15: =SUM(E9:E14) -> 312629.19
A18: Rank by Units
A19: Product Name | B19: ASIN | C19: Avg Price | D19: Estimated 12mo Revenue | E19: Monthly Rev | F19: Estimated 12mo Units | G19: Monthly Units | H19: # of Reviews | I19: Tool Rating | J19: Column1 | K19: Link
A20: Endoscope Camera with Light,1920P HD Borescope Tools with 8 Adjustable LED Lights, Endoscope with Semi-Rigid Snake Camera, IP67 Waterproof Inspection Borescope for iOS and Android-16.4ft Dual-Lens | B20: B0C9JR3N4W | C20: 42.99 | D20: 2162318.4 | E20: 180193.2 | F20: 56496 | G20: 4708 | H20: 5288 | I20: 4.4 | J20: https://amazon.com/dp/B0C9JR3N4W | K20: =HYPERLINK(J20) -> https://amazon.com/dp/B0C9JR3N4W
A21: Endoscope Camera with Light,1920P HD Borescope Tools with 8 Adjustable LED Lights, Endoscope with Semi-Rigid Snake Camera, Inspection Borescope for iOS and Android-16.4ft Single Lens | B21: B0C4V5LWWL | C21: 23.99 | D21: 753020.28 | E21: 62751.69 | F21: 27276 | G21: 2273 | H21: 5278 | I21: 4.4 | J21: https://amazon.com/dp/B0C4V5LWWL | K21: =HYPERLINK(J21) -> https://amazon.com/dp/B0C4V5LWWL
A22: Endoscope Camera with Light,1920P HD Borescope Tools with 8 Adjustable LED Lights, Endoscope with Semi-Rigid Snake Camera, IP67 Waterproof Inspection Borescope for iOS and Android-32.8ft Single Lens | B22: B0BF64PP4F | C22: 40.99 | D22: 400400.76 | E22: 33366.73 | F22: 10980 | G22: 915 | H22: 5287 | I22: 4.4 | J22: https://amazon.com/dp/B0BF64PP4F | K22: =HYPERLINK(J22) -> https://amazon.com/dp/B0BF64PP4F
A23: Endoscope Camera with Light,1920P HD Borescope Tools with 8 Adjustable LED Lights, Endoscope with Semi-Rigid Snake Camera, Inspection Borescope for iOS and Android-16.4ft Single Lens(Yellow) | B23: B0FJ2CFSHR | C23: 25.99 | D23: 215625.24 | E23: 17968.77 | F23: 6204 | G23: 517 | H23: 5288 | I23: 4.4 | J23: https://amazon.com/dp/B0FJ2CFSHR | K23: =HYPERLINK(J23) -> https://amazon.com/dp/B0FJ2CFSHR
A24: Endoscope Camera with Light,1920P HD Borescope Tools with 8 Adjustable LED Lights, Endoscope with Semi-Rigid Snake Camera, Inspection Borescope for iOS and Android-16.4ft Single Lens(Blue) | B24: B0FJ29BJZ7 | C24: 25.99 | D24: 214551.24 | E24: 17879.27 | F24: 6180 | G24: 515 | H24: 5288 | I24: 4.4 | J24: https://amazon.com/dp/B0FJ29BJZ7 | K24: =HYPERLINK(J24) -> https://amazon.com/dp/B0FJ29BJZ7
