Workbook

Sheet Summary
A1: Monthly Summaries- Revenue
A2: Brand | B2: # of Listings | C2: Monthly Rev | D2: Estimated 12mo Revenue | E2: Monthly Units | F2: Monthly Rev Market Share % | G2: Price Per Unit | H2: Reviews | I2: Avg Rating
A3: Teslong | B3: 13 | C3: 1608383.5 | D3: 19300602 | E3: 10891 | F3: 0.54951635 | G3: 147.68006 | H3: 3209 | I3: 4.5788096
A4: DXZtoz | B4: 4 | C4: 354066.15 | D4: 4248793.8 | E4: 2558 | F4: 0.12096937 | G4: 138.41523 | H4: 2364 | I4: 4.5551184
A5: Ralcam | B5: 24 | C5: 215656.91 | D5: 2587882.9 | E5: 1068 | F5: 0.07368081 | G5: 201.92595 | H5: 3676 | I5: 4.4058215
A6: DEPSTECH | B6: 7 | C6: 159287.01 | D6: 1911444.1 | E6: 1290 | F6: 0.054421609 | G6: 123.4783 | H6: 2083 | I6: 4.631109
A7: FOXWELL | B7: 4 | C7: 94159.34 | D7: 1129912.1 | E7: 585 | F7: 0.032170249 | G7: 160.95614 | H7: 373 | I7: 4.6520107
A8: Anykit | B8: 5 | C8: 75439.17 | D8: 905270.04 | E8: 925 | F8: 0.025774362 | G8: 81.555859 | H8: 209 | I8: 4.4330144
A9: UJOYOK | B9: 1 | C9: 61955.85 | D9: 743470.2 | E9: 620 | F9: 0.021167684 | G9: 99.92879 | H9: 424 | I9: 4.6
A10: Acoath | B10: 1 | C10: 52946.87 | D10: 635362.44 | E10: 458 | F10: 0.018089698 | G10: 115.60452 | H10: 322 | I10: 4.6
A11: KAIWEETS | B11: 1 | C11: 44902.94 | D11: 538835.28 | E11: 374 | F11: 0.015341428 | G11: 120.06134 | H11: 73 | I11: 4.8
A12: WANAWONG K | B12: 1 | C12: 43578.89 | D12: 522946.68 | E12: 571 | F12: 0.014889057 | G12: 76.320298 | H12: 211 | I12: 4.5
A14: Market Total | B14: 206 | C14: 2926907.4 | D14: 35122889 | E14: 21200 | F14: 1 | G14: 138.06167 | H14: 19252 | I14: 4.4890401
A16: Monthly Summary - Units
A17: Brand | B17: # of Listings | C17: Monthly Rev | D17: Estimated 12mo Units | E17: Monthly Units | F17: Monthly Unit Market Share % | G17: Price Per Unit | H17: Reviews | I17: Avg Rating
A18: Teslong | B18: 13 | C18: 1608383.5 | D18: 130692 | E18: 10891 | F18: 0.51372642 | G18: 147.68006 | H18: 3209 | I18: 4.5788096
A19: DXZtoz | B19: 4 | C19: 354066.15 | D19: 30696 | E19: 2558 | F19: 0.12066038 | G19: 138.41523 | H19: 2364 | I19: 4.5551184
A20: DEPSTECH | B20: 7 | C20: 159287.01 | D20: 15480 | E20: 1290 | F20: 0.060849057 | G20: 123.4783 | H20: 2083 | I20: 4.631109
A21: Ralcam | B21: 24 | C21: 215656.91 | D21: 12816 | E21: 1068 | F21: 0.050377358 | G21: 201.92595 | H21: 3676 | I21: 4.4058215
A22: Anykit | B22: 5 | C22: 75439.17 | D22: 11100 | E22: 925 | F22: 0.043632075 | G22: 81.555859 | H22: 209 | I22: 4.4330144
A23: UJOYOK | B23: 1 | C23: 61955.85 | D23: 7440 | E23: 620 | F23: 0.029245283 | G23: 99.92879 | H23: 424 | I23: 4.6
A24: FOXWELL | B24: 4 | C24: 94159.34 | D24: 7020 | E24: 585 | F24: 0.02759434 | G24: 160.95614 | H24: 373 | I24: 4.6520107
A25: WANAWONG K | B25: 1 | C25: 43578.89 | D25: 6852 | E25: 571 | F25: 0.026933962 | G25: 76.320298 | H25: 211 | I25: 4.5
A26: Acoath | B26: 1 | C26: 52946.87 | D26: 5496 | E26: 458 | F26: 0.021603774 | G26: 115.60452 | H26: 322 | I26: 4.6
A27: KAIWEETS | B27: 1 | C27: 44902.94 | D27: 4488 | E27: 374 | F27: 0.017641509 | G27: 120.06134 | H27: 73 | I27: 4.8
A29: Market Total | B29: 206 | C29: 2926907.4 | D29: 254400 | E29: 21200 | F29: 1 | G29: 138.06167 | H29: 19252 | I29: 4.4890401

Sheet Top 50
A1: Rank By Monthly Revenue - ONLY
A2: Ranking | B2: ASIN | C2: Product Name | D2: Brand | E2: Type | F2: 2/4-way | G2: Display | H2: Lens diameter | I2: Lens count | J2: Cable length | K2: Price | L2: Est. Monthly Retail Rev | M2: Est. Monthly Units Sold | N2: # of Reviews | O2: Avg. Rating | P2: Column2 | Q2: Link
A3: 1 | B3: B0CJY5C9QX | C3: Teslong Two-Way Articulating Borescope with Light, Industrial Endoscope Inspection Camera with Articulated Probe, Flexible Mechanic Fiber Optic Snake Scope Cam for Wall Automotive Engine Inspect-5FT | D3: teslong | E3: Articulation | F3: 2-way | G3: 4.5" | H3: 8mm | I3: Single | J3: 5ft | K3: 129.99 | L3: 895511.65 | M3: 6889 | N3: 1347 | O3: 4.7 | P3: https://amazon.com/dp/B0CJY5C9QX | Q3: =HYPERLINK(P3) -> https://amazon.com/dp/B0CJY5C9QX
A4: 2 | B4: B0B28HRSBP | C4: DXZtoz Two-Way Articulating Borescope with Light, Video Industrial Endoscope Inspection Camera with 0.33in Articulated Scope for Engine Automotive Aircraft Mechanics- 5.5FT | D4: dxztoz | E4: Articulation | F4: 2-way | G4: 4.3" | H4: 8.5mm | I4: Single | J4: 5.5ft | K4: 139.39 | L4: 211059.89 | M4: 1521 | N4: 1621 | O4: 4.6 | P4: https://amazon.com/dp/B0B28HRSBP | Q4: =HYPERLINK(P4) -> https://amazon.com/dp/B0B28HRSBP
A5: 3 | B5: B0DT4H7QQM | C5: Teslong Two-Way Articulating Borescope, 5.5mm Slim Probe, 5.0'' Industrial Endoscope with Light, 5FT Flexible Snake Scope for Automotive, HVAC & Mechanics | D5: teslong | E5: Articulation | F5: 2-way | G5: 5.0" | H5: 5.5mm | I5: Single | J5: 5ft | K5: 139.99 | L5: 163412.08 | M5: 1359 | N5: 263 | O5: 4.6 | P5: https://amazon.com/dp/B0DT4H7QQM | Q5: =HYPERLINK(P5) -> https://amazon.com/dp/B0DT4H7QQM
A6: 4 | B6: B0CJY6SWBN | C6: Articulating Borescope with Dual Lens Endoscope Camera, Teslong Two-Way Articulated Industrial Inspection Camera with LED Light, Flexible Mechanic Fiber Optic Snake Scope Cam for Wall Automotive-5FT | D6: teslong | E6: Articulation | F6: 2-way | G6: 4.5" | H6: 8mm | I6: Dual | J6: 5ft | K6: 149.99 | L6: 149501.28 | M6: 1126 | N6: 403 | O6: 4.5 | P6: https://amazon.com/dp/B0CJY6SWBN | Q6: =HYPERLINK(P6) -> https://amazon.com/dp/B0CJY6SWBN
A7: 5 | B7: B0C3B32Q9Z | C7: DXZtoz Dual-Lens Articulating Borescope with Light, 5'' Screen Engine Endoscope Inspection Camera with 0.33in Articulated Snake Camera, 1080P Videoscope for Automotive Home Mechanics-5FT | D7: dxztoz | E7: Articulation | F7: 2-way | G7: 5.0" | H7: 8mm | I7: Dual | J7: 5ft | K7: 135.99 | L7: 89923.57 | M7: 683 | N7: 506 | O7: 4.5 | P7: https://amazon.com/dp/B0C3B32Q9Z | Q7: =HYPERLINK(P7) -> https://amazon.com/dp/B0C3B32Q9Z
A8: 6 | B8: B0F62WJY8N | C8: DEPSTECH 10FT Articulating Endoscope Camera with Light: Dual Lens Industrial Borescope with 4.5" Screen and Flexible Cable, Video Inspection Snake Scope Camera Tool for Wall, Auto, Pipe, Mechanics | D8: depstech | E8: Articulation | F8: 2-way | G8: 4.5" | H8: 8mm | I8: Dual | J8: 10ft | K8: 159.99 | L8: 80479.85 | M8: 568 | N8: 338 | O8: 4.6 | P8: https://amazon.com/dp/B0F62WJY8N | Q8: =HYPERLINK(P8) -> https://amazon.com/dp/B0F62WJY8N
A9: 7 | B9: B0CHW4FLS7 | C9: Articulating Borescope with Dual Lens Endoscope, Teslong 5-inch IPS Automotive Inspection Camera with Two-Way Articulation Tip, 6+1 LED Lights, Mechanics Fiber Optic Scope-Dia. 0.25 inch & L 5.0 feet | D9: teslong | E9: Articulation | F9: 2-way | G9: 5.0" | H9: 6.5mm | I9: Dual | J9: 5ft | K9: 241.99 | L9: 70950.96 | M9: 238 | N9: 203 | O9: 4.2 | P9: https://amazon.com/dp/B0CHW4FLS7 | Q9: =HYPERLINK(P9) -> https://amazon.com/dp/B0CHW4FLS7
A10: 8 | B10: B0DTHZDGYD | C10: Teslong 360 Articulating Borescope with Light, 5'' Monitor Industrial Inspection Camera with 4-Way Joystick Articulation, HD Endoscope Camera for Automotive, Pipes, and Mechanics (0.24inch-5FT) | D10: teslong | E10: Articulation | F10: 4-way | G10: 5.0" | H10: 6mm | I10: Single | J10: 5ft | K10: 359.98 | L10: 69085.86 | M10: 166 | N10: 39 | O10: 4.8 | P10: https://amazon.com/dp/B0DTHZDGYD | Q10: =HYPERLINK(P10) -> https://amazon.com/dp/B0DTHZDGYD
A11: 9 | B11: B0CLG67RHF | C11: 360 Articulating Borescope with 6” Monitor, Teslong Mechanics Inspection Camera with 4-Way Joystick Articulation, HD Steerable Endoscope Camera with Light, See in Wall Engine Hole Camera(0.24inch-5FT) | D11: teslong | E11: Articulation | F11: 4-way | G11: 6.0" | H11: 6mm | I11: Single | J11: 5ft | K11: 599.99 | L11: 65086.31 | M11: 108 | N11: 49 | O11: 4.4 | P11: https://amazon.com/dp/B0CLG67RHF | Q11: =HYPERLINK(P11) -> https://amazon.com/dp/B0CLG67RHF
A12: 10 | B12: B0DFHL8YN5 | C12: Two-Way Articulating Borescope with Light, UJOYOK Industrial Endoscope with Snake Scope Camera, Borescope Inspection Camera with Light for Automotive & Aircraft Mechanics, 5.5FT | D12: ujoyok | E12: Articulation | F12: 2-way | G12: 4.3" | H12: 8mm | I12: Single | J12: 5.5ft | K12: 105.99 | L12: 61955.85 | M12: 620 | N12: 424 | O12: 4.6 | P12: https://amazon.com/dp/B0DFHL8YN5 | Q12: =HYPERLINK(P12) -> https://amazon.com/dp/B0DFHL8YN5
A13: 11 | B13: B0FZJ4CQB6 | C13: Acoath Two-Way Articulating Borescope, Endoscope Camera with Light, Dual-Lens 1080P Industrial Inspection Camera, 4.3" IPS Screen, 32GB Card, IP67 Waterproof Sewer Tools - 5FT | D13: acoath | E13: Sewer camera | F13: 2-way | G13: 4.3" | H13: Unknown | I13: Dual | J13: 5ft | K13: 139.99 | L13: 52946.87 | M13: 458 | N13: 322 | O13: 4.6 | P13: https://amazon.com/dp/B0FZJ4CQB6 | Q13: =HYPERLINK(P13) -> https://amazon.com/dp/B0FZJ4CQB6
A14: 12 | B14: B09ZV7KJHL | C14: Teslong Two-Way Articulating Borescope with Light, 5-inch IPS Endoscope Inspection Camera with Articulation Head, Automotive Mechanics Fiber Optic Scope-0.33inch | D14: teslong | E14: Articulation | F14: 2-way | G14: 5.0" | H14: 8mm | I14: Single | J14: 5ft | K14: 279.99 | L14: 52842.24 | M14: 189 | N14: 564 | O14: 4.7 | P14: https://amazon.com/dp/B09ZV7KJHL | Q14: =HYPERLINK(P14) -> https://amazon.com/dp/B09ZV7KJHL
... A38: 36 | B38: B0G48WTXYF | C38: Ralcam Dual Lens 360° Articulating Borescope 5 Inch, 4-Way 180° Endoscope Camera with Light, 6.5mm Slim Probe, 5FT Semi-Rigid Snake Camera for Automotive HVAC Pipe Inspection | D38: ralcam | E38: Articulation | F38: 4-way | G38: 5.0" | H38: 6.5mm | I38: Dual | J38: 5ft | K38: 429.99 | L38: 9244.52 | M38: 21 | N38: 38 | O38: 4.5 | P38: https://amazon.com/dp/B0G48WTXYF | Q38: =HYPERLINK(P38) -> https://amazon.com/dp/B0G48WTXYF
A39: 37 | B39: B09QBDSQ19 | C39: Vividia CT-4010 LCD/WiFi Flexible Two-Way Articulating Inspection Camera Borescope Videoscope with 4mm (0.16") Diameter 1.0m Long Waterproof IP67 Probe | D39: vividia | E39: Wireless | F39: 2-way | G39: App | H39: 3.9mm | I39: Single | J39: 3.3ft | K39: 999.98 | L39: 9206.82 | M39: 9 | P39: https://amazon.com/dp/B09QBDSQ19 | Q39: =HYPERLINK(P39) -> https://amazon.com/dp/B09QBDSQ19
A40: 38 | B40: B0FQBWRMHQ | C40: ZORLET Dual Lens 360° Articulating Borescope with Light, 5'' HD Monitor 4-Way Joystick Inspection Camera, 0.25in Slim Probe 5.0FT Semi-Rigid Snake Industrial Endoscope Camera for Automotive Mechanics | D40: zorlet | E40: Articulation | F40: 4-way | G40: 5.0" | H40: 6.4mm | I40: Dual | J40: 5ft | K40: 309.99 | L40: 8917.75 | M40: 29 | N40: 28 | O40: 4.9 | P40: https://amazon.com/dp/B0FQBWRMHQ | Q40: =HYPERLINK(P40) -> https://amazon.com/dp/B0FQBWRMHQ
A41: 39 | B41: B0FLNJ8CNL | C41: Ralcam 3mm Two-Way Articulating Borescope, 5 Inch HD Industrial Endoscope Inspection Camera with Light, Stainless Steel Flexible Fiber Optic Scope Camera 0.12in Automotive Mechanics Tool | D41: ralcam | E41: Articulation | F41: 2-way | G41: 5.0" | H41: 3mm | I41: Single | J41: 5ft | K41: 799.99 | L41: 8835.99 | M41: 11 | N41: 55 | O41: 4.4 | P41: https://amazon.com/dp/B0FLNJ8CNL | Q41: =HYPERLINK(P41) -> https://amazon.com/dp/B0FLNJ8CNL
A42: 40 | B42: B0DT95GVP1 | C42: Ralcam Articulating Borescope, Industrial Endoscope Inspection Camera for Android and iOS Smartphone, 8.5mm HD 1080P with 10FT Semi Rigid Cable | D42: ralcam | E42: USB | F42: 2-way | G42: App | H42: 8.5mm | I42: Single | J42: 10ft | K42: 119.99 | L42: 7890.41 | M42: 64 | N42: 206 | O42: 4.3 | P42: https://amazon.com/dp/B0DT95GVP1 | Q42: =HYPERLINK(P42) -> https://amazon.com/dp/B0DT95GVP1
A43: 41 | B43: B0FJLL4LY1 | C43: Ralcam 3.9mm Two-Way Articulating Borescope, 5 Inch HD Industrial Endoscope Inspection Camera with Light, Stainless Steel Flexible Fiber Optic Scope Camera 0.15in Automotive Mechanics Tool | D43: ralcam | E43: Articulation | F43: 2-way | G43: 5.0" | H43: 3.9mm | I43: Single | J43: 5ft | K43: 329.99 | L43: 7825.05 | M43: 24 | N43: 55 | O43: 4.4 | P43: https://amazon.com/dp/B0FJLL4LY1 | Q43: =HYPERLINK(P43) -> https://amazon.com/dp/B0FJLL4LY1
A44: 42 | B44: B0FQC32XV7 | C44: DEPSTECH Dual Lens Borescope Camera with Light, Two-Way Articulating Borescope, 5" IPS Dual View Endoscope with 0.33in Slim Probe, 1080P Waterproof Inspection Camera for Wall Auto Engine Inspect-5FT | D44: depstech | E44: Articulation | F44: 2-way | G44: 5.0" | H44: 8.5mm | I44: Dual | J44: 5ft | K44: 105.99 | L44: 7619.81 | M44: 72 | N44: 77 | O44: 4.7 | P44: https://amazon.com/dp/B0FQC32XV7 | Q44: =HYPERLINK(P44) -> https://amazon.com/dp/B0FQC32XV7
A45: 43 | B45: B0DZMN1941 | C45: Anykit 360° Articulated Engine Endoscope, Aviation Hole Sight with 0.25" Convertible Snake Camera, 5" IPS Video Check Camera with Light for Mechanic Maintenance Technician - 3.28' | D45: anykit | E45: Articulation | F45: 2-way | G45: 5.0" | H45: 6.4mm | I45: Single | J45: 3.3ft | K45: 151.99 | L45: 7530.79 | M45: 39 | N45: 8 | O45: 4.5 | P45: https://amazon.com/dp/B0DZMN1941 | Q45: =HYPERLINK(P45) -> https://amazon.com/dp/B0DZMN1941
A46: 44 | B46: B0G1MM25PR | C46: Anykit 360° 4 Ways Articulating Borescope, Industrial Endoscope with 0.26 in Articulated Snake Camera, Inspection Camera with 6 Adjustable LED Lights Compatible with Phone and Android - 3.3 FT | D46: anykit | E46: USB | F46: 4-way | G46: App | H46: 6.5mm | I46: Single | J46: 3.3ft | K46: 199.99 | L46: 7463.09 | M46: 39 | N46: 2 | O46: 5 | P46: https://amazon.com/dp/B0G1MM25PR | Q46: =HYPERLINK(P46) -> https://amazon.com/dp/B0G1MM25PR
A47: 45 | B47: B0FBWTBNTY | C47: NIDAGE Two-Way Articulating Endoscope Camera with Light: 7'' IPS Borescope with Articulated Snake Head and 5.3FT Cable 1080P Waterproof Industrial Inspection Camera for Auto Mechanics Wall | D47: nidage | E47: Articulation | F47: 2-way | G47: 5.0" | H47: Unknown | I47: Single | J47: 5.3ft | K47: 168.98 | L47: 7238.91 | M47: 43 | N47: 47 | O47: 4.7 | P47: https://amazon.com/dp/B0FBWTBNTY | Q47: =HYPERLINK(P47) -> https://amazon.com/dp/B0FBWTBNTY
A48: 46 | B48: B0DHRPXGRL | C48: NIDAGE Two-Way Articulating Endoscope Camera with Light, Industrial Borescope with 0.24in Articulated Snake Inspection Camera, Flexible Fiber Optic Scope Cam for Automotive Aircraft Mechanics, 5.2FT | D48: nidage | E48: Articulation | F48: 2-way | G48: 5.0" | H48: 6mm | I48: Single | J48: 5.2ft | K48: 69.98 | L48: 7138.52 | M48: 102 | N48: 82 | O48: 4.6 | P48: https://amazon.com/dp/B0DHRPXGRL | Q48: =HYPERLINK(P48) -> https://amazon.com/dp/B0DHRPXGRL
A49: 47 | B49: B0D8SDT9HT | C49: Ralcam Two-Way Articulating Borescope, Endoscope Camera with Light 0.24in/6.2mm Articulated Inspection Camera, 3.3 FT Semi-Rigid HD Video Snake Scope for Automotive Aircraft Mechanics | D49: ralcam | E49: Articulation | F49: 2-way | G49: 5.0" | H49: 6.2mm | I49: Single | J49: 3.3ft | K49: 99.99 | L49: 6956.24 | M49: 70 | N49: 182 | O49: 4.6 | P49: https://amazon.com/dp/B0D8SDT9HT | Q49: =HYPERLINK(P49) -> https://amazon.com/dp/B0D8SDT9HT
A50: 48 | B50: B0DPX48VZB | C50: Two-Way Articulating Borescope Camera with Light, DEPSTECH Industrial Endoscope with Articulated Probe, Flexible Mechanic Snake Inspection Camera for Wall Automotive Engine Inspect-5FT | D50: depstech | E50: Articulation | F50: 2-way | G50: 5.0" | H50: Unknown | I50: Single | J50: 5ft | K50: 99.99 | L50: 6778.25 | M50: 56 | N50: 459 | O50: 4.7 | P50: https://amazon.com/dp/B0DPX48VZB | Q50: =HYPERLINK(P50) -> https://amazon.com/dp/B0DPX48VZB
A51: 49 | B51: B0G34PXC7N | C51: 4-Way 360° Articulating Borescope with 6 Light, Endoscope Camera with 6.2mm Probe, 8X Zoom 5.0FT Semi-Rigid Cable Inspection Camera for Automotive Engine Pipe HVAC | D51: mrcartool | E51: Articulation | F51: 4-way | G51: 5.0" | H51: 6.2mm | I51: Single | J51: 5ft | K51: 228 | L51: 6717.31 | M51: 31 | N51: 1 | O51: 5 | P51: https://amazon.com/dp/B0G34PXC7N | Q51: =HYPERLINK(P51) -> https://amazon.com/dp/B0G34PXC7N
A52: 50 | B52: B0DBZ6Q4YH | C52: DEPSTECH 210° Two-Way Articulating Borescope, 0.24in Ultra-Slim Endoscope Camera with Lights, 4.5” IPS Screen, 5ft Waterproof Flexible Snake Tube, Industrial Inspection Camera for Automotive Mechanics | D52: depstech | E52: Articulation | F52: 2-way | G52: 4.5" | H52: 6mm | I52: Single | J52: 5ft | K52: 89.99 | L52: 6425.32 | M52: 61 | N52: 328 | O52: 4.5 | P52: https://amazon.com/dp/B0DBZ6Q4YH | Q52: =HYPERLINK(P52) -> https://amazon.com/dp/B0DBZ6Q4YH
A55: Rank By Monthly Units - ONLY
A56: Ranking | B56: ASIN | C56: Product Name | D56: Brand | E56: Type | F56: 2/4-way | G56: Display | H56: Lens diameter | I56: Lens count | J56: Cable length | K56: Price | L56: Est. Monthly Retail Rev | M56: Est. Monthly Units Sold | N56: # of Reviews | O56: Avg. Rating | P56: Column2 | Q56: Link
A57: 1 | B57: B0CJY5C9QX | C57: Teslong Two-Way Articulating Borescope with Light, Industrial Endoscope Inspection Camera with Articulated Probe, Flexible Mechanic Fiber Optic Snake Scope Cam for Wall Automotive Engine Inspect-5FT | D57: teslong | E57: Articulation | F57: 2-way | G57: 4.5" | H57: 8mm | I57: Single | J57: 5ft | K57: 129.99 | L57: 895511.65 | M57: 6889 | N57: 1347 | O57: 4.7 | P57: https://amazon.com/dp/B0CJY5C9QX | Q57: =HYPERLINK(P57) -> https://amazon.com/dp/B0CJY5C9QX
A58: 2 | B58: B0B28HRSBP | C58: DXZtoz Two-Way Articulating Borescope with Light, Video Industrial Endoscope Inspection Camera with 0.33in Articulated Scope for Engine Automotive Aircraft Mechanics- 5.5FT | D58: dxztoz | E58: Articulation | F58: 2-way | G58: 4.3" | H58: 8.5mm | I58: Single | J58: 5.5ft | K58: 139.39 | L58: 211059.89 | M58: 1521 | N58: 1621 | O58: 4.6 | P58: https://amazon.com/dp/B0B28HRSBP | Q58: =HYPERLINK(P58) -> https://amazon.com/dp/B0B28HRSBP
A59: 3 | B59: B0DT4H7QQM | C59: Teslong Two-Way Articulating Borescope, 5.5mm Slim Probe, 5.0'' Industrial Endoscope with Light, 5FT Flexible Snake Scope for Automotive, HVAC & Mechanics | D59: teslong | E59: Articulation | F59: 2-way | G59: 5.0" | H59: 5.5mm | I59: Single | J59: 5ft | K59: 139.99 | L59: 163412.08 | M59: 1359 | N59: 263 | O59: 4.6 | P59: https://amazon.com/dp/B0DT4H7QQM | Q59: =HYPERLINK(P59) -> https://amazon.com/dp/B0DT4H7QQM
A60: 4 | B60: B0CJY6SWBN | C60: Articulating Borescope with Dual Lens Endoscope Camera, Teslong Two-Way Articulated Industrial Inspection Camera with LED Light, Flexible Mechanic Fiber Optic Snake Scope Cam for Wall Automotive-5FT | D60: teslong | E60: Articulation | F60: 2-way | G60: 4.5" | H60: 8mm | I60: Dual | J60: 5ft | K60: 149.99 | L60: 149501.28 | M60: 1126 | N60: 403 | O60: 4.5 | P60: https://amazon.com/dp/B0CJY6SWBN | Q60: =HYPERLINK(P60) -> https://amazon.com/dp/B0CJY6SWBN
A61: 5 | B61: B0FGJ8WVGP | C61: Anykit Articulating Borescope, 210° Two-Way 0.22in Slim Probe Endoscope with High-Brightness LED Lights, 4.3" IPS HD Video Inspection Snake Camera for Automotive Engine Inspect - 4FT | D61: anykit | E61: Articulation | F61: 2-way | G61: 4.3" | H61: 5.5mm | I61: Single | J61: 4ft | K61: 72.99 | L61: 52520.15 | M61: 777 | N61: 64 | O61: 4.5 | P61: https://amazon.com/dp/B0FGJ8WVGP | Q61: =HYPERLINK(P61) -> https://amazon.com/dp/B0FGJ8WVGP
A62: 6 | B62: B0C3B32Q9Z | C62: DXZtoz Dual-Lens Articulating Borescope with Light, 5'' Screen Engine Endoscope Inspection Camera with 0.33in Articulated Snake Camera, 1080P Videoscope for Automotive Home Mechanics-5FT | D62: dxztoz | E62: Articulation | F62: 2-way | G62: 5.0" | H62: 8mm | I62: Dual | J62: 5ft | K62: 135.99 | L62: 89923.57 | M62: 683 | N62: 506 | O62: 4.5 | P62: https://amazon.com/dp/B0C3B32Q9Z | Q62: =HYPERLINK(P62) -> https://amazon.com/dp/B0C3B32Q9Z
A63: 7 | B63: B0DFHL8YN5 | C63: Two-Way Articulating Borescope with Light, UJOYOK Industrial Endoscope with Snake Scope Camera, Borescope Inspection Camera with Light for Automotive & Aircraft Mechanics, 5.5FT | D63: ujoyok | E63: Articulation | F63: 2-way | G63: 4.3" | H63: 8mm | I63: Single | J63: 5.5ft | K63: 105.99 | L63: 61955.85 | M63: 620 | N63: 424 | O63: 4.6 | P63: https://amazon.com/dp/B0DFHL8YN5 | Q63: =HYPERLINK(P63) -> https://amazon.com/dp/B0DFHL8YN5
A64: 8 | B64: B0F2H49C2D | C64: Teslong Two-Way Articulating Borescope with Light, USB-C Endoscope Inspection Camera with 5FT Semi-Rigid Probe, Flexible Snake Scope for Home Repair, Automotive, Compatible with iPhone 15/16 & Android | D64: teslong | E64: USB | F64: 2-way | G64: App | H64: Unknown | I64: Single | J64: 5ft | K64: 67.99 | L64: 44223.32 | M64: 600 | N64: 125 | O64: 4.3 | P64: https://amazon.com/dp/B0F2H49C2D | Q64: =HYPERLINK(P64) -> https://amazon.com/dp/B0F2H49C2D
A65: 9 | B65: B0DT98YB3X | C65: Two-Way Articulating Borescope Camera with Light: Industrial Endoscope Inspection Snake Camera - Flexible Bore Scope Cam with 0.33in Articulated Probe for Mechanic Automotive Engine Wall - 5.5FT | D65: wanawong k | E65: Articulation | F65: 2-way | G65: 4.3" | H65: 8mm | I65: Single | J65: 5.5ft | K65: 69.99 | L65: 43578.89 | M65: 571 | N65: 211 | O65: 4.5 | P65: https://amazon.com/dp/B0DT98YB3X | Q65: =HYPERLINK(P65) -> https://amazon.com/dp/B0DT98YB3X
...

Sheet Top 50 Type Summary
A1: Top 50 By Revenue Summary
A2: Type | B2: Avg Price | C2: Quantity/Mo | D2: Qty by % | E2: Revenue/Mo | F2: Revenue by %
A3: Articulation | B3: 223.48511 | C3: 18633 | D3: 0.94091804 | E3: 2639534.4 | F3: 0.95591495
A4: Sewer camera | B4: 139.99 | C4: 458 | D4: 0.023127809 | E4: 52946.87 | F4: 0.019174861
A5: USB | B5: 129.32333 | C5: 703 | D5: 0.035499672 | E5: 59576.82 | F5: 0.021575916
A6: Wireless | B6: 999.98 | C6: 9 | D6: 0.00045447659 | E6: 9206.82 | F6: 0.0033342762
A10: Total | B10: 373.19461 | C10: 19803 | D10: 1 | E10: 2761264.9 | F10: 1
A28: Top 50 By Unit Summary
A29: Type | B29: Avg Price | C29: Quantity/Mo | D29: Qty by % | E29: Revenue/Mo | F29: Revenue by %
A30: Articulation | B30: 168.99024 | C30: 18687 | D30: 0.9313232 | E30: 2568621.4 | F30: 0.95447384
A31: Sewer camera | B31: 74.32 | C31: 545 | D31: 0.027161724 | E31: 57521.93 | F31: 0.02137457
A32: USB | B32: 82.972 | C32: 833 | D32: 0.041515076 | E32: 64995.27 | F32: 0.024151588
A35: Total | B35: 108.76075 | C35: 20065 | D35: 1 | E35: 2691138.6 | F35: 1

Sheet Top50 2or4way Summary 
A1: Top 50 By Revenue Summary
A2: 2/4-way | B2: Avg Price | C2: Quantity/Mo | D2: Qty by % | E2: Revenue/Mo | F2: Revenue by %
A3: 2-way | B3: 184.91444 | C3: 18798 | D3: 0.94925011 | E3: 2399952.1 | F3: 0.86914954
A4: 4-way | B4: 351.98929 | C4: 1005 | D4: 0.050749886 | E4: 361312.8 | F4: 0.13085046
A7: Total | B7: 268.45187 | C7: 19803 | D7: 1 | E7: 2761264.9 | F7: 1
A25: Top 50 By Unit Summary
A26: 2/4-way | B26: Avg Price | C26: Quantity/Mo | D26: Qty by % | E26: Revenue/Mo | F26: Revenue by %
A27: 2-way | B27: 122.50605 | C27: 19289 | D27: 0.96132569 | E27: 2411627.6 | F27: 0.89613652
A28: 4-way | B28: 352.52143 | C28: 776 | D28: 0.038674308 | E28: 279511.03 | F28: 0.10386348
A30: Total | B30: 237.51374 | C30: 20065 | D30: 1 | E30: 2691138.6 | F30: 1

Sheet Top 50 Display Summary 
A1: Top 50 By Revenue Summary
A2: Display | B2: Avg Price | C2: Quantity/Mo | D2: Qty by % | E2: Revenue/Mo | F2: Revenue by %
A3: 4.3" | B3: 132.29 | C3: 4662 | D3: 0.23541888 | E3: 534740.86 | F3: 0.19365793
A4: 4.5" | B4: 131.99 | C4: 9062 | D4: 0.45760743 | E4: 1176607.1 | F4: 0.42611163
A5: 5.0" | B5: 236.61933 | C5: 4963 | D5: 0.25061859 | E5: 856116.1 | F5: 0.3100449
A6: 6.0" | B6: 649.99 | C6: 166 | D6: 0.0083825683 | E6: 105950.7 | F6: 0.038370349
A7: App | B7: 293.588 | C7: 950 | D7: 0.047972529 | E7: 87850.18 | F7: 0.031815194
A9: Total | B9: 288.89547 | C9: 19803 | D9: 1 | E9: 2761264.9 | F9: 1
A27: Top 50 By Unit Summary
A28: Display | B28: Avg Price | C28: Quantity/Mo | D28: Qty by % | E28: Revenue/Mo | F28: Revenue by %
A29: 4.3" | B29: 132.29 | C29: 4662 | D29: 0.23234488 | E29: 534740.86 | F29: 0.19870432
A30: 4.5" | B30: 131.99 | C30: 9062 | D30: 0.4516322 | E30: 1176607.1 | F30: 0.43721534
A31: 5.0" | B31: 145.5969 | C31: 5104 | D31: 0.25437329 | E31: 789778.16 | F31: 0.29347361
A32: 6.0" | B32: 649.99 | C32: 166 | D32: 0.0082731124 | E32: 105950.7 | F32: 0.039370213
A33: App | B33: 82.475 | C33: 1071 | D33: 0.053376526 | E33: 84061.81 | F33: 0.031236522
A34: Total | B34: 228.46838 | C34: 20065 | D34: 1 | E34: 2691138.6 | F34: 1

Sheet Top50 Lensdiameter Summary  
A1: Top 50 By Revenue Summary
A2: Lens diameter | B2: Avg Price | C2: Quantity/Mo | D2: Qty by % | E2: Revenue/Mo | F2: Revenue by %
A3: 3.9mm | B3: 594.9875 | C3: 191 | D3: 0.0096450033 | E3: 89441.13 | F3: 0.032391361
A4: 3mm | B4: 799.99 | C4: 11 | D4: 0.00055547139 | E4: 8835.99 | F4: 0.0031999791
A5: 5.5mm | B5: 106.49 | C5: 2136 | D5: 0.10786245 | E5: 215932.23 | F5: 0.078200475
A6: 6.2mm | B6: 207.24125 | C6: 1060 | D6: 0.053527243 | E6: 169747.18 | F6: 0.061474427
A7: 6.4mm | B7: 189.64167 | C7: 877 | D7: 0.044286219 | E7: 131518.76 | F7: 0.047629895
A8: 6.5mm | B8: 235.32167 | C8: 659 | D8: 0.033277786 | E8: 158308.59 | F8: 0.057331909
A9: 6mm | B9: 289.98667 | C9: 690 | D9: 0.034843206 | E9: 191531.08 | F9: 0.069363529
A10: 8.5mm | B10: 121.79 | C10: 1657 | D10: 0.083674191 | E10: 226570.11 | F10: 0.082053014
A11: 8mm | B11: 145.76778 | C11: 11269 | D11: 0.56905519 | E11: 1447695.4 | F11: 0.52428703
A12: Unknown | B12: 113.388 | C12: 1253 | D12: 0.063273241 | E12: 121684.48 | F12: 0.044068383
A13: Total | B13: 280.46045 | C13: 19803 | D13: 1 | E13: 2761264.9 | F13: 1
A30: Top 50 By Unit Summary
A31: Lens diameter | B31: Avg Price | C31: Quantity/Mo | D31: Qty by % | E31: Revenue/Mo | F31: Revenue by %
A32: 3.9mm | B32: 524.99 | C32: 158 | D32: 0.0078744082 | E32: 72409.26 | F32: 0.026906552
A33: 5.5mm | B33: 117.65667 | C33: 2180 | D33: 0.1086469 | E33: 222052.05 | F33: 0.082512305
A34: 6.2mm | B34: 130.85 | C34: 1139 | D34: 0.056765512 | E34: 158269.02 | F34: 0.058811173
A35: 6.4mm | B35: 145.29333 | C35: 768 | D35: 0.038275604 | E35: 102744.81 | F35: 0.038178936
A36: 6.5mm | B36: 195.4875 | C36: 599 | D36: 0.029852978 | E36: 141600.98 | F36: 0.052617498
A37: 6mm | B37: 197.55857 | C37: 766 | D37: 0.038175928 | E37: 179896.1 | F37: 0.066847578
A38: 8.5mm | B38: 116.34 | C38: 1721 | D38: 0.085771243 | E38: 232949.43 | F38: 0.086561661
A39: 8mm | B39: 145.76778 | C39: 11269 | D39: 0.56162472 | E39: 1447695.4 | F39: 0.53794902
A40: Unknown | B40: 86.311111 | C40: 1465 | D40: 0.073012709 | E40: 133521.59 | F40: 0.049615278
A41: Total | B41: 184.47277 | C41: 20065 | D41: 1 | E41: 2691138.6 | F41: 1

Sheet Top50 Lens count Summary 
A1: Top 50 By Revenue Summary
A2: Lens count | B2: Avg Price | C2: Quantity/Mo | D2: Qty by % | E2: Revenue/Mo | F2: Revenue by %
A3: Dual | B3: 216.10706 | C3: 4487 | D3: 0.22658183 | E3: 688143.48 | F3: 0.24921313
A4: Single | B4: 239.72576 | C4: 15316 | D4: 0.77341817 | E4: 2073121.4 | F4: 0.75078687
A7: Total | B7: 227.91641 | C7: 19803 | D7: 1 | E7: 2761264.9 | F7: 1
A25: Top 50 By Unit Summary
A26: Lens count | B26: Avg Price | C26: Quantity/Mo | D26: Qty by % | E26: Revenue/Mo | F26: Revenue by %
A27: Dual | B27: 151.83538 | C27: 4360 | D27: 0.2172938 | E27: 629262.06 | F27: 0.23382744
A28: Single | B28: 155.71757 | C28: 15705 | D28: 0.7827062 | E28: 2061876.6 | F28: 0.76617256
A30: Total | B30: 153.77648 | C30: 20065 | D30: 1 | E30: 2691138.6 | F30: 1

Sheet Top50 Cable length Summary  
A1: Top 50 By Revenue Summary
A2: Cable length | B2: Avg Price | C2: Quantity/Mo | D2: Qty by % | E2: Revenue/Mo | F2: Revenue by %
A3: 10ft | B3: 143.32333 | C3: 837 | D3: 0.042266323 | E3: 117583.32 | F3: 0.042583136
A4: 3.3ft | B4: 338.388 | C4: 294 | D4: 0.014846235 | E4: 64135.61 | F4: 0.023226895
A5: 4ft | B5: 72.99 | C5: 777 | D5: 0.039236479 | E5: 52520.15 | F5: 0.019020323
A6: 5.25ft | B6: 129.99 | C6: 374 | D6: 0.018886027 | E6: 49904.6 | F6: 0.018073094
A7: 5.2ft | B7: 69.98 | C7: 102 | D7: 0.0051507347 | E7: 7138.52 | F7: 0.0025852355
A8: 5.3ft | B8: 169.65333 | C8: 595 | D8: 0.030045953 | E8: 89416.39 | F8: 0.032382402
A9: 5.5ft | B9: 105.12333 | C9: 2712 | D9: 0.13694895 | E9: 316594.63 | F9: 0.11465565
A10: 5.6ft | B10: 79.99 | C10: 238 | D10: 0.012018381 | E10: 19066.54 | F10: 0.006905002
A11: 5ft | B11: 259.21258 | C11: 13738 | D11: 0.69373327 | E11: 2011343.6 | F11: 0.72841385
A12: 6.6ft | B12: 249.99 | C12: 136 | D12: 0.0068676463 | E12: 33561.55 | F12: 0.012154411
A13: Total | B13: 161.86406 | C13: 19803 | D13: 1 | E13: 2761264.9 | F13: 1
A31: Top 50 By Unit Summary
A32: Cable length | B32: Avg Price | C32: Quantity/Mo | D32: Qty by % | E32: Revenue/Mo | F32: Revenue by %
A33: 10ft | B33: 143.32333 | C33: 837 | D33: 0.041714428 | E33: 117583.32 | F33: 0.043692777
A34: 3.3ft | B34: 169.99 | C34: 207 | D34: 0.010316471 | E34: 39934.91 | F34: 0.01483941
A35: 3.9ft | B35: 69.99 | C35: 61 | D35: 0.0030401196 | E35: 3665.94 | F35: 0.0013622264
A36: 4ft | B36: 72.99 | C36: 777 | D36: 0.038724147 | E36: 52520.15 | F36: 0.019515959
A37: 5.25ft | B37: 129.99 | C37: 374 | D37: 0.018639422 | E37: 49904.6 | F37: 0.018544047
A38: 5.2ft | B38: 69.98 | C38: 102 | D38: 0.0050834787 | E38: 7138.52 | F38: 0.0026526021
A39: 5.3ft | B39: 147.2375 | C39: 669 | D39: 0.03334164 | E39: 94627.31 | F39: 0.035162555
A40: 5.5ft | B40: 105.12333 | C40: 2712 | D40: 0.13516073 | E40: 316594.63 | F40: 0.11764338
A41: 5.6ft | B41: 79.99 | C41: 238 | D41: 0.01186145 | E41: 19066.54 | F41: 0.0070849342
A42: 5ft | B42: 168.38156 | C42: 13952 | D42: 0.69534014 | E42: 1956541.1 | F42: 0.72703098
A43: 6.6ft | B43: 249.99 | C43: 136 | D43: 0.0067779716 | E43: 33561.55 | F43: 0.012471134
A44: Total | B44: 127.90779 | C44: 20065 | D44: 1 | E44: 2691138.6 | F44: 1

Sheet Teslong
A1: #VALUE!
A7: Rank by Revenue
A8: Product Name | B8: ASIN | C8: Avg Price | D8: Estimated 12mo Revenue | E8: Monthly Rev | F8: Estimated 12mo Units | G8: Monthly Units | H8: # of Reviews | I8: Tool Rating | J8: Column1 | K8: Link
A9: Teslong Two-Way Articulating Borescope with Light, Industrial Endoscope Inspection Camera with Articulated Probe, Flexible Mechanic Fiber Optic Snake Scope Cam for Wall Automotive Engine Inspect-5FT | B9: B0CJY5C9QX | C9: 129.99 | D9: 10746140 | E9: 895511.65 | F9: 82668 | G9: 6889 | H9: 1347 | I9: 4.7 | J9: https://amazon.com/dp/B0CJY5C9QX | K9: =HYPERLINK(J9) -> https://amazon.com/dp/B0CJY5C9QX
A10: Teslong Two-Way Articulating Borescope, 5.5mm Slim Probe, 5.0'' Industrial Endoscope with Light, 5FT Flexible Snake Scope for Automotive, HVAC & Mechanics | B10: B0DT4H7QQM | C10: 139.99 | D10: 1960945 | E10: 163412.08 | F10: 16308 | G10: 1359 | H10: 263 | I10: 4.6 | J10: https://amazon.com/dp/B0DT4H7QQM | K10: =HYPERLINK(J10) -> https://amazon.com/dp/B0DT4H7QQM
A11: Articulating Borescope with Dual Lens Endoscope Camera, Teslong Two-Way Articulated Industrial Inspection Camera with LED Light, Flexible Mechanic Fiber Optic Snake Scope Cam for Wall Automotive-5FT | B11: B0CJY6SWBN | C11: 149.99 | D11: 1794015.4 | E11: 149501.28 | F11: 13512 | G11: 1126 | H11: 403 | I11: 4.5 | J11: https://amazon.com/dp/B0CJY6SWBN | K11: =HYPERLINK(J11) -> https://amazon.com/dp/B0CJY6SWBN
A12: Articulating Borescope with Dual Lens Endoscope, Teslong 5-inch IPS Automotive Inspection Camera with Two-Way Articulation Tip, 6+1 LED Lights, Mechanics Fiber Optic Scope-Dia. 0.25 inch & L 5.0 feet | B12: B0CHW4FLS7 | C12: 241.99 | D12: 851411.52 | E12: 70950.96 | F12: 2856 | G12: 238 | H12: 203 | I12: 4.2 | J12: https://amazon.com/dp/B0CHW4FLS7 | K12: =HYPERLINK(J12) -> https://amazon.com/dp/B0CHW4FLS7
A13: Teslong 360 Articulating Borescope with Light, 5'' Monitor Industrial Inspection Camera with 4-Way Joystick Articulation, HD Endoscope Camera for Automotive, Pipes, and Mechanics (0.24inch-5FT) | B13: B0DTHZDGYD | C13: 359.98 | D13: 829030.32 | E13: 69085.86 | F13: 1992 | G13: 166 | H13: 39 | I13: 4.8 | J13: https://amazon.com/dp/B0DTHZDGYD | K13: =HYPERLINK(J13) -> https://amazon.com/dp/B0DTHZDGYD
A14: 360 Articulating Borescope with 6” Monitor, Teslong Mechanics Inspection Camera with 4-Way Joystick Articulation, HD Steerable Endoscope Camera with Light, See in Wall Engine Hole Camera(0.24inch-5FT) | B14: B0CLG67RHF | C14: 599.99 | D14: 781035.72 | E14: 65086.31 | F14: 1296 | G14: 108 | H14: 49 | I14: 4.4 | J14: https://amazon.com/dp/B0CLG67RHF | K14: =HYPERLINK(J14) -> https://amazon.com/dp/B0CLG67RHF
A15: Teslong Two-Way Articulating Borescope with Light, 5-inch IPS Endoscope Inspection Camera with Articulation Head, Automotive Mechanics Fiber Optic Scope-0.33inch | B15: B09ZV7KJHL | C15: 279.99 | D15: 634106.88 | E15: 52842.24 | F15: 2268 | G15: 189 | H15: 564 | I15: 4.7 | J15: https://amazon.com/dp/B09ZV7KJHL | K15: =HYPERLINK(J15) -> https://amazon.com/dp/B09ZV7KJHL
A16: Teslong Two-Way Articulating Borescope with Light, USB-C Endoscope Inspection Camera with 5FT Semi-Rigid Probe, Flexible Snake Scope for Home Repair, Automotive, Compatible with iPhone 15/16 & Android | B16: B0F2H49C2D | C16: 67.99 | D16: 530679.84 | E16: 44223.32 | F16: 7200 | G16: 600 | H16: 125 | I16: 4.3 | J16: https://amazon.com/dp/B0F2H49C2D | K16: =HYPERLINK(J16) -> https://amazon.com/dp/B0F2H49C2D
A17: Teslong 3.9mm 4-Way Articulating Borescope with Light, 6'' IPS Endoscope Inspection Camera with 360 Articulated Probe, Flexible Automotive Mechanics Gadgets Fiber Optic Scope Cam (0.15inch-5FT) | B17: B0D7PYRRKD | C17: 699.99 | D17: 490372.68 | E17: 40864.39 | F17: 696 | G17: 58 | H17: 27 | I17: 4.1 | J17: https://amazon.com/dp/B0D7PYRRKD | K17: =HYPERLINK(J17) -> https://amazon.com/dp/B0D7PYRRKD
A18: Teslong 3.9mm Two-Way Articulating Borescope with Light, 5-inch IPS Endoscope Inspection Camera with Articulated Probe, Flexible Automotive Mechanics Gadgets Fiber Optic Scope Cam-0.15inch | B18: B0CLG4LHWP | C18: 349.99 | D18: 378538.44 | E18: 31544.87 | F18: 1200 | G18: 100 | H18: 103 | I18: 4 | J18: https://amazon.com/dp/B0CLG4LHWP | K18: =HYPERLINK(J18) -> https://amazon.com/dp/B0CLG4LHWP
A19: Teslong Dual Lens 360 Articulating Borescope with Light, 5'' Monitor Industrial Inspection Camera with 4-Way Joystick Articulation, HD Endoscope Camera for Automotive and Mechanics (0.24inch-5FT) | B19: B0FFGZC3WX | C19: 499.99 | D19: 239100.6 | E19: 19925.05 | F19: 480 | G19: 40 | H19: 19 | I19: 4 | J19: https://amazon.com/dp/B0FFGZC3WX | K19: =HYPERLINK(J19) -> https://amazon.com/dp/B0FFGZC3WX
A20: Teslong Autofocus Articulating Borescope, 5-inch IPS Endoscope Inspection Camera with Two-Way Articulation Auto Focus Probe, Industrial Fiber Optic Scope for Automotive Mechanics (0.24inch-5FT) | B20: B0D97DVVN3 | C20: 309.99 | D20: 45653.28 | E20: 3804.44 | F20: 144 | G20: 12 | H20: 45 | I20: 4.2 | J20: https://amazon.com/dp/B0D97DVVN3 | K20: =HYPERLINK(J20) -> https://amazon.com/dp/B0D97DVVN3
A21: Teslong Articulating Borescope, Autofocus 5-inch IPS Industrial Endoscope Inspection Camera with Two-Way Articulation Auto Focus Probe, Fiber Optic Scope for Automotive Mechanics (0.33inch-5FT) | B21: B0D9JFTZX5 | C21: 289.99 | D21: 19572.48 | E21: 1631.04 | F21: 72 | G21: 6 | H21: 22 | I21: 4.9 | J21: https://amazon.com/dp/B0D9JFTZX5 | K21: =HYPERLINK(J21) -> https://amazon.com/dp/B0D9JFTZX5
A22: Total | D22: =SUM(D9:D21) -> 19300602 | E22: =SUM(E9:E21) -> 1608383.5
A25: Rank by Units
A26: Product Name | B26: ASIN | C26: Avg Price | D26: Estimated 12mo Revenue | E26: Monthly Rev | F26: Estimated 12mo Units | G26: Monthly Units | H26: # of Reviews | I26: Tool Rating | J26: Column1 | K26: Link
A27: Teslong Two-Way Articulating Borescope with Light, Industrial Endoscope Inspection Camera with Articulated Probe, Flexible Mechanic Fiber Optic Snake Scope Cam for Wall Automotive Engine Inspect-5FT | B27: B0CJY5C9QX | C27: 129.99 | D27: 10746140 | E27: 895511.65 | F27: 82668 | G27: 6889 | H27: 1347 | I27: 4.7 | J27: https://amazon.com/dp/B0CJY5C9QX | K27: =HYPERLINK(J27) -> https://amazon.com/dp/B0CJY5C9QX
A28: Teslong Two-Way Articulating Borescope, 5.5mm Slim Probe, 5.0'' Industrial Endoscope with Light, 5FT Flexible Snake Scope for Automotive, HVAC & Mechanics | B28: B0DT4H7QQM | C28: 139.99 | D28: 1960945 | E28: 163412.08 | F28: 16308 | G28: 1359 | H28: 263 | I28: 4.6 | J28: https://amazon.com/dp/B0DT4H7QQM | K28: =HYPERLINK(J28) -> https://amazon.com/dp/B0DT4H7QQM
A29: Articulating Borescope with Dual Lens Endoscope Camera, Teslong Two-Way Articulated Industrial Inspection Camera with LED Light, Flexible Mechanic Fiber Optic Snake Scope Cam for Wall Automotive-5FT | B29: B0CJY6SWBN | C29: 149.99 | D29: 1794015.4 | E29: 149501.28 | F29: 13512 | G29: 1126 | H29: 403 | I29: 4.5 | J29: https://amazon.com/dp/B0CJY6SWBN | K29: =HYPERLINK(J29) -> https://amazon.com/dp/B0CJY6SWBN
A30: Teslong Two-Way Articulating Borescope with Light, USB-C Endoscope Inspection Camera with 5FT Semi-Rigid Probe, Flexible Snake Scope for Home Repair, Automotive, Compatible with iPhone 15/16 & Android | B30: B0F2H49C2D | C30: 67.99 | D30: 530679.84 | E30: 44223.32 | F30: 7200 | G30: 600 | H30: 125 | I30: 4.3 | J30: https://amazon.com/dp/B0F2H49C2D | K30: =HYPERLINK(J30) -> https://amazon.com/dp/B0F2H49C2D
A31: Articulating Borescope with Dual Lens Endoscope, Teslong 5-inch IPS Automotive Inspection Camera with Two-Way Articulation Tip, 6+1 LED Lights, Mechanics Fiber Optic Scope-Dia. 0.25 inch & L 5.0 feet | B31: B0CHW4FLS7 | C31: 241.99 | D31: 851411.52 | E31: 70950.96 | F31: 2856 | G31: 238 | H31: 203 | I31: 4.2 | J31: https://amazon.com/dp/B0CHW4FLS7 | K31: =HYPERLINK(J31) -> https://amazon.com/dp/B0CHW4FLS7
A32: Teslong Two-Way Articulating Borescope with Light, 5-inch IPS Endoscope Inspection Camera with Articulation Head, Automotive Mechanics Fiber Optic Scope-0.33inch | B32: B09ZV7KJHL | C32: 279.99 | D32: 634106.88 | E32: 52842.24 | F32: 2268 | G32: 189 | H32: 564 | I32: 4.7 | J32: https://amazon.com/dp/B09ZV7KJHL | K32: =HYPERLINK(J32) -> https://amazon.com/dp/B09ZV7KJHL
A33: Teslong 360 Articulating Borescope with Light, 5'' Monitor Industrial Inspection Camera with 4-Way Joystick Articulation, HD Endoscope Camera for Automotive, Pipes, and Mechanics (0.24inch-5FT) | B33: B0DTHZDGYD | C33: 359.98 | D33: 829030.32 | E33: 69085.86 | F33: 1992 | G33: 166 | H33: 39 | I33: 4.8 | J33: https://amazon.com/dp/B0DTHZDGYD | K33: =HYPERLINK(J33) -> https://amazon.com/dp/B0DTHZDGYD
A34: 360 Articulating Borescope with 6” Monitor, Teslong Mechanics Inspection Camera with 4-Way Joystick Articulation, HD Steerable Endoscope Camera with Light, See in Wall Engine Hole Camera(0.24inch-5FT) | B34: B0CLG67RHF | C34: 599.99 | D34: 781035.72 | E34: 65086.31 | F34: 1296 | G34: 108 | H34: 49 | I34: 4.4 | J34: https://amazon.com/dp/B0CLG67RHF | K34: =HYPERLINK(J34) -> https://amazon.com/dp/B0CLG67RHF
A35: Teslong 3.9mm Two-Way Articulating Borescope with Light, 5-inch IPS Endoscope Inspection Camera with Articulated Probe, Flexible Automotive Mechanics Gadgets Fiber Optic Scope Cam-0.15inch | B35: B0CLG4LHWP | C35: 349.99 | D35: 378538.44 | E35: 31544.87 | F35: 1200 | G35: 100 | H35: 103 | I35: 4 | J35: https://amazon.com/dp/B0CLG4LHWP | K35: =HYPERLINK(J35) -> https://amazon.com/dp/B0CLG4LHWP
A36: Teslong 3.9mm 4-Way Articulating Borescope with Light, 6'' IPS Endoscope Inspection Camera with 360 Articulated Probe, Flexible Automotive Mechanics Gadgets Fiber Optic Scope Cam (0.15inch-5FT) | B36: B0D7PYRRKD | C36: 699.99 | D36: 490372.68 | E36: 40864.39 | F36: 696 | G36: 58 | H36: 27 | I36: 4.1 | J36: https://amazon.com/dp/B0D7PYRRKD | K36: =HYPERLINK(J36) -> https://amazon.com/dp/B0D7PYRRKD
A37: Teslong Dual Lens 360 Articulating Borescope with Light, 5'' Monitor Industrial Inspection Camera with 4-Way Joystick Articulation, HD Endoscope Camera for Automotive and Mechanics (0.24inch-5FT) | B37: B0FFGZC3WX | C37: 499.99 | D37: 239100.6 | E37: 19925.05 | F37: 480 | G37: 40 | H37: 19 | I37: 4 | J37: https://amazon.com/dp/B0FFGZC3WX | K37: =HYPERLINK(J37) -> https://amazon.com/dp/B0FFGZC3WX
A38: Teslong Autofocus Articulating Borescope, 5-inch IPS Endoscope Inspection Camera with Two-Way Articulation Auto Focus Probe, Industrial Fiber Optic Scope for Automotive Mechanics (0.24inch-5FT) | B38: B0D97DVVN3 | C38: 309.99 | D38: 45653.28 | E38: 3804.44 | F38: 144 | G38: 12 | H38: 45 | I38: 4.2 | J38: https://amazon.com/dp/B0D97DVVN3 | K38: =HYPERLINK(J38) -> https://amazon.com/dp/B0D97DVVN3
A39: Teslong Articulating Borescope, Autofocus 5-inch IPS Industrial Endoscope Inspection Camera with Two-Way Articulation Auto Focus Probe, Fiber Optic Scope for Automotive Mechanics (0.33inch-5FT) | B39: B0D9JFTZX5 | C39: 289.99 | D39: 19572.48 | E39: 1631.04 | F39: 72 | G39: 6 | H39: 22 | I39: 4.9 | J39: https://amazon.com/dp/B0D9JFTZX5 | K39: =HYPERLINK(J39) -> https://amazon.com/dp/B0D9JFTZX5
A40: Total | F40: =SUM(Teslong!F27:F39) -> 130692 | G40: =SUM(Teslong!G27:G39) -> 10891

Sheet DEPSTECH
A1: #VALUE!
A7: Rank by Revenue
A8: Product Name | B8: ASIN | C8: Avg Price | D8: Estimated 12mo Revenue | E8: Monthly Rev | F8: Estimated 12mo Units | G8: Monthly Units | H8: # of Reviews | I8: Tool Rating | J8: Column1 | K8: Link
A9: DEPSTECH 10FT Articulating Endoscope Camera with Light: Dual Lens Industrial Borescope with 4.5" Screen and Flexible Cable, Video Inspection Snake Scope Camera Tool for Wall, Auto, Pipe, Mechanics | B9: B0F62WJY8N | C9: 159.99 | D9: 965758.2 | E9: 80479.85 | F9: 6816 | G9: 568 | H9: 338 | I9: 4.6 | J9: https://amazon.com/dp/B0F62WJY8N | K9: =HYPERLINK(J9) -> https://amazon.com/dp/B0F62WJY8N
A10: DEPSTECH Dual Lens Two-Way Articulating Borescope Camera with Light, 4.5" Screen and 5FT Flexible Snake Scope Industrial Endoscope, Inspection Video Camera Tool for Wall, Engine, Auto, Mechanics | B10: B0DT16R78W | C10: 129.99 | D10: 536267.88 | E10: 44688.99 | F10: 5016 | G10: 418 | H10: 340 | I10: 4.6 | J10: https://amazon.com/dp/B0DT16R78W | K10: =HYPERLINK(J10) -> https://amazon.com/dp/B0DT16R78W
A11: DEPSTECH Articulating Borescope Camera with Light, 5" IPS HD Screen, Industrial Endoscope Inspection Camera with Two-Way Articulated Probe, 0.24'' Flexible Snake Scope for Wall Automotive Engine - 5FT | B11: B0FD3NRZ5S | C11: 89.99 | D11: 125965.56 | E11: 10497.13 | F11: 1152 | G11: 96 | H11: 101 | I11: 4.6 | J11: https://amazon.com/dp/B0FD3NRZ5S | K11: =HYPERLINK(J11) -> https://amazon.com/dp/B0FD3NRZ5S
A12: DEPSTECH Dual Lens Borescope Camera with Light, Two-Way Articulating Borescope, 5" IPS Dual View Endoscope with 0.33in Slim Probe, 1080P Waterproof Inspection Camera for Wall Auto Engine Inspect-5FT | B12: B0FQC32XV7 | C12: 105.99 | D12: 91437.72 | E12: 7619.81 | F12: 864 | G12: 72 | H12: 77 | I12: 4.7 | J12: https://amazon.com/dp/B0FQC32XV7 | K12: =HYPERLINK(J12) -> https://amazon.com/dp/B0FQC32XV7
A13: Two-Way Articulating Borescope Camera with Light, DEPSTECH Industrial Endoscope with Articulated Probe, Flexible Mechanic Snake Inspection Camera for Wall Automotive Engine Inspect-5FT | B13: B0DPX48VZB | C13: 99.99 | D13: 81339 | E13: 6778.25 | F13: 672 | G13: 56 | H13: 459 | I13: 4.7 | J13: https://amazon.com/dp/B0DPX48VZB | K13: =HYPERLINK(J13) -> https://amazon.com/dp/B0DPX48VZB
A14: DEPSTECH 210° Two-Way Articulating Borescope, 0.24in Ultra-Slim Endoscope Camera with Lights, 4.5” IPS Screen, 5ft Waterproof Flexible Snake Tube, Industrial Inspection Camera for Automotive Mechanics | B14: B0DBZ6Q4YH | C14: 89.99 | D14: 77103.84 | E14: 6425.32 | F14: 732 | G14: 61 | H14: 328 | I14: 4.5 | J14: https://amazon.com/dp/B0DBZ6Q4YH | K14: =HYPERLINK(J14) -> https://amazon.com/dp/B0DBZ6Q4YH
A15: Dual Lens Articulating Borescope, DEPSTECH Endoscope Camera with Light, Articulated Probe, Flexible Snake Inspection Camera for Wall, Automotive Engine Inspect-4.92FT | B15: B0CXSTNWTW | C15: 149.98 | D15: 33571.92 | E15: 2797.66 | F15: 228 | G15: 19 | H15: 440 | I15: 4.7 | J15: https://amazon.com/dp/B0CXSTNWTW | K15: =HYPERLINK(J15) -> https://amazon.com/dp/B0CXSTNWTW
A16: Total | D16: =SUM(D9:D15) -> 1911444.1 | E16: =SUM(E9:E15) -> 159287.01
A19: Rank by Units
A20: Product Name | B20: ASIN | C20: Avg Price | D20: Estimated 12mo Revenue | E20: Monthly Rev | F20: Estimated 12mo Units | G20: Monthly Units | H20: # of Reviews | I20: Tool Rating | J20: Column1 | K20: Link
A21: DEPSTECH 10FT Articulating Endoscope Camera with Light: Dual Lens Industrial Borescope with 4.5" Screen and Flexible Cable, Video Inspection Snake Scope Camera Tool for Wall, Auto, Pipe, Mechanics | B21: B0F62WJY8N | C21: 159.99 | D21: 965758.2 | E21: 80479.85 | F21: 6816 | G21: 568 | H21: 338 | I21: 4.6 | J21: https://amazon.com/dp/B0F62WJY8N | K21: =HYPERLINK(J21) -> https://amazon.com/dp/B0F62WJY8N
A22: DEPSTECH Dual Lens Two-Way Articulating Borescope Camera with Light, 4.5" Screen and 5FT Flexible Snake Scope Industrial Endoscope, Inspection Video Camera Tool for Wall, Engine, Auto, Mechanics | B22: B0DT16R78W | C22: 129.99 | D22: 536267.88 | E22: 44688.99 | F22: 5016 | G22: 418 | H22: 340 | I22: 4.6 | J22: https://amazon.com/dp/B0DT16R78W | K22: =HYPERLINK(J22) -> https://amazon.com/dp/B0DT16R78W
A23: DEPSTECH Articulating Borescope Camera with Light, 5" IPS HD Screen, Industrial Endoscope Inspection Camera with Two-Way Articulated Probe, 0.24'' Flexible Snake Scope for Wall Automotive Engine - 5FT | B23: B0FD3NRZ5S | C23: 89.99 | D23: 125965.56 | E23: 10497.13 | F23: 1152 | G23: 96 | H23: 101 | I23: 4.6 | J23: https://amazon.com/dp/B0FD3NRZ5S | K23: =HYPERLINK(J23) -> https://amazon.com/dp/B0FD3NRZ5S
A24: DEPSTECH Dual Lens Borescope Camera with Light, Two-Way Articulating Borescope, 5" IPS Dual View Endoscope with 0.33in Slim Probe, 1080P Waterproof Inspection Camera for Wall Auto Engine Inspect-5FT | B24: B0FQC32XV7 | C24: 105.99 | D24: 91437.72 | E24: 7619.81 | F24: 864 | G24: 72 | H24: 77 | I24: 4.7 | J24: https://amazon.com/dp/B0FQC32XV7 | K24: =HYPERLINK(J24) -> https://amazon.com/dp/B0FQC32XV7
A25: DEPSTECH 210° Two-Way Articulating Borescope, 0.24in Ultra-Slim Endoscope Camera with Lights, 4.5” IPS Screen, 5ft Waterproof Flexible Snake Tube, Industrial Inspection Camera for Automotive Mechanics | B25: B0DBZ6Q4YH | C25: 89.99 | D25: 77103.84 | E25: 6425.32 | F25: 732 | G25: 61 | H25: 328 | I25: 4.5 | J25: https://amazon.com/dp/B0DBZ6Q4YH | K25: =HYPERLINK(J25) -> https://amazon.com/dp/B0DBZ6Q4YH
A26: Two-Way Articulating Borescope Camera with Light, DEPSTECH Industrial Endoscope with Articulated Probe, Flexible Mechanic Snake Inspection Camera for Wall Automotive Engine Inspect-5FT | B26: B0DPX48VZB | C26: 99.99 | D26: 81339 | E26: 6778.25 | F26: 672 | G26: 56 | H26: 459 | I26: 4.7 | J26: https://amazon.com/dp/B0DPX48VZB | K26: =HYPERLINK(J26) -> https://amazon.com/dp/B0DPX48VZB
A27: Dual Lens Articulating Borescope, DEPSTECH Endoscope Camera with Light, Articulated Probe, Flexible Snake Inspection Camera for Wall, Automotive Engine Inspect-4.92FT | B27: B0CXSTNWTW | C27: 149.98 | D27: 33571.92 | E27: 2797.66 | F27: 228 | G27: 19 | H27: 440 | I27: 4.7 | J27: https://amazon.com/dp/B0CXSTNWTW | K27: =HYPERLINK(J27) -> https://amazon.com/dp/B0CXSTNWTW
A28: Total | F28: =SUM(DEPSTECH!F21:F27) -> 15480 | G28: =SUM(DEPSTECH!G21:G27) -> 1290

Sheet UJOYOK
A1: #VALUE!
A7: Rank by Revenue
A8: Product Name | B8: ASIN | C8: Avg Price | D8: Estimated 12mo Revenue | E8: Monthly Rev | F8: Estimated 12mo Units | G8: Monthly Units | H8: # of Reviews | I8: Tool Rating | J8: Column1 | K8: Link
A9: Two-Way Articulating Borescope with Light, UJOYOK Industrial Endoscope with Snake Scope Camera, Borescope Inspection Camera with Light for Automotive & Aircraft Mechanics, 5.5FT | B9: B0DFHL8YN5 | C9: 105.99 | D9: 743470.2 | E9: 61955.85 | F9: 7440 | G9: 620 | H9: 424 | I9: 4.6 | J9: https://amazon.com/dp/B0DFHL8YN5 | K9: =HYPERLINK(J9) -> https://amazon.com/dp/B0DFHL8YN5
A10: Total | D10: =SUM(D9:D9) -> 743470.2 | E10: =SUM(E9:E9) -> 61955.85
A13: Rank by Units
A14: Product Name | B14: ASIN | C14: Avg Price | D14: Estimated 12mo Revenue | E14: Monthly Rev | F14: Estimated 12mo Units | G14: Monthly Units | H14: # of Reviews | I14: Tool Rating | J14: Column1 | K14: Link
A15: Two-Way Articulating Borescope with Light, UJOYOK Industrial Endoscope with Snake Scope Camera, Borescope Inspection Camera with Light for Automotive & Aircraft Mechanics, 5.5FT | B15: B0DFHL8YN5 | C15: 105.99 | D15: 743470.2 | E15: 61955.85 | F15: 7440 | G15: 620 | H15: 424 | I15: 4.6 | J15: https://amazon.com/dp/B0DFHL8YN5 | K15: =HYPERLINK(J15) -> https://amazon.com/dp/B0DFHL8YN5
A16: Total | F16: =SUM(UJOYOK!F15:F15) -> 7440 | G16: =SUM(UJOYOK!G15:G15) -> 620

Sheet Acoath
A1: #VALUE!
A7: Rank by Revenue
A8: Product Name | B8: ASIN | C8: Avg Price | D8: Estimated 12mo Revenue | E8: Monthly Rev | F8: Estimated 12mo Units | G8: Monthly Units | H8: # of Reviews | I8: Tool Rating | J8: Column1 | K8: Link
A9: Acoath Two-Way Articulating Borescope, Endoscope Camera with Light, Dual-Lens 1080P Industrial Inspection Camera, 4.3" IPS Screen, 32GB Card, IP67 Waterproof Sewer Tools - 5FT | B9: B0FZJ4CQB6 | C9: 139.99 | D9: 635362.44 | E9: 52946.87 | F9: 5496 | G9: 458 | H9: 322 | I9: 4.6 | J9: https://amazon.com/dp/B0FZJ4CQB6 | K9: =HYPERLINK(J9) -> https://amazon.com/dp/B0FZJ4CQB6
A10: Total | D10: =SUM(D9:D9) -> 635362.44 | E10: =SUM(E9:E9) -> 52946.87
A13: Rank by Units
A14: Product Name | B14: ASIN | C14: Avg Price | D14: Estimated 12mo Revenue | E14: Monthly Rev | F14: Estimated 12mo Units | G14: Monthly Units | H14: # of Reviews | I14: Tool Rating | J14: Column1 | K14: Link
A15: Acoath Two-Way Articulating Borescope, Endoscope Camera with Light, Dual-Lens 1080P Industrial Inspection Camera, 4.3" IPS Screen, 32GB Card, IP67 Waterproof Sewer Tools - 5FT | B15: B0FZJ4CQB6 | C15: 139.99 | D15: 635362.44 | E15: 52946.87 | F15: 5496 | G15: 458 | H15: 322 | I15: 4.6 | J15: https://amazon.com/dp/B0FZJ4CQB6 | K15: =HYPERLINK(J15) -> https://amazon.com/dp/B0FZJ4CQB6
A16: Total | F16: =SUM(Acoath!F15:F15) -> 5496 | G16: =SUM(Acoath!G15:G15) -> 458

Sheet Anykit
A1: #VALUE!
A7: Rank by Revenue
A8: Product Name | B8: ASIN | C8: Avg Price | D8: Estimated 12mo Revenue | E8: Monthly Rev | F8: Estimated 12mo Units | G8: Monthly Units | H8: # of Reviews | I8: Tool Rating | J8: Column1 | K8: Link
A9: Anykit Articulating Borescope, 210° Two-Way 0.22in Slim Probe Endoscope with High-Brightness LED Lights, 4.3" IPS HD Video Inspection Snake Camera for Automotive Engine Inspect - 4FT | B9: B0FGJ8WVGP | C9: 72.99 | D9: 503011.68 | E9: 41917.64 | F9: 7560 | G9: 630 | H9: 34 | I9: 4.6 | J9: https://amazon.com/dp/B0FGJ8WVGP | K9: =HYPERLINK(J9) -> https://amazon.com/dp/B0FGJ8WVGP
A10: Borescope Inspection with Light, Industrial Endoscope Camera with 4.3” HD Screen, Waterproof Digital Snake Camera, Semi-Rigid Cable Bore Scope for Home Pipe, Engine, Inside Wall, Duct (11.5 FT) | B10: B0C9L96KF7 | C10: 39.99 | D10: 353871.72 | E10: 29489.31 | F10: 8304 | G10: 692 | H10: 598 | I10: 4.5 | J10: https://amazon.com/dp/B0C9L96KF7 | K10: =HYPERLINK(J10) -> https://amazon.com/dp/B0C9L96KF7
A11: Anykit USB Endoscope Camera with 8 Adjustable LED Lights, Borescope with Semi-Rigid Snake Camera, IP67 Waterproof Inspection Cam Compatible with iPhone and Android Devices (9.8 ft) | B11: B0DQW68W1T | C11: 27.99 | D11: 314760.36 | E11: 26230.03 | F11: 11256 | G11: 938 | H11: 255 | I11: 4.5 | J11: https://amazon.com/dp/B0DQW68W1T | K11: =HYPERLINK(J11) -> https://amazon.com/dp/B0DQW68W1T
A12: Anykit Two-Way Articulating Borescope with Light, 1080P HD Articulating Borescope with Semi-Rigid Snake Camera, Flexible Snake Scope for Wall Automotive, IP67 Waterproof Inspection, 3.9FT | B12: B0FLNCK645 | C12: 55.99 | D12: 280636.08 | E12: 23386.34 | F12: 4872 | G12: 406 | H12: 46 | I12: 4.7 | J12: https://amazon.com/dp/B0FLNCK645 | K12: =HYPERLINK(J12) -> https://amazon.com/dp/B0FLNCK645
A13: Anykit USB Endoscope Camera with 8 Adjustable LED Lights, Borescope with Semi-Rigid Snake Camera, IP67 Waterproof Inspection Cam Compatible with iPhone and Android Devices (50 ft) | B13: B0FGDC15DP | C13: 49.99 | D13: 259798.8 | E13: 21649.9 | F13: 5352 | G13: 446 | H13: 255 | I13: 4.5 | J13: https://amazon.com/dp/B0FGDC15DP | K13: =HYPERLINK(J13) -> https://amazon.com/dp/B0FGDC15DP
A14: Anykit Dual Lens Endoscope Camera with Adjustable Lights, Type C Borescope for Sewer, IP67 Waterproof Semi-Rigid Snake Camera, 1080HD Industrial Scope Inspection Cam, Gadgets for Men(16.5 ft) | B14: B0CKPG2P7F | C14: 16.1 | D14: 237107.76 | E14: 19758.98 | F14: 12036 | G14: 1003 | H14: 151 | I14: 4.5 | J14: https://amazon.com/dp/B0CKPG2P7F | K14: =HYPERLINK(J14) -> https://amazon.com/dp/B0CKPG2P7F
A15: Anykit Dual Lens Endoscope Camera, Type-C Borescope with 8 Adjustable LED Lights, IP67 Waterproof 16.5ft Semi-Rigid Snake Cord Inspection Camera Compatible with Type C iPhone 15 & Android Phone | B15: B0C9C4H2ZH | C15: 26.15 | D15: 133592.88 | E15: 11132.74 | F15: 3576 | G15: 298 | H15: 727 | I15: 4.4 | J15: https://amazon.com/dp/B0C9C4H2ZH | K15: =HYPERLINK(J15) -> https://amazon.com/dp/B0C9C4H2ZH
A16: Anykit Dual Lens Borescope,1080P Industrial Endoscope with Light, IP67 Waterproof Inspection Cam, Sewer Camera with 4.0" IPS Screen, Waterproof 16.5ft Snake Camera, 32GB Card | B16: B0C9L5V3J9 | C16: 79.99 | D16: 110436.36 | E16: 9203.03 | F16: 1380 | G16: 115 | H16: 141 | I16: 4.4 | J16: https://amazon.com/dp/B0C9L5V3J9 | K16: =HYPERLINK(J16) -> https://amazon.com/dp/B0C9L5V3J9
A17: Anykit Dual Lens Endoscope Camera, Type-C Borescope with 8 Adjustable LED Lights, IP67 Waterproof 10ft Semi-Rigid Snake Cord Inspection Camera Compatible with Type C iPhone 15 & Android Phone | B17: B0C9D8MTNC | C17: 25.19 | D17: 98095.92 | E17: 8174.66 | F17: 2688 | G17: 224 | H17: 723 | I17: 4.4 | J17: https://amazon.com/dp/B0C9D8MTNC | K17: =HYPERLINK(J17) -> https://amazon.com/dp/B0C9D8MTNC
A18: Anykit 360° 4 Ways Articulating Borescope, Industrial Endoscope with 0.26 in Articulated Snake Camera, Inspection Camera with 6 Adjustable LED Lights Compatible with Phone and Android - 3.3 FT | B18: B0B74SDPH4 | C18: 472.46 | D18: 64182.48 | E18: 5348.54 | F18: 180 | G18: 15 | H18: 84 | I18: 4.2 | J18: https://amazon.com/dp/B0B74SDPH4 | K18: =HYPERLINK(J18) -> https://amazon.com/dp/B0B74SDPH4
A19: Anykit Borescope Inspection Camera with Light, Industrial Endoscope Camera with 0.3 Slim Probe, 4.3” HD Screen Digital Snake Cam, Semi-Rigid Cable Bore Scope for Pipe, Engine, Inside Wall (33 FT) | B19: B0DCNM5MGW | C19: 49.98 | D19: 39294.6 | E19: 3274.55 | F19: 792 | G19: 66 | H19: 601 | I19: 4.5 | J19: https://amazon.com/dp/B0DCNM5MGW | K19: =HYPERLINK(J19) -> https://amazon.com/dp/B0DCNM5MGW
A20: Anykit 360° Articulated Engine Endoscope, Aviation Hole Sight with 0.25" Convertible Snake Camera, 5" IPS Video Check Camera with Light for Mechanic Maintenance Technician - 3.28' | B20: B0DZMN1941 | C20: 199.99 | D20: 17047.8 | E20: 1420.65 | F20: 84 | G20: 7 | H20: 3 | I20: 4.6 | J20: https://amazon.com/dp/B0DZMN1941 | K20: =HYPERLINK(J20) -> https://amazon.com/dp/B0DZMN1941
A21: Anykit Endoscope Camera with Light,1080P Dual Lens Endoscope，6" IPS Screen Borescope, Plumbing Snake Inspection Camera with Split Screen, 32GB Card, Plumbing Snake Camera for Home (16.5FT) | B21: B0CHH8NY8G | C21: 119.99 | D21: 4022.04 | E21: 335.17 | F21: 36 | G21: 3 | H21: 22 | I21: 4.7 | J21: https://amazon.com/dp/B0CHH8NY8G | K21: =HYPERLINK(J21) -> https://amazon.com/dp/B0CHH8NY8G
A22: Anykit Dual Lens Endoscope Camera with Adjustable Lights, Type C Borescope for Sewer, IP67 Waterproof Semi-Rigid Snake Cameras, 1080HD Industrial Scope Inspection Camera, Gadgets for Men(9.8 ft) | B22: B0CKPHBXXT | C22: 16.1 | F22: 0 | G22: 0 | H22: 151 | I22: 4.5 | J22: https://amazon.com/dp/B0CKPHBXXT | K22: =HYPERLINK(J22) -> https://amazon.com/dp/B0CKPHBXXT
A23: Anykit 1.0MP 1080P Borescope with 8 LED Lights, Endoscope with 3.3ft Semi-Rigid Snake Camera, IP67 Waterproof Inspection Camera for Phone and Tablet | B23: B0CKPG4WCV | C23: 16.1 | F23: 0 | G23: 0 | H23: 151 | I23: 4.5 | J23: https://amazon.com/dp/B0CKPG4WCV | K23: =HYPERLINK(J23) -> https://amazon.com/dp/B0CKPG4WCV
A24: Anykit 360° 4 Ways Articulating Borescope, Industrial Endoscope with 0.26 in Articulated Snake Camera, Inspection Camera with 6 Adjustable LED Lights Compatible with Phone and Android - 3.3 FT | B24: B0G1MM25PR | C24: 169.99 | F24: 0 | G24: 0 | J24: https://amazon.com/dp/B0G1MM25PR | K24: =HYPERLINK(J24) -> https://amazon.com/dp/B0G1MM25PR
A25: Dual Lens Borescope Inspection Cam, Anykit 7.9mm Endoscope Camera with 4.0" IPS Screen, Sewer Cam Adjustble LED Lights, IP67 Waterproof Snake Camera 16.5ft Semi-Rigid Cable 32GB Card | B25: B0CN69DJFX | C25: 33.99 | F25: 0 | G25: 0 | H25: 141 | I25: 4.4 | J25: https://amazon.com/dp/B0CN69DJFX | K25: =HYPERLINK(J25) -> https://amazon.com/dp/B0CN69DJFX
A26: Total | D26: =SUM(D9:D25) -> 2415858.5 | E26: =SUM(E9:E25) -> 201321.54
A29: Rank by Units
A30: Product Name | B30: ASIN | C30: Avg Price | D30: Estimated 12mo Revenue | E30: Monthly Rev | F30: Estimated 12mo Units | G30: Monthly Units | H30: # of Reviews | I30: Tool Rating | J30: Column1 | K30: Link
A31: Anykit Dual Lens Endoscope Camera with Adjustable Lights, Type C Borescope for Sewer, IP67 Waterproof Semi-Rigid Snake Camera, 1080HD Industrial Scope Inspection Cam, Gadgets for Men(16.5 ft) | B31: B0CKPG2P7F | C31: 16.1 | D31: 237107.76 | E31: 19758.98 | F31: 12036 | G31: 1003 | H31: 151 | I31: 4.5 | J31: https://amazon.com/dp/B0CKPG2P7F | K31: =HYPERLINK(J31) -> https://amazon.com/dp/B0CKPG2P7F
A32: Anykit USB Endoscope Camera with 8 Adjustable LED Lights, Borescope with Semi-Rigid Snake Camera, IP67 Waterproof Inspection Cam Compatible with iPhone and Android Devices (9.8 ft) | B32: B0DQW68W1T | C32: 27.99 | D32: 314760.36 | E32: 26230.03 | F32: 11256 | G32: 938 | H32: 255 | I32: 4.5 | J32: https://amazon.com/dp/B0DQW68W1T | K32: =HYPERLINK(J32) -> https://amazon.com/dp/B0DQW68W1T
A33: Borescope Inspection with Light, Industrial Endoscope Camera with 4.3” HD Screen, Waterproof Digital Snake Camera, Semi-Rigid Cable Bore Scope for Home Pipe, Engine, Inside Wall, Duct (11.5 FT) | B33: B0C9L96KF7 | C33: 39.99 | D33: 353871.72 | E33: 29489.31 | F33: 8304 | G33: 692 | H33: 598 | I33: 4.5 | J33: https://amazon.com/dp/B0C9L96KF7 | K33: =HYPERLINK(J33) -> https://amazon.com/dp/B0C9L96KF7
A34: Anykit Articulating Borescope, 210° Two-Way 0.22in Slim Probe Endoscope with High-Brightness LED Lights, 4.3" IPS HD Video Inspection Snake Camera for Automotive Engine Inspect - 4FT | B34: B0FGJ8WVGP | C34: 72.99 | D34: 503011.68 | E34: 41917.64 | F34: 7560 | G34: 630 | H34: 34 | I34: 4.6 | J34: https://amazon.com/dp/B0FGJ8WVGP | K34: =HYPERLINK(J34) -> https://amazon.com/dp/B0FGJ8WVGP
A35: Anykit USB Endoscope Camera with 8 Adjustable LED Lights, Borescope with Semi-Rigid Snake Camera, IP67 Waterproof Inspection Cam Compatible with iPhone and Android Devices (50 ft) | B35: B0FGDC15DP | C35: 49.99 | D35: 259798.8 | E35: 21649.9 | F35: 5352 | G35: 446 | H35: 255 | I35: 4.5 | J35: https://amazon.com/dp/B0FGDC15DP | K35: =HYPERLINK(J35) -> https://amazon.com/dp/B0FGDC15DP
A36: Anykit Two-Way Articulating Borescope with Light, 1080P HD Articulating Borescope with Semi-Rigid Snake Camera, Flexible Snake Scope for Wall Automotive, IP67 Waterproof Inspection, 3.9FT | B36: B0FLNCK645 | C36: 55.99 | D36: 280636.08 | E36: 23386.34 | F36: 4872 | G36: 406 | H36: 46 | I36: 4.7 | J36: https://amazon.com/dp/B0FLNCK645 | K36: =HYPERLINK(J36) -> https://amazon.com/dp/B0FLNCK645
A37: Anykit Dual Lens Endoscope Camera, Type-C Borescope with 8 Adjustable LED Lights, IP67 Waterproof 16.5ft Semi-Rigid Snake Cord Inspection Camera Compatible with Type C iPhone 15 & Android Phone | B37: B0C9C4H2ZH | C37: 26.15 | D37: 133592.88 | E37: 11132.74 | F37: 3576 | G37: 298 | H37: 727 | I37: 4.4 | J37: https://amazon.com/dp/B0C9C4H2ZH | K37: =HYPERLINK(J37) -> https://amazon.com/dp/B0C9C4H2ZH
A38: Anykit Dual Lens Endoscope Camera, Type-C Borescope with 8 Adjustable LED Lights, IP67 Waterproof 10ft Semi-Rigid Snake Cord Inspection Camera Compatible with Type C iPhone 15 & Android Phone | B38: B0C9D8MTNC | C38: 25.19 | D38: 98095.92 | E38: 8174.66 | F38: 2688 | G38: 224 | H38: 723 | I38: 4.4 | J38: https://amazon.com/dp/B0C9D8MTNC | K38: =HYPERLINK(J38) -> https://amazon.com/dp/B0C9D8MTNC
