Workbook

Sheet Summary
A1: Monthly Summaries- Revenue
A2: Brand | B2: # of Listings | C2: Monthly Rev | D2: Estimated 12mo Revenue | E2: Monthly Units | F2: Monthly Rev Market Share % | G2: Price Per Unit | H2: Reviews | I2: Avg Rating
A3: Teslong | B3: 61 | C3: 2346739.8 | D3: 28160877 | E3: 20870 | F3: 0.29056847 | G3: 112.44561 | H3: 29232 | I3: 4.4608956
A4: DEPSTECH | B4: 32 | C4: 758667.51 | D4: 9104010.1 | E4: 9061 | F4: 0.093936643 | G4: 83.728894 | H4: 43809 | I4: 4.5239152
A5: DXZtoz | B5: 4 | C5: 499771.86 | D5: 5997262.3 | E5: 3442 | F5: 0.061880719 | G5: 145.1981 | H5: 2273 | I5: 4.5529256
A6: Kinpthy | B6: 6 | C6: 425188.44 | D6: 5102261.3 | E6: 15011 | F6: 0.052645954 | G6: 28.325124 | H6: 28171 | I6: 4.4
A7: VEVOR | B7: 34 | C7: 385920.01 | D7: 4631040.1 | E7: 2624 | F7: 0.047783818 | G7: 147.07317 | H7: 4450 | I7: 4.2403146
A8: Daxiongmao | B8: 8 | C8: 291064.77 | D8: 3492777.2 | E8: 6631 | F8: 0.036039038 | G8: 43.894551 | H8: 14122 | I8: 4.4558207
A9: Acoath | B9: 6 | C9: 258989.81 | D9: 3107877.7 | E9: 9385 | F9: 0.032067583 | G9: 27.596144 | H9: 4847 | I9: 4.4357334
A10: anysun | B10: 112 | C10: 201584.98 | D10: 2419019.8 | E10: 362 | F10: 0.024959836 | G10: 556.86459 | H10: 6613 | I10: 4.192046
A11: Anykit | B11: 17 | C11: 201321.54 | D11: 2415858.5 | E11: 4843 | F11: 0.024927217 | G11: 41.569593 | H11: 4083 | I11: 4.4556454
A12: WINWEND | B12: 5 | C12: 122350.13 | D12: 1468201.6 | E12: 3683 | F12: 0.01514914 | G12: 33.220236 | H12: 1639 | I12: 4.4926174
A14: Market Total | B14: 1544 | C14: 8076374.5 | D14: 96916494 | E14: 125970 | F14: 1 | G14: 64.113475 | H14: 279685 | I14: 4.3729717
A16: Monthly Summary - Units
A17: Brand | B17: # of Listings | C17: Monthly Rev | D17: Estimated 12mo Units | E17: Monthly Units | F17: Monthly Unit Market Share % | G17: Price Per Unit | H17: Reviews | I17: Avg Rating
A18: Teslong | B18: 61 | C18: 2346739.8 | D18: 250440 | E18: 20870 | F18: 0.16567437 | G18: 112.44561 | H18: 29232 | I18: 4.4608956
A19: Kinpthy | B19: 6 | C19: 425188.44 | D19: 180132 | E19: 15011 | F19: 0.11916329 | G19: 28.325124 | H19: 28171 | I19: 4.4
A20: Acoath | B20: 6 | C20: 258989.81 | D20: 112620 | E20: 9385 | F20: 0.074501866 | G20: 27.596144 | H20: 4847 | I20: 4.4357334
A21: DEPSTECH | B21: 32 | C21: 758667.51 | D21: 108732 | E21: 9061 | F21: 0.071929825 | G21: 83.728894 | H21: 43809 | I21: 4.5239152
A22: Daxiongmao | B22: 8 | C22: 291064.77 | D22: 79572 | E22: 6631 | F22: 0.052639517 | G22: 43.894551 | H22: 14122 | I22: 4.4558207
A23: Anykit | B23: 17 | C23: 201321.54 | D23: 58116 | E23: 4843 | F23: 0.038445662 | G23: 41.569593 | H23: 4083 | I23: 4.4556454
A24: WINWEND | B24: 5 | C24: 122350.13 | D24: 44196 | E24: 3683 | F24: 0.02923712 | G24: 33.220236 | H24: 1639 | I24: 4.4926174
A25: DXZtoz | B25: 4 | C25: 499771.86 | D25: 41304 | E25: 3442 | F25: 0.027323966 | G25: 145.1981 | H25: 2273 | I25: 4.5529256
A26: Elecshion | B26: 2 | C26: 99853.16 | D26: 41112 | E26: 3426 | F26: 0.027196952 | G26: 29.145698 | H26: 2034 | I26: 4.3419371
A27: Ennovor | B27: 8 | C27: 83900.13 | D27: 40668 | E27: 3389 | F27: 0.026903231 | G27: 24.756604 | H27: 12153 | I27: 4.3971859
A29: Market Total | B29: 1544 | C29: 8076374.5 | D29: 1511640 | E29: 125970 | F29: 1 | G29: 64.113475 | H29: 279685 | I29: 4.3729717

Sheet Top 50
A1: Rank By Monthly Revenue - ONLY
A2: Ranking | B2: ASIN | C2: Product Name | D2: Brand | E2: Type | F2: 2/4-way | G2: Display | H2: Lens diameter | I2: Lens count | J2: Cable length | K2: Price | L2: Est. Monthly Retail Rev | M2: Est. Monthly Units Sold | N2: # of Reviews | O2: Avg. Rating | P2: Column2 | Q2: Link
A3: 1 | B3: B0CJY5C9QX | C3: Teslong Two-Way Articulating Borescope with Light, Industrial Endoscope Inspection Camera with Articulated Probe, Flexible Mechanic Fiber Optic Snake Scope Cam for Wall Automotive Engine Inspect-5FT | D3: teslong | E3: Articulation | F3: 2-way | G3: 4.5" | H3: 8mm | I3: Single | J3: 5ft | K3: 129.99 | L3: 987385.82 | M3: 7596 | N3: 1220 | O3: 4.7 | P3: https://amazon.com/dp/B0CJY5C9QX | Q3: =HYPERLINK(P3) -> https://amazon.com/dp/B0CJY5C9QX
A4: 2 | B4: B0B28HRSBP | C4: DXZtoz Two-Way Articulating Borescope, Industrial Endoscope with 0.33in Articulated Snake Camera, Video Inspection Scope with Light for Automotive Aircraft Mechanics- 5.5FT | D4: dxztoz | E4: Articulation | F4: 2-way | G4: 4.3" | H4: 8.5mm | I4: Single | J4: 5.5ft | K4: 139.39 | L4: 344006.92 | M4: 2468 | N4: 1579 | O4: 4.6 | P4: https://amazon.com/dp/B0B28HRSBP | Q4: =HYPERLINK(P4) -> https://amazon.com/dp/B0B28HRSBP
A5: 3 | B5: B0928Q3T42 | C5: DEPSTECH Dual Lens Industrial Endoscope, 1080P Digital Borescope Inspection Camera, 7.9mm IP67 Waterproof Sewer Camera with 4.3" LCD Screen, 7 LED Lights, 16.5FT Semi-Rigid Cable, 32GB Card-Black | D5: depstech | E5: Landscape | G5: 4.3" | H5: 8mm | I5: Dual | J5: 16.5ft | K5: 69.99 | L5: 220851.8 | M5: 3560 | N5: 6846 | O5: 4.6 | P5: https://amazon.com/dp/B0928Q3T42 | Q5: =HYPERLINK(P5) -> https://amazon.com/dp/B0928Q3T42
A6: 4 | B6: B0C4V5LWWL | C6: Endoscope Camera with Light, 1920P HD Borescope Tools with 8 Adjustable LED Lights, Endoscope with Semi-Rigid Snake Camera, Inspection Borescope for iOS and Android - 16.4ft Single Lens | D6: kinpthy | E6: USB | G6: App | H6: 8mm | I6: Single | J6: 16.5ft | K6: 32.99 | L6: 203161.48 | M6: 7427 | N6: 5630 | O6: 4.4 | P6: https://amazon.com/dp/B0C4V5LWWL | Q6: =HYPERLINK(P6) -> https://amazon.com/dp/B0C4V5LWWL
A7: 5 | B7: B0DGFBCH38 | C7: Acoath Endoscope Camera with Light, Dual-Lens 1920P HD Borescope with 8 Adjustable LED Lights, IP67 Waterproof Boroscope Inspection Tools, 16.4ft Semi-Rigid Snake Camera for iOS & Android | D7: acoath | E7: USB | G7: App | H7: 8mm | I7: Dual | J7: 16.5ft | K7: 29.99 | L7: 167216.53 | M7: 6452 | N7: 1327 | O7: 4.4 | P7: https://amazon.com/dp/B0DGFBCH38 | Q7: =HYPERLINK(P7) -> https://amazon.com/dp/B0DGFBCH38
A8: 6 | B8: B0CJY6SWBN | C8: Articulating Borescope with Dual Lens Endoscope Camera, Teslong Two-Way Articulated Industrial Inspection Camera with LED Light, Flexible Mechanic Fiber Optic Snake Scope Cam for Wall Automotive-5FT | D8: teslong | E8: Articulation | F8: 2-way | G8: 4.5" | H8: 8mm | I8: Dual | J8: 5ft | K8: 149.99 | L8: 153980.79 | M8: 1132 | N8: 378 | O8: 4.5 | P8: https://amazon.com/dp/B0CJY6SWBN | Q8: =HYPERLINK(P8) -> https://amazon.com/dp/B0CJY6SWBN
A9: 7 | B9: B07TV2BFVR | C9: Teslong Inspection Camera, Dual Lens Borescope Camera with Light, NTS300 5" IPS Industrial Endoscope, 1080P Waterproof Flexible Mechanic Fiber Optic Snake Scope Cam for Wall Automotive Engine (16.5FT) | D9: teslong | E9: Handheld | G9: 5.0" | H9: 5.5mm | I9: Dual | J9: 16.5ft | K9: 159.99 | L9: 139510.59 | M9: 872 | N9: 3569 | O9: 4.6 | P9: https://amazon.com/dp/B07TV2BFVR | Q9: =HYPERLINK(P9) -> https://amazon.com/dp/B07TV2BFVR
A10: 8 | B10: B0DT4H7QQM | C10: Teslong Two-Way Articulating Borescope, 5.5mm Slim Probe, 5.0'' Industrial Endoscope with Light, 5FT Flexible Snake Scope for Automotive, HVAC & Mechanics | D10: teslong | E10: Articulation | F10: 2-way | G10: 5.0" | H10: 5.5mm | I10: Single | J10: 5ft | K10: 139.99 | L10: 136179 | M10: 1103 | N10: 217 | O10: 4.5 | P10: https://amazon.com/dp/B0DT4H7QQM | Q10: =HYPERLINK(P10) -> https://amazon.com/dp/B0DT4H7QQM
A11: 9 | B11: B0C9JR3N4W | C11: Endoscope Camera with Light,1920P HD Borescope Tools with 8 Adjustable LED Lights, Endoscope with Semi-Rigid Snake Camera, IP67 Waterproof Inspection Borescope for iOS and Android-16.4ft Dual-Lens | D11: kinpthy | E11: USB | G11: App | H11: 8mm | I11: Dual | J11: 16.5ft | K11: 35.99 | L11: 130442.87 | M11: 3613 | N11: 5630 | O11: 4.4 | P11: https://amazon.com/dp/B0C9JR3N4W | Q11: =HYPERLINK(P11) -> https://amazon.com/dp/B0C9JR3N4W
A12: 10 | B12: B0C3B32Q9Z | C12: DXZtoz Dual-Lens Articulating Borescope, Engine Endoscope with 0.33in Two-Way Articulated Snake Camera, 5'' Dual Screen, 1080P Inspection Camera with Light for Automotive Home Mechanics-5FT | D12: dxztoz | E12: Articulation | F12: 2-way | G12: 5.0" | H12: 8mm | I12: Dual | J12: 5ft | K12: 159.99 | L12: 114335.84 | M12: 731 | N12: 477 | O12: 4.5 | P12: https://amazon.com/dp/B0C3B32Q9Z | Q12: =HYPERLINK(P12) -> https://amazon.com/dp/B0C3B32Q9Z
A13: 11 | B13: B0CM3FBXJT | C13: VEVOR Sewer Inspection Camera, 300 ft/91.5 m, 9" Pipeline Camera w/DVR & 512Hz Locator, IP68 Waterproof, 12 LEDs, 16 GB SD Card for Sewer, Drain & Duct Pipe Plumbing | D13: vevor | E13: Sewer camera | G13: 9.0" | H13: 23mm | I13: Single | J13: 300ft | K13: 781.9 | L13: 111145.84 | M13: 187 | N13: 25 | O13: 4.1 | P13: https://amazon.com/dp/B0CM3FBXJT | Q13: =HYPERLINK(P13) -> https://amazon.com/dp/B0CM3FBXJT
A14: 12 | B14: B0C3R381FC | C14: Endoscope Camera with Light, Borescope Camera with 4.3" IPS Screen, 1920P HD with 8 LED Lights, 16.4FT Semi-Rigid Cord Bore Scope, Gadgets for Men & Tools for Men | D14: daxiongmao | E14: Landscape | F14: No camera | G14: 4.3" | H14: 8mm | I14: Single | J14: 16.5ft | K14: 39.99 | L14: 110017.32 | M14: 2910 | N14: 4009 | O14: 4.5 | P14: https://amazon.com/dp/B0C3R381FC | Q14: =HYPERLINK(P14) -> https://amazon.com/dp/B0C3R381FC
A15: 13 | B15: B0DFHL8YN5 | C15: Two-Way Articulating Borescope with Light, UJOYOK Industrial Endoscope with Snake Scope Camera, Borescope Inspection Camera with Light for Automotive & Aircraft Mechanics, 5.5FT | D15: ujoyok | E15: Articulation | F15: 2-way | G15: 4.3" | H15: 8mm | I15: Single | J15: 5.5ft | K15: 105.99 | L15: 107107.5 | M15: 1088 | N15: 368 | O15: 4.6 | P15: https://amazon.com/dp/B0DFHL8YN5 | Q15: =HYPERLINK(P15) -> https://amazon.com/dp/B0DFHL8YN5
A16: 14 | B16: B0CJC65Q9P | C16: Endoscope Camera with Light, 1080P HD Borescope with 8 Adjustable Lights, 4.3" Endoscope with 33 ft Semi-Rigid Snake Camera, IP67 Waterproof Borescopese for Sewer, Cool Gadgets & Tools for Men | D16: daxiongmao | K16: 42.98 | L16: 99487.06 | M16: 1661 | N16: 1934 | O16: 4.4 | P16: https://amazon.com/dp/B0CJC65Q9P | Q16: =HYPERLINK(P16) -> https://amazon.com/dp/B0CJC65Q9P
A17: 15 | B17: B0DK965BZP | C17: Teslong Endoscope Borescope with Light, Snake Inspection Camera for Automotive Engine, Waterproof Fiber Optic Camera for Mechanics - Ideal for Wall, Vent, Wire Video Scope (16.5FT) | D17: teslong | E17: Landscape | G17: 4.3" | H17: 8mm | I17: Single | J17: 16.5ft | K17: 37.99 | L17: 97842.86 | M17: 2035 | N17: 287 | O17: 4.5 | P17: https://amazon.com/dp/B0DK965BZP | Q17: =HYPERLINK(P17) -> https://amazon.com/dp/B0DK965BZP
A18: 16 | B18: B0BL7RK5JJ | C18: Triple Lens Borescope Tool, DEPSTECH 5" IPS Screen Endoscope Camera with Lights, 1080P Sewer Inspection Camera & Split Screen, 180° Rotation, IP67 Snake Cable, Gadget for Automotive Mechanical Repair | D18: depstech | K18: 109.99 | L18: 93363.89 | M18: 931 | N18: 1423 | O18: 4.3 | P18: https://amazon.com/dp/B0BL7RK5JJ | Q18: =HYPERLINK(P18) -> https://amazon.com/dp/B0BL7RK5JJ
A19: 17 | B19: B0CMCSGPJC | C19: [Dual-Lens] Endoscope Camera with Light, 1920P HD Borescope with 8+1 Adjustable LED Lights, IP67 Waterproof 16.5FT Semi-Rigid Snake Cord Inspection Camera for iPhone, iPad and Android Phone (Type C) | D19: elecshion | E19: USB | G19: App | H19: 8mm | I19: Dual | J19: 16.5ft | K19: 35.99 | L19: 89078.92 | M19: 3011 | N19: 1181 | O19: 4.3 | P19: https://amazon.com/dp/B0CMCSGPJC | Q19: =HYPERLINK(P19) -> https://amazon.com/dp/B0CMCSGPJC
A20: 18 | B20: B09ZV7KJHL | C20: Teslong Two-Way Articulating Borescope with Light, 5-inch IPS Endoscope Inspection Camera with Articulation Head, Automotive Mechanics Fiber Optic Scope-0.33inch | D20: teslong | E20: Articulation | F20: 2-way | G20: 5.0" | H20: 8mm | I20: Single | J20: 5ft | K20: 279.99 | L20: 86726.6 | M20: 368 | N20: 555 | O20: 4.7 | P20: https://amazon.com/dp/B09ZV7KJHL | Q20: =HYPERLINK(P20) -> https://amazon.com/dp/B09ZV7KJHL
A21: 19 | B21: B0CP538LN1 | C21: WINWEND Endoscope Camera with Light - IP67 Waterproof Borescope Camera with 8 Adjustable LED Lights | 4.3" LCD Screen Borescope | HD 1080P Inspection Cameras with 16.5ft Semi-Rigid Cord Tools for Men | D21: winwend | E21: Handheld | F21: No camera | G21: 4.3" | H21: 8mm | I21: Single | J21: 16.5ft | K21: 31.96 | L21: 86389.68 | M21: 2558 | N21: 1179 | O21: 4.5 | P21: https://amazon.com/dp/B0CP538LN1 | Q21: =HYPERLINK(P21) -> https://amazon.com/dp/B0CP538LN1
A22: 20 | B22: B0DD6YVBHD | C22: DEPSTECH 50ft Sewer Camera, 1080P HD Triple Lens Borescope, 5" IPS Screen Endoscope with Light, IP67 Waterproof Plumbing Drain Pipe Snake Inspection Camera with 32G Card, Carry Case | D22: depstech | E22: Landscape | G22: 5.0" | H22: 8mm | I22: Triple | J22: 50ft | K22: 99.98 | L22: 78676.55 | M22: 604 | N22: 273 | O22: 4.4 | P22: https://amazon.com/dp/B0DD6YVBHD | Q22: =HYPERLINK(P22) -> https://amazon.com/dp/B0DD6YVBHD
A23: 21 | B23: B0FKM8K5QX | C23: DEPSTECH Inspection Endoscope Camera with Lights: 1080P Triple Lens Snake Camera with 5" Screen and 16.5FT Flexible Cable, Waterproof Industrial Borescope Tool for Auto, Wall, Sewer, Pipe, Mechanics | D23: depstech | K23: 56.98 | L23: 76045.74 | M23: 1014 | N23: 155 | O23: 4.7 | P23: https://amazon.com/dp/B0FKM8K5QX | Q23: =HYPERLINK(P23) -> https://amazon.com/dp/B0FKM8K5QX
A24: 22 | B24: B0CHW4FLS7 | C24: Articulating Borescope with Dual Lens Endoscope, Teslong 5-inch IPS Automotive Inspection Camera with Two-Way Articulation Tip, 6+1 LED Lights, Mechanics Fiber Optic Scope-Dia. 0.25 inch & L 5.0 feet | D24: teslong | E24: Articulation | F24: 2-way | G24: 5.0" | H24: 6.5mm | I24: Dual | J24: 5ft | K24: 299.99 | L24: 68045.02 | M24: 227 | N24: 191 | O24: 4.2 | P24: https://amazon.com/dp/B0CHW4FLS7 | Q24: =HYPERLINK(P24) -> https://amazon.com/dp/B0CHW4FLS7
A25: 23 | B25: B0F62WJY8N | C25: DEPSTECH 10FT Articulating Endoscope Camera with Light: Dual Lens Industrial Borescope with 4.5" Screen and Flexible Cable, Video Inspection Snake Scope Camera Tool for Wall, Auto, Pipe, Mechanics | D25: depstech | E25: Articulation | F25: 2-way | G25: 4.5" | H25: 8mm | I25: Dual | J25: 10ft | K25: 159.99 | L25: 60854.36 | M25: 420 | N25: 303 | O25: 4.5 | P25: https://amazon.com/dp/B0F62WJY8N | Q25: =HYPERLINK(P25) -> https://amazon.com/dp/B0F62WJY8N
A26: 24 | B26: B0DPHJSPBY | C26: FOXWELL 2-Way Articulating Borescope Camera with Light, 0.24in Industrial Endoscope Inspection Camera with Articulated Snake Cameras, HD Video Scope for Automotive Engine HVAC Inspection - 5.25FT | D26: foxwell | E26: Articulation | F26: 2-way | G26: 4.3" | H26: 6.2mm | I26: Single | J26: 5.25ft | K26: 159.99 | L26: 59879.58 | M26: 413 | N26: 123 | O26: 4.8 | P26: https://amazon.com/dp/B0DPHJSPBY | Q26: =HYPERLINK(P26) -> https://amazon.com/dp/B0DPHJSPBY
A27: 25 | B27: B0D54NQWZH | C27: Klein Tools ET17 Utility Borescope with 5.5 mm 9.8-Foot Waterproof Gooseneck Snake, LEDs, 4.3-Inch LCD, Attachments, Endoscope Inspection Camera | D27: klein tools | E27: Landscape | G27: 4.3" | H27: 5.5mm | I27: Single | J27: 9.8ft | K27: 100.99 | L27: 57027.69 | M27: 560 | N27: 113 | O27: 4.5 | P27: https://amazon.com/dp/B0D54NQWZH | Q27: =HYPERLINK(P27) -> https://amazon.com/dp/B0D54NQWZH
A28: 26 | B28: B0FC2HS5GZ | C28: Endoscope with Light, 1920P HD Borescope with 8 Adjustable LED Lights, 16.4FT Semi-Rigid Snake Camera, IP67 Waterproof Inspection Tool for iPhone & Android - Dual Lens (Black) | D28: papiblu | E28: USB | G28: App | H28: 8mm | I28: Dual | J28: 16.5ft | K28: 18.89 | L28: 56608.4 | M28: 2698 | N28: 257 | O28: 4.4 | P28: https://amazon.com/dp/B0FC2HS5GZ | Q28: =HYPERLINK(P28) -> https://amazon.com/dp/B0FC2HS5GZ
A29: 27 | B29: B0DTHZDGYD | C29: Teslong 360 Articulating Borescope with Light, 5'' Monitor Industrial Inspection Camera with 4-Way Joystick Articulation, HD Endoscope Camera for Automotive, Pipes, and Mechanics (0.24inch-5FT) | D29: teslong | E29: Articulation | F29: 4-way | G29: 5.0" | H29: 6mm | I29: Single | J29: 5ft | K29: 359.99 | L29: 55683.1 | M29: 135 | N29: 32 | O29: 4.8 | P29: https://amazon.com/dp/B0DTHZDGYD | Q29: =HYPERLINK(P29) -> https://amazon.com/dp/B0DTHZDGYD
A30: 28 | B30: B0DYDXH1NQ | C30: Teslong Dual Lens Endoscope with Light, Mechanic Borescope Inspection Camera, Fiber Optic Scope, Flexible Snake Probe for Automotive, HVAC, Wall & Home Inspections (16.5FT) | D30: teslong | E30: Landscape | G30: 4.3" | H30: 8mm | I30: Dual | J30: 16.5ft | K30: 59.99 | L30: 55279.46 | M30: 921 | N30: 81 | O30: 4.4 | P30: https://amazon.com/dp/B0DYDXH1NQ | Q30: =HYPERLINK(P30) -> https://amazon.com/dp/B0DYDXH1NQ
A31: 29 | B31: B0DT16R78W | C31: DEPSTECH Dual Lens Two-Way Articulating Borescope Camera with Light, 4.5" Screen and 5FT Flexible Snake Scope Industrial Endoscope, Inspection Video Camera Tool for Wall, Engine, Auto, Mechanics | D31: depstech | E31: Articulation | F31: 2-way | G31: 4.5" | H31: 8mm | I31: Dual | J31: 5ft | K31: 129.99 | L31: 51221.37 | M31: 442 | N31: 299 | O31: 4.5 | P31: https://amazon.com/dp/B0DT16R78W | Q31: =HYPERLINK(P31) -> https://amazon.com/dp/B0DT16R78W
A32: 30 | B32: B0C9GR791B | C32: VEVOR Articulating Borescope Camera with Light, Two-Way Articulated Endoscope Inspection Camera with 6.4mm Tiny Lens, 5" IPS 1080P HD Screen, 8X Zoom, 8 LED Light Snake Cameras for Auto, Plumbing | D32: vevor | E32: Articulation | F32: 2-way | G32: 5.0" | H32: 6.4mm | I32: Single | J32: 5ft | K32: 102.99 | L32: 49433.48 | M32: 600 | N32: 470 | O32: 4.6 | P32: https://amazon.com/dp/B0C9GR791B | Q32: =HYPERLINK(P32) -> https://amazon.com/dp/B0C9GR791B
A33: 31 | B33: B0DT98YB3X | C33: Two-Way Articulating Borescope Camera with Light: Industrial Endoscope Inspection Snake Camera - Flexible Bore Scope Cam with 0.33in Articulated Probe for Mechanic Automotive Engine Wall - 5.5FT | D33: wanawong k | E33: Articulation | F33: 2-way | G33: 4.3" | H33: 8mm | I33: Single | J33: 5.5ft | K33: 79.99 | L33: 47636.37 | M33: 596 | N33: 199 | O33: 4.5 | P33: https://amazon.com/dp/B0DT98YB3X | Q33: =HYPERLINK(P33) -> https://amazon.com/dp/B0DT98YB3X
A34: 32 | B34: B0FKH261T7 | C34: ONDASHCAM Sewer Camera, Self Leveling Drain Camera 100ft with Meter Counter, 9" HD Plumbing Cameras Snake with 12 LED Lights, 5100mAh Battery, IP68 & 32GB DVR Recorder, Duct Sewer Line Pipe Inspection | D34: ondashcam | K34: 341.99 | L34: 47371.55 | M34: 123 | N34: 7 | O34: 3.5 | P34: https://amazon.com/dp/B0FKH261T7 | Q34: =HYPERLINK(P34) -> https://amazon.com/dp/B0FKH261T7
A35: 33 | B35: B08519V6GW | C35: Teslong Inspection Camera, Dual Lens Borescope Camera with Light, NTS300 5" IPS Industrial Endoscope, 1080P Waterproof Flexible Mechanic Fiber Optic Snake Scope Cam for Wall Automotive Engine (10FT) | D35: teslong | K35: 149.99 | L35: 46789.9 | M35: 312 | N35: 3569 | O35: 4.6 | P35: https://amazon.com/dp/B08519V6GW | Q35: =HYPERLINK(P35) -> https://amazon.com/dp/B08519V6GW
A36: 34 | B36: B0DT45G8F3 | C36: Epicmate Triple Lens Sewer Inspection Camera-Endoscope Camera with Light 50 ft, 5" IPS Sewer Snake Camera with Lights 1080P Industrial Borescope, IP67 Waterproof Plumbing Pipe Snake Camera(32G Card) | D36: bestisan | E36: Portrait | G36: 5.0" | H36: 8mm | I36: Triple | J36: 50ft | K36: 125.99 | L36: 44076.03 | M36: 410 | N36: 123 | O36: 4.7 | P36: https://amazon.com/dp/B0DT45G8F3 | Q36: =HYPERLINK(P36) -> https://amazon.com/dp/B0DT45G8F3
A37: 35 | B37: B0DWSKVF5H | C37: Endoscope Camera with Light: 5" Dual-Lens Inspection Borescope Camera for Sewer - 16.4ft Waterproof Industrial Endoscope - Flexible Snake Bore Scope for Plumbing Automotive | D37: tgjor | E37: Handheld | F37: No camera | G37: 5.0" | H37: 8mm | I37: Dual | J37: 16.5ft | K37: 49.99 | L37: 42469.67 | M37: 991 | N37: 874 | O37: 4.5 | P37: https://amazon.com/dp/B0DWSKVF5H | Q37: =HYPERLINK(P37) -> https://amazon.com/dp/B0DWSKVF5H
A38: 36 | B38: B0FGJ8WVGP | C38: Anykit Articulating Borescope, 210° Two-Way 0.22in Slim Probe Endoscope with High-Brightness LED Lights, 4.3" IPS HD Video Inspection Snake Camera for Automotive Engine Inspect - 4FT | D38: anykit | K38: 72.99 | L38: 41917.64 | M38: 630 | N38: 34 | O38: 4.6 | P38: https://amazon.com/dp/B0FGJ8WVGP | Q38: =HYPERLINK(P38) -> https://amazon.com/dp/B0FGJ8WVGP
A39: 37 | B39: B0BXSMSS7M | C39: Endoscope Camera with Light, 1080P HD Borescope with 8 Adjustable Lights, 4.3" Endoscope with 16.4 ft Semi-Rigid Snake Camera, IP67 Waterproof Borescopese for Sewer, Cool Gadgets & Tools for Men | D39: daxiongmao | E39: Handheld | F39: No camera | G39: 4.3" | H39: 8mm | I39: Single | J39: 16.5ft | K39: 29.71 | L39: 40853.74 | M39: 1134 | N39: 1934 | O39: 4.4 | P39: https://amazon.com/dp/B0BXSMSS7M | Q39: =HYPERLINK(P39) -> https://amazon.com/dp/B0BXSMSS7M
A40: 38 | B40: B0F1CXQ3YS | C40: Endoscope Camera with Light, 1920P HD Borescope Inspection Camera with 4.3" IPS Screen, AukonVee IP67 Waterproof with 8 LEDs & 16.5ft Semi-Rigid Snake Camera for Automotive Pipe Tools Gadgets for Men | D40: aukonvee | E40: Landscape | F40: No camera | G40: 4.3" | H40: 8mm | I40: Single | J40: 16.5ft | K40: 39.99 | L40: 38126.65 | M40: 1336 | N40: 322 | O40: 4.5 | P40: https://amazon.com/dp/B0F1CXQ3YS | Q40: =HYPERLINK(P40) -> https://amazon.com/dp/B0F1CXQ3YS
...

Sheet Top 50 Type Summary
A1: Top 50 By Revenue Summary
A2: Type | B2: Avg Price | C2: Quantity/Mo | D2: Qty by % | E2: Revenue/Mo | F2: Revenue by %
A3: Articulation | B3: 171.88333 | C3: 17522 | D3: 0.24262985 | E3: 2357490.6 | F3: 0.48004123
A4: Handheld | B4: 81.688 | C4: 5780 | D4: 0.080036556 | E4: 344790.92 | F4: 0.070207643
A5: Landscape | B5: 69.28 | C5: 14295 | D5: 0.19794508 | E5: 764554.35 | F5: 0.15568147
A6: Portrait | B6: 125.99 | C6: 410 | D6: 0.0056773336 | E6: 44076.03 | F6: 0.0089749294
A7: Sewer camera | B7: 781.9 | C7: 187 | D7: 0.002589418 | E7: 111145.84 | F7: 0.02263194
A8: USB | B8: 30.474286 | C8: 25522 | D8: 0.35340709 | E8: 714946.66 | F8: 0.14558017
B9: 106.07909 | C9: 8501 | D9: 0.11771467 | E9: 574012.51 | F9: 0.11688262
A10: Total | B10: 195.32782 | C10: 72217 | D10: 1 | E10: 4911016.9 | F10: 1
A28: Top 50 By Unit Summary
A29: Type | B29: Avg Price | C29: Quantity/Mo | D29: Qty by % | E29: Revenue/Mo | F29: Revenue by %
A30: Articulation | B30: 137.55667 | C30: 14118 | D30: 0.17054638 | E30: 1842995.9 | F30: 0.42993395
A31: Handheld | B31: 61.528 | C31: 6437 | D31: 0.077759389 | E31: 337349.27 | F31: 0.078696814
A32: Landscape | B32: 42.97 | C32: 14334 | D32: 0.17315568 | E32: 636378.6 | F32: 0.14845435
A33: USB | B33: 27.686429 | C33: 32474 | D33: 0.39228809 | E33: 876990.66 | F33: 0.20458432
B34: 36.933125 | C34: 15418 | D34: 0.18625047 | E34: 592981.01 | F34: 0.13833057
A35: Total | B35: 61.334844 | C35: 82781 | D35: 1 | E35: 4286695.4 | F35: 1

Sheet Top50 2or4way Summary 
A1: Top 50 By Revenue Summary
A2: 2/4-way | B2: Avg Price | C2: Quantity/Mo | D2: Qty by % | E2: Revenue/Mo | F2: Revenue by %
A3: 2-way | B3: 158.44714 | C3: 17387 | D3: 0.24076049 | E3: 2301807.5 | F3: 0.46870282
A4: 4-way | B4: 359.99 | C4: 135 | D4: 0.0018693659 | E4: 55683.1 | F4: 0.011338405
A5: No camera | B5: 37.932857 | C5: 11084 | D5: 0.15348187 | E5: 388441.87 | F5: 0.079096016
B6: 111.56393 | C6: 43611 | D6: 0.60388828 | E6: 2165084.4 | F6: 0.44086276
A7: Total | B7: 166.98348 | C7: 72217 | D7: 1 | E7: 4911016.9 | F7: 1
A25: Top 50 By Unit Summary
A26: 2/4-way | B26: Avg Price | C26: Quantity/Mo | D26: Qty by % | E26: Revenue/Mo | F26: Revenue by %
A27: 2-way | B27: 137.55667 | C27: 14118 | D27: 0.17054638 | E27: 1842995.9 | F27: 0.42993395
A28: No camera | B28: 36.641 | C28: 13383 | D28: 0.16166753 | E28: 460243.16 | F28: 0.10736549
B29: 38.426471 | C29: 55280 | D29: 0.66778609 | E29: 1983456.4 | F29: 0.46270056
A30: Total | B30: 70.874712 | C30: 82781 | D30: 1 | E30: 4286695.4 | F30: 1

Sheet Top 50 Display Summary 
A1: Top 50 By Revenue Summary
A2: Display | B2: Avg Price | C2: Quantity/Mo | D2: Qty by % | E2: Revenue/Mo | F2: Revenue by %
A3: 4.3" | B3: 82.49 | C3: 22151 | D3: 0.30672833 | E3: 1406766.4 | F3: 0.28645115
A4: 4.5" | B4: 142.49 | C4: 9590 | D4: 0.13279422 | E4: 1253442.3 | F4: 0.25523071
A5: 5.0" | B5: 174.15273 | C5: 6266 | D5: 0.086766274 | E5: 850703.12 | F5: 0.17322342
A6: 9.0" | B6: 781.9 | C6: 187 | D6: 0.002589418 | E6: 111145.84 | F6: 0.02263194
A7: App | B7: 30.474286 | C7: 25522 | D7: 0.35340709 | E7: 714946.66 | F7: 0.14558017
B8: 106.07909 | C8: 8501 | D8: 0.11771467 | E8: 574012.51 | F8: 0.11688262
A9: Total | B9: 219.59768 | C9: 72217 | D9: 1 | E9: 4911016.9 | F9: 1
A27: Top 50 By Unit Summary
A28: Display | B28: Avg Price | C28: Quantity/Mo | D28: Qty by % | E28: Revenue/Mo | F28: Revenue by %
A29: 4.3" | B29: 52.126429 | C29: 22464 | D29: 0.27136662 | E29: 1242862 | F29: 0.28993477
A30: 4.5" | B30: 139.99 | C30: 8728 | D30: 0.10543482 | E30: 1141366.6 | F30: 0.26625792
A31: 5.0" | B31: 127.49 | C31: 3697 | D31: 0.044660007 | E31: 432495.1 | F31: 0.10089243
A32: App | B32: 27.686429 | C32: 32474 | D32: 0.39228809 | E32: 876990.66 | F32: 0.20458432
B33: 36.933125 | C33: 15418 | D33: 0.18625047 | E33: 592981.01 | F33: 0.13833057
A34: Total | B34: 76.845196 | C34: 82781 | D34: 1 | E34: 4286695.4 | F34: 1

Sheet Top50 Lensdiameter Summary  
A1: Top 50 By Revenue Summary
A2: Lens diameter | B2: Avg Price | C2: Quantity/Mo | D2: Qty by % | E2: Revenue/Mo | F2: Revenue by %
A3: 23mm | B3: 781.9 | C3: 187 | D3: 0.002589418 | E3: 111145.84 | F3: 0.02263194
A4: 5.5mm | B4: 142.74 | C4: 2749 | D4: 0.038065829 | E4: 368864.49 | F4: 0.075109595
A5: 6.2mm | B5: 159.99 | C5: 413 | D5: 0.0057188751 | E5: 59879.58 | F5: 0.012192909
A6: 6.4mm | B6: 102.99 | C6: 600 | D6: 0.0083082931 | E6: 49433.48 | F6: 0.010065834
A7: 6.5mm | B7: 299.99 | C7: 227 | D7: 0.0031433042 | E7: 68045.02 | F7: 0.013855587
A8: 6mm | B8: 359.99 | C8: 135 | D8: 0.0018693659 | E8: 55683.1 | F8: 0.011338405
A9: 8.5mm | B9: 139.39 | C9: 2468 | D9: 0.034174779 | E9: 344006.92 | F9: 0.070048002
A10: 8mm | B10: 82.258276 | C10: 56937 | D10: 0.78841547 | E10: 3279945.9 | F10: 0.66787511
B11: 106.07909 | C11: 8501 | D11: 0.11771467 | E11: 574012.51 | F11: 0.11688262
A12: Total | B12: 241.70304 | C12: 72217 | D12: 1 | E12: 4911016.9 | F12: 1
A30: Top 50 By Unit Summary
A31: Lens diameter | B31: Avg Price | C31: Quantity/Mo | D31: Qty by % | E31: Revenue/Mo | F31: Revenue by %
A32: 5.5mm | B32: 149.99 | C32: 1975 | D32: 0.023858132 | E32: 275689.59 | F32: 0.064312848
A33: 8.5mm | B33: 139.39 | C33: 2468 | D33: 0.029813605 | E33: 344006.92 | F33: 0.08024991
A34: 8mm | B34: 47.353226 | C34: 62920 | D34: 0.7600778 | E34: 3074017.9 | F34: 0.71710667
B35: 36.933125 | C35: 15418 | D35: 0.18625047 | E35: 592981.01 | F35: 0.13833057
A36: Total | B36: 93.416588 | C36: 82781 | D36: 1 | E36: 4286695.4 | F36: 1

Sheet Top50 Lens count Summary 
A1: Top 50 By Revenue Summary
A2: Lens count | B2: Avg Price | C2: Quantity/Mo | D2: Qty by % | E2: Revenue/Mo | F2: Revenue by %
A3: Dual | B3: 100.29625 | C3: 27593 | D3: 0.38208455 | E3: 1459603.5 | F3: 0.29721004
A4: Single | B4: 141.66 | C4: 34884 | D4: 0.48304416 | E4: 2719081 | F4: 0.55366966
A5: Triple | B5: 120.92 | C5: 1239 | D5: 0.017156625 | E5: 158319.82 | F5: 0.032237686
B6: 106.07909 | C6: 8501 | D6: 0.11771467 | E6: 574012.51 | F6: 0.11688262
A7: Total | B7: 117.23884 | C7: 72217 | D7: 1 | E7: 4911016.9 | F7: 1
A25: Top 50 By Unit Summary
A26: Lens count | B26: Avg Price | C26: Quantity/Mo | D26: Qty by % | E26: Revenue/Mo | F26: Revenue by %
A27: Dual | B27: 64.768571 | C27: 28086 | D27: 0.33928075 | E27: 1293137.1 | F27: 0.30166294
A28: Single | B28: 50.028 | C28: 39277 | D28: 0.47446878 | E28: 2400577.3 | F28: 0.56000649
B29: 36.933125 | C29: 15418 | D29: 0.18625047 | E29: 592981.01 | F29: 0.13833057
A30: Total | B30: 50.576565 | C30: 82781 | D30: 1 | E30: 4286695.4 | F30: 1

Sheet Top50 Cable length Summary  
A1: Top 50 By Revenue Summary
A2: Cable length | B2: Avg Price | C2: Quantity/Mo | D2: Qty by % | E2: Revenue/Mo | F2: Revenue by %
A3: 10ft | B3: 121.82 | C3: 1725 | D3: 0.023886343 | E3: 128052.34 | F3: 0.026074506
A4: 16.5ft | B4: 52.007647 | C4: 41898 | D4: 0.5801681 | E4: 1584002 | F4: 0.32254054
A5: 300ft | B5: 781.9 | C5: 187 | D5: 0.002589418 | E5: 111145.84 | F5: 0.02263194
A6: 33ft | B6: 33.99 | C6: 1219 | D6: 0.016879682 | E6: 36255.3 | F6: 0.0073824426
A7: 5.25ft | B7: 159.99 | C7: 413 | D7: 0.0057188751 | E7: 59879.58 | F7: 0.012192909
A8: 5.5ft | B8: 108.45667 | C8: 4152 | D8: 0.057493388 | E8: 498750.79 | F8: 0.10155754
A9: 50ft | B9: 112.985 | C9: 1014 | D9: 0.014041015 | E9: 122752.58 | F9: 0.024995349
A10: 5ft | B10: 194.76778 | C10: 12334 | D10: 0.17079081 | E10: 1702991 | F10: 0.34676953
A11: 9.8ft | B11: 135.49 | C11: 774 | D11: 0.010717698 | E11: 93174.9 | F11: 0.018972629
B12: 106.07909 | C12: 8501 | D12: 0.11771467 | E12: 574012.51 | F12: 0.11688262
A13: Total | B13: 180.74862 | C13: 72217 | D13: 1 | E13: 4911016.9 | F13: 1
A31: Top 50 By Unit Summary
A32: Cable length | B32: Avg Price | C32: Quantity/Mo | D32: Qty by % | E32: Revenue/Mo | F32: Revenue by %
A33: 10ft | B33: 21.725 | C33: 1916 | D33: 0.023145408 | E33: 46868.79 | F33: 0.010933548
A34: 16.5ft | B34: 40.763478 | C34: 48336 | D34: 0.5839021 | E34: 1713931.4 | F34: 0.3998258
A35: 32.8ft | B35: 39.99 | C35: 685 | D35: 0.0082748457 | E35: 27387.26 | F35: 0.0063888981
A36: 33ft | B36: 33.99 | C36: 1219 | D36: 0.014725601 | E36: 36255.3 | F36: 0.0084576338
A37: 5.5ft | B37: 122.69 | C37: 3556 | D37: 0.042956717 | E37: 451114.42 | F37: 0.10523594
A38: 5ft | B38: 144.99 | C38: 10562 | D38: 0.12758966 | E38: 1391881.4 | F38: 0.32469801
A39: 9.8ft | B39: 26.99 | C39: 1089 | D39: 0.013155193 | E39: 26275.76 | F39: 0.0061296074
B40: 36.933125 | C40: 15418 | D40: 0.18625047 | E40: 592981.01 | F40: 0.13833057
A41: Total | B41: 58.50895 | C41: 82781 | D41: 1 | E41: 4286695.4 | F41: 1

Sheet Teslong
A1: #VALUE!
A7: Rank by Revenue
A8: Product Name | B8: ASIN | C8: Avg Price | D8: Estimated 12mo Revenue | E8: Monthly Rev | F8: Estimated 12mo Units | G8: Monthly Units | H8: # of Reviews | I8: Tool Rating | J8: Column1 | K8: Link
A9: Teslong Two-Way Articulating Borescope with Light, Industrial Endoscope Inspection Camera with Articulated Probe, Flexible Mechanic Fiber Optic Snake Scope Cam for Wall Automotive Engine Inspect-5FT | B9: B0CJY5C9QX | C9: 129.99 | D9: 11848630 | E9: 987385.82 | F9: 91152 | G9: 7596 | H9: 1220 | I9: 4.7 | J9: https://amazon.com/dp/B0CJY5C9QX | K9: =HYPERLINK(J9) -> https://amazon.com/dp/B0CJY5C9QX
A10: Articulating Borescope with Dual Lens Endoscope Camera, Teslong Two-Way Articulated Industrial Inspection Camera with LED Light, Flexible Mechanic Fiber Optic Snake Scope Cam for Wall Automotive-5FT | B10: B0CJY6SWBN | C10: 149.99 | D10: 1847769.5 | E10: 153980.79 | F10: 13584 | G10: 1132 | H10: 378 | I10: 4.5 | J10: https://amazon.com/dp/B0CJY6SWBN | K10: =HYPERLINK(J10) -> https://amazon.com/dp/B0CJY6SWBN
A11: Teslong Inspection Camera, Dual Lens Borescope Camera with Light, NTS300 5" IPS Industrial Endoscope, 1080P Waterproof Flexible Mechanic Fiber Optic Snake Scope Cam for Wall Automotive Engine (16.5FT) | B11: B07TV2BFVR | C11: 159.99 | D11: 1674127.1 | E11: 139510.59 | F11: 10464 | G11: 872 | H11: 3569 | I11: 4.6 | J11: https://amazon.com/dp/B07TV2BFVR | K11: =HYPERLINK(J11) -> https://amazon.com/dp/B07TV2BFVR
A12: Teslong Two-Way Articulating Borescope, 5.5mm Slim Probe, 5.0'' Industrial Endoscope with Light, 5FT Flexible Snake Scope for Automotive, HVAC & Mechanics | B12: B0DT4H7QQM | C12: 139.99 | D12: 1634148 | E12: 136179 | F12: 13236 | G12: 1103 | H12: 217 | I12: 4.5 | J12: https://amazon.com/dp/B0DT4H7QQM | K12: =HYPERLINK(J12) -> https://amazon.com/dp/B0DT4H7QQM
A13: Teslong Endoscope Borescope with Light, Snake Inspection Camera for Automotive Engine, Waterproof Fiber Optic Camera for Mechanics - Ideal for Wall, Vent, Wire Video Scope (16.5FT) | B13: B0DK965BZP | C13: 37.99 | D13: 1174114.3 | E13: 97842.86 | F13: 24420 | G13: 2035 | H13: 287 | I13: 4.5 | J13: https://amazon.com/dp/B0DK965BZP | K13: =HYPERLINK(J13) -> https://amazon.com/dp/B0DK965BZP
A14: Teslong Two-Way Articulating Borescope with Light, 5-inch IPS Endoscope Inspection Camera with Articulation Head, Automotive Mechanics Fiber Optic Scope-0.33inch | B14: B09ZV7KJHL | C14: 279.99 | D14: 1040719.2 | E14: 86726.6 | F14: 4416 | G14: 368 | H14: 555 | I14: 4.7 | J14: https://amazon.com/dp/B09ZV7KJHL | K14: =HYPERLINK(J14) -> https://amazon.com/dp/B09ZV7KJHL
A15: Articulating Borescope with Dual Lens Endoscope, Teslong 5-inch IPS Automotive Inspection Camera with Two-Way Articulation Tip, 6+1 LED Lights, Mechanics Fiber Optic Scope-Dia. 0.25 inch & L 5.0 feet | B15: B0CHW4FLS7 | C15: 299.99 | D15: 816540.24 | E15: 68045.02 | F15: 2724 | G15: 227 | H15: 191 | I15: 4.2 | J15: https://amazon.com/dp/B0CHW4FLS7 | K15: =HYPERLINK(J15) -> https://amazon.com/dp/B0CHW4FLS7
A16: Teslong 360 Articulating Borescope with Light, 5'' Monitor Industrial Inspection Camera with 4-Way Joystick Articulation, HD Endoscope Camera for Automotive, Pipes, and Mechanics (0.24inch-5FT) | B16: B0DTHZDGYD | C16: 359.99 | D16: 668197.2 | E16: 55683.1 | F16: 1620 | G16: 135 | H16: 32 | I16: 4.8 | J16: https://amazon.com/dp/B0DTHZDGYD | K16: =HYPERLINK(J16) -> https://amazon.com/dp/B0DTHZDGYD
A17: Teslong Dual Lens Endoscope with Light, Mechanic Borescope Inspection Camera, Fiber Optic Scope, Flexible Snake Probe for Automotive, HVAC, Wall & Home Inspections (16.5FT) | B17: B0DYDXH1NQ | C17: 59.99 | D17: 663353.52 | E17: 55279.46 | F17: 11052 | G17: 921 | H17: 81 | I17: 4.4 | J17: https://amazon.com/dp/B0DYDXH1NQ | K17: =HYPERLINK(J17) -> https://amazon.com/dp/B0DYDXH1NQ
A18: Teslong Inspection Camera, Dual Lens Borescope Camera with Light, NTS300 5" IPS Industrial Endoscope, 1080P Waterproof Flexible Mechanic Fiber Optic Snake Scope Cam for Wall Automotive Engine (10FT) | B18: B08519V6GW | C18: 149.99 | D18: 561478.8 | E18: 46789.9 | F18: 3744 | G18: 312 | H18: 3569 | I18: 4.6 | J18: https://amazon.com/dp/B08519V6GW | K18: =HYPERLINK(J18) -> https://amazon.com/dp/B08519V6GW
A19: Triple Lens Borescope Inspection Camera, Teslong Professional Endoscope with Light, Digital Video Scope Camera, 5" IPS Screen, Waterproof Flexible Cable for Automotive/Home/Wall/Pipe/Car (16.5FT) | B19: B07Q86XGN2 | C19: 136.79 | D19: 426806.88 | E19: 35567.24 | F19: 2700 | G19: 225 | H19: 341 | I19: 4.4 | J19: https://amazon.com/dp/B07Q86XGN2 | K19: =HYPERLINK(J19) -> https://amazon.com/dp/B07Q86XGN2
A20: Teslong Rifle Borescope for Phone & PC, USB C Bore Scope Camera with Lights & Mirror Set, Fits .20 Caliber & Larger, Flexible Gun Cleaning Camera, Compatible with iPhone 15/16 & USB-C Android Devices | B20: B0DRP8LPF8 | C20: 65.99 | D20: 405036.96 | E20: 33753.08 | F20: 6144 | G20: 512 | H20: 137 | I20: 4.3 | J20: https://amazon.com/dp/B0DRP8LPF8 | K20: =HYPERLINK(J20) -> https://amazon.com/dp/B0DRP8LPF8
... A67: Teslong Endoscope Replacement Cable with Light, Single Lens Inspection Camera 5.5mm/0.21inch Waterproof Probe Compatible with NTS500, NTS300(3.3FT) | B67: B08QCP8YFM | C67: 59.99 | D67: 751.56 | E67: 62.63 | F67: 12 | G67: 1 | H67: 18 | I67: 4.7 | J67: https://amazon.com/dp/B08QCP8YFM | K67: =HYPERLINK(J67) -> https://amazon.com/dp/B08QCP8YFM
A68: Teslong Endoscope Replacement Cable with Light, Dual Lens Inspection Camera 8mm/0.31inch Waterproof Probe Compatible with NTS500, NTS300(3.3FT) | B68: B0DBHT7F23 | C68: 69.99 | F68: 0 | G68: 0 | H68: 6 | I68: 4.8 | J68: https://amazon.com/dp/B0DBHT7F23 | K68: =HYPERLINK(J68) -> https://amazon.com/dp/B0DBHT7F23
A69: 10FT Single Lens Probe, 3.9mm/0.15inch Diameter Semi-Rigid Cable Compatible with MS450 Inspection Camera | B69: B0D9JGJG5R | C69: 59.99 | F69: 0 | G69: 0 | J69: https://amazon.com/dp/B0D9JGJG5R | K69: =HYPERLINK(J69) -> https://amazon.com/dp/B0D9JGJG5R
A70: Total | D70: =SUM(D9:D69) -> 28160877 | E70: =SUM(E9:E69) -> 2346739.8
A73: Rank by Units
A74: Product Name | B74: ASIN | C74: Avg Price | D74: Estimated 12mo Revenue | E74: Monthly Rev | F74: Estimated 12mo Units | G74: Monthly Units | H74: # of Reviews | I74: Tool Rating | J74: Column1 | K74: Link
A75: Teslong Two-Way Articulating Borescope with Light, Industrial Endoscope Inspection Camera with Articulated Probe, Flexible Mechanic Fiber Optic Snake Scope Cam for Wall Automotive Engine Inspect-5FT | B75: B0CJY5C9QX | C75: 129.99 | D75: 11848630 | E75: 987385.82 | F75: 91152 | G75: 7596 | H75: 1220 | I75: 4.7 | J75: https://amazon.com/dp/B0CJY5C9QX | K75: =HYPERLINK(J75) -> https://amazon.com/dp/B0CJY5C9QX
A76: Teslong Endoscope Borescope with Light, Snake Inspection Camera for Automotive Engine, Waterproof Fiber Optic Camera for Mechanics - Ideal for Wall, Vent, Wire Video Scope (16.5FT) | B76: B0DK965BZP | C76: 37.99 | D76: 1174114.3 | E76: 97842.86 | F76: 24420 | G76: 2035 | H76: 287 | I76: 4.5 | J76: https://amazon.com/dp/B0DK965BZP | K76: =HYPERLINK(J76) -> https://amazon.com/dp/B0DK965BZP
A77: Articulating Borescope with Dual Lens Endoscope Camera, Teslong Two-Way Articulated Industrial Inspection Camera with LED Light, Flexible Mechanic Fiber Optic Snake Scope Cam for Wall Automotive-5FT | B77: B0CJY6SWBN | C77: 149.99 | D77: 1847769.5 | E77: 153980.79 | F77: 13584 | G77: 1132 | H77: 378 | I77: 4.5 | J77: https://amazon.com/dp/B0CJY6SWBN | K77: =HYPERLINK(J77) -> https://amazon.com/dp/B0CJY6SWBN
A78: Teslong Two-Way Articulating Borescope, 5.5mm Slim Probe, 5.0'' Industrial Endoscope with Light, 5FT Flexible Snake Scope for Automotive, HVAC & Mechanics | B78: B0DT4H7QQM | C78: 139.99 | D78: 1634148 | E78: 136179 | F78: 13236 | G78: 1103 | H78: 217 | I78: 4.5 | J78: https://amazon.com/dp/B0DT4H7QQM | K78: =HYPERLINK(J78) -> https://amazon.com/dp/B0DT4H7QQM
A79: USB C Endoscope Camera with Light, Teslong Type-C Snake Borescope Camera with 8 LED Lights, 10FT Flexible Waterproof Inspection Cam, Fiber Optic Scope Compatible with iPhone 15/16/17, Android Phone | B79: B0C1GFBTDC | C79: 25.48 | D79: 386197.92 | E79: 32183.16 | F79: 13224 | G79: 1102 | H79: 982 | I79: 4.4 | J79: https://amazon.com/dp/B0C1GFBTDC | K79: =HYPERLINK(J79) -> https://amazon.com/dp/B0C1GFBTDC
A80: Teslong Dual Lens Endoscope with Light, Mechanic Borescope Inspection Camera, Fiber Optic Scope, Flexible Snake Probe for Automotive, HVAC, Wall & Home Inspections (16.5FT) | B80: B0DYDXH1NQ | C80: 59.99 | D80: 663353.52 | E80: 55279.46 | F80: 11052 | G80: 921 | H80: 81 | I80: 4.4 | J80: https://amazon.com/dp/B0DYDXH1NQ | K80: =HYPERLINK(J80) -> https://amazon.com/dp/B0DYDXH1NQ
A81: Teslong Inspection Camera, Dual Lens Borescope Camera with Light, NTS300 5" IPS Industrial Endoscope, 1080P Waterproof Flexible Mechanic Fiber Optic Snake Scope Cam for Wall Automotive Engine (16.5FT) | B81: B07TV2BFVR | C81: 159.99 | D81: 1674127.1 | E81: 139510.59 | F81: 10464 | G81: 872 | H81: 3569 | I81: 4.6 | J81: https://amazon.com/dp/B07TV2BFVR | K81: =HYPERLINK(J81) -> https://amazon.com/dp/B07TV2BFVR
A82: Teslong 50FT USB-C Borescope Camera with Light, Only Compatible with iPhone 15/16/17 Android Phones, 50 ft Flexible Waterproof Endoscope for DIY Pipe Inspection with Drain Snake | B82: B0CL4KT182 | C82: 39.99 | D82: 300235.56 | E82: 25019.63 | F82: 7512 | G82: 626 | H82: 770 | I82: 4.2 | J82: https://amazon.com/dp/B0CL4KT182 | K82: =HYPERLINK(J82) -> https://amazon.com/dp/B0CL4KT182
A83: Teslong Rifle Borescope for Phone & PC, USB C Bore Scope Camera with Lights & Mirror Set, Fits .20 Caliber & Larger, Flexible Gun Cleaning Camera, Compatible with iPhone 15/16 & USB-C Android Devices | B83: B0DRP8LPF8 | C83: 65.99 | D83: 405036.96 | E83: 33753.08 | F83: 6144 | G83: 512 | H83: 137 | I83: 4.3 | J83: https://amazon.com/dp/B0DRP8LPF8 | K83: =HYPERLINK(J83) -> https://amazon.com/dp/B0DRP8LPF8
A84: Teslong Rifle Borescope, Bore Camera Gun Cleaning Camera - Fits .20 Caliber & Larger-Hunting Shooting Firearms Visual Barrel Inspection Tool w/3 Right-Angle Mirrors and Carrying Case(45inch-Flexible) | B84: B07TTQF24F | C84: 55.99 | D84: 318642.36 | E84: 26553.53 | F84: 5688 | G84: 474 | H84: 2126 | I84: 4.4 | J84: https://amazon.com/dp/B07TTQF24F | K84: =HYPERLINK(J84) -> https://amazon.com/dp/B07TTQF24F
A85: Dual Lens Endoscope with Light, Teslong USB-C Borescope Inspection Camera with 8+1 LED Lights, Flexible Waterproof Fiber Optic Snake Camera Scope Compatible with iPhone 15, Android Phone(10FT) | B85: B0CF1VCDBD | C85: 36.99 | D85: 198486.36 | E85: 16540.53 | F85: 5364 | G85: 447 | H85: 310 | I85: 4.3 | J85: https://amazon.com/dp/B0CF1VCDBD | K85: =HYPERLINK(J85) -> https://amazon.com/dp/B0CF1VCDBD
A86: Teslong Two-Way Articulating Borescope with Light, 5-inch IPS Endoscope Inspection Camera with Articulation Head, Automotive Mechanics Fiber Optic Scope-0.33inch | B86: B09ZV7KJHL | C86: 279.99 | D86: 1040719.2 | E86: 86726.6 | F86: 4416 | G86: 368 | H86: 555 | I86: 4.7 | J86: https://amazon.com/dp/B09ZV7KJHL | K86: =HYPERLINK(J86) -> https://amazon.com/dp/B09ZV7KJHL
... A133: Teslong Endoscope Replacement Cable with Light, Single Lens Inspection Camera 5.5mm/0.21inch Waterproof Probe Compatible with NTS500, NTS300(3.3FT) | B133: B08QCP8YFM | C133: 59.99 | D133: 751.56 | E133: 62.63 | F133: 12 | G133: 1 | H133: 18 | I133: 4.7 | J133: https://amazon.com/dp/B08QCP8YFM | K133: =HYPERLINK(J133) -> https://amazon.com/dp/B08QCP8YFM
A134: Teslong Endoscope Replacement Cable with Light, Dual Lens Inspection Camera 8mm/0.31inch Waterproof Probe Compatible with NTS500, NTS300(3.3FT) | B134: B0DBHT7F23 | C134: 69.99 | F134: 0 | G134: 0 | H134: 6 | I134: 4.8 | J134: https://amazon.com/dp/B0DBHT7F23 | K134: =HYPERLINK(J134) -> https://amazon.com/dp/B0DBHT7F23
A135: 10FT Single Lens Probe, 3.9mm/0.15inch Diameter Semi-Rigid Cable Compatible with MS450 Inspection Camera | B135: B0D9JGJG5R | C135: 59.99 | F135: 0 | G135: 0 | J135: https://amazon.com/dp/B0D9JGJG5R | K135: =HYPERLINK(J135) -> https://amazon.com/dp/B0D9JGJG5R
A136: Total | F136: =SUM(Teslong!F75:F135) -> 250440 | G136: =SUM(Teslong!G75:G135) -> 20870

Sheet DEPSTECH
A1: #VALUE!
A7: Rank by Revenue
A8: Product Name | B8: ASIN | C8: Avg Price | D8: Estimated 12mo Revenue | E8: Monthly Rev | F8: Estimated 12mo Units | G8: Monthly Units | H8: # of Reviews | I8: Tool Rating | J8: Column1 | K8: Link
A9: DEPSTECH Dual Lens Industrial Endoscope, 1080P Digital Borescope Inspection Camera, 7.9mm IP67 Waterproof Sewer Camera with 4.3" LCD Screen, 7 LED Lights, 16.5FT Semi-Rigid Cable, 32GB Card-Black | B9: B0928Q3T42 | C9: 69.99 | D9: 2650221.6 | E9: 220851.8 | F9: 42720 | G9: 3560 | H9: 6846 | I9: 4.6 | J9: https://amazon.com/dp/B0928Q3T42 | K9: =HYPERLINK(J9) -> https://amazon.com/dp/B0928Q3T42
A10: Triple Lens Borescope Tool, DEPSTECH 5" IPS Screen Endoscope Camera with Lights, 1080P Sewer Inspection Camera & Split Screen, 180° Rotation, IP67 Snake Cable, Gadget for Automotive Mechanical Repair | B10: B0BL7RK5JJ | C10: 109.99 | D10: 1120366.7 | E10: 93363.89 | F10: 11172 | G10: 931 | H10: 1423 | I10: 4.3 | J10: https://amazon.com/dp/B0BL7RK5JJ | K10: =HYPERLINK(J10) -> https://amazon.com/dp/B0BL7RK5JJ
A11: DEPSTECH 50ft Sewer Camera, 1080P HD Triple Lens Borescope, 5" IPS Screen Endoscope with Light, IP67 Waterproof Plumbing Drain Pipe Snake Inspection Camera with 32G Card, Carry Case | B11: B0DD6YVBHD | C11: 99.98 | D11: 944118.6 | E11: 78676.55 | F11: 7248 | G11: 604 | H11: 273 | I11: 4.4 | J11: https://amazon.com/dp/B0DD6YVBHD | K11: =HYPERLINK(J11) -> https://amazon.com/dp/B0DD6YVBHD
A12: DEPSTECH Inspection Endoscope Camera with Lights: 1080P Triple Lens Snake Camera with 5" Screen and 16.5FT Flexible Cable, Waterproof Industrial Borescope Tool for Auto, Wall, Sewer, Pipe, Mechanics | B12: B0FKM8K5QX | C12: 56.98 | D12: 912548.88 | E12: 76045.74 | F12: 12168 | G12: 1014 | H12: 155 | I12: 4.7 | J12: https://amazon.com/dp/B0FKM8K5QX | K12: =HYPERLINK(J12) -> https://amazon.com/dp/B0FKM8K5QX
A13: DEPSTECH 10FT Articulating Endoscope Camera with Light: Dual Lens Industrial Borescope with 4.5" Screen and Flexible Cable, Video Inspection Snake Scope Camera Tool for Wall, Auto, Pipe, Mechanics | B13: B0F62WJY8N | C13: 159.99 | D13: 730252.32 | E13: 60854.36 | F13: 5040 | G13: 420 | H13: 303 | I13: 4.5 | J13: https://amazon.com/dp/B0F62WJY8N | K13: =HYPERLINK(J13) -> https://amazon.com/dp/B0F62WJY8N
A14: DEPSTECH Dual Lens Two-Way Articulating Borescope Camera with Light, 4.5" Screen and 5FT Flexible Snake Scope Industrial Endoscope, Inspection Video Camera Tool for Wall, Engine, Auto, Mechanics | B14: B0DT16R78W | C14: 129.99 | D14: 614656.44 | E14: 51221.37 | F14: 5304 | G14: 442 | H14: 299 | I14: 4.5 | J14: https://amazon.com/dp/B0DT16R78W | K14: =HYPERLINK(J14) -> https://amazon.com/dp/B0DT16R78W
A15: Dual-Lens Endoscope Camera with Light, DEPSTECH 1080P HD Borescope with 5" IPS Screen, 16.5FT Flexible Sewer Plumbing Snake Camera, Cool Gadgets for Men, Women | B15: B0CT2CX59S | C15: 69.99 | D15: 274797 | E15: 22899.75 | F15: 3924 | G15: 327 | H15: 1316 | I15: 4.6 | J15: https://amazon.com/dp/B0CT2CX59S | K15: =HYPERLINK(J15) -> https://amazon.com/dp/B0CT2CX59S
A16: Triple Lens Endoscope Camera with Light with 50FT Semi-Rigid Cable, DEPSTECH 5" IPS Screen Sewer Inspection Camera, 1080P Industrial Borescope, Split Screen, Waterproof Drain Pipe Tool, Carrying Case | B16: B0BS1CFFH8 | C16: 129.99 | D16: 205635 | E16: 17136.25 | F16: 1716 | G16: 143 | H16: 1423 | I16: 4.3 | J16: https://amazon.com/dp/B0BS1CFFH8 | K16: =HYPERLINK(J16) -> https://amazon.com/dp/B0BS1CFFH8
A17: DEPSTECH Dual Lens Borescope Camera with Light, Two-Way Articulating Borescope, 5" IPS Dual View Endoscope with 0.33in Slim Probe, 1080P Waterproof Inspection Camera for Wall Auto Engine Inspect-5FT | B17: B0FQC32XV7 | C17: 105.99 | D17: 150701.64 | E17: 12558.47 | F17: 1224 | G17: 102 | H17: 71 | I17: 4.8 | J17: https://amazon.com/dp/B0FQC32XV7 | K17: =HYPERLINK(J17) -> https://amazon.com/dp/B0FQC32XV7
A18: DEPSTECH 7'' IPS Endoscope Camera with Lights, 1080P Triple-Lens Digital Borescope Tool, Inspection Camera with Split Screen, Sound Recording, 16.5ft IP67 Waterproof Snake Cable, 180° Rotation View | B18: B0CT5L1H9B | C18: 139.99 | D18: 149726.88 | E18: 12477.24 | F18: 1068 | G18: 89 | H18: 189 | I18: 4.6 | J18: https://amazon.com/dp/B0CT5L1H9B | K18: =HYPERLINK(J18) -> https://amazon.com/dp/B0CT5L1H9B
A19: Two-Way Articulating Borescope Camera with Light, DEPSTECH Industrial Endoscope with Articulated Probe, Flexible Mechanic Snake Inspection Camera for Wall Automotive Engine Inspect-5FT | B19: B0DPX48VZB | C19: 99.99 | D19: 146793.84 | E19: 12232.82 | F19: 1044 | G19: 87 | H19: 400 | I19: 4.6 | J19: https://amazon.com/dp/B0DPX48VZB | K19: =HYPERLINK(J19) -> https://amazon.com/dp/B0DPX48VZB
A20: DEPSTECH Dual Lens Industrial Endoscope, 1080P Digital Borescope Inspection Camera, 7.9mm IP67 Waterproof, Sewer Camera with 4.3" LCD Screen, 7 LED Lights, 16.5FT Semi-Rigid Cable, 32GB Card - Orange | B20: B09DKKJGS7 | C20: 72.99 | D20: 135210 | E20: 11267.5 | F20: 2052 | G20: 171 | H20: 6846 | I20: 4.6 | J20: https://amazon.com/dp/B09DKKJGS7 | K20: =HYPERLINK(J20) -> https://amazon.com/dp/B09DKKJGS7
... A39: DEPSTECH DS520 Triple Lens Borescope Inspection Camera Cable, 7.9mm Dia Probe, IP67 Waterproof Camera Lens with 6+2 LED Lights, 16.5ft Semi-Rigid Cable Replacement | B39: B0BMXGMM1F | C39: 49.99 | D39: 1412.28 | E39: 117.69 | F39: 24 | G39: 2 | H39: 20 | I39: 4.4 | J39: https://amazon.com/dp/B0BMXGMM1F | K39: =HYPERLINK(J39) -> https://amazon.com/dp/B0BMXGMM1F
A40: DEPSTECH DS300 Dual Lens Industrial Endoscope | B40: B0CGT1N3VR | C40: 49.99 | F40: 0 | G40: 0 | H40: 6847 | I40: 4.6 | J40: https://amazon.com/dp/B0CGT1N3VR | K40: =HYPERLINK(J40) -> https://amazon.com/dp/B0CGT1N3VR
A42: Total | D42: =SUM(D9:D41) -> 9104010.1 | E42: =SUM(E9:E41) -> 758667.51
A45: Rank by Units
A46: Product Name | B46: ASIN | C46: Avg Price | D46: Estimated 12mo Revenue | E46: Monthly Rev | F46: Estimated 12mo Units | G46: Monthly Units | H46: # of Reviews | I46: Tool Rating | J46: Column1 | K46: Link
A47: DEPSTECH Dual Lens Industrial Endoscope, 1080P Digital Borescope Inspection Camera, 7.9mm IP67 Waterproof Sewer Camera with 4.3" LCD Screen, 7 LED Lights, 16.5FT Semi-Rigid Cable, 32GB Card-Black | B47: B0928Q3T42 | C47: 69.99 | D47: 2650221.6 | E47: 220851.8 | F47: 42720 | G47: 3560 | H47: 6846 | I47: 4.6 | J47: https://amazon.com/dp/B0928Q3T42 | K47: =HYPERLINK(J47) -> https://amazon.com/dp/B0928Q3T42
A48: DEPSTECH Inspection Endoscope Camera with Lights: 1080P Triple Lens Snake Camera with 5" Screen and 16.5FT Flexible Cable, Waterproof Industrial Borescope Tool for Auto, Wall, Sewer, Pipe, Mechanics | B48: B0FKM8K5QX | C48: 56.98 | D48: 912548.88 | E48: 76045.74 | F48: 12168 | G48: 1014 | H48: 155 | I48: 4.7 | J48: https://amazon.com/dp/B0FKM8K5QX | K48: =HYPERLINK(J48) -> https://amazon.com/dp/B0FKM8K5QX
A49: Triple Lens Borescope Tool, DEPSTECH 5" IPS Screen Endoscope Camera with Lights, 1080P Sewer Inspection Camera & Split Screen, 180° Rotation, IP67 Snake Cable, Gadget for Automotive Mechanical Repair | B49: B0BL7RK5JJ | C49: 109.99 | D49: 1120366.7 | E49: 93363.89 | F49: 11172 | G49: 931 | H49: 1423 | I49: 4.3 | J49: https://amazon.com/dp/B0BL7RK5JJ | K49: =HYPERLINK(J49) -> https://amazon.com/dp/B0BL7RK5JJ
A50: DEPSTECH 50ft Sewer Camera, 1080P HD Triple Lens Borescope, 5" IPS Screen Endoscope with Light, IP67 Waterproof Plumbing Drain Pipe Snake Inspection Camera with 32G Card, Carry Case | B50: B0DD6YVBHD | C50: 99.98 | D50: 944118.6 | E50: 78676.55 | F50: 7248 | G50: 604 | H50: 273 | I50: 4.4 | J50: https://amazon.com/dp/B0DD6YVBHD | K50: =HYPERLINK(J50) -> https://amazon.com/dp/B0DD6YVBHD
A51: DEPSTECH Dual Lens Two-Way Articulating Borescope Camera with Light, 4.5" Screen and 5FT Flexible Snake Scope Industrial Endoscope, Inspection Video Camera Tool for Wall, Engine, Auto, Mechanics | B51: B0DT16R78W | C51: 129.99 | D51: 614656.44 | E51: 51221.37 | F51: 5304 | G51: 442 | H51: 299 | I51: 4.5 | J51: https://amazon.com/dp/B0DT16R78W | K51: =HYPERLINK(J51) -> https://amazon.com/dp/B0DT16R78W
A52: DEPSTECH 10FT Articulating Endoscope Camera with Light: Dual Lens Industrial Borescope with 4.5" Screen and Flexible Cable, Video Inspection Snake Scope Camera Tool for Wall, Auto, Pipe, Mechanics | B52: B0F62WJY8N | C52: 159.99 | D52: 730252.32 | E52: 60854.36 | F52: 5040 | G52: 420 | H52: 303 | I52: 4.5 | J52: https://amazon.com/dp/B0F62WJY8N | K52: =HYPERLINK(J52) -> https://amazon.com/dp/B0F62WJY8N
A53: Dual-Lens Endoscope Camera with Light, DEPSTECH 1080P HD Borescope with 5" IPS Screen, 16.5FT Flexible Sewer Plumbing Snake Camera, Cool Gadgets for Men, Women | B53: B0CT2CX59S | C53: 69.99 | D53: 274797 | E53: 22899.75 | F53: 3924 | G53: 327 | H53: 1316 | I53: 4.6 | J53: https://amazon.com/dp/B0CT2CX59S | K53: =HYPERLINK(J53) -> https://amazon.com/dp/B0CT2CX59S
A54: DEPSTECH 5.5mm Industrial Endoscope, 1080P Digital Borescope Inspection Camera with 4.3" Screen, IP67 Waterproof Snake Camera with Lights,16.5FT Semi-Rigid Cable, 32GB Card &Photo Capture,Helpful Tool | B54: B094XGX6GQ | C54: 49.99 | D54: 123105.48 | E54: 10258.79 | F54: 2460 | G54: 205 | H54: 4275 | I54: 4.4 | J54: https://amazon.com/dp/B094XGX6GQ | K54: =HYPERLINK(J54) -> https://amazon.com/dp/B094XGX6GQ
A55: DEPSTECH Dual Lens Industrial Endoscope, 1080P Digital Borescope Inspection Camera, 7.9mm IP67 Waterproof, Sewer Camera with 4.3" LCD Screen, 7 LED Lights, 16.5FT Semi-Rigid Cable, 32GB Card - Orange | B55: B09DKKJGS7 | C55: 72.99 | D55: 135210 | E55: 11267.5 | F55: 2052 | G55: 171 | H55: 6846 | I55: 4.6 | J55: https://amazon.com/dp/B09DKKJGS7 | K55: =HYPERLINK(J55) -> https://amazon.com/dp/B09DKKJGS7
A56: Triple Lens Endoscope Camera with Light with 50FT Semi-Rigid Cable, DEPSTECH 5" IPS Screen Sewer Inspection Camera, 1080P Industrial Borescope, Split Screen, Waterproof Drain Pipe Tool, Carrying Case | B56: B0BS1CFFH8 | C56: 129.99 | D56: 205635 | E56: 17136.25 | F56: 1716 | G56: 143 | H56: 1423 | I56: 4.3 | J56: https://amazon.com/dp/B0BS1CFFH8 | K56: =HYPERLINK(J56) -> https://amazon.com/dp/B0BS1CFFH8
A57: DEPSTECH Original Endoscope Case, Wireless Borescope Carrying Bag WiFi & USB Scope Cameras, Upgraded Large-Capacity Hardshell Case, Compatible with 4.3" Inspection Camera DS300, Black | B57: B076D86Z7S | C57: 17.59 | D57: 28782.36 | E57: 2398.53 | F57: 1500 | G57: 125 | H57: 2973 | I57: 4.6 | J57: https://amazon.com/dp/B076D86Z7S | K57: =HYPERLINK(J57) -> https://amazon.com/dp/B076D86Z7S
A58: DEPSTECH 5.5mm Industrial Endoscope, 1080P Digital Borescope Inspection Camera with 4.3" Screen, IP67 Waterproof Snake Camera with Lights,16.5FT Semi-Rigid Cable, 32GB Card &Photo Capture (Orange) | B58: B095K8XHY2 | C58: 49.99 | D58: 70547.64 | E58: 5878.97 | F58: 1416 | G58: 118 | H58: 4275 | I58: 4.4 | J58: https://amazon.com/dp/B095K8XHY2 | K58: =HYPERLINK(J58) -> https://amazon.com/dp/B095K8XHY2
... A77: DEPSTECH DS520 Triple Lens Borescope Inspection Camera Cable, 7.9mm Dia Probe, IP67 Waterproof Camera Lens with 6+2 LED Lights, 16.5ft Semi-Rigid Cable Replacement | B77: B0BMXGMM1F | C77: 49.99 | D77: 1412.28 | E77: 117.69 | F77: 24 | G77: 2 | H77: 20 | I77: 4.4 | J77: https://amazon.com/dp/B0BMXGMM1F | K77: =HYPERLINK(J77) -> https://amazon.com/dp/B0BMXGMM1F
A78: DEPSTECH DS300 Dual Lens Industrial Endoscope | B78: B0CGT1N3VR | C78: 49.99 | F78: 0 | G78: 0 | H78: 6847 | I78: 4.6 | J78: https://amazon.com/dp/B0CGT1N3VR | K78: =HYPERLINK(J78) -> https://amazon.com/dp/B0CGT1N3VR
A80: Total | F80: =SUM(DEPSTECH!F47:F79) -> 108732 | G80: =SUM(DEPSTECH!G47:G79) -> 9061

Sheet KINPTHY
A1: #VALUE!
A7: Rank by Revenue
A8: Product Name | B8: ASIN | C8: Avg Price | D8: Estimated 12mo Revenue | E8: Monthly Rev | F8: Estimated 12mo Units | G8: Monthly Units | H8: # of Reviews | I8: Tool Rating | J8: Column1 | K8: Link
A9: Endoscope Camera with Light, 1920P HD Borescope Tools with 8 Adjustable LED Lights, Endoscope with Semi-Rigid Snake Camera, Inspection Borescope for iOS and Android - 16.4ft Single Lens | B9: B0C4V5LWWL | C9: 32.99 | D9: 2437937.8 | E9: 203161.48 | F9: 89124 | G9: 7427 | H9: 5630 | I9: 4.4 | J9: https://amazon.com/dp/B0C4V5LWWL | K9: =HYPERLINK(J9) -> https://amazon.com/dp/B0C4V5LWWL
A10: Endoscope Camera with Light,1920P HD Borescope Tools with 8 Adjustable LED Lights, Endoscope with Semi-Rigid Snake Camera, IP67 Waterproof Inspection Borescope for iOS and Android-16.4ft Dual-Lens | B10: B0C9JR3N4W | C10: 35.99 | D10: 1565314.4 | E10: 130442.87 | F10: 43356 | G10: 3613 | H10: 5630 | I10: 4.4 | J10: https://amazon.com/dp/B0C9JR3N4W | K10: =HYPERLINK(J10) -> https://amazon.com/dp/B0C9JR3N4W
A11: Endoscope Camera with Light, 1920P HD Borescope Tools with 8 Adjustable LED Lights, Endoscope with Semi-Rigid Snake Camera, Inspection Borescope for iOS and Android - 16.3ft Dual Line Single Lens | B11: B0G23P5N7X | C11: 25.99 | D11: 383762.04 | E11: 31980.17 | F11: 17100 | G11: 1425 | H11: 5630 | I11: 4.4 | J11: https://amazon.com/dp/B0G23P5N7X | K11: =HYPERLINK(J11) -> https://amazon.com/dp/B0G23P5N7X
A12: Endoscope Camera with Light, 1920P HD Borescope Tools with 8 Adjustable LED Lights, Endoscope with Semi-Rigid Snake Camera, Inspection Borescope for iOS and Android - 16.3ft Single Line Single Lens | B12: B0G23FH94K | C12: 19.99 | D12: 377762.52 | E12: 31480.21 | F12: 21444 | G12: 1787 | H12: 5630 | I12: 4.4 | J12: https://amazon.com/dp/B0G23FH94K | K12: =HYPERLINK(J12) -> https://amazon.com/dp/B0G23FH94K
A13: Endoscope Camera with Light,1920P HD Borescope Tools with 8 Adjustable LED Lights, Endoscope with Semi-Rigid Snake Camera, IP67 Waterproof Inspection Borescope for iOS and Android-32.8ft Single Lens | B13: B0BF64PP4F | C13: 39.99 | D13: 328647.12 | E13: 27387.26 | F13: 8220 | G13: 685 | H13: 5630 | I13: 4.4 | J13: https://amazon.com/dp/B0BF64PP4F | K13: =HYPERLINK(J13) -> https://amazon.com/dp/B0BF64PP4F
A14: Endoscope 4-Piece Accessories Hook Magnet Side View Mirror Set, 8-Piece Accessories, Suitable for Kinpthy W400 W400-B Series | B14: B0DBDJ3FK2 | C14: 9.99 | D14: 8837.4 | E14: 736.45 | F14: 888 | G14: 74 | H14: 21 | I14: 4.4 | J14: https://amazon.com/dp/B0DBDJ3FK2 | K14: =HYPERLINK(J14) -> https://amazon.com/dp/B0DBDJ3FK2
A15: Total | D15: =SUM(D9:D14) -> 5102261.3 | E15: =SUM(E9:E14) -> 425188.44
A18: Rank by Units
A19: Product Name | B19: ASIN | C19: Avg Price | D19: Estimated 12mo Revenue | E19: Monthly Rev | F19: Estimated 12mo Units | G19: Monthly Units | H19: # of Reviews | I19: Tool Rating | J19: Column1 | K19: Link
A20: Endoscope Camera with Light, 1920P HD Borescope Tools with 8 Adjustable LED Lights, Endoscope with Semi-Rigid Snake Camera, Inspection Borescope for iOS and Android - 16.4ft Single Lens | B20: B0C4V5LWWL | C20: 32.99 | D20: 2437937.8 | E20: 203161.48 | F20: 89124 | G20: 7427 | H20: 5630 | I20: 4.4 | J20: https://amazon.com/dp/B0C4V5LWWL | K20: =HYPERLINK(J20) -> https://amazon.com/dp/B0C4V5LWWL
A21: Endoscope Camera with Light,1920P HD Borescope Tools with 8 Adjustable LED Lights, Endoscope with Semi-Rigid Snake Camera, IP67 Waterproof Inspection Borescope for iOS and Android-16.4ft Dual-Lens | B21: B0C9JR3N4W | C21: 35.99 | D21: 1565314.4 | E21: 130442.87 | F21: 43356 | G21: 3613 | H21: 5630 | I21: 4.4 | J21: https://amazon.com/dp/B0C9JR3N4W | K21: =HYPERLINK(J21) -> https://amazon.com/dp/B0C9JR3N4W
A22: Endoscope Camera with Light, 1920P HD Borescope Tools with 8 Adjustable LED Lights, Endoscope with Semi-Rigid Snake Camera, Inspection Borescope for iOS and Android - 16.3ft Single Line Single Lens | B22: B0G23FH94K | C22: 19.99 | D22: 377762.52 | E22: 31480.21 | F22: 21444 | G22: 1787 | H22: 5630 | I22: 4.4 | J22: https://amazon.com/dp/B0G23FH94K | K22: =HYPERLINK(J22) -> https://amazon.com/dp/B0G23FH94K
A23: Endoscope Camera with Light, 1920P HD Borescope Tools with 8 Adjustable LED Lights, Endoscope with Semi-Rigid Snake Camera, Inspection Borescope for iOS and Android - 16.3ft Dual Line Single Lens | B23: B0G23P5N7X | C23: 25.99 | D23: 383762.04 | E23: 31980.17 | F23: 17100 | G23: 1425 | H23: 5630 | I23: 4.4 | J23: https://amazon.com/dp/B0G23P5N7X | K23: =HYPERLINK(J23) -> https://amazon.com/dp/B0G23P5N7X
A24: Endoscope Camera with Light,1920P HD Borescope Tools with 8 Adjustable LED Lights, Endoscope with Semi-Rigid Snake Camera, IP67 Waterproof Inspection Borescope for iOS and Android-32.8ft Single Lens | B24: B0BF64PP4F | C24: 39.99 | D24: 328647.12 | E24: 27387.26 | F24: 8220 | G24: 685 | H24: 5630 | I24: 4.4 | J24: https://amazon.com/dp/B0BF64PP4F | K24: =HYPERLINK(J24) -> https://amazon.com/dp/B0BF64PP4F
A25: Endoscope 4-Piece Accessories Hook Magnet Side View Mirror Set, 8-Piece Accessories, Suitable for Kinpthy W400 W400-B Series | B25: B0DBDJ3FK2 | C25: 9.99 | D25: 8837.4 | E25: 736.45 | F25: 888 | G25: 74 | H25: 21 | I25: 4.4 | J25: https://amazon.com/dp/B0DBDJ3FK2 | K25: =HYPERLINK(J25) -> https://amazon.com/dp/B0DBDJ3FK2
A26: Total | F26: =SUM(KINPTHY!F20:F25) -> 180132 | G26: =SUM(KINPTHY!G20:G25) -> 15011

Sheet Acoath
A1: #VALUE!
A7: Rank by Revenue
A8: Product Name | B8: ASIN | C8: Avg Price | D8: Estimated 12mo Revenue | E8: Monthly Rev | F8: Estimated 12mo Units | G8: Monthly Units | H8: # of Reviews | I8: Tool Rating | J8: Column1 | K8: Link
A9: Acoath Endoscope Camera with Light, Dual-Lens 1920P HD Borescope with 8 Adjustable LED Lights, IP67 Waterproof Boroscope Inspection Tools, 16.4ft Semi-Rigid Snake Camera for iOS & Android | B9: B0DGFBCH38 | C9: 29.99 | D9: 2006598.4 | E9: 167216.53 | F9: 77424 | G9: 6452 | H9: 1327 | I9: 4.4 | J9: https://amazon.com/dp/B0DGFBCH38 | K9: =HYPERLINK(J9) -> https://amazon.com/dp/B0DGFBCH38
A10: Acoath Endoscope Camera with Light, Dual-Lens 1920P HD Borescope with 8 Adjustable LED Lights, IP67 Waterproof Boroscope Inspection Tools, 33ft Semi-Rigid Snake Camera for iOS & Android | B10: B0DGFC3D9H | C10: 33.99 | D10: 435063.6 | E10: 36255.3 | F10: 14628 | G10: 1219 | H10: 1327 | I10: 4.4 | J10: https://amazon.com/dp/B0DGFC3D9H | K10: =HYPERLINK(J10) -> https://amazon.com/dp/B0DGFC3D9H
