Workbook

Sheet Summary
A1: Monthly Summaries- Revenue
A2: Brand | B2: # of Listings | C2: Monthly Rev | D2: Estimated 12mo Revenue | E2: Monthly Units | F2: Monthly Rev Market Share % | G2: Price Per Unit | H2: Total Reviews | I2: Avg Rating
A3: flir | B3: 22 | C3: 1511571.7 | D3: 18138860 | E3: 4658 | F3: 0.27033396 | G3: 324.51088 | H3: 41452 | I3: 4.2468928
A4: topdon | B4: 15 | C4: 1002815.7 | D4: 12033789 | E4: 3716 | F4: 0.17934654 | G4: 269.8643 | H4: 7174 | I4: 4.5548927
A5: hsftools | B5: 10 | C5: 863866.5 | D5: 10366398 | E5: 3860 | F5: 0.15449644 | G5: 223.79961 | H5: 2909 | I5: 4.4804744
A6: thermal master | B6: 23 | C6: 825828.9 | D6: 9909946.8 | E6: 3076 | F6: 0.14769368 | G6: 268.47493 | H6: 821 | I6: 4.2528624
A7: mileseey | B7: 10 | C7: 254819.29 | D7: 3057831.5 | E7: 1280 | F7: 0.045572636 | G7: 199.07757 | H7: 1005 | I7: 4.2672637
A8: flagfront | B8: 1 | C8: 118067.77 | D8: 1416813.2 | E8: 905 | F8: 0.021115589 | G8: 130.46162 | H8: 89 | I8: 4.4
A9: foxwell | B9: 6 | C9: 97818.16 | D9: 1173817.9 | E9: 523 | F9: 0.017494089 | G9: 187.03281 | H9: 854 | I9: 4.3855972
A10: ampbank | B10: 4 | C10: 75793.76 | D10: 909525.12 | E10: 460 | F10: 0.01355518 | G10: 164.76904 | H10: 209 | I10: 4.3282297
A11: teslong | B11: 4 | C11: 75697.89 | D11: 908374.68 | E11: 513 | F11: 0.013538035 | G11: 147.55924 | H11: 198 | I11: 4.2722222
A12: anxtech | B12: 5 | C12: 75386.86 | D12: 904642.32 | E12: 484 | F12: 0.013482409 | G12: 155.75798 | H12: 44 | I12: 4.4590909
A14: Market Total | B14: 532 | C14: 5591497.7 | D14: 67097973 | E14: 23389 | F14: 1 | G14: 239.06527 | H14: 96169 | I14: 4.1776456
A16: Monthly Summary - Units
A17: Brand | B17: # of Listings | C17: Monthly Rev | D17: Estimated 12mo Units | E17: Monthly Units | F17: Monthly Unit Market Share % | G17: Price Per Unit | H17: Reviews | I17: Avg Rating
A18: flir | B18: 22 | C18: 1511571.7 | D18: 55896 | E18: 4658 | F18: 0.19915345 | G18: 324.51088 | H18: 41452 | I18: 4.2468928
A19: hsftools | B19: 10 | C19: 863866.5 | D19: 46320 | E19: 3860 | F19: 0.16503485 | G19: 223.79961 | H19: 2909 | I19: 4.4804744
A20: topdon | B20: 15 | C20: 1002815.7 | D20: 44592 | E20: 3716 | F20: 0.15887811 | G20: 269.8643 | H20: 7174 | I20: 4.5548927
A21: thermal master | B21: 23 | C21: 825828.9 | D21: 36912 | E21: 3076 | F21: 0.13151481 | G21: 268.47493 | H21: 821 | I21: 4.2528624
A22: mileseey | B22: 10 | C22: 254819.29 | D22: 15360 | E22: 1280 | F22: 0.054726581 | G22: 199.07757 | H22: 1005 | I22: 4.2672637
A23: flagfront | B23: 1 | C23: 118067.77 | D23: 10860 | E23: 905 | F23: 0.038693403 | G23: 130.46162 | H23: 89 | I23: 4.4
A24: goyojo | B24: 8 | C24: 62719.63 | D24: 7176 | E24: 598 | F24: 0.025567575 | G24: 104.88232 | H24: 1283 | I24: 4.3010912
A25: bside | B25: 10 | C25: 70040.5 | D25: 6972 | E25: 581 | F25: 0.024840737 | G25: 120.55164 | H25: 246 | I25: 4.3357724
A26: foxwell | B26: 6 | C26: 97818.16 | D26: 6276 | E26: 523 | F26: 0.022360939 | G26: 187.03281 | H26: 854 | I26: 4.3855972
A27: teslong | B27: 4 | C27: 75697.89 | D27: 6156 | E27: 513 | F27: 0.021933387 | G27: 147.55924 | H27: 198 | I27: 4.2722222
A29: Market Total | B29: 532 | C29: 5591497.7 | D29: 280668 | E29: 23389 | F29: 1 | G29: 239.06527 | H29: 96169 | I29: 4.1776456

Sheet Top 50
A1: Rank By Monthly Revenue - ONLY
A2: Ranking | B2: ASIN | C2: Product Name | D2: Brand | E2: Type | F2: Basic Resolution | G2: Super Resolution | H2: Laser | I2: Wi-Fi | J2: Visual Camera | K2: Display | L2: Price | M2: Est. Monthly Retail Rev | N2: Est. Monthly Units Sold | O2: # of Reviews | P2: Avg. Rating | Q2: Column2 | R2: Link
A3: 1 | B3: B0CWS4BVCX | C3: HF96 Thermal Camera with Laser Pointer, Intelligent Scene Detection, Super Resolution 240 x 240, Thermal Imaging Camera96 x 96 IR Resolution, 25 HZ Infrared Camera, -4°F~1022°F,11h Runtime | D3: hsftools | E3: Handheld | F3: 96x96 | G3: 240x240 | H3: Yes | I3: No | J3: No | K3: 2.4" | L3: 164.98 | M3: 338530.68 | N3: 1539 | O3: 965 | P3: 4.5 | Q3: https://amazon.com/dp/B0CWS4BVCX | R3: =HYPERLINK(Q3) -> https://amazon.com/dp/B0CWS4BVCX
A4: 2 | B4: B0F8MZVFBJ | C4: TOPDON TC002C Duo Thermal Camera, Compatible with Any USB-C iPhone, iPad & Android Device, 512 x 384 Super Resolution, 256 x 192 IR Resolution Thermal Imager, -4°F~1022°F Temp Range | D4: topdon | E4: Dongle (USB-C/both) | F4: 256x192 | G4: 512x384 | H4: No | I4: No | J4: No | K4: App | L4: 242 | M4: 296493.24 | N4: 1226 | O4: 99 | P4: 4.3 | Q4: https://amazon.com/dp/B0F8MZVFBJ | R4: =HYPERLINK(Q4) -> https://amazon.com/dp/B0F8MZVFBJ
A5: 3 | B5: B0CYCKHTVW | C5: HF96V Thermal Camera with Visual Camera & Laser Pointer, Intelligent Scene Detection, 240 * 240 Super Resolution Thermal Imaging Camera,25 Hz, 50° FOV, -4°F to 1022°F, IP54 Infrared Camera | D5: hsftools | E5: Handheld | F5: 96x96 | G5: 240x240 | H5: Yes | I5: No | J5: 0.3MP | K5: 2.4" | L5: 219.99 | M5: 236075.55 | N5: 1073 | O5: 966 | P5: 4.5 | Q5: https://amazon.com/dp/B0CYCKHTVW | R5: =HYPERLINK(Q5) -> https://amazon.com/dp/B0CYCKHTVW
A6: 4 | B6: B0CXNYMG1M | C6: HP96 Thermal Imaging Camera,3.5" Touch Screen Thermal Camera with Visual Camera, Intelligent Scene Detection, 240 x 240 Super Resolution, 96 x 96 IR Resolution, 25 Hz Video Recording, -4°F to 662°F | D6: hsftools | E6: Landscape | F6: 96x96 | G6: 240x240 | H6: No | I6: No | J6: 0.3MP | K6: 3.5" Touchscreen | L6: 239.99 | M6: 199584.78 | N6: 879 | O6: 466 | P6: 4.4 | Q6: https://amazon.com/dp/B0CXNYMG1M | R6: =HYPERLINK(Q6) -> https://amazon.com/dp/B0CXNYMG1M
A7: 5 | B7: B0728C7KNC | C7: Flir One - Thermal Imaging Camera for Android Smartphones (USB-C), 240x180 Super Resolution (80x60 Native IR) | D7: flir | E7: Dongle (USB-C/Android) | F7: 80x60 | G7: 240x180 | H7: No | I7: No | J7: 2MP | K7: App | L7: 209.99 | M7: 194001.73 | N7: 987 | O7: 6657 | P7: 4.2 | Q7: https://amazon.com/dp/B0728C7KNC | R7: =HYPERLINK(Q7) -> https://amazon.com/dp/B0728C7KNC
A8: 6 | B8: B0DPXX7P5M | C8: Flir One - Thermal Imaging Camera for iOS Smartphones (iPhone 15 and Newer w/USB-C), 240x180 Super Resolution (80x60 Native IR) | D8: flir | E8: Dongle (USB-C/iOS) | F8: 80x60 | G8: 240x180 | H8: No | I8: No | J8: 2MP | K8: App | L8: 209.99 | M8: 192739.44 | N8: 943 | O8: 6667 | P8: 4.2 | Q8: https://amazon.com/dp/B0DPXX7P5M | R8: =HYPERLINK(Q8) -> https://amazon.com/dp/B0DPXX7P5M
A9: 7 | B9: B0F5461RX3 | C9: Thermal Master Handheld Thermal Camera, 512×384 X³IR Resolution, Thermal Imaging Camera with 2MP Visual Camera, 640×480 3.5" IPS Screen Thermal Imager with Laser, -4℉to 1022℉, 60Hz, 40mK(Thor 002) | D9: thermal master | E9: Handheld | F9: 256x192 | G9: 512x384 | H9: Yes | I9: Yes | J9: 2MP | K9: 3.5" | L9: 379.04 | M9: 189178.59 | N9: 488 | O9: 126 | P9: 4.2 | Q9: https://amazon.com/dp/B0F5461RX3 | R9: =HYPERLINK(Q9) -> https://amazon.com/dp/B0F5461RX3
A10: 8 | B10: B0DPXWFD12 | C10: Flir One Pro - Thermal Imaging Camera for iOS Smartphones (iPhone 15 and Newer w/USB-C), 480x360 Super Resolution (160x120 Native IR) | D10: flir | E10: Dongle (USB-C/iOS) | F10: 160x120 | G10: 480x360 | H10: No | I10: No | J10: 2MP | K10: App | L10: 429 | M10: 188403.96 | N10: 449 | O10: 3654 | P10: 4.3 | Q10: https://amazon.com/dp/B0DPXWFD12 | R10: =HYPERLINK(Q10) -> https://amazon.com/dp/B0DPXWFD12
A11: 9 | B11: B0892MZZT1 | C11: FLIR C5 Compact Thermal Imaging Camera with Wifi: High Resolution Infrared Imager for Inspection, Electrical/Mechanical, Building, and HVAC Applications | D11: flir | E11: Landscape | F11: 160x120 | G11: - | H11: No | I11: Yes | J11: 5MP | K11: 3.5" Touchscreen | L11: 569.99 | M11: 184784.77 | N11: 308 | O11: 1265 | P11: 4.3 | Q11: https://amazon.com/dp/B0892MZZT1 | R11: =HYPERLINK(Q11) -> https://amazon.com/dp/B0892MZZT1
A12: 10 | B12: B0D8QC83BV | C12: MILESEEY TR10 Thermal Imaging Camera,Super Resolution 192 x 192 Thermal Camera,25 Hz Refresh Rate, -4°F to 1022°F Handheld Infrared Imager,8-Hour Battery Life Infrared Camera | D12: mileseey | E12: Handheld | F12: 96x96 | G12: 240x240 | H12: No | I12: No | J12: No | K12: 2.8" | L12: 169.99 | M12: 173136.7 | N12: 976 | O12: 362 | P12: 4.3 | Q12: https://amazon.com/dp/B0D8QC83BV | R12: =HYPERLINK(Q12) -> https://amazon.com/dp/B0D8QC83BV
A13: 11 | B13: B0FNCDQWJR | C13: Thermal Master P3 - Thermal Camera for iOS & Android, 8mm Macro Vision Infrared Imager w/Manual Lens, 512x384 Super Ir Resolution, 3.6℉ Accuracy, 35mk NETD, Work for Home PCB Inspection, Black | D13: thermal master | E13: Dongle (USB-C/both) | F13: 256x192 | G13: 512x384 | H13: No | I13: No | J13: No | K13: App | L13: 339 | M13: 161121.64 | N13: 475 | O13: 41 | P13: 4.5 | Q13: https://amazon.com/dp/B0FNCDQWJR | R13: =HYPERLINK(Q13) -> https://amazon.com/dp/B0FNCDQWJR
A14: 12 | B14: B0BRK4SGD2 | C14: TOPDON TC004 Thermal Imaging Camera, 320 x 240 TISR Resolution, 256 x 192 IR High Resolution, 12-Hour Battery Life Handheld Infrared Camera with PC Analysis and Video Recording Supported, 32GB SD Card | D14: topdon | E14: Handheld | F14: 256x192 | G14: 320x240 | H14: No | I14: No | J14: No | K14: 2.8" | L14: 284.04 | M14: 156204.18 | N14: 516 | O14: 879 | P14: 4.6 | Q14: https://amazon.com/dp/B0BRK4SGD2 | R14: =HYPERLINK(Q14) -> https://amazon.com/dp/B0BRK4SGD2
... A52: 50 | B52: B09FTFHTPR | C52: HIKMICRO B10 Thermal Imaging Camera 320 x 240 Super IR with 2MP Visual, 3.2" LCD Screen 256 x 192 IR Resolution Thermal Camera, 25 Hz Refresh Rate, -4°F~1022°F, IP54 | D52: hikmicro | E52: - | F52: - | G52: - | H52: - | I52: - | J52: - | K52: - | L52: 399 | M52: 23267.28 | N52: 58 | O52: 477 | P52: 4.3 | Q52: https://amazon.com/dp/B09FTFHTPR | R52: =HYPERLINK(Q52) -> https://amazon.com/dp/B09FTFHTPR
A55: Rank By Monthly Units - ONLY
A56: Ranking | B56: ASIN | C56: Product Name | D56: Brand | E56: Type | F56: Basic Resolution | G56: Super Resolution | H56: Laser | I56: Wi-Fi | J56: Visual Camera | K56: Display | L56: Price | M56: Est. Monthly Retail Rev | N56: Est. Monthly Units Sold | O56: # of Reviews | P56: Avg. Rating | Q56: Column2 | R56: Link
A57: 1 | B57: B0CWS4BVCX | C57: HF96 Thermal Camera with Laser Pointer, Intelligent Scene Detection, Super Resolution 240 x 240, Thermal Imaging Camera96 x 96 IR Resolution, 25 HZ Infrared Camera, -4°F~1022°F,11h Runtime | D57: hsftools | E57: Handheld | F57: 96x96 | G57: 240x240 | H57: Yes | I57: No | J57: No | K57: 2.4" | L57: 164.98 | M57: 338530.68 | N57: 1539 | O57: 965 | P57: 4.5 | Q57: https://amazon.com/dp/B0CWS4BVCX | R57: =HYPERLINK(Q57) -> https://amazon.com/dp/B0CWS4BVCX
A58: 2 | B58: B0F8MZVFBJ | C58: TOPDON TC002C Duo Thermal Camera, Compatible with Any USB-C iPhone, iPad & Android Device, 512 x 384 Super Resolution, 256 x 192 IR Resolution Thermal Imager, -4°F~1022°F Temp Range | D58: topdon | E58: Dongle (USB-C/both) | F58: 256x192 | G58: 512x384 | H58: No | I58: No | J58: No | K58: App | L58: 242 | M58: 296493.24 | N58: 1226 | O58: 99 | P58: 4.3 | Q58: https://amazon.com/dp/B0F8MZVFBJ | R58: =HYPERLINK(Q58) -> https://amazon.com/dp/B0F8MZVFBJ
A59: 3 | B59: B0CYCKHTVW | C59: HF96V Thermal Camera with Visual Camera & Laser Pointer, Intelligent Scene Detection, 240 * 240 Super Resolution Thermal Imaging Camera,25 Hz, 50° FOV, -4°F to 1022°F, IP54 Infrared Camera | D59: hsftools | E59: Handheld | F59: 96x96 | G59: 240x240 | H59: Yes | I59: No | J59: 0.3MP | K59: 2.4" | L59: 219.99 | M59: 236075.55 | N59: 1073 | O59: 966 | P59: 4.5 | Q59: https://amazon.com/dp/B0CYCKHTVW | R59: =HYPERLINK(Q59) -> https://amazon.com/dp/B0CYCKHTVW
A60: 4 | B60: B0728C7KNC | C60: Flir One - Thermal Imaging Camera for Android Smartphones (USB-C), 240x180 Super Resolution (80x60 Native IR) | D60: flir | E60: Dongle (USB-C/Android) | F60: 80x60 | G60: 240x180 | H60: No | I60: No | J60: 2MP | K60: App | L60: 209.99 | M60: 194001.73 | N60: 987 | O60: 6657 | P60: 4.2 | Q60: https://amazon.com/dp/B0728C7KNC | R60: =HYPERLINK(Q60) -> https://amazon.com/dp/B0728C7KNC
A61: 5 | B61: B0D8QC83BV | C61: MILESEEY TR10 Thermal Imaging Camera,Super Resolution 192 x 192 Thermal Camera,25 Hz Refresh Rate, -4°F to 1022°F Handheld Infrared Imager,8-Hour Battery Life Infrared Camera | D61: mileseey | E61: Handheld | F61: 96x96 | G61: 240x240 | H61: No | I61: No | J61: No | K61: 2.8" | L61: 169.99 | M61: 173136.7 | N61: 976 | O61: 362 | P61: 4.3 | Q61: https://amazon.com/dp/B0D8QC83BV | R61: =HYPERLINK(Q61) -> https://amazon.com/dp/B0D8QC83BV
A62: 6 | B62: B0DPXX7P5M | C62: Flir One - Thermal Imaging Camera for iOS Smartphones (iPhone 15 and Newer w/USB-C), 240x180 Super Resolution (80x60 Native IR) | D62: flir | E62: Dongle (USB-C/iOS) | F62: 80x60 | G62: 240x180 | H62: No | I62: No | J62: 2MP | K62: App | L62: 209.99 | M62: 192739.44 | N62: 943 | O62: 6667 | P62: 4.2 | Q62: https://amazon.com/dp/B0DPXX7P5M | R62: =HYPERLINK(Q62) -> https://amazon.com/dp/B0DPXX7P5M
A63: 7 | B63: B0F8VQ7R3R | C63: Flagfront Thermal Camera, 240 x 240 TISR Resolution, -4°F to 1022°F Temp Range, 25Hz Infrared Camera with Temperature Alarm, 50°FOV Handheld Thermal Imaging Camera | D63: flagfront | E63: Handheld | F63: 96x96 | G63: 240x240 | H63: No | I63: No | J63: No | K63: 1.8" | L63: 116.99 | M63: 118067.77 | N63: 905 | O63: 89 | P63: 4.4 | Q63: https://amazon.com/dp/B0F8VQ7R3R | R63: =HYPERLINK(Q63) -> https://amazon.com/dp/B0F8VQ7R3R
A64: 8 | B64: B0CXNYMG1M | C64: HP96 Thermal Imaging Camera,3.5" Touch Screen Thermal Camera with Visual Camera, Intelligent Scene Detection, 240 x 240 Super Resolution, 96 x 96 IR Resolution, 25 Hz Video Recording, -4°F to 662°F | D64: hsftools | E64: Landscape | F64: 96x96 | G64: 240x240 | H64: No | I64: No | J64: 0.3MP | K64: 3.5" Touchscreen | L64: 239.99 | M64: 199584.78 | N64: 879 | O64: 466 | P64: 4.4 | Q64: https://amazon.com/dp/B0CXNYMG1M | R64: =HYPERLINK(Q64) -> https://amazon.com/dp/B0CXNYMG1M
A65: 9 | B65: B0FLK4V7Z6 | C65: Thermal Master Thermal Camera for USB-C iPhone and Android, P1 Thermal Imaging Camera with 320×240 X³ IR Resolution, -4℉ to 1112℉, 160×120 Infrared Camera (iOS and Android) | D65: thermal master | E65: Dongle (USB-C/both) | F65: 160x120 | G65: 320x240 | H65: No | I65: No | J65: No | K65: App | L65: 139 | M65: 121252.34 | N65: 872 | O65: 72 | P65: 4.2 | Q65: https://amazon.com/dp/B0FLK4V7Z6 | R65: =HYPERLINK(Q65) -> https://amazon.com/dp/B0FLK4V7Z6
A66: 10 | B66: B0B7LMB22Q | C66: TOPDON TC001 Thermal Camera for Android, Super IR 512x384 High Resolution, Thermal Imaging Camera, Thermal Imager - Optimized Temperature Accuracy, Works for Smartphones and Tablets & PC(not for iOS) | D66: topdon | E66: Dongle (USB-C/Android) | F66: 256x192 | G66: 512x384 | H66: No | I66: No | J66: No | K66: App | L66: 199.48 | M66: 151999.25 | N66: 706 | O66: 1387 | P66: 4.6 | Q66: https://amazon.com/dp/B0B7LMB22Q | R66: =HYPERLINK(Q66) -> https://amazon.com/dp/B0B7LMB22Q
A67: 11 | B67: B0DX1PQCZR | C67: GOYOJO Thermal Imaging Camera for Android/iphone 15/16/17 iOS Series 192x192 IR Resolution– Water Leak Detection HVAC Electrical Plumbing, Automotive Repair, Home Inspection, DIY-USB-C Infrared Imager | D67: goyojo | E67: Dongle (USB-C/both) | F67: 96x96 | G67: 192x192 | H67: No | I67: No | J67: No | K67: App | L67: 98.1 | M67: 57454 | N67: 572 | O67: 642 | P67: 4.3 | Q67: https://amazon.com/dp/B0DX1PQCZR | R67: =HYPERLINK(Q67) -> https://amazon.com/dp/B0DX1PQCZR
A68: 12 | B68: B0BRK4SGD2 | C68: TOPDON TC004 Thermal Imaging Camera, 320 x 240 TISR Resolution, 256 x 192 IR High Resolution, 12-Hour Battery Life Handheld Infrared Camera with PC Analysis and Video Recording Supported, 32GB SD Card | D68: topdon | E68: Handheld | F68: 256x192 | G68: 320x240 | H68: No | I68: No | J68: No | K68: 2.8" | L68: 284.04 | M68: 156204.18 | N68: 516 | O68: 879 | P68: 4.6 | Q68: https://amazon.com/dp/B0BRK4SGD2 | R68: =HYPERLINK(Q68) -> https://amazon.com/dp/B0BRK4SGD2
... A106: 50 | B106: B0DCZ8CRCS | C106: HSFTOOLS P2W 640x480 Super Resolution Thermal Camera with Dual-Camera, 256x192 IR Resolution Thermal Imaging Camera, 3.5" Touch Screen,Wi-Fi,8MP Visible Camera, Video and Audio Recording | D106: hsftools | E106: Landscape | F106: 256x192 | G106: - | H106: No | I106: Yes | J106: 8MP | K106: 3.5" Touchscreen | L106: 479 | M106: 31475.08 | N106: 67 | O106: 42 | P106: 4.6 | Q106: https://amazon.com/dp/B0DCZ8CRCS | R106: =HYPERLINK(Q106) -> https://amazon.com/dp/B0DCZ8CRCS

Sheet Top 50 Type Summary
A1: Top 50 By Revenue Summary
A2: Type | B2: Avg Price | C2: Quantity/Mo | D2: Qty by % | E2: Revenue/Mo | F2: Revenue by %
A3: - | B3: 427.62 | C3: 1163 | D3: 0.05739242 | E3: 295072.49 | F3: 0.059530322
A4: Dongle | B4: 253.26778 | C4: 8656 | D4: 0.42716147 | E4: 1942457.7 | F4: 0.3918872
A5: Handheld | B5: 298.33133 | C5: 8011 | D5: 0.39533162 | E5: 1879251.4 | F5: 0.37913545
A6: Landscape | B6: 489.66167 | C6: 1712 | D6: 0.084484801 | E6: 629987.86 | F6: 0.12709887
A7: Pocket size | B7: 119.99 | C7: 240 | D7: 0.011843664 | E7: 31253.14 | F7: 0.0063052625
A8: Wireless | B8: 413.75 | C8: 482 | D8: 0.023786024 | E8: 178652.94 | F8: 0.036042896
A9: Total | B9: 333.77013 | C9: 20264 | D9: 1 | E9: 4956675.5 | F9: 1
A26: Top 50 By Unit Summary
A27: Type | B27: Avg Price | C27: Quantity/Mo | D27: Qty by % | E27: Revenue/Mo | F27: Revenue by %
A28: - | B28: 207.99167 | C28: 1198 | D28: 0.058042636 | E28: 238496.64 | F28: 0.048880358
A29: Accessory | B29: 18.49 | C29: 262 | D29: 0.012693798 | E29: 4858.99 | F29: 0.00099585962
A30: Dongle | B30: 242.27444 | C30: 8660 | D30: 0.41957364 | E30: 1930192 | F30: 0.39559666
A31: Handheld | B31: 267.064 | C31: 8086 | D31: 0.39176357 | E31: 1865750.2 | F31: 0.3823892
A32: Landscape | B32: 489.66167 | C32: 1712 | D32: 0.082945736 | E32: 629987.86 | F32: 0.12911726
A33: Pocket size | B33: 119.99 | C33: 240 | D33: 0.011627907 | E33: 31253.14 | F33: 0.0064053929
A34: Wireless | B34: 413.75 | C34: 482 | D34: 0.023352713 | E34: 178652.94 | F34: 0.036615274
A35: Total | B35: 251.3174 | C35: 20640 | D35: 1 | E35: 4879191.7 | F35: 1

Sheet Top50 Basic Resolution Summary 
A1: Top 50 By Revenue Summary
A2: Basic Resolution | B2: Avg Price | C2: Quantity/Mo | D2: Qty by % | E2: Revenue/Mo | F2: Revenue by %
A3: - | B3: 427.62 | C3: 1163 | D3: 0.05739242 | E3: 295072.49 | F3: 0.059530322
A4: 120x90 | B4: 177.99 | C4: 914 | D4: 0.045104619 | E4: 150615.79 | F4: 0.030386454
A5: 128x96 | B5: 450 | C5: 173 | D5: 0.0085373075 | E5: 81004.17 | F5: 0.01634244
A6: 160x120 | B6: 367.42667 | C6: 2950 | D6: 0.14557837 | E6: 900027.48 | F6: 0.18157886
A7: 256x192 | B7: 336.62125 | C7: 5550 | D7: 0.27388472 | E7: 1612498.2 | F7: 0.32531849
A8: 320x240 | B8: 899 | C8: 79 | D8: 0.0038985393 | E8: 71231.47 | F8: 0.014370816
A9: 80x60 | B9: 233.57667 | C9: 3099 | D9: 0.15293131 | E9: 679910.23 | F9: 0.13717062
A10: 96x96 | B10: 160.00429 | C10: 6336 | D10: 0.31267272 | E10: 1166315.7 | F10: 0.235302
A11: Total | B11: 381.52986 | C11: 20264 | D11: 1 | E11: 4956675.5 | F11: 1
A29: Top 50 By Unit Summary
A30: Basic Resolution | B30: Avg Price | C30: Quantity/Mo | D30: Qty by % | E30: Revenue/Mo | F30: Revenue by %
A31: - | B31: 160.61625 | C31: 1460 | D31: 0.070736434 | E31: 243355.63 | F31: 0.049876218
A32: 120x90 | B32: 177.99 | C32: 914 | D32: 0.044282946 | E32: 150615.79 | F32: 0.030869004
A33: 128x96 | B33: 450 | C33: 173 | D33: 0.0083817829 | E33: 81004.17 | F33: 0.016601965
A34: 160x120 | B34: 367.365 | C34: 2883 | D34: 0.13968023 | E34: 874386.35 | F34: 0.17920721
A35: 256x192 | B35: 309.81125 | C35: 5572 | D35: 0.26996124 | E35: 1596643.3 | F35: 0.3272352
A36: 320x240 | B36: 899 | C36: 79 | D36: 0.0038275194 | E36: 71231.47 | F36: 0.014599031
A37: 80x60 | B37: 233.57667 | C37: 3099 | D37: 0.15014535 | E37: 679910.23 | F37: 0.13934895
A38: 96x96 | B38: 156.2525 | C38: 6460 | D38: 0.3129845 | E38: 1182044.8 | F38: 0.24226243
A39: Total | B39: 344.32646 | C39: 20640 | D39: 1 | E39: 4879191.7 | F39: 1

Sheet Top 50 Super Resolutio Summary 
A1: Top 50 By Revenue Summary
A2: Super Resolution | B2: Avg Price | C2: Quantity/Mo | D2: Qty by % | E2: Revenue/Mo | F2: Revenue by %
A3: - | B3: 443.18667 | C3: 2898 | D3: 0.14301224 | E3: 1022898.1 | F3: 0.20636778
A4: 160x120 | B4: 353 | C4: 360 | D4: 0.017765495 | E4: 128895.71 | F4: 0.026004468
A5: 192x192 | B5: 98.1 | C5: 572 | D5: 0.028227398 | E5: 57454 | F5: 0.011591237
A6: 240x180 | B6: 214.075 | C6: 3413 | D6: 0.16842677 | E6: 670377.17 | F6: 0.13524734
A7: 240x240 | B7: 170.32167 | C7: 5764 | D7: 0.28444532 | E7: 1108861.7 | F7: 0.22371077
A8: 320x240 | B8: 187.34667 | C8: 1778 | D8: 0.087741808 | E8: 331636.56 | F8: 0.066907055
A9: 480x360 | B9: 421.23 | C9: 956 | D9: 0.04717726 | E9: 391004.24 | F9: 0.078884373
A10: 512x384 | B10: 305.31 | C10: 4523 | D10: 0.22320371 | E10: 1245548 | F10: 0.25128698
A11: Total | B11: 274.07125 | C11: 20264 | D11: 1 | E11: 4956675.5 | F11: 1
A29: Top 50 By Unit Summary
A30: Super Resolution | B30: Avg Price | C30: Quantity/Mo | D30: Qty by % | E30: Revenue/Mo | F30: Revenue by %
A31: - | B31: 324.51833 | C31: 3195 | D31: 0.15479651 | E31: 971181.25 | F31: 0.19904552
A32: 160x120 | B32: 353 | C32: 360 | D32: 0.01744186 | E32: 128895.71 | F32: 0.026417431
A33: 192x192 | B33: 98.1 | C33: 572 | D33: 0.027713178 | E33: 57454 | F33: 0.011775311
A34: 240x180 | B34: 214.075 | C34: 3413 | D34: 0.16535853 | E34: 670377.17 | F34: 0.13739513
A35: 240x240 | B35: 164.56 | C35: 5888 | D35: 0.28527132 | E35: 1124590.8 | F35: 0.23048712
A36: 320x240 | B36: 187.34667 | C36: 1778 | D36: 0.086143411 | E36: 331636.56 | F36: 0.067969569
A37: 480x360 | B37: 439 | C37: 889 | D37: 0.043071705 | E37: 365363.11 | F37: 0.074881892
A38: 512x384 | B38: 266.31364 | C38: 4545 | D38: 0.22020349 | E38: 1229693.1 | F38: 0.25202803
A39: Total | B39: 255.8642 | C39: 20640 | D39: 1 | E39: 4879191.7 | F39: 1

Sheet Top50 Laser Summary  
A1: Top 50 By Revenue Summary
A2: Laser | B2: Avg Price | C2: Quantity/Mo | D2: Qty by % | E2: Revenue/Mo | F2: Revenue by %
A3: - | B3: 427.62 | C3: 1163 | D3: 0.05739242 | E3: 295072.49 | F3: 0.059530322
A4: No | B4: 305.09765 | C4: 14460 | D4: 0.71358073 | E4: 3502177.8 | F4: 0.70655782
A5: Yes | B5: 318.24125 | C5: 4641 | D5: 0.22902685 | E5: 1159425.2 | F5: 0.23391186
A6: Total | B6: 350.31963 | C6: 20264 | D6: 1 | E6: 4956675.5 | F6: 1
A24: Top 50 By Unit Summary
A25: Laser | B25: Avg Price | C25: Quantity/Mo | D25: Qty by % | E25: Revenue/Mo | F25: Revenue by %
A26: - | B26: 160.61625 | C26: 1460 | D26: 0.070736434 | E26: 243355.63 | F26: 0.049876218
A27: No | B27: 294.44086 | C27: 14588 | D27: 0.70678295 | E27: 3505641.3 | F27: 0.71848812
A28: Yes | B28: 278.13286 | C28: 4592 | D28: 0.22248062 | E28: 1130194.8 | F28: 0.23163566
A29: Total | B29: 244.39665 | C29: 20640 | D29: 1 | E29: 4879191.7 | F29: 1

Sheet Top50 Wi-Fi Summary 
A1: Top 50 By Revenue Summary
A2: Wi-Fi | B2: Avg Price | C2: Quantity/Mo | D2: Qty by % | E2: Revenue/Mo | F2: Revenue by %
A3: - | B3: 427.62 | C3: 1163 | D3: 0.05739242 | E3: 295072.49 | F3: 0.059530322
A4: BT | B4: 413.47 | C4: 578 | D4: 0.02852349 | E4: 215794.21 | F4: 0.043536078
A5: No | B5: 242.24968 | C5: 16632 | D5: 0.82076589 | E5: 3584791.6 | F5: 0.723225
A6: Yes | B6: 509.17444 | C6: 1891 | D6: 0.0933182 | E6: 861017.16 | F6: 0.1737086
A7: Total | B7: 398.12853 | C7: 20264 | D7: 1 | E7: 4956675.5 | F7: 1
A25: Top 50 By Unit Summary
A26: Wi-Fi | B26: Avg Price | C26: Quantity/Mo | D26: Qty by % | E26: Revenue/Mo | F26: Revenue by %
A27: - | B27: 160.61625 | C27: 1460 | D27: 0.070736434 | E27: 243355.63 | F27: 0.049876218
A28: BT | B28: 413.47 | C28: 578 | D28: 0.028003876 | E28: 215794.21 | F28: 0.04422745
A29: No | B29: 232.55781 | C29: 16760 | D29: 0.8120155 | E29: 3588255.1 | F29: 0.73541998
A30: Yes | B30: 497.94625 | C30: 1842 | D30: 0.089244186 | E30: 831786.82 | F30: 0.17047635
A31: Total | B31: 326.14758 | C31: 20640 | D31: 1 | E31: 4879191.7 | F31: 1

Sheet Top50 Visual Camera Summary  
A1: Top 50 By Revenue Summary
A2: Visual Camera | B2: Avg Price | C2: Quantity/Mo | D2: Qty by % | E2: Revenue/Mo | F2: Revenue by %
A3: - | B3: 427.62 | C3: 1163 | D3: 0.05739242 | E3: 295072.49 | F3: 0.059530322
A4: 0.3MP | B4: 321.87 | C4: 2434 | D4: 0.12011449 | E4: 614313.27 | F4: 0.12393655
A5: 1MP | B5: 202.985 | C5: 602 | D5: 0.029707856 | E5: 100600.15 | F5: 0.020295892
A6: 2MP | B6: 360.54182 | C6: 4334 | D6: 0.21387683 | E6: 1267054.4 | F6: 0.25562586
A7: 5MP | B7: 639.66333 | C7: 560 | D7: 0.027635215 | E7: 337020.41 | F7: 0.067993237
A8: 8MP | B8: 479 | C8: 67 | D8: 0.0033063561 | E8: 31475.08 | F8: 0.0063500385
A9: No | B9: 231.51667 | C9: 11104 | D9: 0.54796684 | E9: 2311139.7 | F9: 0.4662681
A10: Total | B10: 380.45669 | C10: 20264 | D10: 1 | E10: 4956675.5 | F10: 1
A28: Top 50 By Unit Summary
A29: Visual Camera | B29: Avg Price | C29: Quantity/Mo | D29: Qty by % | E29: Revenue/Mo | F29: Revenue by %
A30: - | B30: 160.61625 | C30: 1460 | D30: 0.070736434 | E30: 243355.63 | F30: 0.049876218
A31: 0.3MP | B31: 321.87 | C31: 2434 | D31: 0.11792636 | E31: 614313.27 | F31: 0.12590472
A32: 1MP | B32: 202.985 | C32: 602 | D32: 0.029166667 | E32: 100600.15 | F32: 0.0206182
A33: 2MP | B33: 333.22667 | C33: 4218 | D33: 0.20436047 | E33: 1212183 | F33: 0.2484393
A34: 5MP | B34: 639.66333 | C34: 560 | D34: 0.027131783 | E34: 337020.41 | F34: 0.069073
A35: 8MP | B35: 479 | C35: 67 | D35: 0.003246124 | E35: 31475.08 | F35: 0.0064508799
A36: No | B36: 224.42957 | C36: 11299 | D36: 0.54743217 | E36: 2340244.2 | F36: 0.47963769
A37: Total | B37: 337.39869 | C37: 20640 | D37: 1 | E37: 4879191.7 | F37: 1

Sheet Top50 Display Summary 
A1: Top 50 By Revenue Summary
A2: Display | B2: Avg Price | C2: Quantity/Mo | D2: Qty by % | E2: Revenue/Mo | F2: Revenue by %
A3: - | B3: 427.62 | C3: 1163 | D3: 0.05739242 | E3: 295072.49 | F3: 0.059530322
A4: 1.8" | B4: 116.99 | C4: 905 | D4: 0.044660482 | E4: 118067.77 | F4: 0.023819952
A5: 2.4" | B5: 270.315 | C5: 3788 | D5: 0.18693249 | E5: 895774.22 | F5: 0.18072077
A6: 2.8" | B6: 300.602 | C6: 2295 | D6: 0.11325503 | E6: 549481.98 | F6: 0.11085696
A7: 3.2" | B7: 175.99 | C7: 447 | D7: 0.022058824 | E7: 63966.27 | F7: 0.012905075
A8: 3.5" | B8: 452.36 | C8: 782 | D8: 0.038590604 | E8: 313868.73 | F8: 0.063322429
A9: 3.5" Touchscreen | B9: 527.596 | C9: 1506 | D9: 0.074318989 | E9: 568080.27 | F9: 0.11460913
A10: App | B10: 262.20524 | C10: 9378 | D10: 0.46279116 | E10: 2152363.8 | F10: 0.43423536
A11: Total | B11: 316.70978 | C11: 20264 | D11: 1 | E11: 4956675.5 | F11: 1
A29: Top 50 By Unit Summary
A30: Display | B30: Avg Price | C30: Quantity/Mo | D30: Qty by % | E30: Revenue/Mo | F30: Revenue by %
A31: - | B31: 207.99167 | C31: 1198 | D31: 0.058042636 | E31: 238496.64 | F31: 0.048880358
A32: 1.8" | B32: 116.99 | C32: 905 | D32: 0.043846899 | E32: 118067.77 | F32: 0.024198223
A33: 2.4" | B33: 250.26857 | C33: 3912 | D33: 0.18953488 | E33: 911503.38 | F33: 0.18681442
A34: 2.8" | B34: 300.602 | C34: 2295 | D34: 0.11119186 | E34: 549481.98 | F34: 0.11261742
A35: 3.2" | B35: 175.99 | C35: 447 | D35: 0.021656977 | E35: 63966.27 | F35: 0.013110014
A36: 3.5" | B36: 379.04 | C36: 733 | D36: 0.035513566 | E36: 284638.39 | F36: 0.058337201
A37: 3.5" Touchscreen | B37: 527.596 | C37: 1506 | D37: 0.072965116 | E37: 568080.27 | F37: 0.11642918
A38: App | B38: 232.40913 | C38: 9644 | D38: 0.46724806 | E38: 2144957 | F38: 0.43961319
A39: Total | B39: 273.86092 | C39: 20640 | D39: 1 | E39: 4879191.7 | F39: 1

Sheet Flir
A1: #VALUE!
A7: Rank by Revenue
A8: Product Name | B8: ASIN | C8: Avg Price | D8: Estimated 12mo Revenue | E8: Monthly Rev | F8: Estimated 12mo Units | G8: Monthly Units | H8: # of Reviews | I8: Tool Rating | J8: Column1 | K8: Link
A9: Flir One - Thermal Imaging Camera for Android Smartphones (USB-C), 240x180 Super Resolution (80x60 Native IR) | B9: B0728C7KNC | C9: 209.99 | D9: 2328020.8 | E9: 194001.73 | F9: 11844 | G9: 987 | H9: 6657 | I9: 4.2 | J9: https://amazon.com/dp/B0728C7KNC | K9: =HYPERLINK(J9) -> https://amazon.com/dp/B0728C7KNC
A10: Flir One - Thermal Imaging Camera for iOS Smartphones (iPhone 15 and Newer w/USB-C), 240x180 Super Resolution (80x60 Native IR) | B10: B0DPXX7P5M | C10: 209.99 | D10: 2312873.3 | E10: 192739.44 | F10: 11316 | G10: 943 | H10: 6667 | I10: 4.2 | J10: https://amazon.com/dp/B0DPXX7P5M | K10: =HYPERLINK(J10) -> https://amazon.com/dp/B0DPXX7P5M
A11: Flir One Pro - Thermal Imaging Camera for iOS Smartphones (iPhone 15 and Newer w/USB-C), 480x360 Super Resolution (160x120 Native IR) | B11: B0DPXWFD12 | C11: 429 | D11: 2260847.5 | E11: 188403.96 | F11: 5388 | G11: 449 | H11: 3654 | I11: 4.3 | J11: https://amazon.com/dp/B0DPXWFD12 | K11: =HYPERLINK(J11) -> https://amazon.com/dp/B0DPXWFD12
A12: FLIR C5 Compact Thermal Imaging Camera with Wifi: High Resolution Infrared Imager for Inspection, Electrical/Mechanical, Building, and HVAC Applications | B12: B0892MZZT1 | C12: 569.99 | D12: 2217417.2 | E12: 184784.77 | F12: 3696 | G12: 308 | H12: 1265 | I12: 4.3 | J12: https://amazon.com/dp/B0892MZZT1 | K12: =HYPERLINK(J12) -> https://amazon.com/dp/B0892MZZT1
A13: FLIR TG165-X Thermal Imaging Camera with Bullseye Laser: Commercial Grade Infrared Camera for Building Inspection, HVAC and Electrical | B13: B08D3YC5CW | C13: 353 | D13: 1546748.5 | E13: 128895.71 | F13: 4320 | G13: 360 | H13: 1425 | I13: 4.3 | J13: https://amazon.com/dp/B08D3YC5CW | K13: =HYPERLINK(J13) -> https://amazon.com/dp/B08D3YC5CW
A14: Flir Edge Pro - Wireless Bluetooth Thermal Imaging Camera for Smartphones, Compatible with All iOS and Android Devices, 480x360 Super Resolution (160x120 Native IR) | B14: B0BLJD6Q5G | C14: 529 | D14: 1292640.6 | E14: 107720.05 | F14: 2868 | G14: 239 | H14: 386 | I14: 4.1 | J14: https://amazon.com/dp/B0BLJD6Q5G | K14: =HYPERLINK(J14) -> https://amazon.com/dp/B0BLJD6Q5G
A15: FLIR TG267 Thermal Imaging Camera with Bullseye Laser: Commercial Grade Infrared Camera for Building Inspection, HVAC and Electrical | B15: B07XH96SK4 | C15: 473.94 | D15: 1042782 | E15: 86898.5 | F15: 2616 | G15: 218 | H15: 1425 | I15: 4.3 | J15: https://amazon.com/dp/B07XH96SK4 | K15: =HYPERLINK(J15) -> https://amazon.com/dp/B07XH96SK4
A16: FLIR C3-X Compact Thermal Imaging Camera with Wifi: High Resolution Infrared Imager for Inspection, Electrical/Mechanical, Building, and HVAC Applications | B16: B08N6YHQWX | C16: 450 | D16: 972050.04 | E16: 81004.17 | F16: 2076 | G16: 173 | H16: 1265 | I16: 4.3 | J16: https://amazon.com/dp/B08N6YHQWX | K16: =HYPERLINK(J16) -> https://amazon.com/dp/B08N6YHQWX
A17: FLIR Cx Thermal Imaging Camera | B17: B0FMH37XL7 | C17: 899 | D17: 854777.64 | E17: 71231.47 | F17: 948 | G17: 79 | H17: 1265 | I17: 4.3 | J17: https://amazon.com/dp/B0FMH37XL7 | K17: =HYPERLINK(J17) -> https://amazon.com/dp/B0FMH37XL7
A18: Flir Edge - Wireless Bluetooth Thermal Imaging Camera for Smartphones, Compatible with All iOS and Android Devices, 240x180 Super Resolution (80x60 Native IR) | B18: B0BLJ3XJ3Z | C18: 298.5 | D18: 851194.68 | E18: 70932.89 | F18: 2916 | G18: 243 | H18: 386 | I18: 4.1 | J18: https://amazon.com/dp/B0BLJ3XJ3Z | K18: =HYPERLINK(J18) -> https://amazon.com/dp/B0BLJ3XJ3Z
A19: Flir One Pro - Thermal Imaging Camera for Android Smartphones (USB-C), 480x360 Super Resolution (160x120 Native IR) | B19: B0716ZGL7C | C19: 359 | D19: 830869.2 | E19: 69239.1 | F19: 2412 | G19: 201 | H19: 3654 | I19: 4.3 | J19: https://amazon.com/dp/B0716ZGL7C | K19: =HYPERLINK(J19) -> https://amazon.com/dp/B0716ZGL7C
A20: Flir One - Thermal Imaging Camera for iOS Smartphones (iPhone 14 and Older w/Lightning Port), 240x180 Super Resolution (80x60 Native IR) | B20: B0728C7KND | C20: 209.99 | D20: 745047.84 | E20: 62087.32 | F20: 3912 | G20: 326 | H20: 6657 | I20: 4.2 | J20: https://amazon.com/dp/B0728C7KND | K20: =HYPERLINK(J20) -> https://amazon.com/dp/B0728C7KND
... A26: FLIR TG56-2 Infrared Spot Thermometer with Digital Readout: for Non-Contact Temperature Measurements up to 2,372 Degrees F | B26: B0CBL4BBP2 | C26: 225 | D26: 8235.72 | E26: 686.31 | F26: 36 | G26: 3 | H26: 93 | I26: 4.2 | J26: https://amazon.com/dp/B0CBL4BBP2 | K26: =HYPERLINK(J26) -> https://amazon.com/dp/B0CBL4BBP2
A27: FLIR T301030ACC 2 Bay Battery Charger for iXX & Exx Series Cameras | B27: B0FMKQYDTM | C27: 215.1 | D27: 5162.16 | E27: 430.18 | F27: 24 | G27: 2 | J27: https://amazon.com/dp/B0FMKQYDTM | K27: =HYPERLINK(J27) -> https://amazon.com/dp/B0FMKQYDTM
A28: FLIR GPX310 Scion Rechargeable Battery Kit, Operate FLIR Scion Thermal Imaging Monoculars For Up To 10 Hours | B28: B08W1MP8QX | C28: 204.99 | D28: 2820.84 | E28: 235.07 | F28: 12 | G28: 1 | H28: 17 | I28: 2.9 | J28: https://amazon.com/dp/B08W1MP8QX | K28: =HYPERLINK(J28) -> https://amazon.com/dp/B08W1MP8QX
A29: FLIR Weather Cover f/Joystick Control Unit [4113315] | B29: B01N7S4H5H | C29: 27.79 | F29: 0 | G29: 0 | H29: 1 | I29: 5 | J29: https://amazon.com/dp/B01N7S4H5H | K29: =HYPERLINK(J29) -> https://amazon.com/dp/B01N7S4H5H
A30: FLIR T198457ACC Tripod Mount Adapter | B30: B07DH6WQG3 | C30: 26.83 | F30: 0 | G30: 0 | J30: https://amazon.com/dp/B07DH6WQG3 | K30: =HYPERLINK(J30) -> https://amazon.com/dp/B07DH6WQG3
A34: Total | D34: =SUM(D9:D33) -> 18138860 | E34: =SUM(E9:E33) -> 1511571.7
A37: Rank by Units
A38: Product Name | B38: ASIN | C38: Avg Price | D38: Estimated 12mo Revenue | E38: Monthly Rev | F38: Estimated 12mo Units | G38: Monthly Units | H38: # of Reviews | I38: Tool Rating | J38: Column1 | K38: Link
A39: Flir One - Thermal Imaging Camera for Android Smartphones (USB-C), 240x180 Super Resolution (80x60 Native IR) | B39: B0728C7KNC | C39: 209.99 | D39: 2328020.8 | E39: 194001.73 | F39: 11844 | G39: 987 | H39: 6657 | I39: 4.2 | J39: https://amazon.com/dp/B0728C7KNC | K39: =HYPERLINK(J39) -> https://amazon.com/dp/B0728C7KNC
A40: Flir One - Thermal Imaging Camera for iOS Smartphones (iPhone 15 and Newer w/USB-C), 240x180 Super Resolution (80x60 Native IR) | B40: B0DPXX7P5M | C40: 209.99 | D40: 2312873.3 | E40: 192739.44 | F40: 11316 | G40: 943 | H40: 6667 | I40: 4.2 | J40: https://amazon.com/dp/B0DPXX7P5M | K40: =HYPERLINK(J40) -> https://amazon.com/dp/B0DPXX7P5M
A41: Flir One Pro - Thermal Imaging Camera for iOS Smartphones (iPhone 15 and Newer w/USB-C), 480x360 Super Resolution (160x120 Native IR) | B41: B0DPXWFD12 | C41: 429 | D41: 2260847.5 | E41: 188403.96 | F41: 5388 | G41: 449 | H41: 3654 | I41: 4.3 | J41: https://amazon.com/dp/B0DPXWFD12 | K41: =HYPERLINK(J41) -> https://amazon.com/dp/B0DPXWFD12
A42: FLIR TG165-X Thermal Imaging Camera with Bullseye Laser: Commercial Grade Infrared Camera for Building Inspection, HVAC and Electrical | B42: B08D3YC5CW | C42: 353 | D42: 1546748.5 | E42: 128895.71 | F42: 4320 | G42: 360 | H42: 1425 | I42: 4.3 | J42: https://amazon.com/dp/B08D3YC5CW | K42: =HYPERLINK(J42) -> https://amazon.com/dp/B08D3YC5CW
A43: Flir One - Thermal Imaging Camera for iOS Smartphones (iPhone 14 and Older w/Lightning Port), 240x180 Super Resolution (80x60 Native IR) | B43: B0728C7KND | C43: 209.99 | D43: 745047.84 | E43: 62087.32 | F43: 3912 | G43: 326 | H43: 6657 | I43: 4.2 | J43: https://amazon.com/dp/B0728C7KND | K43: =HYPERLINK(J43) -> https://amazon.com/dp/B0728C7KND
A44: FLIR C5 Compact Thermal Imaging Camera with Wifi: High Resolution Infrared Imager for Inspection, Electrical/Mechanical, Building, and HVAC Applications | B44: B0892MZZT1 | C44: 569.99 | D44: 2217417.2 | E44: 184784.77 | F44: 3696 | G44: 308 | H44: 1265 | I44: 4.3 | J44: https://amazon.com/dp/B0892MZZT1 | K44: =HYPERLINK(J44) -> https://amazon.com/dp/B0892MZZT1
A45: Flir Edge - Wireless Bluetooth Thermal Imaging Camera for Smartphones, Compatible with All iOS and Android Devices, 240x180 Super Resolution (80x60 Native IR) | B45: B0BLJ3XJ3Z | C45: 298.5 | D45: 851194.68 | E45: 70932.89 | F45: 2916 | G45: 243 | H45: 386 | I45: 4.1 | J45: https://amazon.com/dp/B0BLJ3XJ3Z | K45: =HYPERLINK(J45) -> https://amazon.com/dp/B0BLJ3XJ3Z
A46: Flir Edge Pro - Wireless Bluetooth Thermal Imaging Camera for Smartphones, Compatible with All iOS and Android Devices, 480x360 Super Resolution (160x120 Native IR) | B46: B0BLJD6Q5G | C46: 529 | D46: 1292640.6 | E46: 107720.05 | F46: 2868 | G46: 239 | H46: 386 | I46: 4.1 | J46: https://amazon.com/dp/B0BLJD6Q5G | K46: =HYPERLINK(J46) -> https://amazon.com/dp/B0BLJD6Q5G
A47: FLIR TG267 Thermal Imaging Camera with Bullseye Laser: Commercial Grade Infrared Camera for Building Inspection, HVAC and Electrical | B47: B07XH96SK4 | C47: 473.94 | D47: 1042782 | E47: 86898.5 | F47: 2616 | G47: 218 | H47: 1425 | I47: 4.3 | J47: https://amazon.com/dp/B07XH96SK4 | K47: =HYPERLINK(J47) -> https://amazon.com/dp/B07XH96SK4
A48: Flir One Pro - Thermal Imaging Camera for Android Smartphones (USB-C), 480x360 Super Resolution (160x120 Native IR) | B48: B0716ZGL7C | C48: 359 | D48: 830869.2 | E48: 69239.1 | F48: 2412 | G48: 201 | H48: 3654 | I48: 4.3 | J48: https://amazon.com/dp/B0716ZGL7C | K48: =HYPERLINK(J48) -> https://amazon.com/dp/B0716ZGL7C
A49: FLIR C3-X Compact Thermal Imaging Camera with Wifi: High Resolution Infrared Imager for Inspection, Electrical/Mechanical, Building, and HVAC Applications | B49: B08N6YHQWX | C49: 450 | D49: 972050.04 | E49: 81004.17 | F49: 2076 | G49: 173 | H49: 1265 | I49: 4.3 | J49: https://amazon.com/dp/B08N6YHQWX | K49: =HYPERLINK(J49) -> https://amazon.com/dp/B08N6YHQWX
A50: FLIR Cx Thermal Imaging Camera | B50: B0FMH37XL7 | C50: 899 | D50: 854777.64 | E50: 71231.47 | F50: 948 | G50: 79 | H50: 1265 | I50: 4.3 | J50: https://amazon.com/dp/B0FMH37XL7 | K50: =HYPERLINK(J50) -> https://amazon.com/dp/B0FMH37XL7
... A55: FLIR TG56-2 Infrared Spot Thermometer with Digital Readout: for Non-Contact Temperature Measurements up to 2,372 Degrees F | B55: B0CBL4BBP2 | C55: 225 | D55: 8235.72 | E55: 686.31 | F55: 36 | G55: 3 | H55: 93 | I55: 4.2 | J55: https://amazon.com/dp/B0CBL4BBP2 | K55: =HYPERLINK(J55) -> https://amazon.com/dp/B0CBL4BBP2
A56: FLIR T301030ACC 2 Bay Battery Charger for iXX & Exx Series Cameras | B56: B0FMKQYDTM | C56: 215.1 | D56: 5162.16 | E56: 430.18 | F56: 24 | G56: 2 | J56: https://amazon.com/dp/B0FMKQYDTM | K56: =HYPERLINK(J56) -> https://amazon.com/dp/B0FMKQYDTM
A57: FLIR K1 Situational Awareness Camera, Compact Thermal Imaging Camera for First Responders, for Firefighters | B57: B081QNTWD6 | C57: 689.99 | D57: 17355.36 | E57: 1446.28 | F57: 24 | G57: 2 | H57: 36 | I57: 4.1 | J57: https://amazon.com/dp/B081QNTWD6 | K57: =HYPERLINK(J57) -> https://amazon.com/dp/B081QNTWD6
A58: FLIR GPX310 Scion Rechargeable Battery Kit, Operate FLIR Scion Thermal Imaging Monoculars For Up To 10 Hours | B58: B08W1MP8QX | C58: 204.99 | D58: 2820.84 | E58: 235.07 | F58: 12 | G58: 1 | H58: 17 | I58: 2.9 | J58: https://amazon.com/dp/B08W1MP8QX | K58: =HYPERLINK(J58) -> https://amazon.com/dp/B08W1MP8QX
A59: FLIR T198457ACC Tripod Mount Adapter | B59: B07DH6WQG3 | C59: 26.83 | F59: 0 | G59: 0 | J59: https://amazon.com/dp/B07DH6WQG3 | K59: =HYPERLINK(J59) -> https://amazon.com/dp/B07DH6WQG3
...

Sheet Topdon
A1: #VALUE!
A7: Rank by Revenue
A8: Product Name | B8: ASIN | C8: Avg Price | D8: Estimated 12mo Revenue | E8: Monthly Rev | F8: Estimated 12mo Units | G8: Monthly Units | H8: # of Reviews | I8: Tool Rating | J8: Column1 | K8: Link
A9: TOPDON TC002C Duo Thermal Camera, Compatible with Any USB-C iPhone, iPad & Android Device, 512 x 384 Super Resolution, 256 x 192 IR Resolution Thermal Imager, -4°F~1022°F Temp Range | B9: B0F8MZVFBJ | C9: 242 | D9: 3557918.9 | E9: 296493.24 | F9: 14712 | G9: 1226 | H9: 99 | I9: 4.3 | J9: https://amazon.com/dp/B0F8MZVFBJ | K9: =HYPERLINK(J9) -> https://amazon.com/dp/B0F8MZVFBJ
A10: TOPDON TC004 Thermal Imaging Camera, 320 x 240 TISR Resolution, 256 x 192 IR High Resolution, 12-Hour Battery Life Handheld Infrared Camera with PC Analysis and Video Recording Supported, 32GB SD Card | B10: B0BRK4SGD2 | C10: 284.04 | D10: 1874450.2 | E10: 156204.18 | F10: 6192 | G10: 516 | H10: 879 | I10: 4.6 | J10: https://amazon.com/dp/B0BRK4SGD2 | K10: =HYPERLINK(J10) -> https://amazon.com/dp/B0BRK4SGD2
A11: TOPDON TC001 Thermal Camera for Android, Super IR 512x384 High Resolution, Thermal Imaging Camera, Thermal Imager - Optimized Temperature Accuracy, Works for Smartphones and Tablets & PC(not for iOS) | B11: B0B7LMB22Q | C11: 199.48 | D11: 1823991 | E11: 151999.25 | F11: 8472 | G11: 706 | H11: 1387 | I11: 4.6 | J11: https://amazon.com/dp/B0B7LMB22Q | K11: =HYPERLINK(J11) -> https://amazon.com/dp/B0B7LMB22Q
A12: TOPDON TC002C Thermal Camera, 512 x 384 Super Resolution, 256 x 192 IR Resolution, Thermal Imager for iPhone 17/16/15 Series & iPads with Type-C Port, -4°F~1022°F Temp Range, Upgraded Version of TC002 | B12: B0D3DZV19P | C12: 299.9 | D12: 1444503.7 | E12: 120375.31 | F12: 4812 | G12: 401 | H12: 747 | I12: 4.6 | J12: https://amazon.com/dp/B0D3DZV19P | K12: =HYPERLINK(J12) -> https://amazon.com/dp/B0D3DZV19P
A13: TOPDON TC005 256 x 192 IR High Resolution Dual-Camera Thermal Imaging Camera with 12-Hour Battery Life and 2MP Visual Light Camera, -4°F~1022°F Handheld Infrared Thermal Imager with PC 2D/3D Analysis | B13: B0BRK5DLR3 | C13: 469.99 | D13: 1106127.7 | E13: 92177.31 | F13: 2628 | G13: 219 | H13: 256 | I13: 4.5 | J13: https://amazon.com/dp/B0BRK5DLR3 | K13: =HYPERLINK(J13) -> https://amazon.com/dp/B0BRK5DLR3
A14: TOPDON TC002 Thermal Camera for iOS (iPhone & iPad), 512 x 384 Super Resolution, 256 x 192 IR High Resolution, Thermal Imager, Thermal Imaging Camera, -4°F~1022°F Temp Range, Support Video Recording | B14: B0BYHP8KM9 | C14: 299 | D14: 723355.44 | E14: 60279.62 | F14: 2424 | G14: 202 | H14: 745 | I14: 4.6 | J14: https://amazon.com/dp/B0BYHP8KM9 | K14: =HYPERLINK(J14) -> https://amazon.com/dp/B0BYHP8KM9
A15: TOPDON Thermal Imaging Camera TC004 SE - 256x192 IR Resolution, 21Hrs Runtime & 32GB Storage with Video Recording, PC Analysis for Electrical/HVAC/Building Inspection | B15: B0DS5XD9WT | C15: 399 | D15: 495771.24 | E15: 41314.27 | F15: 1404 | G15: 117 | H15: 256 | I15: 4.5 | J15: https://amazon.com/dp/B0DS5XD9WT | K15: =HYPERLINK(J15) -> https://amazon.com/dp/B0DS5XD9WT
A16: TOPDON TC001 Plus Thermal Camera for Android, 512 x 384 Super Resolution with Visual Camera, 256 x 192 IR Resolution, Dual-Lens Thermal Imaging Camera for Smartphones and Tablets, PC (not for iOS) | B16: B0D46K5CMK | C16: 229.98 | D16: 439606.56 | E16: 36633.88 | F16: 1860 | G16: 155 | H16: 205 | I16: 4.4 | J16: https://amazon.com/dp/B0D46K5CMK | K16: =HYPERLINK(J16) -> https://amazon.com/dp/B0D46K5CMK
A17: TOPDON TC001 Thermal Imaging Camera Android, 512x384 Super IR Resolution Thermal Imager with Secondary Analysis, Test Report, Temp Alarm, -4°F~1022°F TEM Range for Smartphones(not for iOS) | B17: B0C23Z42KX | C17: 199.48 | D17: 365906.64 | E17: 30492.22 | F17: 1488 | G17: 124 | H17: 1388 | I17: 4.6 | J17: https://amazon.com/dp/B0C23Z42KX | K17: =HYPERLINK(J17) -> https://amazon.com/dp/B0C23Z42KX
A18: TOPDON TC003 256X192 IR Resolution 5" Touch Screen Thermal Imaging Camera with Secondary Analysis, Dual-Light Thermal Imager with Bluetooth and 2 MP Visual Camera, -4°F~1022°F | B18: B0C1RD1Q15 | C18: 399 | D18: 118023.96 | E18: 9835.33 | F18: 300 | G18: 25 | H18: 148 | I18: 4.3 | J18: https://amazon.com/dp/B0C1RD1Q15 | K18: =HYPERLINK(J18) -> https://amazon.com/dp/B0C1RD1Q15
A19: TOPDON TS001 256x192 IR Resolution Thermal Camera for Android, Thermal Night Vision Monocular Thermal Imager with 9mm Adjustable Focus Lens, Infrared Test Report, -4°F~1022°F TEM Range | B19: B0CWN47K4V | C19: 279 | D19: 61509.36 | E19: 5125.78 | F19: 216 | G19: 18 | H19: 55 | I19: 4.4 | J19: https://amazon.com/dp/B0CWN47K4V | K19: =HYPERLINK(J19) -> https://amazon.com/dp/B0CWN47K4V
A20: TOPDON USA - TS001 - Thermal Imaging Camera for Android Devices | B20: B0D3LHZ7JY | C20: 312.98 | D20: 8805.84 | E20: 733.82 | F20: 24 | G20: 2 | H20: 61 | I20: 4.1 | J20: https://amazon.com/dp/B0D3LHZ7JY | K20: =HYPERLINK(J20) -> https://amazon.com/dp/B0D3LHZ7JY
... A22: TOPDON USA - Thermal Imaging Camera for iOS Devices 256X192 RES | B22: B0CFLWQJMN | C22: 226.99 | D22: 6253.8 | E22: 521.15 | F22: 24 | G22: 2 | H22: 1 | I22: 5 | J22: https://amazon.com/dp/B0CFLWQJMN | K22: =HYPERLINK(J22) -> https://amazon.com/dp/B0CFLWQJMN
A23: TOPDON USA - Handheld Thermal Imaging Camera Dual Camera HIGH | B23: B0BZBZDJV2 | C23: 360.34 | F23: 0 | G23: 0 | H23: 43 | I23: 4 | J23: https://amazon.com/dp/B0BZBZDJV2 | K23: =HYPERLINK(J23) -> https://amazon.com/dp/B0BZBZDJV2
A28: Total | D28: =SUM(D9:D27) -> 12033789 | E28: =SUM(E9:E27) -> 1002815.7
A31: Rank by Units
A32: Product Name | B32: ASIN | C32: Avg Price | D32: Estimated 12mo Revenue | E32: Monthly Rev | F32: Estimated 12mo Units | G32: Monthly Units | H32: # of Reviews | I32: Tool Rating | J32: Column1 | K32: Link
A33: TOPDON TC002C Duo Thermal Camera, Compatible with Any USB-C iPhone, iPad & Android Device, 512 x 384 Super Resolution, 256 x 192 IR Resolution Thermal Imager, -4°F~1022°F Temp Range | B33: B0F8MZVFBJ | C33: 242 | D33: 3557918.9 | E33: 296493.24 | F33: 14712 | G33: 1226 | H33: 99 | I33: 4.3 | J33: https://amazon.com/dp/B0F8MZVFBJ | K33: =HYPERLINK(J33) -> https://amazon.com/dp/B0F8MZVFBJ
A34: TOPDON TC001 Thermal Camera for Android, Super IR 512x384 High Resolution, Thermal Imaging Camera, Thermal Imager - Optimized Temperature Accuracy, Works for Smartphones and Tablets & PC(not for iOS) | B34: B0B7LMB22Q | C34: 199.48 | D34: 1823991 | E34: 151999.25 | F34: 8472 | G34: 706 | H34: 1387 | I34: 4.6 | J34: https://amazon.com/dp/B0B7LMB22Q | K34: =HYPERLINK(J34) -> https://amazon.com/dp/B0B7LMB22Q
A35: TOPDON TC004 Thermal Imaging Camera, 320 x 240 TISR Resolution, 256 x 192 IR High Resolution, 12-Hour Battery Life Handheld Infrared Camera with PC Analysis and Video Recording Supported, 32GB SD Card | B35: B0BRK4SGD2 | C35: 284.04 | D35: 1874450.2 | E35: 156204.18 | F35: 6192 | G35: 516 | H35: 879 | I35: 4.6 | J35: https://amazon.com/dp/B0BRK4SGD2 | K35: =HYPERLINK(J35) -> https://amazon.com/dp/B0BRK4SGD2
A36: TOPDON TC002C Thermal Camera, 512 x 384 Super Resolution, 256 x 192 IR Resolution, Thermal Imager for iPhone 17/16/15 Series & iPads with Type-C Port, -4°F~1022°F Temp Range, Upgraded Version of TC002 | B36: B0D3DZV19P | C36: 299.9 | D36: 1444503.7 | E36: 120375.31 | F36: 4812 | G36: 401 | H36: 747 | I36: 4.6 | J36: https://amazon.com/dp/B0D3DZV19P | K36: =HYPERLINK(J36) -> https://amazon.com/dp/B0D3DZV19P
A37: TOPDON TC005 256 x 192 IR High Resolution Dual-Camera Thermal Imaging Camera with 12-Hour Battery Life and 2MP Visual Light Camera, -4°F~1022°F Handheld Infrared Thermal Imager with PC 2D/3D Analysis | B37: B0BRK5DLR3 | C37: 469.99 | D37: 1106127.7 | E37: 92177.31 | F37: 2628 | G37: 219 | H37: 256 | I37: 4.5 | J37: https://amazon.com/dp/B0BRK5DLR3 | K37: =HYPERLINK(J37) -> https://amazon.com/dp/B0BRK5DLR3
A38: TOPDON TC002 Thermal Camera for iOS (iPhone & iPad), 512 x 384 Super Resolution, 256 x 192 IR High Resolution, Thermal Imager, Thermal Imaging Camera, -4°F~1022°F Temp Range, Support Video Recording | B38: B0BYHP8KM9 | C38: 299 | D38: 723355.44 | E38: 60279.62 | F38: 2424 | G38: 202 | H38: 745 | I38: 4.6 | J38: https://amazon.com/dp/B0BYHP8KM9 | K38: =HYPERLINK(J38) -> https://amazon.com/dp/B0BYHP8KM9
A39: TOPDON TC001 Plus Thermal Camera for Android, 512 x 384 Super Resolution with Visual Camera, 256 x 192 IR Resolution, Dual-Lens Thermal Imaging Camera for Smartphones and Tablets, PC (not for iOS) | B39: B0D46K5CMK | C39: 229.98 | D39: 439606.56 | E39: 36633.88 | F39: 1860 | G39: 155 | H39: 205 | I39: 4.4 | J39: https://amazon.com/dp/B0D46K5CMK | K39: =HYPERLINK(J39) -> https://amazon.com/dp/B0D46K5CMK
A40: TOPDON TC001 Thermal Imaging Camera Android, 512x384 Super IR Resolution Thermal Imager with Secondary Analysis, Test Report, Temp Alarm, -4°F~1022°F TEM Range for Smartphones(not for iOS) | B40: B0C23Z42KX | C40: 199.48 | D40: 365906.64 | E40: 30492.22 | F40: 1488 | G40: 124 | H40: 1388 | I40: 4.6 | J40: https://amazon.com/dp/B0C23Z42KX | K40: =HYPERLINK(J40) -> https://amazon.com/dp/B0C23Z42KX
A41: TOPDON Thermal Imaging Camera TC004 SE - 256x192 IR Resolution, 21Hrs Runtime & 32GB Storage with Video Recording, PC Analysis for Electrical/HVAC/Building Inspection | B41: B0DS5XD9WT | C41: 399 | D41: 495771.24 | E41: 41314.27 | F41: 1404 | G41: 117 | H41: 256 | I41: 4.5 | J41: https://amazon.com/dp/B0DS5XD9WT | K41: =HYPERLINK(J41) -> https://amazon.com/dp/B0DS5XD9WT
A42: TOPDON TC003 256X192 IR Resolution 5" Touch Screen Thermal Imaging Camera with Secondary Analysis, Dual-Light Thermal Imager with Bluetooth and 2 MP Visual Camera, -4°F~1022°F | B42: B0C1RD1Q15 | C42: 399 | D42: 118023.96 | E42: 9835.33 | F42: 300 | G42: 25 | H42: 148 | I42: 4.3 | J42: https://amazon.com/dp/B0C1RD1Q15 | K42: =HYPERLINK(J42) -> https://amazon.com/dp/B0C1RD1Q15
A43: TOPDON TS001 256x192 IR Resolution Thermal Camera for Android, Thermal Night Vision Monocular Thermal Imager with 9mm Adjustable Focus Lens, Infrared Test Report, -4°F~1022°F TEM Range | B43: B0CWN47K4V | C43: 279 | D43: 61509.36 | E43: 5125.78 | F43: 216 | G43: 18 | H43: 55 | I43: 4.4 | J43: https://amazon.com/dp/B0CWN47K4V | K43: =HYPERLINK(J43) -> https://amazon.com/dp/B0CWN47K4V
A44: TOPDON USA - Thermal Imaging Camera for Android Devices 256X192 | B44: B0BFCVZC6R | C44: 250.8 | D44: 7564.56 | E44: 630.38 | F44: 36 | G44: 3 | H44: 904 | I44: 4.5 | J44: https://amazon.com/dp/B0BFCVZC6R | K44: =HYPERLINK(J44) -> https://amazon.com/dp/B0BFCVZC6R
... A46: TOPDON USA - Thermal Imaging Camera for iOS Devices 256X192 RES | B46: B0CFLWQJMN | C46: 226.99 | D46: 6253.8 | E46: 521.15 | F46: 24 | G46: 2 | H46: 1 | I46: 5 | J46: https://amazon.com/dp/B0CFLWQJMN | K46: =HYPERLINK(J46) -> https://amazon.com/dp/B0CFLWQJMN
A47: TOPDON USA - Handheld Thermal Imaging Camera Dual Camera HIGH | B47: B0BZBZDJV2 | C47: 360.34 | F47: 0 | G47: 0 | H47: 43 | I47: 4 | J47: https://amazon.com/dp/B0BZBZDJV2 | K47: =HYPERLINK(J47) -> https://amazon.com/dp/B0BZBZDJV2
A52: Total | F52: =SUM(Topdon!F33:F51) -> 44592 | G52: =SUM(Topdon!G33:G51) -> 3716

Sheet HSFTools
A1: #VALUE!
A7: Rank by Revenue
A8: Product Name | B8: ASIN | C8: Avg Price | D8: Estimated 12mo Revenue | E8: Monthly Rev | F8: Estimated 12mo Units | G8: Monthly Units | H8: # of Reviews | I8: Tool Rating | J8: Column1 | K8: Link
A9: HF96 Thermal Camera with Laser Pointer, Intelligent Scene Detection, Super Resolution 240 x 240, Thermal Imaging Camera96 x 96 IR Resolution, 25 HZ Infrared Camera, -4°F~1022°F,11h Runtime | B9: B0CWS4BVCX | C9: 164.98 | D9: 4062368.2 | E9: 338530.68 | F9: 18468 | G9: 1539 | H9: 965 | I9: 4.5 | J9: https://amazon.com/dp/B0CWS4BVCX | K9: =HYPERLINK(J9) -> https://amazon.com/dp/B0CWS4BVCX
A10: HF96V Thermal Camera with Visual Camera & Laser Pointer, Intelligent Scene Detection, 240 * 240 Super Resolution Thermal Imaging Camera,25 Hz, 50° FOV, -4°F to 1022°F, IP54 Infrared Camera | B10: B0CYCKHTVW | C10: 219.99 | D10: 2832906.6 | E10: 236075.55 | F10: 12876 | G10: 1073 | H10: 966 | I10: 4.5 | J10: https://amazon.com/dp/B0CYCKHTVW | K10: =HYPERLINK(J10) -> https://amazon.com/dp/B0CYCKHTVW
A11: HP96 Thermal Imaging Camera,3.5" Touch Screen Thermal Camera with Visual Camera, Intelligent Scene Detection, 240 x 240 Super Resolution, 96 x 96 IR Resolution, 25 Hz Video Recording, -4°F to 662°F | B11: B0CXNYMG1M | C11: 239.99 | D11: 2395017.4 | E11: 199584.78 | F11: 10548 | G11: 879 | H11: 466 | I11: 4.4 | J11: https://amazon.com/dp/B0CXNYMG1M | K11: =HYPERLINK(J11) -> https://amazon.com/dp/B0CXNYMG1M
A12: HSFTOOLS P2W 640x480 Super Resolution Thermal Camera with Dual-Camera, 256x192 IR Resolution Thermal Imaging Camera, 3.5" Touch Screen,Wi-Fi,8MP Visible Camera, Video and Audio Recording | B12: B0DCZ8CRCS | C12: 479 | D12: 377700.96 | E12: 31475.08 | F12: 804 | G12: 67 | H12: 42 | I12: 4.6 | J12: https://amazon.com/dp/B0DCZ8CRCS | K12: =HYPERLINK(J12) -> https://amazon.com/dp/B0DCZ8CRCS
A13: Finder S1 Thermal Camera for Android, 192x192 Super Resolution Thermal Imaging Camera,Thermal Imager for Android Phones and Tablets, 96x96 IR Resolution, Carrying Case,USB-C(not for iPhone) | B13: B0DT6H42MY | C13: 119 | D13: 283529.16 | E13: 23627.43 | F13: 2388 | G13: 199 | H13: 83 | I13: 4.2 | J13: https://amazon.com/dp/B0DT6H42MY | K13: =HYPERLINK(J13) -> https://amazon.com/dp/B0DT6H42MY
A14: F2VW Thermal Camera 256x192 IR Resolution with 2MP Visual Camera, 640x480 3.2" Screen Thermal Imaging Camera,Super Resolution Image,Dual-Camera Thermal Imager,16 GB Storage,Carrying Case | B14: B0D8W7MQGR | C14: 439 | D14: 253818.84 | E14: 21151.57 | F14: 576 | G14: 48 | H14: 214 | I14: 4.7 | J14: https://amazon.com/dp/B0D8W7MQGR | K14: =HYPERLINK(J14) -> https://amazon.com/dp/B0D8W7MQGR
A15: HF256 Thermal Imaging Camera, 256 x 192 IR Resolution, Super Resolution 320 x 240 Therma Camera, 3.2" LCD Screen, 25 Hz Frame Rate, High/Low-Temperature Alarm, 16 GB Storage Infrared Camera | B15: B0CXNVV89D | C15: 299.99 | D15: 104376 | E15: 8698 | F15: 348 | G15: 29 | H15: 96 | I15: 4.5 | J15: https://amazon.com/dp/B0CXNVV89D | K15: =HYPERLINK(J15) -> https://amazon.com/dp/B0CXNVV89D
A16: Finder S2 Thermal Camera Andriod,512x384 Super Resolution,256x192 IR Resolution Thermal Imaging Camera,Thermal Imager for Andriod Phones and Tablets,Carrying Case,USB-C(not for iPhone15/16) | B16: B0DT759N6K | C16: 199 | D16: 35764.08 | E16: 2980.34 | F16: 180 | G16: 15 | H16: 48 | I16: 4.2 | J16: https://amazon.com/dp/B0DT759N6K | K16: =HYPERLINK(J16) -> https://amazon.com/dp/B0DT759N6K
A17: HSFTOOLS Finder S2 Android Thermal Imager,512x384 Super Resolution,256x192 IR Resolution,Thermal Camera for Andriod Phones and Tablets,Carrying Case,USB-C(Not Compatible with iPhone 15/16) | B17: B0D961JM3J | C17: 199 | D17: 15718.8 | E17: 1309.9 | F17: 84 | G17: 7 | H17: 20 | I17: 4.1 | J17: https://amazon.com/dp/B0D961JM3J | K17: =HYPERLINK(J17) -> https://amazon.com/dp/B0D961JM3J
A18: HSFTOOLS Finder S1 Thermal Camera for Android,192x192 Super IR Resolution Thermal Imaging Camera,96x96 IR Resolution, Thermal Imager for Android Phones and Tablets,Carrying Case,USB-C(not for iPhone) | B18: B0DK3D9TFL | C18: 119 | D18: 5198.04 | E18: 433.17 | F18: 48 | G18: 4 | H18: 9 | I18: 3.4 | J18: https://amazon.com/dp/B0DK3D9TFL | K18: =HYPERLINK(J18) -> https://amazon.com/dp/B0DK3D9TFL
A20: Total | D20: =SUM(D9:D19) -> 10366398 | E20: =SUM(E9:E19) -> 863866.5
A23: Rank by Units
A24: Product Name | B24: ASIN | C24: Avg Price | D24: Estimated 12mo Revenue | E24: Monthly Rev | F24: Estimated 12mo Units | G24: Monthly Units | H24: # of Reviews | I24: Tool Rating | J24: Column1 | K24: Link
A25: HF96 Thermal Camera with Laser Pointer, Intelligent Scene Detection, Super Resolution 240 x 240, Thermal Imaging Camera96 x 96 IR Resolution, 25 HZ Infrared Camera, -4°F~1022°F,11h Runtime | B25: B0CWS4BVCX | C25: 164.98 | D25: 4062368.2 | E25: 338530.68 | F25: 18468 | G25: 1539 | H25: 965 | I25: 4.5 | J25: https://amazon.com/dp/B0CWS4BVCX | K25: =HYPERLINK(J25) -> https://amazon.com/dp/B0CWS4BVCX
A26: HF96V Thermal Camera with Visual Camera & Laser Pointer, Intelligent Scene Detection, 240 * 240 Super Resolution Thermal Imaging Camera,25 Hz, 50° FOV, -4°F to 1022°F, IP54 Infrared Camera | B26: B0CYCKHTVW | C26: 219.99 | D26: 2832906.6 | E26: 236075.55 | F26: 12876 | G26: 1073 | H26: 966 | I26: 4.5 | J26: https://amazon.com/dp/B0CYCKHTVW | K26: =HYPERLINK(J26) -> https://amazon.com/dp/B0CYCKHTVW
A27: HP96 Thermal Imaging Camera,3.5" Touch Screen Thermal Camera with Visual Camera, Intelligent Scene Detection, 240 x 240 Super Resolution, 96 x 96 IR Resolution, 25 Hz Video Recording, -4°F to 662°F | B27: B0CXNYMG1M | C27: 239.99 | D27: 2395017.4 | E27: 199584.78 | F27: 10548 | G27: 879 | H27: 466 | I27: 4.4 | J27: https://amazon.com/dp/B0CXNYMG1M | K27: =HYPERLINK(J27) -> https://amazon.com/dp/B0CXNYMG1M
A28: Finder S1 Thermal Camera for Android, 192x192 Super Resolution Thermal Imaging Camera,Thermal Imager for Android Phones and Tablets, 96x96 IR Resolution, Carrying Case,USB-C(not for iPhone) | B28: B0DT6H42MY | C28: 119 | D28: 283529.16 | E28: 23627.43 | F28: 2388 | G28: 199 | H28: 83 | I28: 4.2 | J28: https://amazon.com/dp/B0DT6H42MY | K28: =HYPERLINK(J28) -> https://amazon.com/dp/B0DT6H42MY
A29: HSFTOOLS P2W 640x480 Super Resolution Thermal Camera with Dual-Camera, 256x192 IR Resolution Thermal Imaging Camera, 3.5" Touch Screen,Wi-Fi,8MP Visible Camera, Video and Audio Recording | B29: B0DCZ8CRCS | C29: 479 | D29: 377700.96 | E29: 31475.08 | F29: 804 | G29: 67 | H29: 42 | I29: 4.6 | J29: https://amazon.com/dp/B0DCZ8CRCS | K29: =HYPERLINK(J29) -> https://amazon.com/dp/B0DCZ8CRCS
A30: F2VW Thermal Camera 256x192 IR Resolution with 2MP Visual Camera, 640x480 3.2" Screen Thermal Imaging Camera,Super Resolution Image,Dual-Camera Thermal Imager,16 GB Storage,Carrying Case | B30: B0D8W7MQGR | C30: 439 | D30: 253818.84 | E30: 21151.57 | F30: 576 | G30: 48 | H30: 214 | I30: 4.7 | J30: https://amazon.com/dp/B0D8W7MQGR | K30: =HYPERLINK(J30) -> https://amazon.com/dp/B0D8W7MQGR
A31: HF256 Thermal Imaging Camera, 256 x 192 IR Resolution, Super Resolution 320 x 240 Therma Camera, 3.2" LCD Screen, 25 Hz Frame Rate, High/Low-Temperature Alarm, 16 GB Storage Infrared Camera | B31: B0CXNVV89D | C31: 299.99 | D31: 104376 | E31: 8698 | F31: 348 | G31: 29 | H31: 96 | I31: 4.5 | J31: https://amazon.com/dp/B0CXNVV89D | K31: =HYPERLINK(J31) -> https://amazon.com/dp/B0CXNVV89D
A32: Finder S2 Thermal Camera Andriod,512x384 Super Resolution,256x192 IR Resolution Thermal Imaging Camera,Thermal Imager for Andriod Phones and Tablets,Carrying Case,USB-C(not for iPhone15/16) | B32: B0DT759N6K | C32: 199 | D32: 35764.08 | E32: 2980.34 | F32: 180 | G32: 15 | H32: 48 | I32: 4.2 | J32: https://amazon.com/dp/B0DT759N6K | K32: =HYPERLINK(J32) -> https://amazon.com/dp/B0DT759N6K
A33: HSFTOOLS Finder S2 Android Thermal Imager,512x384 Super Resolution,256x192 IR Resolution,Thermal Camera for Andriod Phones and Tablets,Carrying Case,USB-C(Not Compatible with iPhone 15/16) | B33: B0D961JM3J | C33: 199 | D33: 15718.8 | E33: 1309.9 | F33: 84 | G33: 7 | H33: 20 | I33: 4.1 | J33: https://amazon.com/dp/B0D961JM3J | K33: =HYPERLINK(J33) -> https://amazon.com/dp/B0D961JM3J
A34: HSFTOOLS Finder S1 Thermal Camera for Android,192x192 Super IR Resolution Thermal Imaging Camera,96x96 IR Resolution, Thermal Imager for Android Phones and Tablets,Carrying Case,USB-C(not for iPhone) | B34: B0DK3D9TFL | C34: 119 | D34: 5198.04 | E34: 433.17 | F34: 48 | G34: 4 | H34: 9 | I34: 3.4 | J34: https://amazon.com/dp/B0DK3D9TFL | K34: =HYPERLINK(J34) -> https://amazon.com/dp/B0DK3D9TFL
A36: Total | F36: =SUM(HSFTools!F25:F35) -> 46320 | G36: =SUM(HSFTools!G25:G35) -> 3860

Sheet Thermal Master
A1: #VALUE!
A7: Rank by Revenue
A8: Product Name | B8: ASIN | C8: Avg Price | D8: Estimated 12mo Revenue | E8: Monthly Rev | F8: Estimated 12mo Units | G8: Monthly Units | H8: # of Reviews | I8: Tool Rating | J8: Column1 | K8: Link
A9: Thermal Master Handheld Thermal Camera, 512×384 X³IR Resolution, Thermal Imaging Camera with 2MP Visual Camera, 640×480 3.5" IPS Screen Thermal Imager with Laser, -4℉to 1022℉, 60Hz, 40mK(Thor 002) | B9: B0F5461RX3 | C9: 379.04 | D9: 2270143.1 | E9: 189178.59 | F9: 5856 | G9: 488 | H9: 126 | I9: 4.2 | J9: https://amazon.com/dp/B0F5461RX3 | K9: =HYPERLINK(J9) -> https://amazon.com/dp/B0F5461RX3
A10: Thermal Master P3 - Thermal Camera for iOS & Android, 8mm Macro Vision Infrared Imager w/Manual Lens, 512x384 Super Ir Resolution, 3.6℉ Accuracy, 35mk NETD, Work for Home PCB Inspection, Black | B10: B0FNCDQWJR | C10: 339 | D10: 1933459.7 | E10: 161121.64 | F10: 5700 | G10: 475 | H10: 41 | I10: 4.5 | J10: https://amazon.com/dp/B0FNCDQWJR | K10: =HYPERLINK(J10) -> https://amazon.com/dp/B0FNCDQWJR
A11: Thermal Master Thermal Camera for USB-C iPhone and Android, P1 Thermal Imaging Camera with 320×240 X³ IR Resolution, -4℉ to 1112℉, 160×120 Infrared Camera (iOS and Android) | B11: B0FLK4V7Z6 | C11: 139 | D11: 1455028.1 | E11: 121252.34 | F11: 10464 | G11: 872 | H11: 72 | I11: 4.2 | J11: https://amazon.com/dp/B0FLK4V7Z6 | K11: =HYPERLINK(J11) -> https://amazon.com/dp/B0FLK4V7Z6
