Workbook

Sheet Summary
A1: July '26 Monthly Summary
B3: Avg Price | C3: Avg Price MoM | D3: Avg Price YoY | E3: Quantity/Mo | F3: Qty by % | G3: Qty MoM | H3: Qty YoY | I3: Revenue/Mo | J3: Revenue by % | K3: Revenue MoM | L3: Revenue YoY
A4: Tablet $800+ | B4: 1406.8611 | C4: -0.022631585 | D4: -0.052279211 | E4: 2768 | F4: 0.0094059759 | G4: -0.14329929 | H4: -0.042214533 | I4: 3894191.6 | J4: 0.12036917 | K4: -0.16268778 | L4: -0.092286802
A5: Tablet $400-$800 | B5: 539.83251 | C5: -0.037189415 | D5: 0.035243678 | E5: 12352 | F5: 0.041973488 | G5: -0.18950131 | H5: 0.029762401 | I5: 6668011.1 | J5: 0.20610772 | K5: -0.21964328 | L5: 0.066055015
A6: Tablet $400- | B6: 209.72935 | C6: -0.018292626 | D6: 0.036285409 | E6: 24480 | F6: 0.083185799 | G6: -0.1179332 | H6: 0.27089606 | I6: 5134174.6 | J6: 0.15869695 | K6: -0.13406851 | L6: 0.31701105
A7: Total Tablet | B7: 396.37317 | C7: -0.041975622 | D7: -0.062891283 | E7: 39600 | F7: 0.13456526 | G7: -0.14330218 | H7: 0.15969192 | I7: 15696377 | J7: 0.48517384 | K7: -0.1792626 | L7: 0.086757408
A8: Handheld $75+ | B8: 180.22417 | C8: -0.0016173916 | D8: 0.051403239 | E8: 19050 | F8: 0.064734047 | G8: -0.02870545 | H8: 0.026566794 | I8: 3433270.4 | J8: 0.10612213 | K8: -0.030276414 | L8: 0.079335653
A9: Handheld $75- | B9: 30.780802 | C9: -0.018278528 | D9: -0.030450769 | E9: 99909 | F9: 0.33950204 | G9: -0.0014292568 | H9: -0.037513367 | I9: 3075279.1 | J9: 0.095056645 | K9: -0.01968166 | L9: -0.066821825
A10: Total Handheld | B10: 54.712543 | C10: -0.019514423 | D10: 0.033695623 | E10: 118959 | F10: 0.40423609 | G10: -0.0058998036 | H10: -0.027795031 | I10: 6508549.5 | J10: 0.20117877 | K10: -0.025299096 | L10: 0.0049640211
A11: Total Dongle | B11: 79.634064 | C11: -0.081148913 | D11: 0.01093587 | E11: 70393 | F11: 0.23920335 | G11: -0.042975229 | H11: 0.024613548 | I11: 5605680.7 | J11: 0.17327117 | K11: -0.12063675 | L11: 0.035818589
A12: Total Other Tools | B12: 70.644106 | C12: -0.11515887 | D12: -0.08130698 | E12: 63693 | F12: 0.21643599 | G12: -0.0099790161 | H12: 0.38698227 | I12: 4499535 | J12: 0.13908029 | K12: -0.12398871 | L12: 0.27421093
A13: Total | B13: 110.40729 | C13: -0.10114344 | D13: 0.0024129621 | E13: 292645 | F13: 0.99444069 | G13: -0.036648474 | H13: 0.079349097 | I13: 32310143 | J13: 0.99870406 | K13: -0.13408516 | L13: 0.081953525
A45: July '26 Monthly Summary - Revenue
A46: Brand | B46: # of Listings | C46: Monthly Rev | D46: Estimated 12mo Revenue | E46: Monthly Units | F46: Monthly Rev Market Share % | G46: Price Per Unit | H46: Total Reviews | I46: Avg Rating
A47: autel | B47: 549 | C47: 5379094.3 | D47: 65893996 | E47: 19094 | F47: 0.1663 | G47: 281.72 | H47: 133280 | I47: 4.2
A48: ancel | B48: 98 | C48: 2928004.5 | D48: 35077611 | E48: 45181 | F48: 0.0905 | G48: 64.81 | H48: 132284 | I48: 3.9
A49: topdon | B49: 62 | C49: 2709586.9 | D49: 36642541 | E49: 11551 | F49: 0.0838 | G49: 234.58 | H49: 31472 | I49: 4.1
A50: launch | B50: 282 | C50: 2115401.8 | D50: 31923133 | E50: 5646 | F50: 0.0654 | G50: 374.67 | H50: 76897 | I50: 3.8
A51: foxwell | B51: 55 | C51: 2070737.2 | D51: 23299903 | E51: 14797 | F51: 0.064 | G51: 139.94 | H51: 71849 | I51: 4
A52: innova | B52: 28 | C52: 1704290.9 | D52: 19448456 | E52: 8901 | F52: 0.0527 | G52: 191.47 | H52: 18620 | I52: 3.9
A53: xtool | B53: 71 | C53: 1688939.4 | D53: 18764664 | E53: 7046 | F53: 0.0522 | G53: 239.7 | H53: 12839 | I53: 4.2
A54: obdlink | B54: 4 | C54: 1234069.9 | D54: 15618816 | E54: 14008 | F54: 0.0381 | G54: 88.1 | H54: 37983 | I54: 4.6
A55: bluedriver | B55: 3 | C55: 1102294.6 | D55: 12527462 | E55: 11010 | F55: 0.0341 | G55: 100.12 | H55: 125779 | I55: 3
A56: mucar | B56: 19 | C56: 819251.95 | D56: 6048042 | E56: 2131 | F56: 0.0253 | G56: 384.44 | H56: 3734 | I56: 4.4
A57: generic | B57: 203 | C57: 816277.77 | D57: 5956257.6 | E57: 3466 | F57: 0.0252 | G57: 235.51 | H57: 1623 | I57: 1.8
A58: thinkcar | B58: 28 | C58: 746388.21 | D58: 10402801 | E58: 2980 | F58: 0.0231 | G58: 250.47 | H58: 10953 | I58: 3.8
... A71: bosch | B71: 15 | C71: 222987.61 | D71: 1711230.6 | E71: 206 | F71: 0.0069 | G71: 1082.46 | H71: 285 | I71: 3.2
A73: Total | B73: =SUM(B46:B71) -> 1750 | C73: =SUM(C47:C71) -> 28079752 | D73: =SUM(D47:D71) -> 3.3307135e+08 | E73: =SUM(E47:E71) -> 195083 | F73: =SUM(F47:F71) -> 0.8682 | G73: =AVERAGE(G47:G71) -> 263.3616 | H73: =SUM(H47:H71) -> 877051 | I73: =AVERAGE(I47:I71) -> 3.876
A76: July '26 Summary - Units
A77: Brand | B77: # of Listings | C77: Monthly Rev | D77: Estimated 12mo Units | E77: Monthly Units | F77: Monthly Unit Market Share % | G77: Price Per Unit | H77: Reviews | I77: Avg Rating
A78: ancel | B78: 98 | C78: 2928004.5 | D78: 589947.69 | E78: 45181 | F78: 0.1535 | G78: 64.81 | H78: 132284 | I78: 3.9
A79: autel | B79: 549 | C79: 5379094.3 | D79: 228949.85 | E79: 19094 | F79: 0.0649 | G79: 281.72 | H79: 133280 | I79: 4.2
A80: foxwell | B80: 55 | C80: 2070737.2 | D80: 177126.46 | E80: 14797 | F80: 0.0503 | G80: 139.94 | H80: 71849 | I80: 4
A81: obdlink | B81: 4 | C81: 1234069.9 | D81: 161243.08 | E81: 14008 | F81: 0.0476 | G81: 88.1 | H81: 37983 | I81: 4.6
A82: motopower | B82: 9 | C82: 289964.62 | D82: 133705.85 | E82: 12161 | F82: 0.0413 | G82: 23.84 | H82: 62031 | I82: 4.3
A83: topdon | B83: 62 | C83: 2709586.9 | D83: 150843.69 | E83: 11551 | F83: 0.0393 | G83: 234.58 | H83: 31472 | I83: 4.1
A84: bluedriver | B84: 3 | C84: 1102294.6 | D84: 144433.85 | E84: 11010 | F84: 0.0374 | G84: 100.12 | H84: 125779 | I84: 3
A85: veepeak | B85: 5 | C85: 323973.18 | D85: 91291.385 | E85: 9819 | F85: 0.0334 | G85: 32.99 | H85: 54026 | I85: 4.6
A86: innova | B86: 28 | C86: 1704290.9 | D86: 101092.62 | E86: 8901 | F86: 0.0302 | G86: 191.47 | H86: 18620 | I86: 3.9
A87: vgate | B87: 39 | C87: 364403.93 | D87: 79697.538 | E87: 8637 | F87: 0.0293 | G87: 42.19 | H87: 21714 | I87: 4.2
...

Sheet Top 50
A1: Top 50 Products - July '26 ONLY
B3: Avg Price | C3: Avg Price MoM | D3: Avg Price YoY | E3: Quantity/Mo | F3: Qty by % | G3: Qty MoM | H3: Qty YoY | I3: Revenue/Mo | J3: Revenue by % | L3: Revenue MoM | M3: Revenue YoY
A4: Total Tablet | B4: 404.67979 | C4: -0.15055658 | D4: -0.030231171 | E4: 15463 | F4: 0.13399248 | G4: 0.06296831 | H4: 0.08733563 | I4: 6257563.6 | J4: 0.44341701 | L4: -0.09706856 | M4: 0.054464201
A5: Total Handheld | B5: 52.857726 | C5: -0.10467711 | D5: -0.029039156 | E5: 58474 | F5: 0.50669832 | G5: 0.34163913 | H5: 0.10338711 | I5: 3090802.7 | J5: 0.21901727 | L5: 0.20120022 | M5: 0.071345682
A6: Total Dongle | B6: 98.066479 | C6: -0.14106376 | D6: 0.14905742 | E6: 32467 | F6: 0.28133828 | G6: -0.014239738 | H6: -0.20637986 | I6: 3183924.4 | J6: 0.22561596 | L6: -0.15329479 | M6: -0.088084889
A7: Total Other Tools | B7: 175.578 | C7: -0.23709824 | D7: -0.042269602 | E7: 8998 | F7: 0.077970919 | G7: 0.036635945 | H7: 0.35818868 | I7: 1579850.9 | J7: 0.11194976 | L7: -0.20914861 | M7: 0.30077858
A8: Total | B8: 122.2868 | C8: -0.20074549 | D8: 0.037499546 | E8: 115402 | F8: 1 | G8: 0.15694708 | H8: 0.0056731532 | I8: 14112142 | J8: 1 | L8: -0.075304829 | M8: 0.04338544
A40: Rank By Monthly Revenue - Jul '26 ONLY
A41: Ranking | B41: ASIN | C41: Product Name | D41: Brand | E41: Type | F41: Price | G41: Est. Monthly Retail Rev | H41: Est. Monthly Units Sold | I41: # of Reviews | J41: Avg. Rating | K41: Column2 | L41: Link
A42: 1 | B42: B07Z481NJM | C42: Innova 5610 OBD2 Bidirectional Scan Tool - Understand Your Vehicle, Pinpoint What's Wrong, and Complete Your Repairs with Less Headache, Updates Included, US-Based Technical Support | D42: innova | E42: Handheld | F42: 304.05607 | G42: 1174264.6 | H42: 3862 | I42: 3791 | J42: 4.4 | K42: https://amazon.com/dp/B07Z481NJM | L42: =IF(K42="","",HYPERLINK(K42,K42)) -> https://amazon.com/dp/B07Z481NJM
A43: 2 | B43: B0GL9RL3XS | C43: BlueDriver OBD2 Scanner Bluetooth, No Subscription, ABS SRS TPMS | D43: bluedriver | E43: Dongle | F43: 95.184528 | G43: 926145.46 | H43: 9730 | I43: 63029 | J43: 4.5 | K43: https://amazon.com/dp/B0GL9RL3XS | L43: =IF(K43="","",HYPERLINK(K43,K43)) -> https://amazon.com/dp/B0GL9RL3XS
A44: 3 | B44: B01G5EA74I | C44: ANCEL AD310 Classic Enhanced Universal OBD II Scanner Car Engine Fault Code Reader CAN Diagnostic Scan Tool, Read and Clear Error Codes for 1996 or Newer OBD2 Protocol Vehicle (Black) | D44: ancel | E44: Handheld | F44: 27.817391 | G44: 815550.26 | H44: 29318 | I44: 65760 | J44: 4.6 | K44: https://amazon.com/dp/B01G5EA74I | L44: =IF(K44="","",HYPERLINK(K44,K44)) -> https://amazon.com/dp/B01G5EA74I
A45: 4 | B45: B081VQVD3F | C45: OBDLink EX FORScan OBD Adapter | D45: obdlink | E45: Cable/Adapter | F45: 69.947921 | G45: 494182.06 | H45: 7065 | I45: 10265 | J45: 4.8 | K45: https://amazon.com/dp/B081VQVD3F | L45: =IF(K45="","",HYPERLINK(K45,K45)) -> https://amazon.com/dp/B081VQVD3F
A46: 5 | B46: B0BPYPNDVP | C46: Diesel Laptops Nexiq USB Link 3 Wired Edition with Repair Information & Diagnostic Software | D46: diesel laptops | E46: VCI | F46: 759.48003 | G46: 463282.82 | H46: 610 | I46: 290 | J46: 4.5 | K46: https://amazon.com/dp/B0BPYPNDVP | L46: =IF(K46="","",HYPERLINK(K46,K46)) -> https://amazon.com/dp/B0BPYPNDVP
A47: 6 | B47: B098PYB8XG | C47: Autel Scanner MaxiCOM MK900BT Bidirectional Tool, 40+ Service, CAN-FD& DOIP | D47: autel | E47: Tablet | F47: 658.71861 | G47: 425532.22 | H47: 646 | I47: 778 | J47: 4.6 | K47: https://amazon.com/dp/B098PYB8XG | L47: =IF(K47="","",HYPERLINK(K47,K47)) -> https://amazon.com/dp/B098PYB8XG
A48: 7 | B48: B07JFRFJG6 | C48: OBDLink MX+ OBD2 Bluetooth Scanner for iPhone, Android, and Windows | D48: obdlink | E48: Dongle | F48: 139.92839 | G48: 419085.53 | H48: 2995 | I48: 15453 | J48: 4.6 | K48: https://amazon.com/dp/B07JFRFJG6 | L48: =IF(K48="","",HYPERLINK(K48,K48)) -> https://amazon.com/dp/B07JFRFJG6
A49: 8 | B49: B0GK9G6YDL | C49: TOPDON ONE Bidirectional Scan Tool, 10.1" Professional Diagnostic Tool | D49: topdon | E49: Tablet | F49: 734.64028 | G49: 418010.32 | H49: 569 | I49: 206 | J49: 4.5 | K49: https://amazon.com/dp/B0GK9G6YDL | L49: =IF(K49="","",HYPERLINK(K49,K49)) -> https://amazon.com/dp/B0GK9G6YDL
A50: 9 | B50: B00UJV3E12 | C50: FOXWELL NT301 OBD2 Scanner Live Data Professional Mechanic OBDII Diagnostic Code Reader Tool for Check Engine Light | D50: foxwell | E50: Handheld | F50: 64.043987 | G50: 358198.02 | H50: 5593 | I50: 30049 | J50: 4.5 | K50: https://amazon.com/dp/B00UJV3E12 | L50: =IF(K50="","",HYPERLINK(K50,K50)) -> https://amazon.com/dp/B00UJV3E12
A51: 10 | B51: B0DV2N2FND | C51: BLCKTEC 460T OBD2 Scanner Car Code Reader Engine ABS SRS Transmission Diagnostic Tool, 12 Reset Services, Oil/TPMS/EPB/BMS/SAS/DPF/Throttle Reset, ABS Bleeding, Battery Test, Auto VIN, Free Update | D51: blcktec | E51: Tablet | F51: 189.09779 | G51: 347561.74 | H51: 1838 | I51: 773 | J51: 4.4 | K51: https://amazon.com/dp/B0DV2N2FND | L51: =IF(K51="","",HYPERLINK(K51,K51)) -> https://amazon.com/dp/B0DV2N2FND
A52: 11 | B52: B0DTK24XKB | C52: MUCAR 892BT AI-Assisted Bidirectional Scan Tool, Full System OBD2 Scanner, Bi-Directional OBD2 Scanner Diagnostic Tool,ECU Coding, 35 Services, FCA Autoauth, CANFD and DOIP, Free Lifetime Updates | D52: mucar | E52: Tablet | F52: 586.13082 | G52: 341128.14 | H52: 582 | I52: 477 | J52: 4.2 | K52: https://amazon.com/dp/B0DTK24XKB | L52: =IF(K52="","",HYPERLINK(K52,K52)) -> https://amazon.com/dp/B0DTK24XKB
A53: 12 | B53: B0C33Y285Y | C53: TOPDON AD900 Lite OBD2 Scanner, Bidirectional Scan Tool, 8" Large Screen | D53: topdon | E53: Tablet | F53: 313.50156 | G53: 323847.11 | H53: 1033 | I53: 3990 | J53: 4.3 | K53: https://amazon.com/dp/B0C33Y285Y | L53: =IF(K53="","",HYPERLINK(K53,K53)) -> https://amazon.com/dp/B0C33Y285Y
... A91: 50 | B91: B08XK3DJ42 | C91: TOPDON AD500 OBD2 Scanner Car Diagnostic Tool, Engine ABS SRS Transmission | D91: topdon | E91: Tablet | F91: 155.79363 | G91: 131801.41 | H91: 846 | I91: 1841 | J91: 4.4 | K91: https://amazon.com/dp/B08XK3DJ42 | L91: =IF(K91="","",HYPERLINK(K91,K91)) -> https://amazon.com/dp/B08XK3DJ42
A94: Rank By Monthly Units - Jul '26 ONLY
A95: Ranking | B95: ASIN | C95: Product Name | D95: Brand | E95: Type | F95: Price | G95: Est. Monthly Retail Rev | H95: Est. Monthly Units Sold | I95: # of Reviews | J95: Avg. Rating | K95: Column2 | L95: Link
A96: 1 | B96: B01G5EA74I | C96: ANCEL AD310 Classic Enhanced Universal OBD II Scanner Car Engine Fault Code Reader CAN Diagnostic Scan Tool, Read and Clear Error Codes for 1996 or Newer OBD2 Protocol Vehicle (Black) | D96: ancel | E96: Handheld | F96: 27.817391 | G96: 815550.26 | H96: 29318 | I96: 65760 | J96: 4.6 | K96: https://amazon.com/dp/B01G5EA74I | L96: =IF(K96="","",HYPERLINK(K96,K96)) -> https://amazon.com/dp/B01G5EA74I
A97: 2 | B97: B07Z3HB7DR | C97: MOTOPOWER MP69033 Car OBD2 Scanner Code Reader Engine Fault Scanner CAN Diagnostic Scan Tool for All OBD II Protocol Cars Since 1996, Yellow | D97: motopower | E97: Handheld | F97: 23.211108 | G97: 259500.19 | H97: 11180 | I97: 51762 | J97: 4.6 | K97: https://amazon.com/dp/B07Z3HB7DR | L97: =IF(K97="","",HYPERLINK(K97,K97)) -> https://amazon.com/dp/B07Z3HB7DR
A98: 3 | B98: B0GL9RL3XS | C98: BlueDriver OBD2 Scanner Bluetooth, No Subscription, ABS SRS TPMS | D98: bluedriver | E98: Dongle | F98: 95.184528 | G98: 926145.46 | H98: 9730 | I98: 63029 | J98: 4.5 | K98: https://amazon.com/dp/B0GL9RL3XS | L98: =IF(K98="","",HYPERLINK(K98,K98)) -> https://amazon.com/dp/B0GL9RL3XS
A99: 4 | B99: B081VQVD3F | C99: OBDLink EX FORScan OBD Adapter | D99: obdlink | E99: Cable/Adapter | F99: 69.947921 | G99: 494182.06 | H99: 7065 | I99: 10265 | J99: 4.8 | K99: https://amazon.com/dp/B081VQVD3F | L99: =IF(K99="","",HYPERLINK(K99,K99)) -> https://amazon.com/dp/B081VQVD3F
A100: 5 | B100: B073XKQQQW | C100: Veepeak OBDCheck BLE Bluetooth OBD II Scanner for iOS & Android, Car Wireless Check Engine Light Code Reader Diagnostic Tool | D100: veepeak | E100: Dongle | F100: 31.98093 | G100: 205317.57 | H100: 6420 | I100: 23908 | J100: 4.5 | K100: https://amazon.com/dp/B073XKQQQW | L100: =IF(K100="","",HYPERLINK(K100,K100)) -> https://amazon.com/dp/B073XKQQQW
A101: 6 | B101: B071FSNL73 | C101: ANCEL AD410 Enhanced OBD2 Scanner, Vehicle Code Reader for Check Engine Light, Automotive OBD II Scanner Fault Diagnosis, OBDII Scan Tool for All OBDII Cars 1996+, Black/Yellow | D101: ancel | E101: Handheld | F101: 41.468081 | G101: 234211.72 | H101: 5648 | I101: 15482 | J101: 4.5 | K101: https://amazon.com/dp/B071FSNL73 | L101: =IF(K101="","",HYPERLINK(K101,K101)) -> https://amazon.com/dp/B071FSNL73
A102: 7 | B102: B00UJV3E12 | C102: FOXWELL NT301 OBD2 Scanner Live Data Professional Mechanic OBDII Diagnostic Code Reader Tool for Check Engine Light | D102: foxwell | E102: Handheld | F102: 64.043987 | G102: 358198.02 | H102: 5593 | I102: 30049 | J102: 4.5 | K102: https://amazon.com/dp/B00UJV3E12 | L102: =IF(K102="","",HYPERLINK(K102,K102)) -> https://amazon.com/dp/B00UJV3E12
A103: 8 | B103: B0BY1TS725 | C103: VDIAGTOOL VD10 OBD2 Scanner Code Reader Car Diagnostic Tool Engine Fault Code Reader for Turn Off CEL with Freeze Frame/I/M Readiness for All OBDII Protocol Cars, OBD2 Scanner Diagnostic Tool | D103: vdiagtool | E103: Handheld | F103: 18.105488 | G103: 98186.06 | H103: 5423 | I103: 3034 | J103: 4.6 | K103: https://amazon.com/dp/B0BY1TS725 | L103: =IF(K103="","",HYPERLINK(K103,K103)) -> https://amazon.com/dp/B0BY1TS725
A104: 9 | B104: B013RIQMEO | C104: FIXD Bluetooth OBD2 Scanner - Car Diagnostic Check Engine Code Reader | D104: fixd | E104: Dongle | F104: 39.987912 | G104: 192821.71 | H104: 4822 | I104: 35597 | J104: 4.2 | K104: https://amazon.com/dp/B013RIQMEO | L104: =IF(K104="","",HYPERLINK(K104,K104)) -> https://amazon.com/dp/B013RIQMEO
A105: 10 | B105: B07Z481NJM | C105: Innova 5610 OBD2 Bidirectional Scan Tool - Understand Your Vehicle, Pinpoint What's Wrong, and Complete Your Repairs with Less Headache, Updates Included, US-Based Technical Support | D105: innova | E105: Handheld | F105: 304.05607 | G105: 1174264.6 | H105: 3862 | I105: 3791 | J105: 4.4 | K105: https://amazon.com/dp/B07Z481NJM | L105: =IF(K105="","",HYPERLINK(K105,K105)) -> https://amazon.com/dp/B07Z481NJM
A106: 11 | B106: B08NFLL3NT | C106: OBDLink CX Bimmercode Bluetooth 5.1 OBD2 Adapter for BMW/Mini, Works with iPhone/iOS & Android, Car Coding, OBD II Diagnostic Scanner | D106: obdlink | E106: Dongle | F106: 79.945739 | G106: 274133.94 | H106: 3429 | I106: 4614 | J106: 4.6 | K106: https://amazon.com/dp/B08NFLL3NT | L106: =IF(K106="","",HYPERLINK(K106,K106)) -> https://amazon.com/dp/B08NFLL3NT
A107: 12 | B107: B07JFRFJG6 | C107: OBDLink MX+ OBD2 Bluetooth Scanner for iPhone, Android, and Windows | D107: obdlink | E107: Dongle | F107: 139.92839 | G107: 419085.53 | H107: 2995 | I107: 15453 | J107: 4.6 | K107: https://amazon.com/dp/B07JFRFJG6 | L107: =IF(K107="","",HYPERLINK(K107,K107)) -> https://amazon.com/dp/B07JFRFJG6
... A145: 50 | B145: B019QCG5RE | C145: FOXWELL NT510 Elite Scan Tool fit for BMW Scanner Full Diagnostic Tool OBD2 Scanner, All System Bi-Directional Control Code Reader with All Reset Services, Battery Registration Tool fit for BMW Mini | D145: foxwell | E145: Handheld | F145: 177.72473 | G145: 125118.21 | H145: 704 | I145: 3174 | J145: 4.3 | K145: https://amazon.com/dp/B019QCG5RE | L145: =IF(K145="","",HYPERLINK(K145,K145)) -> https://amazon.com/dp/B019QCG5RE

Sheet Tablet Total
A1: Tablet Monthly Summary
A3: Tablet Overall
B4: Avg Price | C4: Avg Price MoM | D4: Avg Price YoY | E4: Quantity/Mo | F4: Qty by % | G4: Qty MoM | H4: Qty YoY | I4: Revenue/Mo | J4: Revenue by % | L4: Revenue MoM | M4: Revenue YoY
A5: autel | B5: 714.95074 | C5: -0.044762822 | D5: -0.10853758 | E5: 6439 | F5: 0.16260101 | G5: -0.064778504 | H5: 0.15997118 | I5: 4603567.8 | J5: 0.29328855 | L5: -0.10664166 | M5: 0.034070713
A6: topdon | B6: 348.71624 | C6: -0.087407675 | D6: -0.0017426969 | E6: 6338 | F6: 0.16005051 | G6: -0.11947763 | H6: -0.011540861 | I6: 2210163.5 | J6: 0.14080724 | L6: -0.19644205 | M6: -0.013263446
A7: launch | B7: 478.3969 | C7: -0.092444713 | D7: 0.1934296 | E7: 4300 | F7: 0.10858586 | G7: -0.21974233 | H7: -0.36334024 | I7: 2057106.7 | J7: 0.13105614 | L7: -0.29187303 | M7: -0.2401914
A8: xtool | B8: 317.4671 | C8: -0.078522711 | D8: -0.26726577 | E8: 4369 | F8: 0.11032828 | G8: -0.0079473206 | H8: 0.40844616 | I8: 1387013.8 | J8: 0.088365216 | L8: -0.085845986 | M8: 0.032016709
A9: ancel | B9: 496.93086 | C9: 0.045223408 | D9: 0.55125435 | E9: 2541 | F9: 0.064166667 | G9: -0.27791986 | H9: 0.091026191 | I9: 1262701.3 | J9: 0.080445398 | L9: -0.24526494 | M9: 0.69245912
A10: blcktec | B10: 189.09779 | C10: -0.054412014 | D10: -0.054359836 | E10: 1838 | F10: 0.046414141 | G10: 0.047293447 | H10: 1.2889166 | I10: 347561.74 | J10: 0.0221428 | L10: -0.0096918982 | M10: 1.1644914
A11: innova | B11: 141.40307 | C11: -0.098281875 | D11: -0.24429351 | E11: 672 | F11: 0.016969697 | G11: -0.14503817 | H11: 2.5368421 | I11: 95022.86 | J11: 0.0060538083 | L11: -0.22906542 | M11: 1.6728145
A12: Other | B12: 284.91488 | C12: -0.0098235417 | D12: -0.069624852 | E12: 13103 | F12: 0.33088384 | G12: -0.18947173 | H12: 0.45491894 | I12: 3733239.7 | J12: 0.23784085 | L12: -0.19743399 | M12: 0.35362043
A13: Total Tablet | B13: 396.37317 | C13: -0.041975622 | D13: -0.062891283 | E13: 39600 | F13: 1 | G13: -0.14330218 | H13: 0.15969192 | I13: 15696377 | J13: 1 | L13: -0.1792626 | M13: 0.086757408
A45: Rank By Monthly Revenue - Jul '26 ONLY
A46: Ranking | B46: ASIN | C46: Product Name | D46: Brand | E46: Type | F46: Price | G46: Est. Monthly Retail Rev | H46: Est. Monthly Units Sold | I46: # of Reviews | J46: Avg. Rating | K46: Column2 | L46: Link
A47: 1 | B47: B098PYB8XG | C47: Autel Scanner MaxiCOM MK900BT Bidirectional Tool, 40+ Service, CAN-FD& DOIP | D47: autel | E47: Tablet | F47: 658.71861 | G47: 425532.22 | H47: 646 | I47: 778 | J47: 4.6 | K47: https://amazon.com/dp/B098PYB8XG | L47: =IF(K47="","",HYPERLINK(K47,K47)) -> https://amazon.com/dp/B098PYB8XG
A48: 2 | B48: B0GK9G6YDL | C48: TOPDON ONE Bidirectional Scan Tool, 10.1" Professional Diagnostic Tool | D48: topdon | E48: Tablet | F48: 734.64028 | G48: 418010.32 | H48: 569 | I48: 206 | J48: 4.5 | K48: https://amazon.com/dp/B0GK9G6YDL | L48: =IF(K48="","",HYPERLINK(K48,K48)) -> https://amazon.com/dp/B0GK9G6YDL
A49: 3 | B49: B0DV2N2FND | C49: BLCKTEC 460T OBD2 Scanner Car Code Reader Engine ABS SRS Transmission Diagnostic Tool, 12 Reset Services, Oil/TPMS/EPB/BMS/SAS/DPF/Throttle Reset, ABS Bleeding, Battery Test, Auto VIN, Free Update | D49: blcktec | E49: Tablet | F49: 189.09779 | G49: 347561.74 | H49: 1838 | I49: 773 | J49: 4.4 | K49: https://amazon.com/dp/B0DV2N2FND | L49: =IF(K49="","",HYPERLINK(K49,K49)) -> https://amazon.com/dp/B0DV2N2FND
A50: 4 | B50: B0DTK24XKB | C50: MUCAR 892BT AI-Assisted Bidirectional Scan Tool, Full System OBD2 Scanner, Bi-Directional OBD2 Scanner Diagnostic Tool,ECU Coding, 35 Services, FCA Autoauth, CANFD and DOIP, Free Lifetime Updates | D50: mucar | E50: Tablet | F50: 586.13082 | G50: 341128.14 | H50: 582 | I50: 477 | J50: 4.2 | K50: https://amazon.com/dp/B0DTK24XKB | L50: =IF(K50="","",HYPERLINK(K50,K50)) -> https://amazon.com/dp/B0DTK24XKB
A51: 5 | B51: B0C33Y285Y | C51: TOPDON AD900 Lite OBD2 Scanner, Bidirectional Scan Tool, 8" Large Screen | D51: topdon | E51: Tablet | F51: 313.50156 | G51: 323847.11 | H51: 1033 | I51: 3990 | J51: 4.3 | K51: https://amazon.com/dp/B0C33Y285Y | L51: =IF(K51="","",HYPERLINK(K51,K51)) -> https://amazon.com/dp/B0C33Y285Y
A52: 6 | B52: B0BMZW65LJ | C52: ANCEL MT700 Motorcycle OBD2 Scanner Full Systems, ABS Engine Meter TPMS Diagnostic Tool with 35+ Reset Functions for Harley Indian Yamaha Polaris Piaggio Ducati Honda BMW, AutoVIN, 7”Touch Screen,16G | D52: ancel | E52: Tablet | F52: 954.64527 | G52: 322670.1 | H52: 338 | I52: 914 | J52: 4.5 | K52: https://amazon.com/dp/B0BMZW65LJ | L52: =IF(K52="","",HYPERLINK(K52,K52)) -> https://amazon.com/dp/B0BMZW65LJ
A53: 7 | B53: B08PFJMTY3 | C53: FOXWELL Car Scanner NT604 Elite OBD2 Scanner ABS SRS Transmission | D53: foxwell | E53: Tablet | F53: 149.44571 | G53: 290373.01 | H53: 1943 | I53: 5051 | J53: 4.4 | K53: https://amazon.com/dp/B08PFJMTY3 | L53: =IF(K53="","",HYPERLINK(K53,K53)) -> https://amazon.com/dp/B08PFJMTY3
A54: 8 | B54: B0GX1WPD31 | C54: Autel Scanner MaxiCOM MK808S: 3000+ Active Tests 28+ Service as MK900-BT | D54: autel | E54: Tablet | F54: 468.70797 | G54: 284505.74 | H54: 607 | I54: 381 | J54: 4.4 | K54: https://amazon.com/dp/B0GX1WPD31 | L54: =IF(K54="","",HYPERLINK(K54,K54)) -> https://amazon.com/dp/B0GX1WPD31
A55: 9 | B55: B0744B55QV | C55: Autel Scanner MaxiCOM MK808S Bidirectional Tool, 28+ Hot Service All System | D55: autel | E55: Tablet | F55: 457.87741 | G55: 263737.39 | H55: 576 | I55: 3903 | J55: 4.4 | K55: https://amazon.com/dp/B0744B55QV | L55: =IF(K55="","",HYPERLINK(K55,K55)) -> https://amazon.com/dp/B0744B55QV
A56: 10 | B56: B08ML7T7KZ | C56: Autel Scanner MaxiCheck MX808S, Bidirectional OBD2 Scan Tool 28+ Service | D56: autel | E56: Tablet | F56: 430.55856 | G56: 248432.29 | H56: 577 | I56: 756 | J56: 4.6 | K56: https://amazon.com/dp/B08ML7T7KZ | L56: =IF(K56="","",HYPERLINK(K56,K56)) -> https://amazon.com/dp/B08ML7T7KZ
A58: Rank By Monthly Units - Jul '26 ONLY
A59: Ranking | B59: ASIN | C59: Product Name | D59: Brand | E59: Type | F59: Price | G59: Est. Monthly Retail Rev | H59: Est. Monthly Units Sold | I59: # of Reviews | J59: Avg. Rating | K59: Column2 | L59: Link
A60: 1 | B60: B08PFJMTY3 | C60: FOXWELL Car Scanner NT604 Elite OBD2 Scanner ABS SRS Transmission | D60: foxwell | E60: Tablet | F60: 149.44571 | G60: 290373.01 | H60: 1943 | I60: 5051 | J60: 4.4 | K60: https://amazon.com/dp/B08PFJMTY3 | L60: =IF(K60="","",HYPERLINK(K60,K60)) -> https://amazon.com/dp/B08PFJMTY3
A61: 2 | B61: B0DV2N2FND | C61: BLCKTEC 460T OBD2 Scanner Car Code Reader Engine ABS SRS Transmission Diagnostic Tool, 12 Reset Services, Oil/TPMS/EPB/BMS/SAS/DPF/Throttle Reset, ABS Bleeding, Battery Test, Auto VIN, Free Update | D61: blcktec | E61: Tablet | F61: 189.09779 | G61: 347561.74 | H61: 1838 | I61: 773 | J61: 4.4 | K61: https://amazon.com/dp/B0DV2N2FND | L61: =IF(K61="","",HYPERLINK(K61,K61)) -> https://amazon.com/dp/B0DV2N2FND
A62: 3 | B62: B0C33Y285Y | C62: TOPDON AD900 Lite OBD2 Scanner, Bidirectional Scan Tool, 8" Large Screen | D62: topdon | E62: Tablet | F62: 313.50156 | G62: 323847.11 | H62: 1033 | I62: 3990 | J62: 4.3 | K62: https://amazon.com/dp/B0C33Y285Y | L62: =IF(K62="","",HYPERLINK(K62,K62)) -> https://amazon.com/dp/B0C33Y285Y
A63: 4 | B63: B09KZTYD18 | C63: TOPDON AD600S OBD2 Scanner, Engine ABS SRS Transmission Diagnostic Tool | D63: topdon | E63: Tablet | F63: 191.15372 | G63: 187139.49 | H63: 979 | I63: 1944 | J63: 4.4 | K63: https://amazon.com/dp/B09KZTYD18 | L63: =IF(K63="","",HYPERLINK(K63,K63)) -> https://amazon.com/dp/B09KZTYD18
A64: 5 | B64: B08XK3DJ42 | C64: TOPDON AD500 OBD2 Scanner Car Diagnostic Tool, Engine ABS SRS Transmission | D64: topdon | E64: Tablet | F64: 155.79363 | G64: 131801.41 | H64: 846 | I64: 1841 | J64: 4.4 | K64: https://amazon.com/dp/B08XK3DJ42 | L64: =IF(K64="","",HYPERLINK(K64,K64)) -> https://amazon.com/dp/B08XK3DJ42
A65: 6 | B65: B08DCNDFVK | C65: 2026 FOXWELL NT614 Elite OBD2 Scanner, 4 Systems, 5 Resets Code Reader | D65: foxwell | E65: Tablet | F65: 168.11133 | G65: 125074.83 | H65: 744 | I65: 796 | J65: 4.3 | K65: https://amazon.com/dp/B08DCNDFVK | L65: =IF(K65="","",HYPERLINK(K65,K65)) -> https://amazon.com/dp/B08DCNDFVK
A66: 7 | B66: B098PYB8XG | C66: Autel Scanner MaxiCOM MK900BT Bidirectional Tool, 40+ Service, CAN-FD& DOIP | D66: autel | E66: Tablet | F66: 658.71861 | G66: 425532.22 | H66: 646 | I66: 778 | J66: 4.6 | K66: https://amazon.com/dp/B098PYB8XG | L66: =IF(K66="","",HYPERLINK(K66,K66)) -> https://amazon.com/dp/B098PYB8XG
A67: 8 | B67: B0F254MVB5 | C67: Innova SD35 OBD2 Scanner – ABS, SRS, TPMS & Check Engine Code Reader, Live Data, All System Diagnostics, Compatible with Most Vehicles | D67: innova | E67: Tablet | F67: 131.7605 | G67: 84063.2 | H67: 638 | I67: 430 | J67: 4.4 | K67: https://amazon.com/dp/B0F254MVB5 | L67: =IF(K67="","",HYPERLINK(K67,K67)) -> https://amazon.com/dp/B0F254MVB5
A68: 9 | B68: B0GX1WPD31 | C68: Autel Scanner MaxiCOM MK808S: 3000+ Active Tests 28+ Service as MK900-BT | D68: autel | E68: Tablet | F68: 468.70797 | G68: 284505.74 | H68: 607 | I68: 381 | J68: 4.4 | K68: https://amazon.com/dp/B0GX1WPD31 | L68: =IF(K68="","",HYPERLINK(K68,K68)) -> https://amazon.com/dp/B0GX1WPD31
A69: 10 | B69: B0DFCMT416 | C69: XTOOL D5S OBD2 Scanner, 16 Resets, Engine ABS SRS Transmission Scan Tool | D69: xtool | E69: Tablet | F69: 170.41203 | G69: 102417.63 | H69: 601 | I69: 518 | J69: 4.3 | K69: https://amazon.com/dp/B0DFCMT416 | L69: =IF(K69="","",HYPERLINK(K69,K69)) -> https://amazon.com/dp/B0DFCMT416
A71: Tablet $800+
B72: Avg Price | C72: Avg Price MoM | D72: Avg Price YoY | E72: Quantity/Mo | F72: Qty by % | G72: Qty MoM | H72: Qty YoY | I72: Revenue/Mo | J72: Revenue by % | L72: Revenue MoM | M72: Revenue YoY
A73: autel | B73: 2023.8071 | C73: 0.012531454 | D73: 0.037540182 | E73: 810 | F73: 0.29263006 | G73: -0.16062176 | H73: -0.24581006 | I73: 1639283.8 | J73: 0.42095612 | L73: -0.15010313 | M73: -0.21749763
A74: launch | B74: 1289.4599 | C74: 0.033920138 | D74: -0.013875621 | E74: 703 | F74: 0.25397399 | G74: -0.30943026 | H74: -0.14580802 | I74: 906490.33 | J74: 0.2327801 | L74: -0.28600603 | M74: -0.15766046
...

Sheet Tablet $800+
A1: Tablet $800+ Monthly Summary
A3: ='Tablet Total'!A71 -> Tablet $800+
B4: Avg Price | C4: Avg Price MoM | D4: Avg Price YoY | E4: Quantity/Mo | F4: Qty by % | G4: Qty MoM | H4: Qty YoY | I4: Revenue/Mo | J4: Revenue by % | L4: Revenue MoM | M4: Revenue YoY
A5: ='Tablet Total'!A73 -> autel | B5: ='Tablet Total'!B73 -> 2023.8071 | C5: ='Tablet Total'!C73 -> 0.012531454 | D5: ='Tablet Total'!D73 -> 0.037540182 | E5: ='Tablet Total'!E73 -> 810 | F5: ='Tablet Total'!F73 -> 0.29263006 | G5: ='Tablet Total'!G73 -> -0.16062176 | H5: ='Tablet Total'!H73 -> -0.24581006 | ... M5: ='Tablet Total'!M73 -> -0.21749763
A6: ='Tablet Total'!A74 -> launch | B6: ='Tablet Total'!B74 -> 1289.4599 | C6: ='Tablet Total'!C74 -> 0.033920138 | D6: ='Tablet Total'!D74 -> -0.013875621 | E6: ='Tablet Total'!E74 -> 703 | F6: ='Tablet Total'!F74 -> 0.25397399 | G6: ='Tablet Total'!G74 -> -0.30943026 | H6: ='Tablet Total'!H74 -> -0.14580802 | ... M6: ='Tablet Total'!M74 -> -0.15766046
A7: ='Tablet Total'!A75 -> ancel | B7: ='Tablet Total'!B75 -> 939.33984 | C7: ='Tablet Total'!C75 -> -0.013969347 | D7: ='Tablet Total'!D75 -> 0.082263364 | E7: ='Tablet Total'!E75 -> 551 | F7: ='Tablet Total'!F75 -> 0.19906069 | G7: ='Tablet Total'!G75 -> 0.091089109 | H7: ='Tablet Total'!H75 -> 1.9308511 | ... M7: ='Tablet Total'!M75 -> 2.1719527
A8: ='Tablet Total'!A76 -> topdon | B8: ='Tablet Total'!B76 -> 1200.1367 | C8: ='Tablet Total'!C76 -> -0.033244164 | D8: ='Tablet Total'!D76 -> -0.014638563 | E8: ='Tablet Total'!E76 -> 324 | F8: ='Tablet Total'!F76 -> 0.11705202 | G8: ='Tablet Total'!G76 -> -0.21927711 | H8: ='Tablet Total'!H76 -> -0.3106383 | ... M8: ='Tablet Total'!M76 -> -0.32072956
A9: ='Tablet Total'!A77 -> xtool | B9: ='Tablet Total'!B77 -> 1307.0251 | C9: ='Tablet Total'!C77 -> 0.046914868 | D9: ='Tablet Total'!D77 -> 0.06847153 | E9: ='Tablet Total'!E77 -> 146 | F9: ='Tablet Total'!F77 -> 0.052745665 | G9: ='Tablet Total'!G77 -> -0.039473684 | H9: ='Tablet Total'!H77 -> -0.15116279 | ... M9: ='Tablet Total'!M77 -> -0.093041608
A10: ='Tablet Total'!A78 -> Other | B10: ='Tablet Total'!B78 -> 1073.3816 | C10: ='Tablet Total'!C78 -> -0.29080559 | D10: ='Tablet Total'!D78 -> 0.011272512 | E10: ='Tablet Total'!E78 -> 234 | F10: ='Tablet Total'!F78 -> 0.084537572 | G10: ='Tablet Total'!G78 -> 0.32954545 | H10: ='Tablet Total'!H78 -> 0.43558282 | ... M10: ='Tablet Total'!M78 -> 0.45176545
A11: ='Tablet Total'!A79 -> Tablet $800+ | B11: ='Tablet Total'!B79 -> 1406.8611 | C11: ='Tablet Total'!C79 -> -0.022631585 | D11: ='Tablet Total'!D79 -> -0.052279211 | E11: ='Tablet Total'!E79 -> 2768 | F11: ='Tablet Total'!F79 -> 1 | G11: ='Tablet Total'!G79 -> -0.14329929 | H11: ='Tablet Total'!H79 -> -0.042214533 | ... M11: ='Tablet Total'!M79 -> -0.092286802
A43: Rank By Monthly Revenue - Jul '26 ONLY
A44: Ranking | B44: ASIN | C44: Product Name | D44: Brand | E44: Type | F44: Price | G44: Est. Monthly Retail Rev | H44: Est. Monthly Units Sold | I44: # of Reviews | J44: Avg. Rating | K44: Column2 | L44: Link
A45: 1 | B45: B0BMZW65LJ | C45: ANCEL MT700 Motorcycle OBD2 Scanner Full Systems, ABS Engine Meter TPMS Diagnostic Tool with 35+ Reset Functions for Harley Indian Yamaha Polaris Piaggio Ducati Honda BMW, AutoVIN, 7”Touch Screen,16G | D45: ancel | E45: Tablet | F45: 954.64527 | G45: 322670.1 | H45: 338 | I45: 914 | J45: 4.5 | K45: https://amazon.com/dp/B0BMZW65LJ | L45: =IF(K45="","",HYPERLINK(K45,K45)) -> https://amazon.com/dp/B0BMZW65LJ
A46: 2 | B46: B0DTTTJWYH | C46: Launch X431 PRO3 V+ Elite SmartlinkC Bidirectional Scan Tool J2534 Protocol | D46: launch | E46: Tablet | F46: 1327.7482 | G46: 217750.71 | H46: 164 | I46: 113 | J46: 4.4 | K46: https://amazon.com/dp/B0DTTTJWYH | L46: =IF(K46="","",HYPERLINK(K46,K46)) -> https://amazon.com/dp/B0DTTTJWYH
A47: 3 | B47: B091BQNR3S | C47: TOPDON Phoenix Plus 2 Scanner with ECU Coding & Configuration, FCA SGW | D47: topdon | E47: Tablet | F47: 1004.0686 | G47: 211858.47 | H47: 211 | I47: 526 | J47: 4.5 | K47: https://amazon.com/dp/B091BQNR3S | L47: =IF(K47="","",HYPERLINK(K47,K47)) -> https://amazon.com/dp/B091BQNR3S
A48: 4 | B48: B0GLFSPMZ4 | C48: ANCEL X7HD PRO 10.1'' Heavy Duty Truck Scanner, Full-System Diesel Diagnostic Tool with DPF Regen, 42+ Reset, Bi-Directional and Active Test, ECU Coding, HDOBD/OBD2 Scanner for Diesel Trucks - Grey | D48: ancel | E48: Tablet | F48: 898.63143 | G48: 157260.5 | H48: 175 | I48: 48 | J48: 4.7 | K48: https://amazon.com/dp/B0GLFSPMZ4 | L48: =IF(K48="","",HYPERLINK(K48,K48)) -> https://amazon.com/dp/B0GLFSPMZ4
A49: 5 | B49: B0DZC1M7MZ | C49: Autel MaxiSys Ultra S2 Scanner, 2026 Top Intelligen Scan Diagnostic with AI, 6-in-1 VCMI2, Up of MSUltra MS919, Topology 3.0, Multi-Point DVI, Motor Truspeed Repair, EV Test, 48+ Service, ECU Program | D49: autel | E49: Tablet | F49: 5726.4109 | G49: 131707.45 | H49: 23 | I49: 24 | J49: 4.9 | K49: https://amazon.com/dp/B0DZC1M7MZ | L49: =IF(K49="","",HYPERLINK(K49,K49)) -> https://amazon.com/dp/B0DZC1M7MZ
A50: 6 | B50: B08V59JNYP | C50: LAUNCH X431 PRO3S+ Smartlink HD Heavy Duty Truck Scanner,J2534 Protocols | D50: launch | E50: Tablet | F50: 1881.0209 | G50: 129790.44 | H50: 69 | I50: 186 | J50: 4.3 | K50: https://amazon.com/dp/B08V59JNYP | L50: =IF(K50="","",HYPERLINK(K50,K50)) -> https://amazon.com/dp/B08V59JNYP
A51: 7 | B51: B0D7VS8SHS | C51: LAUNCH X431 PRO3S+ Elite, 2026 Bidirectional Scan Tool with J2534 Protocols | D51: launch | E51: Tablet | F51: 1218.3985 | G51: 102345.47 | H51: 84 | I51: 172 | J51: 4.2 | K51: https://amazon.com/dp/B0D7VS8SHS | L51: =IF(K51="","",HYPERLINK(K51,K51)) -> https://amazon.com/dp/B0D7VS8SHS
A52: 8 | B52: B0G7P96Y1B | C52: GEARWRENCH 10" Pro Command Wireless Bi-Directional Diagnostic Tablet with Rapid-Charge Dock, Includes 4 Years of Software Updates | GWSMART10 | D52: gearwrench | E52: Tablet | F52: 1556.5595 | G52: 99619.81 | H52: 64 | I52: 24 | J52: 4.8 | K52: https://amazon.com/dp/B0G7P96Y1B | L52: =IF(K52="","",HYPERLINK(K52,K52)) -> https://amazon.com/dp/B0G7P96Y1B
A53: 9 | B53: B0GL6G61LW | C53: MUCAR 892BT PRO OBD2 Scanner with Topology Map, AI-Assisted Diagnostic Tool | D53: mucar | E53: Tablet | F53: 801.61017 | G53: 96193.22 | H53: 120 | I53: 164 | J53: 4.6 | K53: https://amazon.com/dp/B0GL6G61LW | L53: =IF(K53="","",HYPERLINK(K53,K53)) -> https://amazon.com/dp/B0GL6G61LW
A54: 10 | B54: B08PNTTMQ8 | C54: Autel MaxiIM IM608 PRO 2 Scanner, ECU Coding 40+ Service $1316 Bundle | D54: autel | E54: Tablet | F54: 3264.3671 | G54: 55494.24 | H54: 17 | I54: 81 | J54: 4.8 | K54: https://amazon.com/dp/B08PNTTMQ8 | L54: =IF(K54="","",HYPERLINK(K54,K54)) -> https://amazon.com/dp/B08PNTTMQ8
A56: Rank By Monthly Units - Jul '26 ONLY
A57: Ranking | B57: ASIN | C57: Product Name | D57: Brand | E57: Type | F57: Price | G57: Est. Monthly Retail Rev | H57: Est. Monthly Units Sold | I57: # of Reviews | J57: Avg. Rating | K57: Column2 | L57: Link
A58: 1 | B58: B0BMZW65LJ | C58: ANCEL MT700 Motorcycle OBD2 Scanner Full Systems, ABS Engine Meter TPMS Diagnostic Tool with 35+ Reset Functions for Harley Indian Yamaha Polaris Piaggio Ducati Honda BMW, AutoVIN, 7”Touch Screen,16G | D58: ancel | E58: Tablet | F58: 954.64527 | G58: 322670.1 | H58: 338 | I58: 914 | J58: 4.5 | K58: https://amazon.com/dp/B0BMZW65LJ | L58: =IF(K58="","",HYPERLINK(K58,K58)) -> https://amazon.com/dp/B0BMZW65LJ
A59: 2 | B59: B091BQNR3S | C59: TOPDON Phoenix Plus 2 Scanner with ECU Coding & Configuration, FCA SGW | D59: topdon | E59: Tablet | F59: 1004.0686 | G59: 211858.47 | H59: 211 | I59: 526 | J59: 4.5 | K59: https://amazon.com/dp/B091BQNR3S | L59: =IF(K59="","",HYPERLINK(K59,K59)) -> https://amazon.com/dp/B091BQNR3S
A60: 3 | B60: B0GLFSPMZ4 | C60: ANCEL X7HD PRO 10.1'' Heavy Duty Truck Scanner, Full-System Diesel Diagnostic Tool with DPF Regen, 42+ Reset, Bi-Directional and Active Test, ECU Coding, HDOBD/OBD2 Scanner for Diesel Trucks - Grey | D60: ancel | E60: Tablet | F60: 898.63143 | G60: 157260.5 | H60: 175 | I60: 48 | J60: 4.7 | K60: https://amazon.com/dp/B0GLFSPMZ4 | L60: =IF(K60="","",HYPERLINK(K60,K60)) -> https://amazon.com/dp/B0GLFSPMZ4
A61: 4 | B61: B0DTTTJWYH | C61: Launch X431 PRO3 V+ Elite SmartlinkC Bidirectional Scan Tool J2534 Protocol | D61: launch | E61: Tablet | F61: 1327.7482 | G61: 217750.71 | H61: 164 | I61: 113 | J61: 4.4 | K61: https://amazon.com/dp/B0DTTTJWYH | L61: =IF(K61="","",HYPERLINK(K61,K61)) -> https://amazon.com/dp/B0DTTTJWYH
A62: 5 | B62: B0GL6G61LW | C62: MUCAR 892BT PRO OBD2 Scanner with Topology Map, AI-Assisted Diagnostic Tool | D62: mucar | E62: Tablet | F62: 801.61017 | G62: 96193.22 | H62: 120 | I62: 164 | J62: 4.6 | K62: https://amazon.com/dp/B0GL6G61LW | L62: =IF(K62="","",HYPERLINK(K62,K62)) -> https://amazon.com/dp/B0GL6G61LW
A63: 6 | B63: B0D7VS8SHS | C63: LAUNCH X431 PRO3S+ Elite, 2026 Bidirectional Scan Tool with J2534 Protocols | D63: launch | E63: Tablet | F63: 1218.3985 | G63: 102345.47 | H63: 84 | I63: 172 | J63: 4.2 | K63: https://amazon.com/dp/B0D7VS8SHS | L63: =IF(K63="","",HYPERLINK(K63,K63)) -> https://amazon.com/dp/B0D7VS8SHS
A64: 7 | B64: B08V59JNYP | C64: LAUNCH X431 PRO3S+ Smartlink HD Heavy Duty Truck Scanner,J2534 Protocols | D64: launch | E64: Tablet | F64: 1881.0209 | G64: 129790.44 | H64: 69 | I64: 186 | J64: 4.3 | K64: https://amazon.com/dp/B08V59JNYP | L64: =IF(K64="","",HYPERLINK(K64,K64)) -> https://amazon.com/dp/B08V59JNYP
A65: 8 | B65: B0G7P96Y1B | C65: GEARWRENCH 10" Pro Command Wireless Bi-Directional Diagnostic Tablet with Rapid-Charge Dock, Includes 4 Years of Software Updates | GWSMART10 | D65: gearwrench | E65: Tablet | F65: 1556.5595 | G65: 99619.81 | H65: 64 | I65: 24 | J65: 4.8 | K65: https://amazon.com/dp/B0G7P96Y1B | L65: =IF(K65="","",HYPERLINK(K65,K65)) -> https://amazon.com/dp/B0G7P96Y1B
A66: 9 | B66: B092894STV | C66: Launch X431 PRO3S+ V5.0,2026 Upgrade All-in-One Bidirectional Scan Tool,HD Trucks Scan,Topology Map,ECU Code,55+ Service,Full System,CANFD&DOIP,DBSCar VII VCI 2-Year Update | D66: launch | E66: Tablet | F66: 1046.2453 | G66: 55451 | H66: 53 | I66: 699 | J66: 4.2 | K66: https://amazon.com/dp/B092894STV | L66: =IF(K66="","",HYPERLINK(K66,K66)) -> https://amazon.com/dp/B092894STV
A67: 10 | B67: B08PB6DHBS | C67: Autel MaxiCOM MK900TS Scanner, Bidirectional Scan Tool w/Top TPMS Function | D67: autel | E67: Tablet | F67: 886.63267 | G67: 39898.47 | H67: 45 | I67: 96 | J67: 4.8 | K67: https://amazon.com/dp/B08PB6DHBS | L67: =IF(K67="","",HYPERLINK(K67,K67)) -> https://amazon.com/dp/B08PB6DHBS

Sheet Tablet $400-$800
A1: Tablet $400-$800 Monthly Summary
A3: ='Tablet Total'!A81 -> Tablet $400-$800
B4: Avg Price | C4: Avg Price MoM | D4: Avg Price YoY | E4: Quantity/Mo | F4: Qty by % | G4: Qty MoM | H4: Qty YoY | I4: Revenue/Mo | J4: Revenue by % | L4: Revenue MoM | M4: Revenue YoY
A5: ='Tablet Total'!A83 -> autel | B5: ='Tablet Total'!B83 -> 536.14049 | C5: ='Tablet Total'!C83 -> -0.031530742 | D5: ='Tablet Total'!D83 -> 0.018309988 | E5: ='Tablet Total'!E83 -> 5461 | F5: ='Tablet Total'!F83 -> 0.44211464 | G5: ='Tablet Total'!G83 -> -0.052238806 | H5: ='Tablet Total'!H83 -> 0.22006256 | ... M5: ='Tablet Total'!M83 -> 0.24240189
A6: ='Tablet Total'!A84 -> launch | B6: ='Tablet Total'!B84 -> 554.10393 | C6: ='Tablet Total'!C84 -> -0.038343847 | D6: ='Tablet Total'!D84 -> 0.0027720742 | E6: ='Tablet Total'!E84 -> 1307 | F6: ='Tablet Total'!F84 -> 0.10581282 | G6: ='Tablet Total'!G84 -> -0.34747878 | H6: ='Tablet Total'!H84 -> -0.16164208 | ... M6: ='Tablet Total'!M84 -> -0.15931809
A7: ='Tablet Total'!A85 -> topdon | B7: ='Tablet Total'!B85 -> 615.18187 | C7: ='Tablet Total'!C85 -> -0.020308442 | D7: ='Tablet Total'!D85 -> 0.29935597 | E7: ='Tablet Total'!E85 -> 1053 | F7: ='Tablet Total'!F85 -> 0.085249352 | G7: ='Tablet Total'!G85 -> -0.28269755 | H7: ='Tablet Total'!H85 -> -0.3965616 | ... M7: ='Tablet Total'!M85 -> -0.21591872
A8: ='Tablet Total'!A86 -> xtool | B8: ='Tablet Total'!B86 -> 496.94875 | C8: ='Tablet Total'!C86 -> -0.016668468 | D8: ='Tablet Total'!D86 -> -0.028920039 | E8: ='Tablet Total'!E86 -> 997 | F8: ='Tablet Total'!F86 -> 0.080715674 | G8: ='Tablet Total'!G86 -> -0.35594315 | H8: ='Tablet Total'!H86 -> -0.4420817 | ... M8: ='Tablet Total'!M86 -> -0.45821672
A9: ='Tablet Total'!A87 -> ancel | B9: ='Tablet Total'!B87 -> 540.73332 | C9: ='Tablet Total'!C87 -> -0.023584292 | D9: ='Tablet Total'!D87 -> 0.11696695 | E9: ='Tablet Total'!E87 -> 906 | F9: ='Tablet Total'!F87 -> 0.073348446 | G9: ='Tablet Total'!G87 -> -0.36995828 | H9: ='Tablet Total'!H87 -> 1.0590909 | ... M9: ='Tablet Total'!M87 -> 1.2999365
A10: ='Tablet Total'!A88 -> innova | B10: ='Tablet Total'!B88 -> 514.99 | C10: ='Tablet Total'!C88 -> 0 | D10: ='Tablet Total'!D88 -> 0 | E10: ='Tablet Total'!E88 -> 4 | F10: ='Tablet Total'!F88 -> 0.0003238342 | G10: ='Tablet Total'!G88 -> 0 | H10: ='Tablet Total'!H88 -> 0 | ... M10: ='Tablet Total'!M88 -> 0
A11: ='Tablet Total'!A89 -> Other | B11: ='Tablet Total'!B89 -> 526.19106 | C11: ='Tablet Total'!C89 -> -0.065148451 | D11: ='Tablet Total'!D89 -> -0.034188075 | E11: ='Tablet Total'!E89 -> 2624 | F11: ='Tablet Total'!F89 -> 0.21243523 | G11: ='Tablet Total'!G89 -> -0.13141344 | H11: ='Tablet Total'!H89 -> 0.31991952 | ... M11: ='Tablet Total'!M89 -> 0.27479401
A12: ='Tablet Total'!A90 -> Tablet $400-$800 | B12: ='Tablet Total'!B90 -> 539.83251 | C12: ='Tablet Total'!C90 -> -0.037189415 | D12: ='Tablet Total'!D90 -> 0.035243678 | E12: ='Tablet Total'!E90 -> 12352 | F12: ='Tablet Total'!F90 -> 1 | G12: ='Tablet Total'!G90 -> -0.18950131 | H12: ='Tablet Total'!H90 -> 0.029762401 | ... M12: ='Tablet Total'!M90 -> 0.066055015
A44: Rank By Monthly Revenue - Jul '26 ONLY
A45: Ranking | B45: ASIN | C45: Product Name | D45: Brand | E45: Type | F45: Price | G45: Est. Monthly Retail Rev | H45: Est. Monthly Units Sold | I45: # of Reviews | J45: Avg. Rating | K45: Column2 | L45: Link
A46: 1 | B46: B098PYB8XG | C46: Autel Scanner MaxiCOM MK900BT Bidirectional Tool, 40+ Service, CAN-FD& DOIP | D46: autel | E46: Tablet | F46: 658.71861 | G46: 425532.22 | H46: 646 | I46: 778 | J46: 4.6 | K46: https://amazon.com/dp/B098PYB8XG | L46: =IF(K46="","",HYPERLINK(K46,K46)) -> https://amazon.com/dp/B098PYB8XG
A47: 2 | B47: B0GK9G6YDL | C47: TOPDON ONE Bidirectional Scan Tool, 10.1" Professional Diagnostic Tool | D47: topdon | E47: Tablet | F47: 734.64028 | G47: 418010.32 | H47: 569 | I47: 206 | J47: 4.5 | K47: https://amazon.com/dp/B0GK9G6YDL | L47: =IF(K47="","",HYPERLINK(K47,K47)) -> https://amazon.com/dp/B0GK9G6YDL
A48: 3 | B48: B0DTK24XKB | C48: MUCAR 892BT AI-Assisted Bidirectional Scan Tool, Full System OBD2 Scanner, Bi-Directional OBD2 Scanner Diagnostic Tool,ECU Coding, 35 Services, FCA Autoauth, CANFD and DOIP, Free Lifetime Updates | D48: mucar | E48: Tablet | F48: 586.13082 | G48: 341128.14 | H48: 582 | I48: 477 | J48: 4.2 | K48: https://amazon.com/dp/B0DTK24XKB | L48: =IF(K48="","",HYPERLINK(K48,K48)) -> https://amazon.com/dp/B0DTK24XKB
A49: 4 | B49: B0GX1WPD31 | C49: Autel Scanner MaxiCOM MK808S: 3000+ Active Tests 28+ Service as MK900-BT | D49: autel | E49: Tablet | F49: 468.70797 | G49: 284505.74 | H49: 607 | I49: 381 | J49: 4.4 | K49: https://amazon.com/dp/B0GX1WPD31 | L49: =IF(K49="","",HYPERLINK(K49,K49)) -> https://amazon.com/dp/B0GX1WPD31
A50: 5 | B50: B0744B55QV | C50: Autel Scanner MaxiCOM MK808S Bidirectional Tool, 28+ Hot Service All System | D50: autel | E50: Tablet | F50: 457.87741 | G50: 263737.39 | H50: 576 | I50: 3903 | J50: 4.4 | K50: https://amazon.com/dp/B0744B55QV | L50: =IF(K50="","",HYPERLINK(K50,K50)) -> https://amazon.com/dp/B0744B55QV
A51: 6 | B51: B08ML7T7KZ | C51: Autel Scanner MaxiCheck MX808S, Bidirectional OBD2 Scan Tool 28+ Service | D51: autel | E51: Tablet | F51: 430.55856 | G51: 248432.29 | H51: 577 | I51: 756 | J51: 4.6 | K51: https://amazon.com/dp/B08ML7T7KZ | L51: =IF(K51="","",HYPERLINK(K51,K51)) -> https://amazon.com/dp/B08ML7T7KZ
A52: 7 | B52: B09712X5CW | C52: Autel Scanner MaxiCOM MK900BT, 2026 MK900-BT 8in V2.0 Bidirectional Tool | D52: autel | E52: Tablet | F52: 659.4073 | G52: 222220.26 | H52: 337 | I52: 248 | J52: 4.6 | K52: https://amazon.com/dp/B09712X5CW | L52: =IF(K52="","",HYPERLINK(K52,K52)) -> https://amazon.com/dp/B09712X5CW
A53: 8 | B53: B0DCFRF2TF | C53: THINKCAR Bidirectional Scan Tool, THINKSCAN 689BT All System Automotive Diagnostic Tool, Bi Directional OBD2 Scanner with ECU Coding, 34 Services, FCA Autoauth, CANFD and DoIP, Wireless Update | D53: thinkcar | E53: Tablet | F53: 495.72564 | G53: 190854.37 | H53: 385 | I53: 642 | J53: 4.3 | K53: https://amazon.com/dp/B0DCFRF2TF | L53: =IF(K53="","",HYPERLINK(K53,K53)) -> https://amazon.com/dp/B0DCFRF2TF
A54: 9 | B54: B073CQMF25 | C54: Autel Scanner MaxiCOM MK900: 3000+ Active Tests 40+ Service as MK900-BT | D54: autel | E54: Tablet | F54: 588.2876 | G54: 186487.17 | H54: 317 | I54: 606 | J54: 4.4 | K54: https://amazon.com/dp/B073CQMF25 | L54: =IF(K54="","",HYPERLINK(K54,K54)) -> https://amazon.com/dp/B073CQMF25
A55: 10 | B55: B07PGYY8SS | C55: Autel Scanner MaxiCOM MK900BT: MK900-BT 8in V2.0 Bidirectional Scan Tool | D55: autel | E55: Tablet | F55: 660.23368 | G55: 159776.55 | H55: 242 | I55: 199 | J55: 4.5 | K55: https://amazon.com/dp/B07PGYY8SS | L55: =IF(K55="","",HYPERLINK(K55,K55)) -> https://amazon.com/dp/B07PGYY8SS
A57: Rank By Monthly Units - Jul '26 ONLY
A58: Ranking | B58: ASIN | C58: Product Name | D58: Brand | E58: Type | F58: Price | G58: Est. Monthly Retail Rev | H58: Est. Monthly Units Sold | I58: # of Reviews | J58: Avg. Rating | K58: Column2 | L58: Link
A59: 1 | B59: B098PYB8XG | C59: Autel Scanner MaxiCOM MK900BT Bidirectional Tool, 40+ Service, CAN-FD& DOIP | D59: autel | E59: Tablet | F59: 658.71861 | G59: 425532.22 | H59: 646 | I59: 778 | J59: 4.6 | K59: https://amazon.com/dp/B098PYB8XG | L59: =IF(K59="","",HYPERLINK(K59,K59)) -> https://amazon.com/dp/B098PYB8XG
A60: 2 | B60: B0GX1WPD31 | C60: Autel Scanner MaxiCOM MK808S: 3000+ Active Tests 28+ Service as MK900-BT | D60: autel | E60: Tablet | F60: 468.70797 | G60: 284505.74 | H60: 607 | I60: 381 | J60: 4.4 | K60: https://amazon.com/dp/B0GX1WPD31 | L60: =IF(K60="","",HYPERLINK(K60,K60)) -> https://amazon.com/dp/B0GX1WPD31
A61: 3 | B61: B0DTK24XKB | C61: MUCAR 892BT AI-Assisted Bidirectional Scan Tool, Full System OBD2 Scanner, Bi-Directional OBD2 Scanner Diagnostic Tool,ECU Coding, 35 Services, FCA Autoauth, CANFD and DOIP, Free Lifetime Updates | D61: mucar | E61: Tablet | F61: 586.13082 | G61: 341128.14 | H61: 582 | I61: 477 | J61: 4.2 | K61: https://amazon.com/dp/B0DTK24XKB | L61: =IF(K61="","",HYPERLINK(K61,K61)) -> https://amazon.com/dp/B0DTK24XKB
A62: 4 | B62: B08ML7T7KZ | C62: Autel Scanner MaxiCheck MX808S, Bidirectional OBD2 Scan Tool 28+ Service | D62: autel | E62: Tablet | F62: 430.55856 | G62: 248432.29 | H62: 577 | I62: 756 | J62: 4.6 | K62: https://amazon.com/dp/B08ML7T7KZ | L62: =IF(K62="","",HYPERLINK(K62,K62)) -> https://amazon.com/dp/B08ML7T7KZ
A63: 5 | B63: B0744B55QV | C63: Autel Scanner MaxiCOM MK808S Bidirectional Tool, 28+ Hot Service All System | D63: autel | E63: Tablet | F63: 457.87741 | G63: 263737.39 | H63: 576 | I63: 3903 | J63: 4.4 | K63: https://amazon.com/dp/B0744B55QV | L63: =IF(K63="","",HYPERLINK(K63,K63)) -> https://amazon.com/dp/B0744B55QV
A64: 6 | B64: B0GK9G6YDL | C64: TOPDON ONE Bidirectional Scan Tool, 10.1" Professional Diagnostic Tool | D64: topdon | E64: Tablet | F64: 734.64028 | G64: 418010.32 | H64: 569 | I64: 206 | J64: 4.5 | K64: https://amazon.com/dp/B0GK9G6YDL | L64: =IF(K64="","",HYPERLINK(K64,K64)) -> https://amazon.com/dp/B0GK9G6YDL
A65: 7 | B65: B0DCFRF2TF | C65: THINKCAR Bidirectional Scan Tool, THINKSCAN 689BT All System Automotive Diagnostic Tool, Bi Directional OBD2 Scanner with ECU Coding, 34 Services, FCA Autoauth, CANFD and DoIP, Wireless Update | D65: thinkcar | E65: Tablet | F65: 495.72564 | G65: 190854.37 | H65: 385 | I65: 642 | J65: 4.3 | K65: https://amazon.com/dp/B0DCFRF2TF | L65: =IF(K65="","",HYPERLINK(K65,K65)) -> https://amazon.com/dp/B0DCFRF2TF
A66: 8 | B66: B0BNKHCXVC | C66: TOPDON ArtiDiag Pro Bidirectional Scan Tool with ECU Coding, 35+ Services | D66: topdon | E66: Tablet | F66: 417.12327 | G66: 142656.16 | H66: 342 | I66: 801 | J66: 4.3 | K66: https://amazon.com/dp/B0BNKHCXVC | L66: =IF(K66="","",HYPERLINK(K66,K66)) -> https://amazon.com/dp/B0BNKHCXVC
A67: 9 | B67: B09712X5CW | C67: Autel Scanner MaxiCOM MK900BT, 2026 MK900-BT 8in V2.0 Bidirectional Tool | D67: autel | E67: Tablet | F67: 659.4073 | G67: 222220.26 | H67: 337 | I67: 248 | J67: 4.6 | K67: https://amazon.com/dp/B09712X5CW | L67: =IF(K67="","",HYPERLINK(K67,K67)) -> https://amazon.com/dp/B09712X5CW
A68: 10 | B68: B073CQMF25 | C68: Autel Scanner MaxiCOM MK900: 3000+ Active Tests 40+ Service as MK900-BT | D68: autel | E68: Tablet | F68: 588.2876 | G68: 186487.17 | H68: 317 | I68: 606 | J68: 4.4 | K68: https://amazon.com/dp/B073CQMF25 | L68: =IF(K68="","",HYPERLINK(K68,K68)) -> https://amazon.com/dp/B073CQMF25

Sheet Tablet $400-
A1: Tablet $400- Monthly Summary
A3: ='Tablet Total'!A91 -> 0
B4: Avg Price | C4: Avg Price MoM | D4: Avg Price YoY | E4: Quantity/Mo | F4: Qty by % | G4: Qty MoM | H4: Qty YoY | I4: Revenue/Mo | J4: Revenue by % | L4: Revenue MoM | M4: Revenue YoY
A5: ='Tablet Total'!A94 -> topdon | B5: ='Tablet Total'!B94 -> 236.55165 | C5: ='Tablet Total'!C94 -> -0.04279377 | D5: ='Tablet Total'!D94 -> 0.18014981 | E5: ='Tablet Total'!E94 -> 4961 | F5: ='Tablet Total'!F94 -> 0.20265523 | G5: ='Tablet Total'!G94 -> -0.066603951 | H5: ='Tablet Total'!H94 -> 0.18203479 | ... M5: ='Tablet Total'!M94 -> 0.39497812
A6: ='Tablet Total'!A95 -> foxwell | B6: ='Tablet Total'!B95 -> 197.28926 | C6: ='Tablet Total'!C95 -> -0.026523972 | D6: ='Tablet Total'!D95 -> 0.017417114 | E6: ='Tablet Total'!E95 -> 4481 | F6: ='Tablet Total'!F95 -> 0.18304739 | G6: ='Tablet Total'!G95 -> -0.13959293 | H6: ='Tablet Total'!H95 -> 0.38046827 | ... M6: ='Tablet Total'!M95 -> 0.40451204
A7: ='Tablet Total'!A96 -> xtool | B7: ='Tablet Total'!B96 -> 217.21334 | C7: ='Tablet Total'!C96 -> 0.077334866 | D7: ='Tablet Total'!D96 -> 0.13322267 | E7: ='Tablet Total'!E96 -> 3226 | F7: ='Tablet Total'!F96 -> 0.13178105 | G7: ='Tablet Total'!G96 -> 0.19304734 | H7: ='Tablet Total'!H96 -> 1.8223972 | ... M7: ='Tablet Total'!M96 -> 2.1984045
A8: ='Tablet Total'!A97 -> launch | B8: ='Tablet Total'!B97 -> 186.20196 | C8: ='Tablet Total'!C97 -> -0.036622572 | D8: ='Tablet Total'!D97 -> 0.057537918 | E8: ='Tablet Total'!E97 -> 2290 | F8: ='Tablet Total'!F97 -> 0.093545752 | G8: ='Tablet Total'!G97 -> -0.080321285 | H8: ='Tablet Total'!H97 -> -0.47621226 | ... M8: ='Tablet Total'!M97 -> -0.4460746
A9: ='Tablet Total'!A98 -> icarsoft | B9: ='Tablet Total'!B98 -> 204.08907 | C9: ='Tablet Total'!C98 -> 0.006354074 | D9: ='Tablet Total'!D98 -> 0.0044221043 | E9: ='Tablet Total'!E98 -> 1882 | F9: ='Tablet Total'!F98 -> 0.076879085 | G9: ='Tablet Total'!G98 -> -0.16578014 | H9: ='Tablet Total'!H98 -> 0.093550261 | ... M9: ='Tablet Total'!M98 -> 0.098386055
A10: ='Tablet Total'!A99 -> blcktec | B10: ='Tablet Total'!B99 -> 189.09779 | C10: ='Tablet Total'!C99 -> -0.054412014 | D10: ='Tablet Total'!D99 -> -0.054359836 | E10: ='Tablet Total'!E99 -> 1838 | F10: ='Tablet Total'!F99 -> 0.075081699 | G10: ='Tablet Total'!G99 -> 0.047293447 | H10: ='Tablet Total'!H99 -> 1.2889166 | ... M10: ='Tablet Total'!M99 -> 1.1644914
A11: ='Tablet Total'!A100 -> innova | B11: ='Tablet Total'!B100 -> 139.16602 | C11: ='Tablet Total'!C100 -> -0.11254738 | D11: ='Tablet Total'!D100 -> -0.25624906 | E11: ='Tablet Total'!E100 -> 668 | F11: ='Tablet Total'!F100 -> 0.027287582 | G11: ='Tablet Total'!G100 -> -0.15012723 | H11: ='Tablet Total'!H100 -> 2.5157895 | ... M11: ='Tablet Total'!M100 -> 1.6148717
A12: ='Tablet Total'!A101 -> Other | B12: ='Tablet Total'!B101 -> 219.09539 | C12: ='Tablet Total'!C101 -> -0.0099241479 | D12: ='Tablet Total'!D101 -> -0.11917528 | E12: ='Tablet Total'!E101 -> 5134 | F12: ='Tablet Total'!F101 -> 0.20972222 | G12: ='Tablet Total'!G101 -> -0.29078602 | H12: ='Tablet Total'!H101 -> 0.43008357 | ... M12: ='Tablet Total'!M101 -> 0.25965295
A13: ='Tablet Total'!A102 -> Tablet $400- | B13: ='Tablet Total'!B102 -> 209.72935 | C13: ='Tablet Total'!C102 -> -0.018292626 | D13: ='Tablet Total'!D102 -> 0.036285409 | E13: ='Tablet Total'!E102 -> 24480 | F13: ='Tablet Total'!F102 -> 1 | G13: ='Tablet Total'!G102 -> -0.1179332 | H13: ='Tablet Total'!H102 -> 0.27089606 | ... M13: ='Tablet Total'!M102 -> 0.31701105
A45: Rank By Monthly Revenue - Jul '26 ONLY
A46: Ranking | B46: ASIN | C46: Product Name | D46: Brand | E46: Type | F46: Price | G46: Est. Monthly Retail Rev | H46: Est. Monthly Units Sold | I46: # of Reviews | J46: Avg. Rating | K46: Column2 | L46: Link
A47: 1 | B47: B0DV2N2FND | C47: BLCKTEC 460T OBD2 Scanner Car Code Reader Engine ABS SRS Transmission Diagnostic Tool, 12 Reset Services, Oil/TPMS/EPB/BMS/SAS/DPF/Throttle Reset, ABS Bleeding, Battery Test, Auto VIN, Free Update | D47: blcktec | E47: Tablet | F47: 189.09779 | G47: 347561.74 | H47: 1838 | I47: 773 | J47: 4.4 | K47: https://amazon.com/dp/B0DV2N2FND | L47: =IF(K47="","",HYPERLINK(K47,K47)) -> https://amazon.com/dp/B0DV2N2FND
A48: 2 | B48: B0C33Y285Y | C48: TOPDON AD900 Lite OBD2 Scanner, Bidirectional Scan Tool, 8" Large Screen | D48: topdon | E48: Tablet | F48: 313.50156 | G48: 323847.11 | H48: 1033 | I48: 3990 | J48: 4.3 | K48: https://amazon.com/dp/B0C33Y285Y | L48: =IF(K48="","",HYPERLINK(K48,K48)) -> https://amazon.com/dp/B0C33Y285Y
A49: 3 | B49: B08PFJMTY3 | C49: FOXWELL Car Scanner NT604 Elite OBD2 Scanner ABS SRS Transmission | D49: foxwell | E49: Tablet | F49: 149.44571 | G49: 290373.01 | H49: 1943 | I49: 5051 | J49: 4.4 | K49: https://amazon.com/dp/B08PFJMTY3 | L49: =IF(K49="","",HYPERLINK(K49,K49)) -> https://amazon.com/dp/B08PFJMTY3
A50: 4 | B50: B098LF38DS | C50: XTOOL D7 Bidirectional Scan Tool, 39+ Resets, ECU Coding OBD2 Scanner | D50: xtool | E50: Tablet | F50: 356.70991 | G50: 199757.55 | H50: 560 | I50: 1679 | J50: 4.4 | K50: https://amazon.com/dp/B098LF38DS | L50: =IF(K50="","",HYPERLINK(K50,K50)) -> https://amazon.com/dp/B098LF38DS
A51: 5 | B51: B09KZTYD18 | C51: TOPDON AD600S OBD2 Scanner, Engine ABS SRS Transmission Diagnostic Tool | D51: topdon | E51: Tablet | F51: 191.15372 | G51: 187139.49 | H51: 979 | I51: 1944 | J51: 4.4 | K51: https://amazon.com/dp/B09KZTYD18 | L51: =IF(K51="","",HYPERLINK(K51,K51)) -> https://amazon.com/dp/B09KZTYD18
A52: 6 | B52: B08TR5PS5V | C52: TOPDON AD800BT 2 OBD2 Scanner, Bidirectional Scan Tool, 28+ Reset Service | D52: topdon | E52: Tablet | F52: 312.08133 | G52: 151983.61 | H52: 487 | I52: 870 | J52: 4.4 | K52: https://amazon.com/dp/B08TR5PS5V | L52: =IF(K52="","",HYPERLINK(K52,K52)) -> https://amazon.com/dp/B08TR5PS5V
A53: 7 | B53: B0BFBQZZMC | C53: ScanGauge 3 Touch Screen OBD2 Scanner, Digital Gauges & Trip Computer SG3 | D53: scangauge | E53: Tablet | F53: 269.97451 | G53: 143626.44 | H53: 532 | I53: 451 | J53: 4.5 | K53: https://amazon.com/dp/B0BFBQZZMC | L53: =IF(K53="","",HYPERLINK(K53,K53)) -> https://amazon.com/dp/B0BFBQZZMC
A54: 8 | B54: B08XK3DJ42 | C54: TOPDON AD500 OBD2 Scanner Car Diagnostic Tool, Engine ABS SRS Transmission | D54: topdon | E54: Tablet | F54: 155.79363 | G54: 131801.41 | H54: 846 | I54: 1841 | J54: 4.4 | K54: https://amazon.com/dp/B08XK3DJ42 | L54: =IF(K54="","",HYPERLINK(K54,K54)) -> https://amazon.com/dp/B08XK3DJ42
A55: 9 | B55: B08DCNDFVK | C55: 2026 FOXWELL NT614 Elite OBD2 Scanner, 4 Systems, 5 Resets Code Reader | D55: foxwell | E55: Tablet | F55: 168.11133 | G55: 125074.83 | H55: 744 | I55: 796 | J55: 4.3 | K55: https://amazon.com/dp/B08DCNDFVK | L55: =IF(K55="","",HYPERLINK(K55,K55)) -> https://amazon.com/dp/B08DCNDFVK
A56: 10 | B56: B0F3XRK4P9 | C56: 2026 FOXWELL NT726 OBD2 Scanner, 12Resets, All System Bidirectional Scanner | D56: foxwell | E56: Tablet | F56: 342.43927 | G56: 121565.94 | H56: 355 | I56: 135 | J56: 4.4 | K56: https://amazon.com/dp/B0F3XRK4P9 | L56: =IF(K56="","",HYPERLINK(K56,K56)) -> https://amazon.com/dp/B0F3XRK4P9
A58: Rank By Monthly Units - Jul '26 ONLY
A59: Ranking | B59: ASIN | C59: Product Name | D59: Brand | E59: Type | F59: Price | G59: Est. Monthly Retail Rev | H59: Est. Monthly Units Sold | I59: # of Reviews | J59: Avg. Rating | K59: Column2 | L59: Link
A60: 1 | B60: B08PFJMTY3 | C60: FOXWELL Car Scanner NT604 Elite OBD2 Scanner ABS SRS Transmission | D60: foxwell | E60: Tablet | F60: 149.44571 | G60: 290373.01 | H60: 1943 | I60: 5051 | J60: 4.4 | K60: https://amazon.com/dp/B08PFJMTY3 | L60: =IF(K60="","",HYPERLINK(K60,K60)) -> https://amazon.com/dp/B08PFJMTY3
A61: 2 | B61: B0DV2N2FND | C61: BLCKTEC 460T OBD2 Scanner Car Code Reader Engine ABS SRS Transmission Diagnostic Tool, 12 Reset Services, Oil/TPMS/EPB/BMS/SAS/DPF/Throttle Reset, ABS Bleeding, Battery Test, Auto VIN, Free Update | D61: blcktec | E61: Tablet | F61: 189.09779 | G61: 347561.74 | H61: 1838 | I61: 773 | J61: 4.4 | K61: https://amazon.com/dp/B0DV2N2FND | L61: =IF(K61="","",HYPERLINK(K61,K61)) -> https://amazon.com/dp/B0DV2N2FND
A62: 3 | B62: B0C33Y285Y | C62: TOPDON AD900 Lite OBD2 Scanner, Bidirectional Scan Tool, 8" Large Screen | D62: topdon | E62: Tablet | F62: 313.50156 | G62: 323847.11 | H62: 1033 | I62: 3990 | J62: 4.3 | K62: https://amazon.com/dp/B0C33Y285Y | L62: =IF(K62="","",HYPERLINK(K62,K62)) -> https://amazon.com/dp/B0C33Y285Y
A63: 4 | B63: B09KZTYD18 | C63: TOPDON AD600S OBD2 Scanner, Engine ABS SRS Transmission Diagnostic Tool | D63: topdon | E63: Tablet | F63: 191.15372 | G63: 187139.49 | H63: 979 | I63: 1944 | J63: 4.4 | K63: https://amazon.com/dp/B09KZTYD18 | L63: =IF(K63="","",HYPERLINK(K63,K63)) -> https://amazon.com/dp/B09KZTYD18
A64: 5 | B64: B08XK3DJ42 | C64: TOPDON AD500 OBD2 Scanner Car Diagnostic Tool, Engine ABS SRS Transmission | D64: topdon | E64: Tablet | F64: 155.79363 | G64: 131801.41 | H64: 846 | I64: 1841 | J64: 4.4 | K64: https://amazon.com/dp/B08XK3DJ42 | L64: =IF(K64="","",HYPERLINK(K64,K64)) -> https://amazon.com/dp/B08XK3DJ42
A65: 6 | B65: B08DCNDFVK | C65: 2026 FOXWELL NT614 Elite OBD2 Scanner, 4 Systems, 5 Resets Code Reader | D65: foxwell | E65: Tablet | F65: 168.11133 | G65: 125074.83 | H65: 744 | I65: 796 | J65: 4.3 | K65: https://amazon.com/dp/B08DCNDFVK | L65: =IF(K65="","",HYPERLINK(K65,K65)) -> https://amazon.com/dp/B08DCNDFVK
A66: 7 | B66: B0F254MVB5 | C66: Innova SD35 OBD2 Scanner – ABS, SRS, TPMS & Check Engine Code Reader, Live Data, All System Diagnostics, Compatible with Most Vehicles | D66: innova | E66: Tablet | F66: 131.7605 | G66: 84063.2 | H66: 638 | I66: 430 | J66: 4.4 | K66: https://amazon.com/dp/B0F254MVB5 | L66: =IF(K66="","",HYPERLINK(K66,K66)) -> https://amazon.com/dp/B0F254MVB5
A67: 8 | B67: B0DFCMT416 | C67: XTOOL D5S OBD2 Scanner, 16 Resets, Engine ABS SRS Transmission Scan Tool | D67: xtool | E67: Tablet | F67: 170.41203 | G67: 102417.63 | H67: 601 | I67: 518 | J67: 4.3 | K67: https://amazon.com/dp/B0DFCMT416 | L67: =IF(K67="","",HYPERLINK(K67,K67)) -> https://amazon.com/dp/B0DFCMT416
A68: 9 | B68: B098LF38DS | C68: XTOOL D7 Bidirectional Scan Tool, 39+ Resets, ECU Coding OBD2 Scanner | D68: xtool | E68: Tablet | F68: 356.70991 | G68: 199757.55 | H68: 560 | I68: 1679 | J68: 4.4 | K68: https://amazon.com/dp/B098LF38DS | L68: =IF(K68="","",HYPERLINK(K68,K68)) -> https://amazon.com/dp/B098LF38DS
A69: 10 | B69: B0BFBQZZMC | C69: ScanGauge 3 Touch Screen OBD2 Scanner, Digital Gauges & Trip Computer SG3 | D69: scangauge | E69: Tablet | F69: 269.97451 | G69: 143626.44 | H69: 532 | I69: 451 | J69: 4.5 | K69: https://amazon.com/dp/B0BFBQZZMC | L69: =IF(K69="","",HYPERLINK(K69,K69)) -> https://amazon.com/dp/B0BFBQZZMC

Sheet Handheld Total
A1: Handheld Monthly Summary
A3: Handheld Overall
B4: Avg Price | C4: Avg Price MoM | D4: Avg Price YoY | E4: Quantity/Mo | F4: Qty by % | G4: Qty MoM | H4: Qty YoY | I4: Revenue/Mo | J4: Revenue by % | L4: Revenue MoM | M4: Revenue YoY
A5: innova | B5: 202.87034 | C5: -0.061848381 | D5: -0.021625905 | E5: 7792 | F5: 0.065501559 | G5: 0.19987681 | H5: 0.32314485 | I5: 1580765.7 | J5: 0.24287527 | L5: 0.12566637 | M5: 0.29453064
A6: ancel | B6: 36.162241 | C6: -0.010861046 | D6: -0.14298288 | E6: 40165 | F6: 0.33763734 | G6: 0.048968399 | H6: 0.015036644 | I6: 1452456.4 | J6: 0.22316131 | L6: 0.037575505 | M6: -0.13009622
A7: foxwell | B7: 96.752896 | C7: -0.025143489 | D7: 0.094259908 | E7: 9668 | F7: 0.081271699 | G7: -0.0072902762 | H7: -0.035803331 | I7: 935407 | J7: 0.14371973 | L7: -0.032250462 | M7: 0.055081759
