Workbook

Sheet Summary
A1: November '25 Monthly Summary
B3: Avg Price | C3: Avg Price MoM | D3: Avg Price YoY | E3: Quantity/Mo | F3: Qty by % | G3: Qty MoM | H3: Qty YoY | I3: Revenue/Mo | J3: Revenue by % | K3: Revenue MoM | L3: Revenue YoY
A4: Tablet $800+ | B4: 1456.7424 | C4: -0.029265699 | D4: -0.08928515 | E4: 2861 | F4: 0.0093000728 | G4: -0.026870748 | H4: 0.14899598 | I4: 4167739.9 | J4: 0.12714231 | K4: -0.055350056 | L4: 0.046407706
A5: Tablet $400-$800 | B5: 527.27126 | C5: 0.0062141033 | D5: 0.003051364 | E5: 10794 | F5: 0.035087377 | G5: -0.025548434 | H5: 0.37503185 | I5: 5691366 | J5: 0.1736225 | K5: -0.019493091 | L5: 0.37922757
A6: Tablet $400- | B6: 220.0284 | C6: 0.017310952 | D6: 0.056287993 | E6: 25919 | F6: 0.084253264 | G6: 0.20078758 | H6: 0.81049176 | I6: 5702916.1 | J6: 0.17397485 | K6: 0.22157436 | L6: 0.91240071
A7: Total Tablet | B7: 393.23854 | C7: -0.059447514 | D7: -0.12584209 | E7: 39574 | F7: 0.12864071 | G7: 0.11156677 | H7: 0.60504543 | I7: 15562022 | J7: 0.47473967 | K7: 0.045486885 | L7: 0.40306315
A8: Handheld $75+ | B8: 164.58942 | C8: -0.050551412 | D8: -0.074970791 | E8: 19418 | F8: 0.063120872 | G8: 0.12210344 | H8: 0.41882215 | I8: 3195997.3 | J8: 0.097498044 | K8: 0.065379525 | L8: 0.31245193
A9: Handheld $75- | B9: 32.09868 | C9: 0.016644668 | D9: -0.051736376 | E9: 114697 | F9: 0.37283833 | G9: 0.09855661 | H9: 0.41588998 | I9: 3681622.3 | J9: 0.11231266 | K9: 0.11684172 | L9: 0.34263697
A10: Total Handheld | B10: 51.281509 | C10: -0.0086956713 | D10: -0.062044522 | E10: 134115 | F10: 0.4359592 | G10: 0.1019045 | H10: 0.41631377 | I10: 6877619.6 | J10: 0.20981071 | K10: 0.092322697 | L10: 0.32843926
A11: Total Dongle | B11: 71.773221 | C11: -0.055297537 | D11: 0.0040103229 | E11: 67553 | F11: 0.21959029 | G11: 0.087354731 | H11: 0.084317817 | I11: 4848496.4 | J11: 0.14790967 | K11: 0.027226693 | L11: 0.088666282
A12: Total Other Tools | B12: 65.215505 | C12: -0.09560381 | D12: -0.18747043 | E12: 44726 | F12: 0.145388 | G12: -0.029067622 | H12: 0.81010968 | I12: 2916828.7 | J12: 0.088981642 | K12: -0.12189246 | L12: 0.47076764
A13: Total | B13: 105.62359 | C13: -0.040358463 | D13: -0.040044069 | E13: 285968 | F13: 0.9295782 | G13: 0.077071995 | H13: 0.38578587 | I13: 30204967 | J13: 0.92144169 | K13: 0.033603025 | L13: 0.33029336
A45: November '25 Monthly Summary- Revenue
A46: Brand | B46: # of Listings | C46: Monthly Rev | D46: Estimated 12mo Revenue | E46: Monthly Units | F46: Monthly Rev Market Share % | G46: Price Per Unit | H46: Total Reviews | I46: Avg Rating
A47: autel | B47: 560 | C47: 5474504.9 | D47: 58623848 | E47: 19081 | F47: 0.167 | G47: 286.91 | H47: 132237 | I47: 4.5
A48: topdon | B48: 53 | C48: 3543161 | D48: 27983534 | E48: 13907 | F48: 0.1081 | G48: 254.78 | H48: 21711 | I48: 4.4
A49: ancel | B49: 75 | C49: 3020274.3 | D49: 26010885 | E49: 57813 | F49: 0.0921 | G49: 52.24 | H49: 119616 | I49: 4.2
A50: launch | B50: 256 | C50: 2827315.9 | D50: 29800141 | E50: 9093 | F50: 0.0863 | G50: 310.93 | H50: 80730 | I50: 4.2
A51: innova | B51: 20 | C51: 1786011.3 | D51: 11806561 | E51: 10062 | F51: 0.0545 | G51: 177.5 | H51: 14416 | I51: 4.2
A52: foxwell | B52: 48 | C52: 1771619.6 | D52: 18380377 | E52: 14649 | F52: 0.054 | G52: 120.94 | H52: 68025 | I52: 4.2
A53: xtool | B53: 58 | C53: 1671808.4 | D53: 13195976 | E53: 6085 | F53: 0.051 | G53: 274.74 | H53: 10712 | I53: 4.4
A54: bluedriver | B54: 1 | C54: 1319399.8 | D54: 12294051 | E54: 17744 | F54: 0.0403 | G54: 74.36 | H54: 60886 | I54: 4.4
A55: obdlink | B55: 4 | C55: 1186053.6 | D55: 12199618 | E55: 11756 | F55: 0.0362 | G55: 100.89 | H55: 35402 | I55: 4.6
A56: thinkcar | B56: 21 | C56: 997358.64 | D56: 6409132 | E56: 3436 | F56: 0.0304 | G56: 290.27 | H56: 11082 | I56: 4.3
A57: diesel laptops | B57: 18 | C57: 578085.79 | D57: 6188170.1 | E57: 880 | F57: 0.0176 | G57: 656.92 | H57: 532 | I57: 4.1
A58: blcktec | B58: 6 | C58: 561934.45 | D58: 3585625.9 | E58: 4957 | F58: 0.0171 | G58: 113.36 | H58: 4898 | I58: 4.4
... A71: kingbolen | B71: 15 | C71: 208303.91 | D71: 2654784 | E71: 1759 | F71: 0.0064 | G71: 118.42 | H71: 3186 | I71: 4.2
A73: Total | B73: =SUM(B46:B71) -> 1595 | C73: =SUM(C47:C71) -> 28507387 | D73: =SUM(D47:D71) -> 2.6106088e+08 | E73: =SUM(E47:E71) -> 217681 | F73: =SUM(F47:F71) -> 0.8697 | G73: =AVERAGE(G47:G71) -> 217.27 | H73: =SUM(H47:H71) -> 794810 | I73: =AVERAGE(I47:I71) -> 4.28
A76: Monthly Summary - Units
A77: Brand | B77: # of Listings | C77: Monthly Rev | D77: Estimated 12mo Units | E77: Monthly Units | F77: Monthly Unit Market Share % | G77: Price Per Unit | H77: Reviews | I77: Avg Rating
A78: ancel | B78: 75 | C78: 3020274.3 | D78: 508372.62 | E78: 57813 | F78: 0.1879 | G78: 52.24 | H78: 119616 | I78: 4.2
A79: autel | B79: 560 | C79: 5474504.9 | D79: 192381.23 | E79: 19081 | F79: 0.062 | G79: 286.91 | H79: 132237 | I79: 4.5
A80: bluedriver | B80: 1 | C80: 1319399.8 | D80: 142107.69 | E80: 17744 | F80: 0.0577 | G80: 74.36 | H80: 60886 | I80: 4.4
A81: foxwell | B81: 48 | C81: 1771619.6 | D81: 144397.85 | E81: 14649 | F81: 0.0476 | G81: 120.94 | H81: 68025 | I81: 4.2
A82: topdon | B82: 53 | C82: 3543161 | D82: 128028.92 | E82: 13907 | F82: 0.0452 | G82: 254.78 | H82: 21711 | I82: 4.4
A83: motopower | B83: 6 | C83: 318008.37 | D83: 108366.46 | E83: 12166 | F83: 0.0395 | G83: 26.14 | H83: 55132 | I83: 4.4
A84: obdlink | B84: 4 | C84: 1186053.6 | D84: 128833.85 | E84: 11756 | F84: 0.0382 | G84: 100.89 | H84: 35402 | I84: 4.6
A85: innova | B85: 20 | C85: 1786011.3 | D85: 63731.077 | E85: 10062 | F85: 0.0327 | G85: 177.5 | H85: 14416 | I85: 4.2
A86: launch | B86: 256 | C86: 2827315.9 | D86: 97113.231 | E86: 9093 | F86: 0.0296 | G86: 310.93 | H86: 80730 | I86: 4.2
A87: fixd | B87: 3 | C87: 312500.11 | D87: 124167.69 | E87: 7721 | F87: 0.0251 | G87: 40.47 | H87: 34866 | I87: 4.2
...

Sheet Top 50
A1: Top 50 Products - November '25 ONLY
B3: Avg Price | C3: Avg Price MoM | D3: Avg Price YoY | E3: Quantity/Mo | F3: Qty by % | G3: Qty MoM | H3: Qty YoY | I3: Revenue/Mo | J3: Revenue by % | L3: Revenue MoM | M3: Revenue YoY
A4: Tablets | B4: 344.22355 | C4: -0.11859123 | D4: -0.1353626 | E4: 21723 | F4: 0.15237474 | G4: 0.32070768 | H4: 1.2259453 | I4: 7477568.1 | J4: 0.47963781 | K4: 0.16408334 | L4: 0.16408334 | M4: 0.92463555
A5: Handheld | B5: 51.801609 | C5: 0.026728513 | D5: 0.065916428 | E5: 74974 | F5: 0.52590083 | G5: 0.29336876 | H5: 0.66909326 | I5: 3883773.8 | J5: 0.24911906 | K5: 0.32793858 | L5: 0.32793858 | M5: 0.77911392
A6: Dongle | B6: 81.218528 | C6: -0.065713874 | D6: -0.057140899 | E6: 40076 | F6: 0.28111081 | G6: 0.14290603 | H6: 0.06729873 | I6: 3254913.7 | J6: 0.20878174 | K6: 0.067801249 | L6: 0.067801249 | M6: 0.0063123209
A7: Other Tools | B7: 168.18222 | C7: -0.11163752 | D7: 0.33730085 | E7: 5790 | F7: 0.040613623 | G7: 0.04230423 | H7: 0.3639576 | I7: 973775.03 | J7: 0.062461393 | K7: -0.074056032 | L7: -0.074056032 | M7: 0.82402166
A8: Total | B8: 109.35538 | C8: -0.064568251 | D8: 0.072505803 | E8: 142563 | F8: 1 | G8: 0.23929031 | H8: 0.47776557 | I8: 15590031 | J8: 1 | K8: 0.1592715 | L8: 0.1592715 | M8: 0.58491215
A40: Rank By Monthly Revenue - Nov '25 ONLY
A41: Ranking | B41: ASIN | C41: Product Name | D41: Brand | E41: Type | F41: Price | G41: Est. Monthly Retail Rev | H41: Est. Monthly Units Sold | I41: # of Reviews | J41: Avg. Rating | K41: Column2 | L41: Link
A42: 1 | B42: B00652G4TS | C42: BlueDriver Bluetooth Pro OBDII Scan Tool for iPhone & Android - No Subscription Fee - OBD2 Car Scanner and Code Reader - Diagnose Check Engine, ABS, SRS, Airbag & 7000+ Issues on Vehicles 1996+ | D42: bluedriver | E42: Dongle | F42: 74.357517 | G42: 1319399.8 | H42: 17744 | I42: 60886 | J42: 4.4 | K42: https://amazon.com/dp/B00652G4TS | L42: =HYPERLINK(K42) -> https://amazon.com/dp/B00652G4TS
A43: 2 | B43: B01G5EA74I | C43: ANCEL AD310 Classic Enhanced Universal OBD II Scanner Car Engine Fault Code Reader CAN Diagnostic Scan Tool, Read and Clear Error Codes for 1996 or Newer OBD2 Protocol Vehicle (Black) | D43: ancel | E43: Handheld | F43: 28.282506 | G43: 1131017.4 | H43: 39990 | I43: 59738 | J43: 4.6 | K43: https://amazon.com/dp/B01G5EA74I | L43: =HYPERLINK(K43) -> https://amazon.com/dp/B01G5EA74I
A44: 3 | B44: B07Z481NJM | C44: Innova 5610 OBD2 Bidirectional Scan Tool - Understand Your Vehicle, Pinpoint What's Wrong, and Complete Your Repairs with Less Headache, Updates Included, US-Based Technical Support | D44: innova | E44: Handheld | F44: 287.32292 | G44: 1127455.1 | H44: 3924 | I44: 2889 | J44: 4.4 | K44: https://amazon.com/dp/B07Z481NJM | L44: =HYPERLINK(K44) -> https://amazon.com/dp/B07Z481NJM
A45: 4 | B45: B0744B55QV | C45: Autel Scanner MaxiCOM MK808S: 2025 Bidirectional Tool as MK808BT Pro MX808S M808Z, Work as MaxiCheck MX900 MK900BT, 28+ Service, Active Test, All System Diagnose, Injector C0ding, FCA Autoauth OS 11 | D45: autel | E45: Tablet | F45: 451.83728 | G45: 684985.31 | H45: 1516 | I45: 3604 | J45: 4.5 | K45: https://amazon.com/dp/B0744B55QV | L45: =HYPERLINK(K45) -> https://amazon.com/dp/B0744B55QV
A46: 5 | B46: B07JFRFJG6 | C46: OBDLink MX+ OBD2 Bluetooth Scanner for iPhone, Android, and Windows | D46: obdlink | E46: Dongle | F46: 139.94207 | G46: 666544.1 | H46: 4763 | I46: 14685 | J46: 4.6 | K46: https://amazon.com/dp/B07JFRFJG6 | L46: =HYPERLINK(K46) -> https://amazon.com/dp/B07JFRFJG6
A47: 6 | B47: B0C33Y285Y | C47: TOPDON Bidirectional Scan Tool, 2025 New ArtiDiag900 Lite Automotive Diagnostic Tool for Full System, Scanner for Car with Active Test, 8 Reset, Wireless OBD2 Scanner Diagnostic Tool for All Vehicles | D47: topdon | E47: Tablet | F47: 313.53909 | G47: 520788.43 | H47: 1661 | I47: 999 | J47: 4.3 | K47: https://amazon.com/dp/B0C33Y285Y | L47: =HYPERLINK(K47) -> https://amazon.com/dp/B0C33Y285Y
A48: 7 | B48: B098PYB8XG | C48: Autel Scanner MaxiCOM MK900BT, 2025 MK900-BT V2.0 Bidirectional Diagnostic Tool, 8in Up of MK900 MX900 MK808S MK808BT MX808S MK808Z, 3000+ Active Tests, 40+ Service, CAN-FD&DOIP, All System, FCA 11 OS | D48: autel | E48: Tablet | F48: 659.22073 | G48: 479912.69 | H48: 728 | I48: 580 | J48: 4.6 | K48: https://amazon.com/dp/B098PYB8XG | L48: =HYPERLINK(K48) -> https://amazon.com/dp/B098PYB8XG
A49: 8 | B49: B00UJV3E12 | C49: FOXWELL NT301 OBD2 Scanner Live Data Professional Mechanic OBDII Diagnostic Code Reader Tool for Check Engine Light | D49: foxwell | E49: Handheld | F49: 64.359672 | G49: 410035.47 | H49: 6371 | I49: 29066 | J49: 4.5 | K49: https://amazon.com/dp/B00UJV3E12 | L49: =HYPERLINK(K49) -> https://amazon.com/dp/B00UJV3E12
A50: 9 | B50: B0DV2N2FND | C50: BLCKTEC 460T OBD2 Scanner Car Code Reader Engine ABS SRS Transmission Diagnostic Tool, 12 Reset Services, Oil/TPMS/EPB/BMS/SAS/DPF/Throttle Reset, ABS Bleeding, Battery Test, Auto VIN, Free Update | D50: blcktec | E50: Tablet | F50: 198.0568 | G50: 402451.42 | H50: 2032 | I50: 312 | J50: 4.4 | K50: https://amazon.com/dp/B0DV2N2FND | L50: =HYPERLINK(K50) -> https://amazon.com/dp/B0DV2N2FND
A51: 10 | B51: B0DCFRF2TF | C51: THINKCAR Bidirectional Scan Tool, THINKSCAN 689BT All System Automotive Diagnostic Tool, Bi Directional OBD2 Scanner with ECU Coding, 34 Services, FCA Autoauth, CANFD and DoIP, Wireless Update | D51: thinkcar | E51: Tablet | F51: 501.58996 | G51: 393748.12 | H51: 785 | I51: 401 | J51: 4.4 | K51: https://amazon.com/dp/B0DCFRF2TF | L51: =HYPERLINK(K51) -> https://amazon.com/dp/B0DCFRF2TF
A52: 11 | B52: B0DTK24XKB | C52: MUCAR 892BT AI-Assisted Bidirectional Scan Tool, Full System OBD2 Scanner, Bi-Directional OBD2 Scanner Diagnostic Tool,ECU Coding, 35 Services, FCA Autoauth, CANFD and DOIP, Free Lifetime Upgrade | D52: mucar | E52: Tablet | F52: 612.13041 | G52: 385030.03 | H52: 629 | I52: 249 | J52: 4.3 | K52: https://amazon.com/dp/B0DTK24XKB | L52: =HYPERLINK(K52) -> https://amazon.com/dp/B0DTK24XKB
A53: 12 | B53: B091BQNR3S | C53: TOPDON Phoenix Plus 2, ECU Code TOPDON Scanner V2.0, Bidirectional Scan Tool, Topology Map, CANFD, High-End OEM Full System, 42+ Service, FCA SGW AutoAuth, V.A.G Guided, 2 Years Free Update | D53: topdon | E53: Tablet | F53: 1096.3385 | G53: 368369.72 | H53: 336 | I53: 447 | J53: 4.5 | K53: https://amazon.com/dp/B091BQNR3S | L53: =HYPERLINK(K53) -> https://amazon.com/dp/B091BQNR3S
... A91: 50 | B91: B09712X5CW | C91: Autel Scanner MaxiCOM MK900BT, 2025 MK900-BT Bidirectional Diagnostic Scan Tool, 2.0 BT Ver. of MK900 MX900, 8in Up of MK808S MK808BT PRO MX808S MK808Z, 40+ Reset, 3K+ Active Tests, CAN FD & DoIP, FCA | D91: autel | E91: Tablet | F91: 659.10106 | G91: 112047.18 | H91: 170 | I91: 165 | J91: 4.6 | K91: https://amazon.com/dp/B09712X5CW | L91: =HYPERLINK(K91) -> https://amazon.com/dp/B09712X5CW
A94: Rank By Monthly Units - Nov '25 ONLY
A95: Ranking | B95: ASIN | C95: Product Name | D95: Brand | E95: Type | F95: Price | G95: Est. Monthly Retail Rev | H95: Est. Monthly Units Sold | I95: # of Reviews | J95: Avg. Rating | K95: Column2 | L95: Link
A96: 1 | B96: B01G5EA74I | C96: ANCEL AD310 Classic Enhanced Universal OBD II Scanner Car Engine Fault Code Reader CAN Diagnostic Scan Tool, Read and Clear Error Codes for 1996 or Newer OBD2 Protocol Vehicle (Black) | D96: ancel | E96: Handheld | F96: 28.282506 | G96: 1131017.4 | H96: 39990 | I96: 59738 | J96: 4.6 | K96: https://amazon.com/dp/B01G5EA74I | L96: =HYPERLINK(K96) -> https://amazon.com/dp/B01G5EA74I
A97: 2 | B97: B00652G4TS | C97: BlueDriver Bluetooth Pro OBDII Scan Tool for iPhone & Android - No Subscription Fee - OBD2 Car Scanner and Code Reader - Diagnose Check Engine, ABS, SRS, Airbag & 7000+ Issues on Vehicles 1996+ | D97: bluedriver | E97: Dongle | F97: 74.357517 | G97: 1319399.8 | H97: 17744 | I97: 60886 | J97: 4.4 | K97: https://amazon.com/dp/B00652G4TS | L97: =HYPERLINK(K97) -> https://amazon.com/dp/B00652G4TS
A98: 3 | B98: B07Z3HB7DR | C98: MOTOPOWER MP69033 Car OBD2 Scanner Code Reader Engine Fault Scanner CAN Diagnostic Scan Tool for All OBD II Protocol Cars Since 1996, Yellow | D98: motopower | E98: Handheld | F98: 25.196317 | G98: 261109.43 | H98: 10363 | I98: 48232 | J98: 4.6 | K98: https://amazon.com/dp/B07Z3HB7DR | L98: =HYPERLINK(K98) -> https://amazon.com/dp/B07Z3HB7DR
A99: 4 | B99: B013RIQMEO | C99: FIXD Bluetooth OBD2 Scanner for Car - Car Code Readers & Scan Tools for iPhone/Android - Wireless OBD2 Auto Diagnostic Tool - Check Engine & Fix All Vehicles 1996+ (1 Pack w/Free FIXD Premium Trial) | D99: fixd | E99: Dongle | F99: 39.990511 | G99: 306207.34 | H99: 7657 | I99: 33653 | J99: 4.1 | K99: https://amazon.com/dp/B013RIQMEO | L99: =HYPERLINK(K99) -> https://amazon.com/dp/B013RIQMEO
A100: 5 | B100: B071FSNL73 | C100: ANCEL AD410 Enhanced OBD2 Scanner, Vehicle Code Reader for Check Engine Light, Automotive OBD II Scanner Fault Diagnosis, OBDII Scan Tool for All OBDII Cars 1996+, Black/Yellow | D100: ancel | E100: Handheld | F100: 49.987904 | G100: 347165.99 | H100: 6945 | I100: 14142 | J100: 4.5 | K100: https://amazon.com/dp/B071FSNL73 | L100: =HYPERLINK(K100) -> https://amazon.com/dp/B071FSNL73
A101: 6 | B101: B00UJV3E12 | C101: FOXWELL NT301 OBD2 Scanner Live Data Professional Mechanic OBDII Diagnostic Code Reader Tool for Check Engine Light | D101: foxwell | E101: Handheld | F101: 64.359672 | G101: 410035.47 | H101: 6371 | I101: 29066 | J101: 4.5 | K101: https://amazon.com/dp/B00UJV3E12 | L101: =HYPERLINK(K101) -> https://amazon.com/dp/B00UJV3E12
A102: 7 | B102: B07JFRFJG6 | C102: OBDLink MX+ OBD2 Bluetooth Scanner for iPhone, Android, and Windows | D102: obdlink | E102: Dongle | F102: 139.94207 | G102: 666544.1 | H102: 4763 | I102: 14685 | J102: 4.6 | K102: https://amazon.com/dp/B07JFRFJG6 | L102: =HYPERLINK(K102) -> https://amazon.com/dp/B07JFRFJG6
A103: 8 | B103: B073XKQQQW | C103: Veepeak OBDCheck BLE Bluetooth OBD II Scanner for iOS & Android, Car Wireless Check Engine Light Code Reader Diagnostic Tool | D103: veepeak | E103: Dongle | F103: 30.040911 | G103: 135214.14 | H103: 4501 | I103: 22552 | J103: 4.5 | K103: https://amazon.com/dp/B073XKQQQW | L103: =HYPERLINK(K103) -> https://amazon.com/dp/B073XKQQQW
A104: 9 | B104: B081VQVD3F | C104: OBDLink EX FORScan OBD Adapter | D104: obdlink | E104: Cable/Adapter | F104: 69.934779 | G104: 306454.2 | H104: 4382 | I104: 9449 | J104: 4.8 | K104: https://amazon.com/dp/B081VQVD3F | L104: =HYPERLINK(K104) -> https://amazon.com/dp/B081VQVD3F
A105: 10 | B105: B0BY1TS725 | C105: VDIAGTOOL VD10 OBD2 Scanner Code Reader Car Diagnostic Tool Engine Fault Code Reader for Turn Off CEL with Freeze Frame/I/M Readiness for All OBDII Protocol Cars, OBD2 Scanner Diagnostic Tool | D105: vdiagtool | E105: Handheld | F105: 19.98077 | G105: 80142.87 | H105: 4011 | I105: 1843 | J105: 4.6 | K105: https://amazon.com/dp/B0BY1TS725 | L105: =HYPERLINK(K105) -> https://amazon.com/dp/B0BY1TS725
A106: 11 | B106: B07Z481NJM | C106: Innova 5610 OBD2 Bidirectional Scan Tool - Understand Your Vehicle, Pinpoint What's Wrong, and Complete Your Repairs with Less Headache, Updates Included, US-Based Technical Support | D106: innova | E106: Handheld | F106: 287.32292 | G106: 1127455.1 | H106: 3924 | I106: 2889 | J106: 4.4 | K106: https://amazon.com/dp/B07Z481NJM | L106: =HYPERLINK(K106) -> https://amazon.com/dp/B07Z481NJM
A107: 12 | B107: B07Z46L5FG | C107: Innova 5210 OBD2 Scanner & Engine Code Reader, Battery Tester, Live Data, Oil Reset, Car Diagnostic Tool for Most Vehicles, Bluetooth Compatible with America's Top Car Repair App | D107: innova | E107: Handheld | F107: 84.710609 | G107: 265821.89 | H107: 3138 | I107: 3668 | J107: 4.5 | K107: https://amazon.com/dp/B07Z46L5FG | L107: =HYPERLINK(K107) -> https://amazon.com/dp/B07Z46L5FG
... A145: 50 | B145: B0BLRV8QQP | C145: Zmoon OBD2 Scanner Diagnostic Tool, Vehicle Check Engine Code Readers with Reset & I/M Readiness & More, Car OBDII/EOBD Diagnostic Scan Tool for All Vehicles After 1996 | D145: zmoon | E145: Handheld | F145: 19.869085 | G145: 16928.46 | H145: 852 | I145: 1624 | J145: 4.5 | K145: https://amazon.com/dp/B0BLRV8QQP | L145: =HYPERLINK(K145) -> https://amazon.com/dp/B0BLRV8QQP

Sheet Tablet Total
A1: Tablet Monthly Summary
A3: Tablet Overall
B4: Avg Price | C4: Avg Price MoM | D4: Avg Price YoY | E4: Quantity/Mo | F4: Qty by % | G4: Qty MoM | H4: Qty YoY | I4: Revenue/Mo | J4: Revenue by % | L4: Revenue MoM | M4: Revenue YoY
A5: autel | B5: 778.9176 | C5: -0.058217228 | D5: -0.1138579 | E5: 5661 | F5: 0.14304847 | G5: 0.033783784 | H5: 0.20421187 | I5: 4409452.5 | J5: 0.28334702 | K5: -0.026400242 | L5: -0.026400242 | M5: 0.06710284
A6: topdon | B6: 318.11918 | C6: -0.023844596 | D6: -0.032768095 | E6: 9829 | F6: 0.24837014 | G6: 0.20675261 | H6: 1.2826289 | I6: 3126793.5 | J6: 0.20092463 | K6: 0.17797808 | L6: 0.17797808 | M6: 1.2078315
A7: launch | B7: 386.26828 | C7: -0.048693863 | D7: -0.13372217 | E7: 6596 | F7: 0.16667509 | G7: 0.032722718 | H7: 0.2278481 | I7: 2547825.6 | J7: 0.16372073 | K7: -0.017564541 | L7: -0.017564541 | M7: 0.063657585
A8: xtool | B8: 394.61118 | C8: -0.0088289936 | D8: -0.22188385 | E8: 3265 | F8: 0.082503664 | G8: 0.04313099 | H8: 0.9239835 | I8: 1288405.5 | J8: 0.08279165 | K8: 0.033921194 | L8: 0.033921194 | M8: 0.49708264
A9: foxwell | B9: 228.69419 | C9: -0.056322602 | D9: -0.057541937 | E9: 3287 | F9: 0.083059585 | G9: 0.038546603 | H9: -0.07486631 | I9: 751717.8 | J9: 0.048304635 | K9: -0.019947043 | L9: -0.019947043 | M9: -0.12810029
A10: blcktec | B10: 198.0568 | C10: 0.018644659 | E10: 2032 | F10: 0.051346844 | G10: 0.41209173 | I10: 402451.42 | J10: 0.025861126 | K10: 0.4384197 | L10: 0.4384197
A11: innova | B11: 137.95047 | C11: -0.034313523 | E11: 1336 | F11: 0.033759539 | G11: 0.91404011 | I11: 184301.83 | J11: 0.011843052 | K11: 0.84836266 | L11: 0.84836266
A12: Other | B12: 376.72754 | C12: -0.0064107823 | D12: 0.32903884 | E12: 7568 | F12: 0.19123667 | G12: 0.056688076 | H12: 0.50547046 | I12: 2851074 | J12: 0.18320717 | K12: 0.049913879 | L12: 0.049913879 | M12: 1.0008287
A13: Total | B13: =Summary!B7 -> 393.23854 | C13: =Summary!C7 -> -0.059447514 | D13: =Summary!D7 -> -0.12584209 | E13: =Summary!E7 -> 39574 | F13: =SUM(F5:F12) -> 1 | G13: =Summary!G7 -> 0.11156677 | H13: =Summary!H7 -> 0.60504543 | I13: =Summary!I7 -> 15562022 | J13: =SUM(J5:J12) -> 1 | L13: =Summary!K7 -> 0.045486885 | M13: =Summary!L7 -> 0.40306315
A45: Rank By Monthly Revenue - Nov '25 ONLY
A46: Ranking | B46: ASIN | C46: Product Name | D46: Brand | E46: Type | F46: Price | G46: Est. Monthly Retail Rev | H46: Est. Monthly Units Sold | I46: # of Reviews | J46: Avg. Rating | K46: Column2 | L46: Link
A47: 1 | B47: B0744B55QV | C47: Autel Scanner MaxiCOM MK808S: 2025 Bidirectional Tool as MK808BT Pro MX808S M808Z, Work as MaxiCheck MX900 MK900BT, 28+ Service, Active Test, All System Diagnose, Injector C0ding, FCA Autoauth OS 11 | D47: autel | E47: Tablet | F47: 451.83728 | G47: 684985.31 | H47: 1516 | I47: 3604 | J47: 4.5 | K47: https://amazon.com/dp/B0744B55QV | L47: =HYPERLINK(K47) -> https://amazon.com/dp/B0744B55QV
A48: 2 | B48: B0C33Y285Y | C48: TOPDON Bidirectional Scan Tool, 2025 New ArtiDiag900 Lite Automotive Diagnostic Tool for Full System, Scanner for Car with Active Test, 8 Reset, Wireless OBD2 Scanner Diagnostic Tool for All Vehicles | D48: topdon | E48: Tablet | F48: 313.53909 | G48: 520788.43 | H48: 1661 | I48: 999 | J48: 4.3 | K48: https://amazon.com/dp/B0C33Y285Y | L48: =HYPERLINK(K48) -> https://amazon.com/dp/B0C33Y285Y
A49: 3 | B49: B098PYB8XG | C49: Autel Scanner MaxiCOM MK900BT, 2025 MK900-BT V2.0 Bidirectional Diagnostic Tool, 8in Up of MK900 MX900 MK808S MK808BT MX808S MK808Z, 3000+ Active Tests, 40+ Service, CAN-FD&DOIP, All System, FCA 11 OS | D49: autel | E49: Tablet | F49: 659.22073 | G49: 479912.69 | H49: 728 | I49: 580 | J49: 4.6 | K49: https://amazon.com/dp/B098PYB8XG | L49: =HYPERLINK(K49) -> https://amazon.com/dp/B098PYB8XG
A50: 4 | B50: B0DV2N2FND | C50: BLCKTEC 460T OBD2 Scanner Car Code Reader Engine ABS SRS Transmission Diagnostic Tool, 12 Reset Services, Oil/TPMS/EPB/BMS/SAS/DPF/Throttle Reset, ABS Bleeding, Battery Test, Auto VIN, Free Update | D50: blcktec | E50: Tablet | F50: 198.0568 | G50: 402451.42 | H50: 2032 | I50: 312 | J50: 4.4 | K50: https://amazon.com/dp/B0DV2N2FND | L50: =HYPERLINK(K50) -> https://amazon.com/dp/B0DV2N2FND
A51: 5 | B51: B0DCFRF2TF | C51: THINKCAR Bidirectional Scan Tool, THINKSCAN 689BT All System Automotive Diagnostic Tool, Bi Directional OBD2 Scanner with ECU Coding, 34 Services, FCA Autoauth, CANFD and DoIP, Wireless Update | D51: thinkcar | E51: Tablet | F51: 501.58996 | G51: 393748.12 | H51: 785 | I51: 401 | J51: 4.4 | K51: https://amazon.com/dp/B0DCFRF2TF | L51: =HYPERLINK(K51) -> https://amazon.com/dp/B0DCFRF2TF
A52: 6 | B52: B0DTK24XKB | C52: MUCAR 892BT AI-Assisted Bidirectional Scan Tool, Full System OBD2 Scanner, Bi-Directional OBD2 Scanner Diagnostic Tool,ECU Coding, 35 Services, FCA Autoauth, CANFD and DOIP, Free Lifetime Upgrade | D52: mucar | E52: Tablet | F52: 612.13041 | G52: 385030.03 | H52: 629 | I52: 249 | J52: 4.3 | K52: https://amazon.com/dp/B0DTK24XKB | L52: =HYPERLINK(K52) -> https://amazon.com/dp/B0DTK24XKB
A53: 7 | B53: B091BQNR3S | C53: TOPDON Phoenix Plus 2, ECU Code TOPDON Scanner V2.0, Bidirectional Scan Tool, Topology Map, CANFD, High-End OEM Full System, 42+ Service, FCA SGW AutoAuth, V.A.G Guided, 2 Years Free Update | D53: topdon | E53: Tablet | F53: 1096.3385 | G53: 368369.72 | H53: 336 | I53: 447 | J53: 4.5 | K53: https://amazon.com/dp/B091BQNR3S | L53: =HYPERLINK(K53) -> https://amazon.com/dp/B091BQNR3S
A54: 8 | B54: B0BNKHCXVC | C54: TOPDON ArtiDiag Pro OBD2 Scanner Diagnostic Tool, Bidirectional Scan Tool with ECU Coding, 35+ Services, V.A.G Guided, FCA SGW, Can FD DoIP/All System Diagnosis | D54: topdon | E54: Tablet | F54: 478.70164 | G54: 321687.5 | H54: 672 | I54: 677 | J54: 4.4 | K54: https://amazon.com/dp/B0BNKHCXVC | L54: =HYPERLINK(K54) -> https://amazon.com/dp/B0BNKHCXVC
A55: 9 | B55: B08XK3DJ42 | C55: OBD2 Scanner TOPDON AD500, Oil SAS Throttle TPMS BMS EPB Reset, Engine ABS SRS Transmission, Diagnostic Scan Tool, AutoVIN, Car Check Engine Code Reader with Battery Test, Lifetime Wi-Fi Free Update | D55: topdon | E55: Tablet | F55: 149.94128 | G55: 315626.4 | H55: 2105 | I55: 1431 | J55: 4.4 | K55: https://amazon.com/dp/B08XK3DJ42 | L55: =HYPERLINK(K55) -> https://amazon.com/dp/B08XK3DJ42
A56: 10 | B56: B08TR5PS5V | C56: TOPDON AD800BT 2 OBD2 Scanner, 2025 Bidirectional Scan Tool, Function as AD900 Lite AD Pro, All System Automotive Diagnostic Scanner, Active Test, 28+ Reset Service, FCA Autoauth, 2 Years Free Update | D56: topdon | E56: Tablet | F56: 390.68245 | G56: 300044.12 | H56: 768 | I56: 728 | J56: 4.3 | K56: https://amazon.com/dp/B08TR5PS5V | L56: =HYPERLINK(K56) -> https://amazon.com/dp/B08TR5PS5V
A58: Rank By Monthly Units - Nov '25 ONLY
A59: Ranking | B59: ASIN | C59: Product Name | D59: Brand | E59: Type | F59: Price | G59: Est. Monthly Retail Rev | H59: Est. Monthly Units Sold | I59: # of Reviews | J59: Avg. Rating | K59: Column2 | L59: Link
A60: 1 | B60: B08XK3DJ42 | C60: OBD2 Scanner TOPDON AD500, Oil SAS Throttle TPMS BMS EPB Reset, Engine ABS SRS Transmission, Diagnostic Scan Tool, AutoVIN, Car Check Engine Code Reader with Battery Test, Lifetime Wi-Fi Free Update | D60: topdon | E60: Tablet | F60: 149.94128 | G60: 315626.4 | H60: 2105 | I60: 1431 | J60: 4.4 | K60: https://amazon.com/dp/B08XK3DJ42 | L60: =HYPERLINK(K60) -> https://amazon.com/dp/B08XK3DJ42
A61: 2 | B61: B0DV2N2FND | C61: BLCKTEC 460T OBD2 Scanner Car Code Reader Engine ABS SRS Transmission Diagnostic Tool, 12 Reset Services, Oil/TPMS/EPB/BMS/SAS/DPF/Throttle Reset, ABS Bleeding, Battery Test, Auto VIN, Free Update | D61: blcktec | E61: Tablet | F61: 198.0568 | G61: 402451.42 | H61: 2032 | I61: 312 | J61: 4.4 | K61: https://amazon.com/dp/B0DV2N2FND | L61: =HYPERLINK(K61) -> https://amazon.com/dp/B0DV2N2FND
A62: 3 | B62: B0C33Y285Y | C62: TOPDON Bidirectional Scan Tool, 2025 New ArtiDiag900 Lite Automotive Diagnostic Tool for Full System, Scanner for Car with Active Test, 8 Reset, Wireless OBD2 Scanner Diagnostic Tool for All Vehicles | D62: topdon | E62: Tablet | F62: 313.53909 | G62: 520788.43 | H62: 1661 | I62: 999 | J62: 4.3 | K62: https://amazon.com/dp/B0C33Y285Y | L62: =HYPERLINK(K62) -> https://amazon.com/dp/B0C33Y285Y
A63: 4 | B63: B0744B55QV | C63: Autel Scanner MaxiCOM MK808S: 2025 Bidirectional Tool as MK808BT Pro MX808S M808Z, Work as MaxiCheck MX900 MK900BT, 28+ Service, Active Test, All System Diagnose, Injector C0ding, FCA Autoauth OS 11 | D63: autel | E63: Tablet | F63: 451.83728 | G63: 684985.31 | H63: 1516 | I63: 3604 | J63: 4.5 | K63: https://amazon.com/dp/B0744B55QV | L63: =HYPERLINK(K63) -> https://amazon.com/dp/B0744B55QV
A64: 5 | B64: B09KZTYD18 | C64: OBD2 Scanner TOPDON AD600S Scan Tool, Code Reader, Diagnostics Scanner for ABS/SRS/AT/Engine, 9 Reset Services, Oil/Brake/BMS/SAS/DPF/TPMS/ETS Reset/ABS Bleeding/Injector Coding, Free Lifetime Upgrade | D64: topdon | E64: Tablet | F64: 210.06127 | G64: 288414.13 | H64: 1373 | I64: 1535 | J64: 4.4 | K64: https://amazon.com/dp/B09KZTYD18 | L64: =HYPERLINK(K64) -> https://amazon.com/dp/B09KZTYD18
A65: 6 | B65: B08PFJMTY3 | C65: FOXWELL Car Scanner NT604 Elite OBD2 Scanner ABS SRS Transmission, Check Engine Code Reader for Cars and Trucks, Diagnostic Scan Tool with SRS Airbag, Automotive Diagnostic Tool with Live Data | D65: foxwell | E65: Tablet | F65: 158.82678 | G65: 214416.15 | H65: 1350 | I65: 4495 | J65: 4.3 | K65: https://amazon.com/dp/B08PFJMTY3 | L65: =HYPERLINK(K65) -> https://amazon.com/dp/B08PFJMTY3
A66: 7 | B66: B0F254MVB5 | C66: Innova SD35 OBD2 Scanner – ABS, SRS, TPMS & Check Engine Code Reader, Live Data, All System Diagnostics, Compatible with Most Vehicles | D66: innova | E66: Tablet | F66: 129.97499 | G66: 161428.94 | H66: 1242 | I66: 101 | J66: 4.5 | K66: https://amazon.com/dp/B0F254MVB5 | L66: =HYPERLINK(K66) -> https://amazon.com/dp/B0F254MVB5
A67: 8 | B67: B07RLF8FBC | C67: LAUNCH OBD2 Scanner CRP123X Elite, 2025 Lifetime Free WiFi Update scan Tool, FCA SGW, SAS Calibration/Throttle/Brake/BMS/D-P-F/Oil Reset/ABS bleeding, Multi Systems Car Scanner, Battery Test, Auto VIN | D67: launch | E67: Tablet | F67: 160.31228 | G67: 173297.57 | H67: 1081 | I67: 3227 | J67: 4.4 | K67: https://amazon.com/dp/B07RLF8FBC | L67: =HYPERLINK(K67) -> https://amazon.com/dp/B07RLF8FBC
A68: 9 | B68: B0CTHJW813 | C68: TOPDON Upgraded AD600S OBD2 Scanner, Diagnostic Tool, ABS SRS Transmission Engine Code Reader, 9 Reset Services Scan Tool, Oil/Brake/BMS/SAS/DPF/TPMS/ETS Reset, Injector Coding, Lifetime Free Update | D68: topdon | E68: Tablet | F68: 216.01884 | G68: 204785.86 | H68: 948 | I68: 665 | J68: 4.5 | K68: https://amazon.com/dp/B0CTHJW813 | L68: =HYPERLINK(K68) -> https://amazon.com/dp/B0CTHJW813
A69: 10 | B69: B0DCFRF2TF | C69: THINKCAR Bidirectional Scan Tool, THINKSCAN 689BT All System Automotive Diagnostic Tool, Bi Directional OBD2 Scanner with ECU Coding, 34 Services, FCA Autoauth, CANFD and DoIP, Wireless Update | D69: thinkcar | E69: Tablet | F69: 501.58996 | G69: 393748.12 | H69: 785 | I69: 401 | J69: 4.4 | K69: https://amazon.com/dp/B0DCFRF2TF | L69: =HYPERLINK(K69) -> https://amazon.com/dp/B0DCFRF2TF
A71: Tablet $800+
B72: Avg Price | C72: Avg Price MoM | D72: Avg Price YoY | E72: Quantity/Mo | F72: Qty by % | G72: Qty MoM | H72: Qty YoY | I72: Revenue/Mo | J72: Revenue by % | L72: Revenue MoM | M72: Revenue YoY
A73: autel | B73: 1911.1723 | C73: 0.03079727 | D73: -0.051980902 | E73: 1031 | F73: 0.36036351 | G73: -0.16720517 | H73: -0.070333634 | I73: 1970418.6 | J73: 0.4727787 | K73: -0.14155736 | L73: -0.14155736 | M73: -0.11865853
A74: launch | B74: 1279.214 | C74: -0.04524597 | D74: -0.020425317 | E74: 868 | F74: 0.30339042 | G74: 0.1043257 | H74: 0.028436019 | I74: 1110357.8 | J74: 0.26641724 | K74: 0.054359412 | L74: 0.054359412 | M74: 0.0074298873
...

Sheet Tablet $800+
A1: Tablet $800+ Monthly Summary
A3: ='Tablet Total'!A71 -> Tablet $800+
B4: Avg Price | C4: Avg Price MoM | D4: Avg Price YoY | E4: Quantity/Mo | F4: Qty by % | G4: Qty MoM | H4: Qty YoY | I4: Revenue/Mo | J4: Revenue by % | L4: Revenue MoM | M4: Revenue YoY
A5: ='Tablet Total'!A73 -> autel | B5: ='Tablet Total'!B73 -> 1911.1723 | C5: ='Tablet Total'!C73 -> 0.03079727 | D5: ='Tablet Total'!D73 -> -0.051980902 | E5: ='Tablet Total'!E73 -> 1031 | F5: ='Tablet Total'!F73 -> 0.36036351 | G5: ='Tablet Total'!G73 -> -0.16720517 | H5: ='Tablet Total'!H73 -> -0.070333634 | ... J5: ='Tablet Total'!J73 -> 0.4727787 | L5: ='Tablet Total'!L73 -> -0.14155736 | M5: ='Tablet Total'!M73 -> -0.11865853
A6: ='Tablet Total'!A74 -> launch | B6: ='Tablet Total'!B74 -> 1279.214 | C6: ='Tablet Total'!C74 -> -0.04524597 | D6: ='Tablet Total'!D74 -> -0.020425317 | E6: ='Tablet Total'!E74 -> 868 | F6: ='Tablet Total'!F74 -> 0.30339042 | G6: ='Tablet Total'!G74 -> 0.1043257 | H6: ='Tablet Total'!H74 -> 0.028436019 | ... J6: ='Tablet Total'!J74 -> 0.26641724 | L6: ='Tablet Total'!L74 -> 0.054359412 | M6: ='Tablet Total'!M74 -> 0.0074298873
A7: ='Tablet Total'!A75 -> topdon | B7: ='Tablet Total'!B75 -> 1194.9252 | C7: ='Tablet Total'!C75 -> -0.08924766 | D7: ='Tablet Total'!D75 -> -0.068075016 | E7: ='Tablet Total'!E75 -> 489 | F7: ='Tablet Total'!F75 -> 0.17091926 | G7: ='Tablet Total'!G75 -> 0.4092219 | H7: ='Tablet Total'!H75 -> 1.0720339 | ... J7: ='Tablet Total'!J75 -> 0.1402003 | L7: ='Tablet Total'!L75 -> 0.28345214 | M7: ='Tablet Total'!M75 -> 0.93098016
A8: ='Tablet Total'!A76 -> xtool | B8: ='Tablet Total'!B76 -> 1457.9837 | C8: ='Tablet Total'!C76 -> 0.051819597 | D8: ='Tablet Total'!D76 -> 0.28148187 | E8: ='Tablet Total'!E76 -> 139 | F8: ='Tablet Total'!F76 -> 0.048584411 | G8: ='Tablet Total'!G76 -> -0.17261905 | H8: ='Tablet Total'!H76 -> -0.060810811 | ... J8: ='Tablet Total'!J76 -> 0.048625812 | L8: ='Tablet Total'!L76 -> -0.1297445 | M8: ='Tablet Total'!M76 -> 0.20355392
A9: ='Tablet Total'!A77 -> ancel | B9: ='Tablet Total'!B77 -> 829.74557 | C9: ='Tablet Total'!C77 -> -0.048725546 | D9: ='Tablet Total'!D77 -> -0.20974596 | E9: ='Tablet Total'!E77 -> 221 | F9: ='Tablet Total'!F77 -> 0.077245718 | G9: ='Tablet Total'!G77 -> -0.14341085 | H9: ='Tablet Total'!H77 -> 3.1698113 | ... J9: ='Tablet Total'!J77 -> 0.043998371 | L9: ='Tablet Total'!L77 -> -0.18514863 | M9: ='Tablet Total'!M77 -> 2.2952102
A10: ='Tablet Total'!A78 -> Other | B10: ='Tablet Total'!B78 -> 1031.961 | C10: ='Tablet Total'!C78 -> -0.018190344 | D10: ='Tablet Total'!D78 -> -0.12837299 | E10: ='Tablet Total'!E78 -> 113 | F10: ='Tablet Total'!F78 -> 0.039496679 | G10: ='Tablet Total'!G78 -> -0.20979021 | H10: ='Tablet Total'!H78 -> 0.13 | ... J10: ='Tablet Total'!J78 -> 0.027979574 | L10: ='Tablet Total'!L78 -> -0.2241644 | M10: ='Tablet Total'!M78 -> -0.015061474
A11: ='Tablet Total'!A79 -> Total | B11: ='Tablet Total'!B79 -> 1456.7424 | C11: ='Tablet Total'!C79 -> -0.029265699 | D11: ='Tablet Total'!D79 -> -0.08928515 | E11: ='Tablet Total'!E79 -> 2861 | F11: ='Tablet Total'!F79 -> 1 | G11: ='Tablet Total'!G79 -> -0.026870748 | H11: ='Tablet Total'!H79 -> 0.14899598 | ... J11: ='Tablet Total'!J79 -> 1 | L11: ='Tablet Total'!L79 -> -0.055350056 | M11: ='Tablet Total'!M79 -> 0.046407706
A43: Rank By Monthly Revenue - Nov '25 ONLY
A44: Ranking | B44: ASIN | C44: Product Name | D44: Brand | E44: Type | F44: Price | G44: Est. Monthly Retail Rev | H44: Est. Monthly Units Sold | I44: # of Reviews | J44: Avg. Rating | K44: Column2 | L44: Link
A45: 1 | B45: B091BQNR3S | C45: TOPDON Phoenix Plus 2, ECU Code TOPDON Scanner V2.0, Bidirectional Scan Tool, Topology Map, CANFD, High-End OEM Full System, 42+ Service, FCA SGW AutoAuth, V.A.G Guided, 2 Years Free Update | D45: topdon | E45: Tablet | F45: 1096.3385 | G45: 368369.72 | H45: 336 | I45: 447 | J45: 4.5 | K45: https://amazon.com/dp/B091BQNR3S | L45: =HYPERLINK(K45) -> https://amazon.com/dp/B091BQNR3S
A46: 2 | B46: B0BZ82WQ4Q | C46: ANCEL X7HD 10'' Heavy Duty Truck Scanner, Semi Trucks Full System Diagnostic Tool, Bidirectional Diesel Scan Tool with DPF, ECU Coding, 40+ Reset for Cummins, Detroit, Caterpillar, Volvo, Paccar etc | D46: ancel | E46: Tablet | F46: 815.06799 | G46: 170349.21 | H46: 209 | I46: 764 | J46: 3.9 | K46: https://amazon.com/dp/B0BZ82WQ4Q | L46: =HYPERLINK(K46) -> https://amazon.com/dp/B0BZ82WQ4Q
A47: 3 | B47: B0DZC1M7MZ | C47: Autel MaxiSys Ultra S2 Scanner, 2025 Top Intelligen Scan Diagnostic with AI, 6-in-1 VCMI2, Up of MSUltra/ MS919, Topology 3.0, Multi-Point DVI, Programming, Motor Truspeed Repair, EV Test, 48+ Service | D47: autel | E47: Tablet | F47: 5586.271 | G47: 162001.86 | H47: 29 | I47: 16 | J47: 4.6 | K47: https://amazon.com/dp/B0DZC1M7MZ | L47: =HYPERLINK(K47) -> https://amazon.com/dp/B0DZC1M7MZ
A48: 4 | B48: B08V59JNYP | C48: LAUNCH X431 PRO3S+ Smartlink HD Heavy Duty Truck Scanner,2025 Diesel&Gasoline Bidirectional Diagnostic Scan Tool with J2534 Protocols,Topology Map,60+Service,ECU Code,CANFD &DOIP,2 Yrs Free Update | D48: launch | E48: Tablet | F48: 1898.2964 | G48: 146168.82 | H48: 77 | I48: 169 | J48: 4.3 | K48: https://amazon.com/dp/B08V59JNYP | L48: =HYPERLINK(K48) -> https://amazon.com/dp/B08V59JNYP
A49: 5 | B49: B0D7VS8SHS | C49: LAUNCH X431 PRO3S+ Elite, 2025 All-in-One Bidirectional Scan Tool with J2534 Protocols, HD Trucks Scanner, Topology Map, 60+Service, ECU Code Full Function Scanner, CANFD/DoIP/D-PDU/FCA, 2 Yrs Update | D49: launch | E49: Tablet | F49: 1268.8326 | G49: 131958.59 | H49: 104 | I49: 110 | J49: 4.3 | K49: https://amazon.com/dp/B0D7VS8SHS | L49: =HYPERLINK(K49) -> https://amazon.com/dp/B0D7VS8SHS
A50: 6 | B50: B092894STV | C50: Launch X431 PRO3S+ V5.0,2025 Upgrade All-in-One Bidirectional Scan Tool,HD Trucks Scan,Topology Map,ECU Code,55+ Service,Full System,CANFD&DOIP,DBSCar VII VCI 2-Year Update | D50: launch | E50: Tablet | F50: 1036.781 | G50: 81905.7 | H50: 79 | I50: 635 | J50: 4.2 | K50: https://amazon.com/dp/B092894STV | L50: =HYPERLINK(K50) -> https://amazon.com/dp/B092894STV
A51: 7 | B51: B0DBLQXQ6W | C51: XTOOL IP919 PRO Scan Tool, ECU Pr0 gramming Car OBD2 Scanner with Topology Mapping, Upgrade of D9S PRO, 51+ Resets, ECU C 0ding, FCA/CAN FD/DoIP, Automotive Bidirectional Scan Tool with 3-Year Updates | D51: xtool | E51: Tablet | F51: 1601.6151 | G51: 81682.37 | H51: 51 | I51: 61 | J51: 4.5 | K51: https://amazon.com/dp/B0DBLQXQ6W | L51: =HYPERLINK(K51) -> https://amazon.com/dp/B0DBLQXQ6W
A52: 8 | B52: B0CLS8B1BK | C52: LAUNCH X431 PROS V 5.0, Bidirectional Scan Tool PROS V+ 5.0 Elite with 2025 Newly Released DBSCar VII Connector,38+ Reset for All Cars,ECU Online Coding,CANFD,FCA AutoAuth,VAG Guide,2 Yrs F-Ree Update | D52: launch | E52: Tablet | F52: 826.64878 | G52: 74398.39 | H52: 90 | I52: 214 | J52: 4.4 | K52: https://amazon.com/dp/B0CLS8B1BK | L52: =HYPERLINK(K52) -> https://amazon.com/dp/B0CLS8B1BK
A53: 9 | B53: B01GRN4BRQ | C53: LAUNCH X431 PRO V 5.0,2025 New Gen. OEM Bluetooth Bidirectional Scan Tool w/Canfd Doip,Same as Pro3s+ 5.0,Online Code & 38+ Reset for All Cars,2 Yrs Free Update | D53: launch | E53: Tablet | F53: 815.80747 | G53: 70975.25 | H53: 87 | I53: 1035 | J53: 4.3 | K53: https://amazon.com/dp/B01GRN4BRQ | L53: =HYPERLINK(K53) -> https://amazon.com/dp/B01GRN4BRQ
A54: 10 | B54: B0F2HNM2VH | C54: LAUNCH Scanner X431 1MM* Plus Car Tool with X-PROG3 (Valued $800), Engine/Gearbox ECU Cl**é, All-in-One Diagnostic Tool, ECU Coding as X431 PAD, 39+ Services, All-System Scan, 2-Year Update | D54: launch | E54: Tablet | F54: 1467.1006 | G54: 68953.73 | H54: 47 | I54: 36 | J54: 4 | K54: https://amazon.com/dp/B0F2HNM2VH | L54: =HYPERLINK(K54) -> https://amazon.com/dp/B0F2HNM2VH
A56: Rank By Monthly Units - Nov '25 ONLY
A57: Ranking | B57: ASIN | C57: Product Name | D57: Brand | E57: Type | F57: Price | G57: Est. Monthly Retail Rev | H57: Est. Monthly Units Sold | I57: # of Reviews | J57: Avg. Rating | K57: Column2 | L57: Link
A58: 1 | B58: B091BQNR3S | C58: TOPDON Phoenix Plus 2, ECU Code TOPDON Scanner V2.0, Bidirectional Scan Tool, Topology Map, CANFD, High-End OEM Full System, 42+ Service, FCA SGW AutoAuth, V.A.G Guided, 2 Years Free Update | D58: topdon | E58: Tablet | F58: 1096.3385 | G58: 368369.72 | H58: 336 | I58: 447 | J58: 4.5 | K58: https://amazon.com/dp/B091BQNR3S | L58: =HYPERLINK(K58) -> https://amazon.com/dp/B091BQNR3S
A59: 2 | B59: B0BZ82WQ4Q | C59: ANCEL X7HD 10'' Heavy Duty Truck Scanner, Semi Trucks Full System Diagnostic Tool, Bidirectional Diesel Scan Tool with DPF, ECU Coding, 40+ Reset for Cummins, Detroit, Caterpillar, Volvo, Paccar etc | D59: ancel | E59: Tablet | F59: 815.06799 | G59: 170349.21 | H59: 209 | I59: 764 | J59: 3.9 | K59: https://amazon.com/dp/B0BZ82WQ4Q | L59: =HYPERLINK(K59) -> https://amazon.com/dp/B0BZ82WQ4Q
A60: 3 | B60: B0D7VS8SHS | C60: LAUNCH X431 PRO3S+ Elite, 2025 All-in-One Bidirectional Scan Tool with J2534 Protocols, HD Trucks Scanner, Topology Map, 60+Service, ECU Code Full Function Scanner, CANFD/DoIP/D-PDU/FCA, 2 Yrs Update | D60: launch | E60: Tablet | F60: 1268.8326 | G60: 131958.59 | H60: 104 | I60: 110 | J60: 4.3 | K60: https://amazon.com/dp/B0D7VS8SHS | L60: =HYPERLINK(K60) -> https://amazon.com/dp/B0D7VS8SHS
A61: 4 | B61: B0CLS8B1BK | C61: LAUNCH X431 PROS V 5.0, Bidirectional Scan Tool PROS V+ 5.0 Elite with 2025 Newly Released DBSCar VII Connector,38+ Reset for All Cars,ECU Online Coding,CANFD,FCA AutoAuth,VAG Guide,2 Yrs F-Ree Update | D61: launch | E61: Tablet | F61: 826.64878 | G61: 74398.39 | H61: 90 | I61: 214 | J61: 4.4 | K61: https://amazon.com/dp/B0CLS8B1BK | L61: =HYPERLINK(K61) -> https://amazon.com/dp/B0CLS8B1BK
A62: 5 | B62: B01GRN4BRQ | C62: LAUNCH X431 PRO V 5.0,2025 New Gen. OEM Bluetooth Bidirectional Scan Tool w/Canfd Doip,Same as Pro3s+ 5.0,Online Code & 38+ Reset for All Cars,2 Yrs Free Update | D62: launch | E62: Tablet | F62: 815.80747 | G62: 70975.25 | H62: 87 | I62: 1035 | J62: 4.3 | K62: https://amazon.com/dp/B01GRN4BRQ | L62: =HYPERLINK(K62) -> https://amazon.com/dp/B01GRN4BRQ
A63: 6 | B63: B092894STV | C63: Launch X431 PRO3S+ V5.0,2025 Upgrade All-in-One Bidirectional Scan Tool,HD Trucks Scan,Topology Map,ECU Code,55+ Service,Full System,CANFD&DOIP,DBSCar VII VCI 2-Year Update | D63: launch | E63: Tablet | F63: 1036.781 | G63: 81905.7 | H63: 79 | I63: 635 | J63: 4.2 | K63: https://amazon.com/dp/B092894STV | L63: =HYPERLINK(K63) -> https://amazon.com/dp/B092894STV
A64: 7 | B64: B08V59JNYP | C64: LAUNCH X431 PRO3S+ Smartlink HD Heavy Duty Truck Scanner,2025 Diesel&Gasoline Bidirectional Diagnostic Scan Tool with J2534 Protocols,Topology Map,60+Service,ECU Code,CANFD &DOIP,2 Yrs Free Update | D64: launch | E64: Tablet | F64: 1898.2964 | G64: 146168.82 | H64: 77 | I64: 169 | J64: 4.3 | K64: https://amazon.com/dp/B08V59JNYP | L64: =HYPERLINK(K64) -> https://amazon.com/dp/B08V59JNYP
A65: 8 | B65: B0DFLWDPK2 | C65: TOPDON Phoenix Lite 3, 2025 Upgraded Scanner of Lite 2, Bidirectional Scan Tool with CAN-FD, Car Scanner Diagnostic Tool, 35+ Maintenance Resets, Topology Mapping, ECU Coding, FCA Autoauth | D65: topdon | E65: Tablet | F65: 863.2663 | G65: 46616.38 | H65: 54 | I65: 13 | J65: 4.6 | K65: https://amazon.com/dp/B0DFLWDPK2 | L65: =HYPERLINK(K65) -> https://amazon.com/dp/B0DFLWDPK2
A66: 9 | B66: B0DBLQXQ6W | C66: XTOOL IP919 PRO Scan Tool, ECU Pr0 gramming Car OBD2 Scanner with Topology Mapping, Upgrade of D9S PRO, 51+ Resets, ECU C 0ding, FCA/CAN FD/DoIP, Automotive Bidirectional Scan Tool with 3-Year Updates | D66: xtool | E66: Tablet | F66: 1601.6151 | G66: 81682.37 | H66: 51 | I66: 61 | J66: 4.5 | K66: https://amazon.com/dp/B0DBLQXQ6W | L66: =HYPERLINK(K66) -> https://amazon.com/dp/B0DBLQXQ6W
A67: 10 | B67: B0F2HNM2VH | C67: LAUNCH Scanner X431 1MM* Plus Car Tool with X-PROG3 (Valued $800), Engine/Gearbox ECU Cl**é, All-in-One Diagnostic Tool, ECU Coding as X431 PAD, 39+ Services, All-System Scan, 2-Year Update | D67: launch | E67: Tablet | F67: 1467.1006 | G67: 68953.73 | H67: 47 | I67: 36 | J67: 4 | K67: https://amazon.com/dp/B0F2HNM2VH | L67: =HYPERLINK(K67) -> https://amazon.com/dp/B0F2HNM2VH

Sheet Tablet $400-$800
A1: Tablet $400-$800 Monthly Summary
A3: ='Tablet Total'!A81 -> Tablet $400-$800
B4: Avg Price | C4: Avg Price MoM | D4: Avg Price YoY | E4: Quantity/Mo | F4: Qty by % | G4: Qty MoM | H4: Qty YoY | I4: Revenue/Mo | J4: Revenue by % | L4: Revenue MoM | M4: Revenue YoY
A5: ='Tablet Total'!A83 -> autel | B5: ='Tablet Total'!B83 -> 528.17359 | C5: ='Tablet Total'!C83 -> 0.0017846352 | D5: ='Tablet Total'!D83 -> 0.00038571678 | E5: ='Tablet Total'!E83 -> 4587 | F5: ='Tablet Total'!F83 -> 0.42495831 | G5: ='Tablet Total'!G83 -> 0.083372697 | H5: ='Tablet Total'!H83 -> 0.27700445 | ... J5: ='Tablet Total'!J83 -> 0.42568554 | L5: ='Tablet Total'!L83 -> 0.085306122 | M5: ='Tablet Total'!M83 -> 0.27749702
A6: ='Tablet Total'!A84 -> thinkcar | B6: ='Tablet Total'!B84 -> 491.03136 | C6: ='Tablet Total'!C84 -> -0.10993403 | D6: ='Tablet Total'!D84 -> 0.088471286 | E6: ='Tablet Total'!E84 -> 1289 | F6: ='Tablet Total'!F84 -> 0.1194182 | G6: ='Tablet Total'!G84 -> 0.13969938 | H6: ='Tablet Total'!H84 -> 21.614035 | ... J6: ='Tablet Total'!J84 -> 0.11121046 | L6: ='Tablet Total'!L84 -> 0.014407634 | M6: ='Tablet Total'!M84 -> 23.614728
A7: ='Tablet Total'!A85 -> launch | B7: ='Tablet Total'!B85 -> 519.47139 | C7: ='Tablet Total'!C85 -> -0.056736789 | D7: ='Tablet Total'!D85 -> -0.12619994 | E7: ='Tablet Total'!E85 -> 1163 | F7: ='Tablet Total'!F85 -> 0.10774504 | G7: ='Tablet Total'!G85 -> -0.18784916 | H7: ='Tablet Total'!H85 -> 0.17831814 | ... J7: ='Tablet Total'!J85 -> 0.10615118 | L7: ='Tablet Total'!L85 -> -0.23392799 | M7: ='Tablet Total'!M85 -> 0.029614461
A8: ='Tablet Total'!A86 -> xtool | B8: ='Tablet Total'!B86 -> 534.86478 | C8: ='Tablet Total'!C86 -> 0.010377328 | D8: ='Tablet Total'!D86 -> -0.0088714545 | E8: ='Tablet Total'!E86 -> 1093 | F8: ='Tablet Total'!F86 -> 0.10125996 | G8: ='Tablet Total'!G86 -> 0.13146998 | H8: ='Tablet Total'!H86 -> 0.35776398 | ... J8: ='Tablet Total'!J86 -> 0.10271826 | L8: ='Tablet Total'!L86 -> 0.14321161 | M8: ='Tablet Total'!M86 -> 0.34571863
A9: ='Tablet Total'!A87 -> topdon | B9: ='Tablet Total'!B87 -> 530.79979 | C9: ='Tablet Total'!C87 -> 0.17806903 | D9: ='Tablet Total'!D87 -> 0.15606933 | E9: ='Tablet Total'!E87 -> 913 | F9: ='Tablet Total'!F87 -> 0.084584028 | G9: ='Tablet Total'!G87 -> -0.52718799 | H9: ='Tablet Total'!H87 -> -0.29661017 | ... J9: ='Tablet Total'!J87 -> 0.085150069 | L9: ='Tablet Total'!L87 -> -0.44299481 | M9: ='Tablet Total'!M87 -> -0.18683259
A10: ='Tablet Total'!A88 -> Other | B10: ='Tablet Total'!B88 -> 550.21253 | C10: ='Tablet Total'!C88 -> -0.022193195 | D10: ='Tablet Total'!D88 -> 0.041104512 | E10: ='Tablet Total'!E88 -> 1749 | F10: ='Tablet Total'!F88 -> 0.16203446 | G10: ='Tablet Total'!G88 -> 0.26464208 | H10: ='Tablet Total'!H88 -> 0.57425743 | ... J10: ='Tablet Total'!J88 -> 0.16908449 | L10: ='Tablet Total'!L88 -> 0.23657563 | M10: ='Tablet Total'!M88 -> 0.63896651
A11: ='Tablet Total'!A89 -> Total | B11: ='Tablet Total'!B89 -> 527.27126 | C11: ='Tablet Total'!C89 -> 0.0062141033 | D11: ='Tablet Total'!D89 -> 0.003051364 | E11: ='Tablet Total'!E89 -> 10794 | F11: ='Tablet Total'!F89 -> 1 | G11: ='Tablet Total'!G89 -> -0.025548434 | H11: ='Tablet Total'!H89 -> 0.37503185 | ... J11: ='Tablet Total'!J89 -> 1 | L11: ='Tablet Total'!L89 -> -0.019493091 | M11: ='Tablet Total'!M89 -> 0.37922757
A43: Rank By Monthly Revenue - Nov '25 ONLY
A44: Ranking | B44: ASIN | C44: Product Name | D44: Brand | E44: Type | F44: Price | G44: Est. Monthly Retail Rev | H44: Est. Monthly Units Sold | I44: # of Reviews | J44: Avg. Rating | K44: Column2 | L44: Link
A45: 1 | B45: B0744B55QV | C45: Autel Scanner MaxiCOM MK808S: 2025 Bidirectional Tool as MK808BT Pro MX808S M808Z, Work as MaxiCheck MX900 MK900BT, 28+ Service, Active Test, All System Diagnose, Injector C0ding, FCA Autoauth OS 11 | D45: autel | E45: Tablet | F45: 451.83728 | G45: 684985.31 | H45: 1516 | I45: 3604 | J45: 4.5 | K45: https://amazon.com/dp/B0744B55QV | L45: =HYPERLINK(K45) -> https://amazon.com/dp/B0744B55QV
A46: 2 | B46: B098PYB8XG | C46: Autel Scanner MaxiCOM MK900BT, 2025 MK900-BT V2.0 Bidirectional Diagnostic Tool, 8in Up of MK900 MX900 MK808S MK808BT MX808S MK808Z, 3000+ Active Tests, 40+ Service, CAN-FD&DOIP, All System, FCA 11 OS | D46: autel | E46: Tablet | F46: 659.22073 | G46: 479912.69 | H46: 728 | I46: 580 | J46: 4.6 | K46: https://amazon.com/dp/B098PYB8XG | L46: =HYPERLINK(K46) -> https://amazon.com/dp/B098PYB8XG
A47: 3 | B47: B0DCFRF2TF | C47: THINKCAR Bidirectional Scan Tool, THINKSCAN 689BT All System Automotive Diagnostic Tool, Bi Directional OBD2 Scanner with ECU Coding, 34 Services, FCA Autoauth, CANFD and DoIP, Wireless Update | D47: thinkcar | E47: Tablet | F47: 501.58996 | G47: 393748.12 | H47: 785 | I47: 401 | J47: 4.4 | K47: https://amazon.com/dp/B0DCFRF2TF | L47: =HYPERLINK(K47) -> https://amazon.com/dp/B0DCFRF2TF
A48: 4 | B48: B0DTK24XKB | C48: MUCAR 892BT AI-Assisted Bidirectional Scan Tool, Full System OBD2 Scanner, Bi-Directional OBD2 Scanner Diagnostic Tool,ECU Coding, 35 Services, FCA Autoauth, CANFD and DOIP, Free Lifetime Upgrade | D48: mucar | E48: Tablet | F48: 612.13041 | G48: 385030.03 | H48: 629 | I48: 249 | J48: 4.3 | K48: https://amazon.com/dp/B0DTK24XKB | L48: =HYPERLINK(K48) -> https://amazon.com/dp/B0DTK24XKB
A49: 5 | B49: B0BNKHCXVC | C49: TOPDON ArtiDiag Pro OBD2 Scanner Diagnostic Tool, Bidirectional Scan Tool with ECU Coding, 35+ Services, V.A.G Guided, FCA SGW, Can FD DoIP/All System Diagnosis | D49: topdon | E49: Tablet | F49: 478.70164 | G49: 321687.5 | H49: 672 | I49: 677 | J49: 4.4 | K49: https://amazon.com/dp/B0BNKHCXVC | L49: =HYPERLINK(K49) -> https://amazon.com/dp/B0BNKHCXVC
A50: 6 | B50: B08ML7T7KZ | C50: Autel Scanner MaxiCheck MX808S, 2025 US Ver. of MaxiCOM MK808S/ MK808Z, Bidirectional 11OS as MX900 MK900 MK900BT, 3000+ Active Test, 28+ Service, OE All System OBDII Diagnostic Tool, FCA Autoauth | D50: autel | E50: Tablet | F50: 443.71323 | G50: 287526.17 | H50: 648 | I50: 643 | J50: 4.7 | K50: https://amazon.com/dp/B08ML7T7KZ | L50: =HYPERLINK(K50) -> https://amazon.com/dp/B08ML7T7KZ
A51: 7 | B51: B0DCFF7VGF | C51: THINKCAR THINKSCAN 689 OBD2 Scanner, Bidirectional Scan Tool with Lifetime Free Update, 34+ Reset, 3000+ Active Test, ECU Coding, PMI, All System Diagnostic Scanner for Cars, CANFD & DOIP, FCA SGW | D51: thinkcar | E51: Tablet | F51: 475.76669 | G51: 234077.21 | H51: 492 | I51: 181 | J51: 4.4 | K51: https://amazon.com/dp/B0DCFF7VGF | L51: =HYPERLINK(K51) -> https://amazon.com/dp/B0DCFF7VGF
A52: 8 | B52: B073CQMF25 | C52: Autel Scanner MaxiCOM MK900: 2025 Same as MK900BT MK900-BT MX900 Bidirectional Diagnostic Tool, 8in Up of MK808S MK808BT Pro MX808S MK808Z, 3K+ Active Tests, 40+ Service, CAN-FD&DOIP, All System, FCA | D52: autel | E52: Tablet | F52: 546.5021 | G52: 159032.11 | H52: 291 | I52: 265 | J52: 4.4 | K52: https://amazon.com/dp/B073CQMF25 | L52: =HYPERLINK(K52) -> https://amazon.com/dp/B073CQMF25
A53: 9 | B53: B07MBSZH48 | C53: Autel Scanner MaxiCOM MK808BT PRO, 2025 2.0 Full Bidirectional Diagnostic Tool as MK900 MX900 MK900BT, Pro Ver. of MK808S MX808S, 3000+ Test, 28+ Service, All System, Brake Bleed, Injector Coding, FCA | D53: autel | E53: Tablet | F53: 512.48232 | G53: 154769.66 | H53: 302 | I53: 1750 | J53: 4.6 | K53: https://amazon.com/dp/B07MBSZH48 | L53: =HYPERLINK(K53) -> https://amazon.com/dp/B07MBSZH48
A54: 10 | B54: B09712X5CW | C54: Autel Scanner MaxiCOM MK900BT, 2025 MK900-BT Bidirectional Diagnostic Scan Tool, 2.0 BT Ver. of MK900 MX900, 8in Up of MK808S MK808BT PRO MX808S MK808Z, 40+ Reset, 3K+ Active Tests, CAN FD & DoIP, FCA | D54: autel | E54: Tablet | F54: 659.10106 | G54: 112047.18 | H54: 170 | I54: 165 | J54: 4.6 | K54: https://amazon.com/dp/B09712X5CW | L54: =HYPERLINK(K54) -> https://amazon.com/dp/B09712X5CW
A56: Rank By Monthly Units - Nov '25 ONLY
A57: Ranking | B57: ASIN | C57: Product Name | D57: Brand | E57: Type | F57: Price | G57: Est. Monthly Retail Rev | H57: Est. Monthly Units Sold | I57: # of Reviews | J57: Avg. Rating | K57: Column2 | L57: Link
A58: 1 | B58: B0744B55QV | C58: Autel Scanner MaxiCOM MK808S: 2025 Bidirectional Tool as MK808BT Pro MX808S M808Z, Work as MaxiCheck MX900 MK900BT, 28+ Service, Active Test, All System Diagnose, Injector C0ding, FCA Autoauth OS 11 | D58: autel | E58: Tablet | F58: 451.83728 | G58: 684985.31 | H58: 1516 | I58: 3604 | J58: 4.5 | K58: https://amazon.com/dp/B0744B55QV | L58: =HYPERLINK(K58) -> https://amazon.com/dp/B0744B55QV
A59: 2 | B59: B0DCFRF2TF | C59: THINKCAR Bidirectional Scan Tool, THINKSCAN 689BT All System Automotive Diagnostic Tool, Bi Directional OBD2 Scanner with ECU Coding, 34 Services, FCA Autoauth, CANFD and DoIP, Wireless Update | D59: thinkcar | E59: Tablet | F59: 501.58996 | G59: 393748.12 | H59: 785 | I59: 401 | J59: 4.4 | K59: https://amazon.com/dp/B0DCFRF2TF | L59: =HYPERLINK(K59) -> https://amazon.com/dp/B0DCFRF2TF
A60: 3 | B60: B098PYB8XG | C60: Autel Scanner MaxiCOM MK900BT, 2025 MK900-BT V2.0 Bidirectional Diagnostic Tool, 8in Up of MK900 MX900 MK808S MK808BT MX808S MK808Z, 3000+ Active Tests, 40+ Service, CAN-FD&DOIP, All System, FCA 11 OS | D60: autel | E60: Tablet | F60: 659.22073 | G60: 479912.69 | H60: 728 | I60: 580 | J60: 4.6 | K60: https://amazon.com/dp/B098PYB8XG | L60: =HYPERLINK(K60) -> https://amazon.com/dp/B098PYB8XG
A61: 4 | B61: B0BNKHCXVC | C61: TOPDON ArtiDiag Pro OBD2 Scanner Diagnostic Tool, Bidirectional Scan Tool with ECU Coding, 35+ Services, V.A.G Guided, FCA SGW, Can FD DoIP/All System Diagnosis | D61: topdon | E61: Tablet | F61: 478.70164 | G61: 321687.5 | H61: 672 | I61: 677 | J61: 4.4 | K61: https://amazon.com/dp/B0BNKHCXVC | L61: =HYPERLINK(K61) -> https://amazon.com/dp/B0BNKHCXVC
A62: 5 | B62: B08ML7T7KZ | C62: Autel Scanner MaxiCheck MX808S, 2025 US Ver. of MaxiCOM MK808S/ MK808Z, Bidirectional 11OS as MX900 MK900 MK900BT, 3000+ Active Test, 28+ Service, OE All System OBDII Diagnostic Tool, FCA Autoauth | D62: autel | E62: Tablet | F62: 443.71323 | G62: 287526.17 | H62: 648 | I62: 643 | J62: 4.7 | K62: https://amazon.com/dp/B08ML7T7KZ | L62: =HYPERLINK(K62) -> https://amazon.com/dp/B08ML7T7KZ
A63: 6 | B63: B0DTK24XKB | C63: MUCAR 892BT AI-Assisted Bidirectional Scan Tool, Full System OBD2 Scanner, Bi-Directional OBD2 Scanner Diagnostic Tool,ECU Coding, 35 Services, FCA Autoauth, CANFD and DOIP, Free Lifetime Upgrade | D63: mucar | E63: Tablet | F63: 612.13041 | G63: 385030.03 | H63: 629 | I63: 249 | J63: 4.3 | K63: https://amazon.com/dp/B0DTK24XKB | L63: =HYPERLINK(K63) -> https://amazon.com/dp/B0DTK24XKB
A64: 7 | B64: B0DCFF7VGF | C64: THINKCAR THINKSCAN 689 OBD2 Scanner, Bidirectional Scan Tool with Lifetime Free Update, 34+ Reset, 3000+ Active Test, ECU Coding, PMI, All System Diagnostic Scanner for Cars, CANFD & DOIP, FCA SGW | D64: thinkcar | E64: Tablet | F64: 475.76669 | G64: 234077.21 | H64: 492 | I64: 181 | J64: 4.4 | K64: https://amazon.com/dp/B0DCFF7VGF | L64: =HYPERLINK(K64) -> https://amazon.com/dp/B0DCFF7VGF
A65: 8 | B65: B07MBSZH48 | C65: Autel Scanner MaxiCOM MK808BT PRO, 2025 2.0 Full Bidirectional Diagnostic Tool as MK900 MX900 MK900BT, Pro Ver. of MK808S MX808S, 3000+ Test, 28+ Service, All System, Brake Bleed, Injector Coding, FCA | D65: autel | E65: Tablet | F65: 512.48232 | G65: 154769.66 | H65: 302 | I65: 1750 | J65: 4.6 | K65: https://amazon.com/dp/B07MBSZH48 | L65: =HYPERLINK(K65) -> https://amazon.com/dp/B07MBSZH48
A66: 9 | B66: B073CQMF25 | C66: Autel Scanner MaxiCOM MK900: 2025 Same as MK900BT MK900-BT MX900 Bidirectional Diagnostic Tool, 8in Up of MK808S MK808BT Pro MX808S MK808Z, 3K+ Active Tests, 40+ Service, CAN-FD&DOIP, All System, FCA | D66: autel | E66: Tablet | F66: 546.5021 | G66: 159032.11 | H66: 291 | I66: 265 | J66: 4.4 | K66: https://amazon.com/dp/B073CQMF25 | L66: =HYPERLINK(K66) -> https://amazon.com/dp/B073CQMF25
A67: 10 | B67: B0CJDTPDPB | C67: LAUNCH X431 CRP919XBT OBD2 Scanner, 2025 Wireless Bidirectional Scan Tool with DBSCar VII Connector, ECU Coding, FCA AutoAuth, 2-Year Free Update, V.A.G Guide, 35+ Services, All Systems, CANFD | D67: launch | E67: Tablet | F67: 483.21842 | G67: 88428.97 | H67: 183 | I67: 283 | J67: 4.5 | K67: https://amazon.com/dp/B0CJDTPDPB | L67: =HYPERLINK(K67) -> https://amazon.com/dp/B0CJDTPDPB

Sheet Tablet $400-
A1: Tablet $400- Monthly Summary
A3: ='Tablet Total'!A91 -> Tablet $400-
B4: Avg Price | C4: Avg Price MoM | D4: Avg Price YoY | E4: Quantity/Mo | F4: Qty by % | G4: Qty MoM | H4: Qty YoY | I4: Revenue/Mo | J4: Revenue by % | L4: Revenue MoM | M4: Revenue YoY
A5: ='Tablet Total'!A93 -> topdon | B5: ='Tablet Total'!B93 -> 244.1978 | C5: ='Tablet Total'!C93 -> 0.0779894 | D5: ='Tablet Total'!D93 -> 0.30764591 | E5: ='Tablet Total'!E93 -> 8427 | F5: ='Tablet Total'!F93 -> 0.32512828 | G5: ='Tablet Total'!G93 -> 0.43633884 | H5: ='Tablet Total'!H93 -> 2.0400433 | ... J5: ='Tablet Total'!J93 -> 0.36084256 | L5: ='Tablet Total'!L93 -> 0.54835805 | M5: ='Tablet Total'!M93 -> 2.9753002
A6: ='Tablet Total'!A94 -> launch | B6: ='Tablet Total'!B94 -> 182.54601 | C6: ='Tablet Total'!C94 -> 0.012500387 | D6: ='Tablet Total'!D94 -> -0.084952687 | E6: ='Tablet Total'!E94 -> 4565 | F6: ='Tablet Total'!F94 -> 0.17612562 | G6: ='Tablet Total'!G94 -> 0.094986807 | H6: ='Tablet Total'!H94 -> 0.28918385 | ... J6: ='Tablet Total'!J94 -> 0.14612218 | L6: ='Tablet Total'!L94 -> 0.10867457 | M6: ='Tablet Total'!M94 -> 0.17966421
A7: ='Tablet Total'!A95 -> foxwell | B7: ='Tablet Total'!B95 -> 191.86211 | C7: ='Tablet Total'!C95 -> -0.057409781 | D7: ='Tablet Total'!D95 -> -0.069300025 | E7: ='Tablet Total'!E95 -> 2973 | F7: ='Tablet Total'!F95 -> 0.1147035 | G7: ='Tablet Total'!G95 -> 0.049788136 | H7: ='Tablet Total'!H95 -> -0.063916877 | ... J7: ='Tablet Total'!J95 -> 0.10002007 | L7: ='Tablet Total'!L95 -> -0.010479971 | M7: ='Tablet Total'!M95 -> -0.12878746
A8: ='Tablet Total'!A96 -> xtool | B8: ='Tablet Total'!B96 -> 246.50199 | C8: ='Tablet Total'!C96 -> -0.019666903 | D8: ='Tablet Total'!D96 -> -0.28862292 | E8: ='Tablet Total'!E96 -> 2033 | F8: ='Tablet Total'!F96 -> 0.078436668 | G8: ='Tablet Total'!G96 -> 0.018537074 | H8: ='Tablet Total'!H96 -> 1.7325269 | ... J8: ='Tablet Total'!J96 -> 0.087874086 | L8: ='Tablet Total'!L96 -> -0.0014943955 | M8: ='Tablet Total'!M96 -> 0.94385699
A9: ='Tablet Total'!A97 -> blcktec | B9: ='Tablet Total'!B97 -> 198.0568 | C9: ='Tablet Total'!C97 -> 0.018644659 | D9: ='Tablet Total'!D97 -> 0 | E9: ='Tablet Total'!E97 -> 2032 | F9: ='Tablet Total'!F97 -> 0.078398086 | G9: ='Tablet Total'!G97 -> 0.41209173 | H9: ='Tablet Total'!H97 -> 0 | ... J9: ='Tablet Total'!J97 -> 0.070569409 | L9: ='Tablet Total'!L97 -> 0.4384197 | M9: ='Tablet Total'!M97 -> 0
A10: ='Tablet Total'!A98 -> innova | B10: ='Tablet Total'!B98 -> 137.95047 | C10: ='Tablet Total'!C98 -> -0.034313523 | D10: ='Tablet Total'!D98 -> 0 | E10: ='Tablet Total'!E98 -> 1336 | F10: ='Tablet Total'!F98 -> 0.051545199 | G10: ='Tablet Total'!G98 -> 0.91404011 | H10: ='Tablet Total'!H98 -> 0 | ... J10: ='Tablet Total'!J98 -> 0.032317121 | L10: ='Tablet Total'!L98 -> 0.84836266 | M10: ='Tablet Total'!M98 -> 0
A11: ='Tablet Total'!A99 -> Other | B11: ='Tablet Total'!B99 -> 253.33645 | C11: ='Tablet Total'!C99 -> 0.027722874 | D11: ='Tablet Total'!D99 -> 0.22342632 | E11: ='Tablet Total'!E99 -> 4553 | F11: ='Tablet Total'!F99 -> 0.17566264 | G11: ='Tablet Total'!G99 -> -0.0067626527 | H11: ='Tablet Total'!H99 -> 0.11511144 | ... J11: ='Tablet Total'!J99 -> 0.20225457 | L11: ='Tablet Total'!L99 -> 0.020772741 | M11: ='Tablet Total'!M99 -> 0.36425669
A13: ='Tablet Total'!A100 -> Total | B13: ='Tablet Total'!B100 -> 220.0284 | C13: ='Tablet Total'!C100 -> 0.017310952 | D13: ='Tablet Total'!D100 -> 0.017310952 | E13: ='Tablet Total'!E100 -> 25919 | F13: ='Tablet Total'!F100 -> 1 | G13: ='Tablet Total'!G100 -> 0.20078758 | H13: ='Tablet Total'!H100 -> 0.81049176 | ... J13: ='Tablet Total'!J100 -> 1 | L13: ='Tablet Total'!L100 -> 0.22157436 | M13: ='Tablet Total'!M100 -> 0.91240071
A45: Rank By Monthly Revenue - Nov '25 ONLY
A46: Ranking | B46: ASIN | C46: Product Name | D46: Brand | E46: Type | F46: Price | G46: Est. Monthly Retail Rev | H46: Est. Monthly Units Sold | I46: # of Reviews | J46: Avg. Rating | K46: Column2 | L46: Link
A47: 1 | B47: B0C33Y285Y | C47: TOPDON Bidirectional Scan Tool, 2025 New ArtiDiag900 Lite Automotive Diagnostic Tool for Full System, Scanner for Car with Active Test, 8 Reset, Wireless OBD2 Scanner Diagnostic Tool for All Vehicles | D47: topdon | E47: Tablet | F47: 313.53909 | G47: 520788.43 | H47: 1661 | I47: 999 | J47: 4.3 | K47: https://amazon.com/dp/B0C33Y285Y | L47: =HYPERLINK(K47) -> https://amazon.com/dp/B0C33Y285Y
A48: 2 | B48: B0DV2N2FND | C48: BLCKTEC 460T OBD2 Scanner Car Code Reader Engine ABS SRS Transmission Diagnostic Tool, 12 Reset Services, Oil/TPMS/EPB/BMS/SAS/DPF/Throttle Reset, ABS Bleeding, Battery Test, Auto VIN, Free Update | D48: blcktec | E48: Tablet | F48: 198.0568 | G48: 402451.42 | H48: 2032 | I48: 312 | J48: 4.4 | K48: https://amazon.com/dp/B0DV2N2FND | L48: =HYPERLINK(K48) -> https://amazon.com/dp/B0DV2N2FND
A49: 3 | B49: B08XK3DJ42 | C49: OBD2 Scanner TOPDON AD500, Oil SAS Throttle TPMS BMS EPB Reset, Engine ABS SRS Transmission, Diagnostic Scan Tool, AutoVIN, Car Check Engine Code Reader with Battery Test, Lifetime Wi-Fi Free Update | D49: topdon | E49: Tablet | F49: 149.94128 | G49: 315626.4 | H49: 2105 | I49: 1431 | J49: 4.4 | K49: https://amazon.com/dp/B08XK3DJ42 | L49: =HYPERLINK(K49) -> https://amazon.com/dp/B08XK3DJ42
A50: 4 | B50: B08TR5PS5V | C50: TOPDON AD800BT 2 OBD2 Scanner, 2025 Bidirectional Scan Tool, Function as AD900 Lite AD Pro, All System Automotive Diagnostic Scanner, Active Test, 28+ Reset Service, FCA Autoauth, 2 Years Free Update | D50: topdon | E50: Tablet | F50: 390.68245 | G50: 300044.12 | H50: 768 | I50: 728 | J50: 4.3 | K50: https://amazon.com/dp/B08TR5PS5V | L50: =HYPERLINK(K50) -> https://amazon.com/dp/B08TR5PS5V
