Workbook

Sheet Summary
A1: Monthly Summaries- Revenue
A2: Brand | B2: # of Listings | C2: Monthly Rev | D2: Estimated 12mo Revenue | E2: Monthly Units | F2: Monthly Rev Market Share % | G2: Price Per Unit | H2: Reviews | I2: Avg Rating
A3: topdon | B3: 2 | C3: 500691.66 | D3: 6008299.9 | E3: 1038 | F3: 0.17401572 | G3: 482.36191 | H3: 348 | I3: 4.4
A4: rix | B4: 3 | C4: 385302.43 | D4: 4623629.2 | E4: 378 | F4: 0.13391211 | G4: 1019.3186 | H4: 86 | I4: 4.6418605
A5: terunsoul | B5: 2 | C5: 380930.95 | D5: 4571171.4 | E5: 3710 | F5: 0.1323928 | G5: 102.67681 | H5: 476 | I5: 4.6
A6: goyojo | B6: 19 | C6: 311030.43 | D6: 3732365.2 | E6: 788 | F6: 0.10809883 | G6: 394.70867 | H6: 1927 | I6: 4.265698
A7: pulsar | B7: 14 | C7: 278454.58 | D7: 3341455 | E7: 150 | F7: 0.096777072 | G7: 1856.3639 | H7: 222 | I7: 4.409009
A8: agm global vision | B8: 25 | C8: 153146.12 | D8: 1837753.4 | E8: 145 | F8: 0.053226035 | G8: 1056.1801 | H8: 1845 | I8: 4.2938753
A9: hotpeak | B9: 3 | C9: 124542.8 | D9: 1494513.6 | E9: 1266 | F9: 0.043284932 | G9: 98.375039 | H9: 812 | I9: 4.4
A10: armasight | B10: 8 | C10: 90346.29 | D10: 1084155.5 | E10: 46 | F10: 0.031399912 | G10: 1964.0498 | H10: 44 | I10: 3.7068182
A11: yuanzimoo | B11: 3 | C11: 80425.52 | D11: 965106.24 | E11: 1157 | F11: 0.027951942 | G11: 69.512118 | H11: 976 | I11: 4
A12: bushnell | B12: 4 | C12: 58955.24 | D12: 707462.88 | E12: 323 | F12: 0.020489932 | G12: 182.52396 | H12: 2111 | I12: 3.8232591
A14: Market Total | B14: 413 | C14: 2877278.4 | D14: 34527341 | E14: 11436 | F14: 1 | G14: 251.59832 | H14: 16952 | I14: 4.0836597
A16: Monthly Summary - Units
A17: Brand | B17: # of Listings | C17: Monthly Rev | D17: Estimated 12mo Units | E17: Monthly Units | F17: Monthly Unit Market Share % | G17: Price Per Unit | H17: Reviews | I17: Avg Rating
A18: terunsoul | B18: 2 | C18: 380930.95 | D18: 44520 | E18: 3710 | F18: 0.32441413 | G18: 102.67681 | H18: 476 | I18: 4.6
A19: hotpeak | B19: 3 | C19: 124542.8 | D19: 15192 | E19: 1266 | F19: 0.11070304 | G19: 98.375039 | H19: 812 | I19: 4.4
A20: yuanzimoo | B20: 3 | C20: 80425.52 | D20: 13884 | E20: 1157 | F20: 0.10117174 | G20: 69.512118 | H20: 976 | I20: 4
A21: topdon | B21: 2 | C21: 500691.66 | D21: 12456 | E21: 1038 | F21: 0.090766002 | G21: 482.36191 | H21: 348 | I21: 4.4
A22: gipsot | B22: 1 | C22: 56678.34 | D22: 9852 | E22: 821 | F22: 0.071790836 | G22: 69.035737 | H22: 129 | I22: 4.5
A23: goyojo | B23: 19 | C23: 311030.43 | D23: 9456 | E23: 788 | F23: 0.068905212 | G23: 394.70867 | H23: 1927 | I23: 4.265698
A24: rix | B24: 3 | C24: 385302.43 | D24: 4536 | E24: 378 | F24: 0.033053515 | G24: 1019.3186 | H24: 86 | I24: 4.6418605
A25: bushnell | B25: 4 | C25: 58955.24 | D25: 3876 | E25: 323 | F25: 0.028244141 | G25: 182.52396 | H25: 2111 | I25: 3.8232591
A26: kolinlov | B26: 5 | C26: 17263.89 | D26: 2136 | E26: 178 | F26: 0.015564883 | G26: 96.988146 | H26: 136 | I26: 3.5779412
A27: pulsar | B27: 14 | C27: 278454.58 | D27: 1800 | E27: 150 | F27: 0.013116474 | G27: 1856.3639 | H27: 222 | I27: 4.409009
A29: Market Total | B29: 413 | C29: 2877278.4 | D29: 137232 | E29: 11436 | F29: 1 | G29: 251.59832 | H29: 16952 | I29: 4.0836597

Sheet Top 50
A1: Rank By Monthly Revenue - ONLY
A2: Ranking | B2: ASIN | C2: Product Name | D2: Brand | E2: Type | F2: 2/4-way | G2: Display | H2: Lens diameter | I2: Lens count | J2: Cable length | K2: Price | L2: Est. Monthly Retail Rev | M2: Est. Monthly Units Sold | N2: # of Reviews | O2: Avg. Rating | P2: Column2 | Q2: Link
A3: 1 | B3: B0D56CNCW1 | C3: TOPDON TS004 Thermal Imaging Monocular, 320 x 240 TISR 256 x 192 IR Resolution, Supported Wireless Connection, 13mm 50Hz Thermal Night Vision with 11h Battery Life, IP67 Monocular for Hunting | D3: topdon | E3: - | K3: 406.6 | L3: 390473.49 | M3: 915 | N3: 172 | O3: 4.4 | P3: https://amazon.com/dp/B0D56CNCW1 | Q3: =HYPERLINK(P3) -> https://amazon.com/dp/B0D56CNCW1
A4: 2 | B4: B0FMDQK4S8 | C4: Night Vision Goggles - Smart APP 4K Night Vision Binoculars, 10000mAh Battery, 128GB Card for Photo and Video, 3'' UHD Screen & 8X Zoom Binoculars for Camping, Hunting, Security (Black) | D4: terunsoul | E4: - | K4: 99.98 | L4: 321020.94 | M4: 3211 | N4: 238 | O4: 4.6 | P4: https://amazon.com/dp/B0FMDQK4S8 | Q4: =HYPERLINK(P4) -> https://amazon.com/dp/B0FMDQK4S8
A5: 3 | B5: B0D5QXY5JN | C5: RIX Pocket K3 Portable Thermal Monocular for Hunting, 384x288 (50Hz), Wi-Fi, Handheld Night Vision Monocular | D5: rix | E5: - | K5: 899 | L5: 306407.5 | M5: 346 | N5: 77 | O5: 4.6 | P5: https://amazon.com/dp/B0D5QXY5JN | Q5: =HYPERLINK(P5) -> https://amazon.com/dp/B0D5QXY5JN
A6: 4 | B6: B0CNXP8JBV | C6: GOYOJO Thermal Monocular, 256x192 (25 Hz) Thermal Imaging Monoscope Camera for Adults, 10mm Focal Lens Vision Goggles Thermal Scopes for Night Hunting Camping | D6: goyojo | E6: - | K6: 369 | L6: 116832.27 | M6: 317 | N6: 251 | O6: 4.3 | P6: https://amazon.com/dp/B0CNXP8JBV | Q6: =HYPERLINK(P6) -> https://amazon.com/dp/B0CNXP8JBV
A7: 5 | B7: B0FW4H9MXB | C7: TOPDON TS004 Pro Thermal Imaging Monocular, 512 x 384 TISR 384 x 288 IR Resolution, Supported Wireless Connection, 19mm 50Hz Thermal Night Vision with 11h Battery Life, IP67 Monocular for Hunting | D7: topdon | E7: - | K7: 899 | L7: 110218.17 | M7: 123 | N7: 176 | O7: 4.4 | P7: https://amazon.com/dp/B0FW4H9MXB | Q7: =HYPERLINK(P7) -> https://amazon.com/dp/B0FW4H9MXB
A8: 6 | B8: B0CNXPDG7R | C8: GOYOJO Thermal Imaging Monocular for Hunting, 15mm Focal Lens 256x192 Infrared Night Vision Telescope with Long Battery Life, Thermal Scopes for Outdoor Night Vision Camera Telescope (15mm) | D8: goyojo | E8: - | K8: 404.1 | L8: 105720.5 | M8: 262 | N8: 251 | O8: 4.3 | P8: https://amazon.com/dp/B0CNXPDG7R | Q8: =HYPERLINK(P8) -> https://amazon.com/dp/B0CNXPDG7R
A9: 7 | B9: B0F5WCSL4H | C9: Night Vision Goggles, 112 MP 4K Night Vision Binoculars for Adults, 12X Zoom & 5000mAh Battery, 64GB Card Included, Infrared Night Vision, 1500ft View Range, Perfect for Hunting, Camping & Security | D9: hotpeak | E9: - | K9: 89.99 | L9: 75319.79 | M9: 809 | N9: 242 | O9: 4.4 | P9: https://amazon.com/dp/B0F5WCSL4H | Q9: =HYPERLINK(P9) -> https://amazon.com/dp/B0F5WCSL4H
A10: 8 | B10: B0DZNNGH3P | C10: RIX Titan-T6 Thermal Monocular LRF 35mm 640x480 Thermal Imaging Monocular with Laser Rangefinder (50 Hz) 1920×1080 OLED Display Ideal for Night Hunting, Safety Level-Class I, Power Output＜1mW | D10: rix | E10: - | K10: 2399 | L10: 68090.31 | M10: 28 | N10: 3 | O10: 5 | P10: https://amazon.com/dp/B0DZNNGH3P | Q10: =HYPERLINK(P10) -> https://amazon.com/dp/B0DZNNGH3P
A11: 9 | B11: B0FMDJC7VB | C11: Night Vision Goggles - Smart APP 4K Night Vision Binoculars, 10000mAh Battery, 128GB Card Included, 3'' UHD Screen & 8X Zoom Binoculars, 2000FT Range Goggles for Camping, Hunting, Security (Silver) | D11: terunsoul | E11: - | K11: 99.98 | L11: 59910.01 | M11: 499 | N11: 238 | O11: 4.6 | P11: https://amazon.com/dp/B0FMDJC7VB | Q11: =HYPERLINK(P11) -> https://amazon.com/dp/B0FMDJC7VB
A12: 10 | B12: B0FNM6ZFGG | C12: 4K Night Vision Goggles, 4.0" HD Screen Night Vision Binoculars with 5000mAh Rechargeable Battery, 64GB TF Card for Photo & Video, Infrared Binocular for Adults, Camping, Wildlife Observation | D12: gipsot | E12: - | K12: 89.99 | L12: 56678.34 | M12: 821 | N12: 129 | O12: 4.5 | P12: https://amazon.com/dp/B0FNM6ZFGG | Q12: =HYPERLINK(P12) -> https://amazon.com/dp/B0FNM6ZFGG
A13: 11 | B13: B0DW3ZPC1N | C13: MiLESEEY TNV10 PRO 320x240 IR Resolution Thermal Monocular, 13mm 50Hz Aircraft Mg-Al Alloy Handheld Thermal Camera, Night Vision Imager, Hot Spot Tracking | D13: mileseey | E13: - | K13: 399.99 | L13: 54148.36 | M13: 135 | N13: 151 | O13: 4.1 | P13: https://amazon.com/dp/B0DW3ZPC1N | Q13: =HYPERLINK(P13) -> https://amazon.com/dp/B0DW3ZPC1N
A14: 12 | B14: B0C37XZWZJ | C14: Pulsar Axion 2 LRF XQ35 Pro Thermal Monocular with Laser Range Finder | D14: pulsar | E14: - | K14: 1859.99 | L14: 49246.81 | M14: 26 | N14: 39 | O14: 4.3 | P14: https://amazon.com/dp/B0C37XZWZJ | Q14: =HYPERLINK(P14) -> https://amazon.com/dp/B0C37XZWZJ
... A43: 41 | B43: B09LWY7717 | C43: AGM Global Vision Fuzion LRF TM35-384 Fusion Thermal Imaging & CMOS Monocular with Laser Range Finder, 12 Micron 384x288 (50 Hz), 35 mm Lens, Black | D43: agm global vision | E43: - | K43: 1599 | L43: 12427.62 | M43: 8 | N43: 28 | O43: 4.4 | P43: https://amazon.com/dp/B09LWY7717 | Q43: =HYPERLINK(P43) -> https://amazon.com/dp/B09LWY7717
A44: 42 | B44: B0FTG8VLSM | C44: SIG SAUER Echo MV50-LRF 3-24x50mm Thermal Monocular with 1000-Yard Laser Rangefinder - High-Sensitivity IP67 Waterproof Nighttime Hunting Monocular - Photo & Video Capture, App Control (SOEC42310) | D44: sig sauer | E44: - | K44: 3299.99 | L44: 12207.96 | M44: 4 | P44: https://amazon.com/dp/B0FTG8VLSM | Q44: =HYPERLINK(P44) -> https://amazon.com/dp/B0FTG8VLSM
A45: 43 | B45: B09JT1VXGG | C45: Superior Tactical White Phosphor XLSH Gen 3 PVS-14 Night Vision MonocularsI Helmet Mounted, Waterproof, Rugged & Durable Goggles I Hands- Free & Perfect for Outdoor Adventures | D45: superior tactical llc s | E45: - | K45: 3499 | L45: 11928.86 | M45: 3 | N45: 20 | O45: 4.5 | P45: https://amazon.com/dp/B09JT1VXGG | Q45: =HYPERLINK(P45) -> https://amazon.com/dp/B09JT1VXGG
A46: 44 | B46: B0DNJZB9RK | C46: ATN BlazeHunter 335 4-32x, 384x288, <18 NETD, 12 Micron, 50 Hz, Pro Thermal Imaging Monocular | D46: atn | E46: - | K46: 1595 | L46: 11167.19 | M46: 6 | N46: 18 | O46: 4 | P46: https://amazon.com/dp/B0DNJZB9RK | Q46: =HYPERLINK(P46) -> https://amazon.com/dp/B0DNJZB9RK
A47: 45 | B47: B0C4TCBPHX | C47: AGM Global Vision Sidewinder TM25-384 Thermal Imaging Monocular | D47: agm global vision | E47: - | K47: 1595 | L47: 10941.71 | M47: 7 | N47: 2 | O47: 5 | P47: https://amazon.com/dp/B0C4TCBPHX | Q47: =HYPERLINK(P47) -> https://amazon.com/dp/B0C4TCBPHX
A48: 46 | B48: B0CY16GT91 | C48: RIX Thermal Monocular Stride ST6 Thermal Imaging Monocular for Hunting 640x512 (50 Hz), Handheld Thermal Monocular for Hunters, Monocular Thermal Vision | D48: rix | E48: - | K48: 2999 | L48: 10804.62 | M48: 4 | N48: 6 | O48: 5 | P48: https://amazon.com/dp/B0CY16GT91 | Q48: =HYPERLINK(P48) -> https://amazon.com/dp/B0CY16GT91
A49: 47 | B49: B0B8M93WR8 | C49: AGM Global Vision 11P14123483121 Model PVS-14 3AL2 Night Vision Monocular, Black, Gen 3 Auto-Gated Level 2", 64-72 lp/mm Resolution, 1x Magnification, Built-in Infrared Illuminator and Flood Lens | D49: agm global vision | E49: - | K49: 4837.75 | L49: 10557.16 | M49: 2 | P49: https://amazon.com/dp/B0B8M93WR8 | Q49: =HYPERLINK(P49) -> https://amazon.com/dp/B0B8M93WR8
A50: 48 | B50: B06XGS6611 | C50: FLIR Breach PTQ136 Multi-Purpose Thermal Imaging Monocular, Black | D50: flir | E50: - | K50: 2899 | L50: 10321.83 | M50: 4 | N50: 126 | O50: 4 | P50: https://amazon.com/dp/B06XGS6611 | Q50: =HYPERLINK(P50) -> https://amazon.com/dp/B06XGS6611
A51: 49 | B51: B0D1R935KD | C51: Thermal Imaging Monocular for Hunting, 384x288(50Hz) Infrared Night Vision Telescope with Long Battery Life, 15mm Focal Lens Thermal Scopes for Outdoor Night Vision Camera Telescope | D51: goyojo | E51: - | K51: 664.99 | L51: 10135.36 | M51: 15 | N51: 52 | O51: 4.3 | P51: https://amazon.com/dp/B0D1R935KD | Q51: =HYPERLINK(P51) -> https://amazon.com/dp/B0D1R935KD
A52: 50 | B52: B0D1RB6PBJ | C52: GOYOJO Thermal Monocular Night Vision, 25mm Focal Lens Thermal Imaging Monoscope 384x288 (50 Hz) Night Vision Goggles Thermal Scopes for Hunting | D52: goyojo | E52: - | K52: 759.05 | L52: 10131.83 | M52: 13 | N52: 51 | O52: 4.3 | P52: https://amazon.com/dp/B0D1RB6PBJ | Q52: =HYPERLINK(P52) -> https://amazon.com/dp/B0D1RB6PBJ
A55: Rank By Monthly Units - ONLY
A56: Ranking | B56: ASIN | C56: Product Name | D56: Brand | E56: Type | F56: 2/4-way | G56: Display | H56: Lens diameter | I56: Lens count | J56: Cable length | K56: Price | L56: Est. Monthly Retail Rev | M56: Est. Monthly Units Sold | N56: # of Reviews | O56: Avg. Rating | P56: Column2 | Q56: Link
A57: 1 | B57: B0FMDQK4S8 | C57: Night Vision Goggles - Smart APP 4K Night Vision Binoculars, 10000mAh Battery, 128GB Card for Photo and Video, 3'' UHD Screen & 8X Zoom Binoculars for Camping, Hunting, Security (Black) | D57: terunsoul | E57: - | K57: 99.98 | L57: 321020.94 | M57: 3211 | N57: 238 | O57: 4.6 | P57: https://amazon.com/dp/B0FMDQK4S8 | Q57: =HYPERLINK(P57) -> https://amazon.com/dp/B0FMDQK4S8
A58: 2 | B58: B0D56CNCW1 | C58: TOPDON TS004 Thermal Imaging Monocular, 320 x 240 TISR 256 x 192 IR Resolution, Supported Wireless Connection, 13mm 50Hz Thermal Night Vision with 11h Battery Life, IP67 Monocular for Hunting | D58: topdon | E58: - | K58: 406.6 | L58: 390473.49 | M58: 915 | N58: 172 | O58: 4.4 | P58: https://amazon.com/dp/B0D56CNCW1 | Q58: =HYPERLINK(P58) -> https://amazon.com/dp/B0D56CNCW1
A59: 3 | B59: B0FNM6ZFGG | C59: 4K Night Vision Goggles, 4.0" HD Screen Night Vision Binoculars with 5000mAh Rechargeable Battery, 64GB TF Card for Photo & Video, Infrared Binocular for Adults, Camping, Wildlife Observation | D59: gipsot | E59: - | K59: 89.99 | L59: 56678.34 | M59: 821 | N59: 129 | O59: 4.5 | P59: https://amazon.com/dp/B0FNM6ZFGG | Q59: =HYPERLINK(P59) -> https://amazon.com/dp/B0FNM6ZFGG
A60: 4 | B60: B0F5WCSL4H | C60: Night Vision Goggles, 112 MP 4K Night Vision Binoculars for Adults, 12X Zoom & 5000mAh Battery, 64GB Card Included, Infrared Night Vision, 1500ft View Range, Perfect for Hunting, Camping & Security | D60: hotpeak | E60: - | K60: 89.99 | L60: 75319.79 | M60: 809 | N60: 242 | O60: 4.4 | P60: https://amazon.com/dp/B0F5WCSL4H | Q60: =HYPERLINK(P60) -> https://amazon.com/dp/B0F5WCSL4H
A61: 5 | B61: B0BRY2694B | C61: Night Vision Monocular Digital Infrared Monocular Telescope for 100% Darkness with 8X Zoom 2000mAh Rechargeable Battery Upgrade Tripod 32 GB SD Card & Card Reader, for Adult Hunting Camping Green | D61: yuanzimoo | E61: - | K61: 65.99 | L61: 36088.16 | M61: 561 | N61: 435 | O61: 4 | P61: https://amazon.com/dp/B0BRY2694B | Q61: =HYPERLINK(P61) -> https://amazon.com/dp/B0BRY2694B
A62: 6 | B62: B0FMDJC7VB | C62: Night Vision Goggles - Smart APP 4K Night Vision Binoculars, 10000mAh Battery, 128GB Card Included, 3'' UHD Screen & 8X Zoom Binoculars, 2000FT Range Goggles for Camping, Hunting, Security (Silver) | D62: terunsoul | E62: - | K62: 99.98 | L62: 59910.01 | M62: 499 | N62: 238 | O62: 4.6 | P62: https://amazon.com/dp/B0FMDJC7VB | Q62: =HYPERLINK(P62) -> https://amazon.com/dp/B0FMDJC7VB
A63: 7 | B63: B0D5QXY5JN | C63: RIX Pocket K3 Portable Thermal Monocular for Hunting, 384x288 (50Hz), Wi-Fi, Handheld Night Vision Monocular | D63: rix | E63: - | K63: 899 | L63: 306407.5 | M63: 346 | N63: 77 | O63: 4.6 | P63: https://amazon.com/dp/B0D5QXY5JN | Q63: =HYPERLINK(P63) -> https://amazon.com/dp/B0D5QXY5JN
A64: 8 | B64: B0CNXP8JBV | C64: GOYOJO Thermal Monocular, 256x192 (25 Hz) Thermal Imaging Monoscope Camera for Adults, 10mm Focal Lens Vision Goggles Thermal Scopes for Night Hunting Camping | D64: goyojo | E64: - | K64: 369 | L64: 116832.27 | M64: 317 | N64: 251 | O64: 4.3 | P64: https://amazon.com/dp/B0CNXP8JBV | Q64: =HYPERLINK(P64) -> https://amazon.com/dp/B0CNXP8JBV
A65: 9 | B65: B0BRY25L5X | C65: Night Vision Monocular Digital Infrared Monocular Telescope for 100% Darkness with 8X Zoom 2000mAh Rechargeable Battery Upgrade Tripod 32 GB SD Card & Card Reader, for Adult Hunting Camping Black | D65: yuanzimoo | E65: - | K65: 65.99 | L65: 20313.04 | M65: 316 | N65: 434 | O65: 4 | P65: https://amazon.com/dp/B0BRY25L5X | Q65: =HYPERLINK(P65) -> https://amazon.com/dp/B0BRY25L5X
A66: 10 | B66: B0DMZSBPNT | C66: YUANZIMOO Head-Mounted Night Vision Monocular Digital Infrared Monocular | D66: yuanzimoo | E66: - | K66: 83.99 | L66: 24024.32 | M66: 280 | N66: 107 | O66: 4 | P66: https://amazon.com/dp/B0DMZSBPNT | Q66: =HYPERLINK(P66) -> https://amazon.com/dp/B0DMZSBPNT
A67: 11 | B67: B0CNXPDG7R | C67: GOYOJO Thermal Imaging Monocular for Hunting, 15mm Focal Lens 256x192 Infrared Night Vision Telescope with Long Battery Life, Thermal Scopes for Outdoor Night Vision Camera Telescope (15mm) | D67: goyojo | E67: - | K67: 404.1 | L67: 105720.5 | M67: 262 | N67: 251 | O67: 4.3 | P67: https://amazon.com/dp/B0CNXPDG7R | Q67: =HYPERLINK(P67) -> https://amazon.com/dp/B0CNXPDG7R
A68: 12 | B68: B096HD7WYC | C68: Bushnell EX650 Digital Equinox X650 Night Vision 5x 32mm Monocular | D68: bushnell | E68: - | K68: 199.95 | L68: 38106.74 | M68: 255 | N68: 491 | O68: 3.9 | P68: https://amazon.com/dp/B096HD7WYC | Q68: =HYPERLINK(P68) -> https://amazon.com/dp/B096HD7WYC
... A106: 50 | B106: B0DK2KPKW8 | C106: CASEMATIX Thermal Vision Monocular Case Compatible with Flir Scout TKx Thermal Monocular for Hunting and Night Vision Scopes - 8.5" x 4.0" x 3.5" | D106: casematix | E106: - | K106: 18.99 | L106: 368.38 | M106: 19 | N106: 13 | O106: 4.1 | P106: https://amazon.com/dp/B0DK2KPKW8 | Q106: =HYPERLINK(P106) -> https://amazon.com/dp/B0DK2KPKW8

Sheet Top 50 Type Summary
A1: Top 50 By Revenue Summary
A2: Type | B2: Avg Price | C2: Quantity/Mo | D2: Qty by % | E2: Revenue/Mo | F2: Revenue by %
A3: - | B3: 1517.6032 | C3: 9987 | D3: 1 | E3: 2486547.1 | F3: 1
A10: Total | B10: 1517.6032 | C10: 9987 | D10: 1 | E10: 2486547.1 | F10: 1
A28: Top 50 By Unit Summary
A29: Type | B29: Avg Price | C29: Quantity/Mo | D29: Qty by % | E29: Revenue/Mo | F29: Revenue by %
A30: - | B30: 343.1652 | C30: 10554 | D30: 1 | E30: 2189175.7 | F30: 1
A34: Total | B34: 343.1652 | C34: 10554 | D34: 1 | E34: 2189175.7 | F34: 1

Sheet Top50 2or4way Summary 
A1: Top 50 By Revenue Summary
A2: 2/4-way | B2: Avg Price | C2: Quantity/Mo | D2: Qty by % | E2: Revenue/Mo | F2: Revenue by %
A3: 2-way | B3: 151.215 | C3: 14280 | D3: 0.28413952 | E3: 1876739.6 | F3: 0.51593327
A4: 4-way | B4: 483.32333 | C4: 224 | D4: 0.0044570906 | E4: 99487.32 | F4: 0.027349994
A5: No camera | B5: 38.231667 | C5: 9741 | D5: 0.19382375 | E5: 327595.06 | F5: 0.090058945
B6: 112.4752 | C6: 26012 | D6: 0.51757964 | E6: 1333740.7 | F6: 0.36665779
A7: Total | B7: 196.3113 | C7: 50257 | D7: 1 | E7: 3637562.7 | F7: 1
A25: Top 50 By Unit Summary
A26: 2/4-way | B26: Avg Price | C26: Quantity/Mo | D26: Qty by % | E26: Revenue/Mo | F26: Revenue by %
A27: 2-way | B27: 125.215 | C27: 12014 | D27: 0.20775403 | E27: 1536111.9 | F27: 0.46797832
A28: No camera | B28: 33.44875 | C28: 15781 | D28: 0.27289548 | E28: 514452.73 | F28: 0.15672864
B29: 46.160385 | C29: 30033 | D29: 0.51935049 | E29: 1231877.8 | F29: 0.37529305
A30: Total | B30: 68.274712 | C30: 57828 | D30: 1 | E30: 3282442.4 | F30: 1

Sheet Top 50 Display Summary 
A1: Top 50 By Revenue Summary
A2: Display | B2: Avg Price | C2: Quantity/Mo | D2: Qty by % | E2: Revenue/Mo | F2: Revenue by %
A3: 4.3" | B3: 90.504706 | C3: 16596 | D3: 0.33022266 | E3: 1058372.8 | F3: 0.29095657
A4: 4.5" | B4: 142.49 | C4: 7113 | D4: 0.14153252 | E4: 927695.57 | F4: 0.25503219
A5: 5.0" | B5: 189.22077 | C5: 6508 | D5: 0.1294944 | E5: 877990.86 | F5: 0.2413679
A6: 6.0" | B6: 699.99 | C6: 58 | D6: 0.0011540681 | E6: 40745.77 | F6: 0.011201393
A7: 9.0" | B7: 659.99 | C7: 48 | D7: 0.00095509083 | E7: 33096.25 | F7: 0.0090984686
A8: App | B8: 38.134 | C8: 18839 | D8: 0.37485325 | E8: 589842.49 | F8: 0.16215322
B9: 150.2375 | C9: 1095 | D9: 0.02178801 | E9: 109818.99 | F9: 0.030190267
A10: Total | B10: 281.50957 | C10: 50257 | D10: 1 | E10: 3637562.7 | F10: 1
A28: Top 50 By Unit Summary
A29: Display | B29: Avg Price | C29: Quantity/Mo | D29: Qty by % | E29: Revenue/Mo | F29: Revenue by %
A30: 2.4" | B30: 29.9 | C30: 599 | D30: 0.010358304 | E30: 17916.11 | F30: 0.0054581643
A31: 4.3" | B31: 47.4315 | C31: 20510 | D31: 0.35467248 | E31: 1037368.9 | F31: 0.31603568
A32: 4.5" | B32: 136.65667 | C32: 6727 | D32: 0.11632773 | E32: 872541.08 | F32: 0.26582068
A33: 5.0" | B33: 124.02333 | C33: 5160 | D33: 0.089230131 | E33: 607604.95 | F33: 0.18510757
A34: App | B34: 28.917895 | C34: 24174 | D34: 0.41803279 | E34: 710814.25 | F34: 0.21655041
B35: 54.99 | C35: 658 | D35: 0.011378571 | E35: 36197.11 | F35: 0.011027493
A36: Total | B36: 70.319899 | C36: 57828 | D36: 1 | E36: 3282442.4 | F36: 1

Sheet Top50 Lensdiameter Summary  
A1: Top 50 By Revenue Summary
A2: Lens diameter | B2: Avg Price | C2: Quantity/Mo | D2: Qty by % | E2: Revenue/Mo | F2: Revenue by %
A3: 23mm | B3: 659.99 | C3: 48 | D3: 0.00095509083 | E3: 33096.25 | F3: 0.0090984686
A4: 3.9mm | B4: 699.99 | C4: 58 | D4: 0.0011540681 | E4: 40745.77 | F4: 0.011201393
A5: 5.5mm | B5: 134.84 | C5: 2029 | D5: 0.040372485 | E5: 289538.83 | F5: 0.079596932
A6: 6.2mm | B6: 149.99 | C6: 595 | D6: 0.011839147 | E6: 65856.69 | F6: 0.01810462
A7: 6.4mm | B7: 84.89 | C7: 298 | D7: 0.0059295223 | E7: 28620.75 | F7: 0.0078681118
A8: 6.5mm | B8: 299.99 | C8: 348 | D8: 0.0069244085 | E8: 102859.3 | F8: 0.028276983
A9: 6mm | B9: 449.99 | C9: 71 | D9: 0.0014127385 | E9: 31681.51 | F9: 0.0087095433
A10: 8.5mm | B10: 139.39 | C10: 2210 | D10: 0.043973974 | E10: 300981.94 | F10: 0.082742749
A11: 8mm | B11: 85.033824 | C11: 44163 | D11: 0.87874326 | E11: 2670559.8 | F11: 0.73416186
B12: 181.98667 | C12: 437 | D12: 0.0086953061 | E12: 73621.88 | F12: 0.020239343
A13: Total | B13: 288.60905 | C13: 50257 | D13: 1 | E13: 3637562.7 | F13: 1
A31: Top 50 By Unit Summary
A32: Lens diameter | B32: Avg Price | C32: Quantity/Mo | D32: Qty by % | E32: Revenue/Mo | F32: Revenue by %
A33: 3.9mm | B33: 39.98 | C33: 533 | D33: 0.0092169883 | E33: 21020.51 | F33: 0.0064039235
A34: 5.5mm | B34: 133.19 | C34: 1575 | D34: 0.027235941 | E34: 232842.09 | F34: 0.070935621
A35: 8.5mm | B35: 89.69 | C35: 2800 | D35: 0.048419451 | E35: 321694.51 | F35: 0.098004617
A36: 8mm | B36: 50.029556 | C36: 52920 | D36: 0.91512762 | E36: 2706885.3 | F36: 0.82465584
A37: Total | B37: 78.222389 | C37: 57828 | D37: 1 | E37: 3282442.4 | F37: 1

Sheet Top50 Lens count Summary 
A1: Top 50 By Revenue Summary
A2: Lens count | B2: Avg Price | C2: Quantity/Mo | D2: Qty by % | E2: Revenue/Mo | F2: Revenue by %
A3: Dual | B3: 113.49 | C3: 20239 | D3: 0.40271007 | E3: 1220047.5 | F3: 0.33540246
A4: Single | B4: 150.1296 | C4: 27353 | D4: 0.54426249 | E4: 2069390.5 | F4: 0.56889481
A5: Triple | B5: 142.165 | C5: 2228 | D5: 0.044332133 | E5: 274502.81 | F5: 0.075463389
B6: 181.98667 | C6: 437 | D6: 0.0086953061 | E6: 73621.88 | F6: 0.020239343
A7: Total | B7: 146.94282 | C7: 50257 | D7: 1 | E7: 3637562.7 | F7: 1
A25: Top 50 By Unit Summary
A26: Lens count | B26: Avg Price | C26: Quantity/Mo | D26: Qty by % | E26: Revenue/Mo | F26: Revenue by %
A27: Dual | B27: 65.282222 | C27: 22164 | D27: 0.38327454 | E27: 1102923.2 | F27: 0.33600687
A28: Single | B28: 43.140333 | C28: 33888 | D28: 0.5860137 | E28: 1968776.2 | F28: 0.59979003
A29: Triple | B29: 133.89 | C29: 1776 | D29: 0.030711766 | E29: 210742.98 | F29: 0.064203101
A30: Total | B30: 80.770852 | C30: 57828 | D30: 1 | E30: 3282442.4 | F30: 1

Sheet Top50 Cable length Summary  
A1: Top 50 By Revenue Summary
A2: Cable length | B2: Avg Price | C2: Quantity/Mo | D2: Qty by % | E2: Revenue/Mo | F2: Revenue by %
A3: 10ft | B3: 120.95667 | C3: 1678 | D3: 0.033388384 | E3: 126034.43 | F3: 0.034648043
A4: 16.5ft | B4: 52.773684 | C4: 30505 | D4: 0.60698012 | E4: 1165435.6 | F4: 0.32038915
A5: 300ft | B5: 659.99 | C5: 48 | D5: 0.00095509083 | E5: 33096.25 | F5: 0.0090984686
A6: 32.8ft | B6: 40.99 | C6: 915 | D6: 0.018206419 | E6: 33366.73 | F6: 0.0091728261
A7: 5.25ft | B7: 199.99 | C7: 232 | D7: 0.0046162724 | E7: 36138.18 | F7: 0.0099347236
A8: 5.5ft | B8: 108.45667 | C8: 3453 | D8: 0.068706847 | E8: 406987.28 | F8: 0.11188461
A9: 5.6ft | B9: 99.99 | C9: 363 | D9: 0.0072228744 | E9: 29718.51 | F9: 0.0081698963
A10: 50ft | B10: 122.165 | C10: 2314 | D10: 0.046043337 | E10: 266749.69 | F10: 0.073331984
A11: 5ft | B11: 242.59833 | C11: 9858 | D11: 0.19615178 | E11: 1409717.4 | F11: 0.38754449
A12: 9.8ft | B12: 136.49 | C12: 454 | D12: 0.0090335675 | E12: 56696.74 | F12: 0.015586464
B13: 181.98667 | C13: 437 | D13: 0.0086953061 | E13: 73621.88 | F13: 0.020239343
A14: Total | B14: 178.76246 | C14: 50257 | D14: 1 | E14: 3637562.7 | F14: 1
A32: Top 50 By Unit Summary
A33: Cable length | B33: Avg Price | C33: Quantity/Mo | D33: Qty by % | E33: Revenue/Mo | F33: Revenue by %
A34: 10ft | B34: 22.73 | C34: 1675 | D34: 0.028965207 | E34: 42400.6 | F34: 0.012917393
A35: 16.5ft | B35: 37.308182 | C35: 39098 | D35: 0.67610846 | E35: 1382202.1 | F35: 0.42108951
A36: 32.8ft | B36: 40.99 | C36: 915 | D36: 0.015822785 | E36: 33366.73 | F36: 0.010165214
A37: 33ft | B37: 39.99 | C37: 581 | D37: 0.010047036 | E37: 19298.9 | F37: 0.0058794329
A38: 5.5ft | B38: 108.45667 | C38: 3453 | D38: 0.059711558 | E38: 406987.28 | F38: 0.12398916
A39: 50ft | B39: 102.59 | C39: 2366 | D39: 0.040914436 | E39: 231455.55 | F39: 0.07051321
A40: 5ft | B40: 119.38833 | C40: 9094 | D40: 0.15725946 | E40: 1150145.1 | F40: 0.35039308
A41: 9.8ft | B41: 29.99 | C41: 646 | D41: 0.011171059 | E41: 16586.2 | F41: 0.0050530056
A42: Total | B42: 62.680398 | C42: 57828 | D42: 1 | E42: 3282442.4 | F42: 1

Sheet rix
A1: #VALUE!
A7: Rank by Revenue
A8: Product Name | B8: ASIN | C8: Avg Price | D8: Estimated 12mo Revenue | E8: Monthly Rev | F8: Estimated 12mo Units | G8: Monthly Units | H8: # of Reviews | I8: Tool Rating | J8: Column1 | K8: Link
A9: RIX Pocket K3 Portable Thermal Monocular for Hunting, 384x288 (50Hz), Wi-Fi, Handheld Night Vision Monocular | B9: B0D5QXY5JN | C9: 899 | D9: 3676890 | E9: 306407.5 | F9: 4152 | G9: 346 | H9: 77 | I9: 4.6 | J9: https://amazon.com/dp/B0D5QXY5JN | K9: =HYPERLINK(J9) -> https://amazon.com/dp/B0D5QXY5JN
A10: RIX Titan-T6 Thermal Monocular LRF 35mm 640x480 Thermal Imaging Monocular with Laser Rangefinder (50 Hz) 1920×1080 OLED Display Ideal for Night Hunting, Safety Level-Class I, Power Output＜1mW | B10: B0DZNNGH3P | C10: 2399 | D10: 817083.72 | E10: 68090.31 | F10: 336 | G10: 28 | H10: 3 | I10: 5 | J10: https://amazon.com/dp/B0DZNNGH3P | K10: =HYPERLINK(J10) -> https://amazon.com/dp/B0DZNNGH3P
A11: RIX Thermal Monocular Stride ST6 Thermal Imaging Monocular for Hunting 640x512 (50 Hz), Handheld Thermal Monocular for Hunters, Monocular Thermal Vision | B11: B0CY16GT91 | C11: 2999 | D11: 129655.44 | E11: 10804.62 | F11: 48 | G11: 4 | H11: 6 | I11: 5 | J11: https://amazon.com/dp/B0CY16GT91 | K11: =HYPERLINK(J11) -> https://amazon.com/dp/B0CY16GT91
A12: Total | D12: =SUM(rix!D9:D13) -> 4623629.2 | E12: =SUM(rix!E9:E11) -> 385302.43 | K12: =HYPERLINK(J12)
A15: Rank by Units
A16: Product Name | B16: ASIN | C16: Avg Price | D16: Estimated 12mo Revenue | E16: Monthly Rev | F16: Estimated 12mo Units | G16: Monthly Units | H16: # of Reviews | I16: Tool Rating | J16: Column1 | K16: Link
A17: RIX Pocket K3 Portable Thermal Monocular for Hunting, 384x288 (50Hz), Wi-Fi, Handheld Night Vision Monocular | B17: B0D5QXY5JN | C17: 899 | D17: 3676890 | E17: 306407.5 | F17: 4152 | G17: 346 | H17: 77 | I17: 4.6 | J17: https://amazon.com/dp/B0D5QXY5JN | K17: =HYPERLINK(J17) -> https://amazon.com/dp/B0D5QXY5JN
A18: RIX Titan-T6 Thermal Monocular LRF 35mm 640x480 Thermal Imaging Monocular with Laser Rangefinder (50 Hz) 1920×1080 OLED Display Ideal for Night Hunting, Safety Level-Class I, Power Output＜1mW | B18: B0DZNNGH3P | C18: 2399 | D18: 817083.72 | E18: 68090.31 | F18: 336 | G18: 28 | H18: 3 | I18: 5 | J18: https://amazon.com/dp/B0DZNNGH3P | K18: =HYPERLINK(J18) -> https://amazon.com/dp/B0DZNNGH3P
A19: RIX Thermal Monocular Stride ST6 Thermal Imaging Monocular for Hunting 640x512 (50 Hz), Handheld Thermal Monocular for Hunters, Monocular Thermal Vision | B19: B0CY16GT91 | C19: 2999 | D19: 129655.44 | E19: 10804.62 | F19: 48 | G19: 4 | H19: 6 | I19: 5 | J19: https://amazon.com/dp/B0CY16GT91 | K19: =HYPERLINK(J19) -> https://amazon.com/dp/B0CY16GT91
A78: Total | F78: =SUM(rix!F17:F77) -> 4536 | G78: =SUM(rix!G17:G77) -> 378

Sheet goyojo
A1: #VALUE!
A7: Rank by Revenue
A8: Product Name | B8: ASIN | C8: Avg Price | D8: Estimated 12mo Revenue | E8: Monthly Rev | F8: Estimated 12mo Units | G8: Monthly Units | H8: # of Reviews | I8: Tool Rating | J8: Column1 | K8: Link
A9: GOYOJO Thermal Monocular, 256x192 (25 Hz) Thermal Imaging Monoscope Camera for Adults, 10mm Focal Lens Vision Goggles Thermal Scopes for Night Hunting Camping | B9: B0CNXP8JBV | C9: 369 | D9: 1401987.2 | E9: 116832.27 | F9: 3804 | G9: 317 | H9: 251 | I9: 4.3 | J9: https://amazon.com/dp/B0CNXP8JBV | K9: =HYPERLINK(J9) -> https://amazon.com/dp/B0CNXP8JBV
A10: GOYOJO Thermal Imaging Monocular for Hunting, 15mm Focal Lens 256x192 Infrared Night Vision Telescope with Long Battery Life, Thermal Scopes for Outdoor Night Vision Camera Telescope (15mm) | B10: B0CNXPDG7R | C10: 404.1 | D10: 1268646 | E10: 105720.5 | F10: 3144 | G10: 262 | H10: 251 | I10: 4.3 | J10: https://amazon.com/dp/B0CNXPDG7R | K10: =HYPERLINK(J10) -> https://amazon.com/dp/B0CNXPDG7R
A11: GOYOJO GNG2K Night Vision Monocular - 2K / 60Hz Refresh Digital Night Vision Goggles, Helmet Mountable, Stealth Infrared 940nm NVG with 0.0001 Lux Sensor, 4 Color Modes for Tactical/Hunting/Camping | B11: B0FNWKSKYK | C11: 519 | D11: 287397 | E11: 23949.75 | F11: 552 | G11: 46 | H11: 181 | I11: 4.3 | J11: https://amazon.com/dp/B0FNWKSKYK | K11: =HYPERLINK(J11) -> https://amazon.com/dp/B0FNWKSKYK
A12: GOYOJO Night Vision Goggles Helmet-Mounted Monocular | 1080P HD NVG with 3X Zoom & Adjustable Infrared | IP66 Waterproof for Hunting, Surveillance, Camping | Built-in Compass (100% Darkness) | B12: B0CFH7SGZK | C12: 229 | D12: 174313.32 | E12: 14526.11 | F12: 756 | G12: 63 | H12: 182 | I12: 4.4 | J12: https://amazon.com/dp/B0CFH7SGZK | K12: =HYPERLINK(J12) -> https://amazon.com/dp/B0CFH7SGZK
A13: Thermal Imaging Monocular for Hunting, 384x288(50Hz) Infrared Night Vision Telescope with Long Battery Life, 15mm Focal Lens Thermal Scopes for Outdoor Night Vision Camera Telescope | B13: B0D1R935KD | C13: 664.99 | D13: 121624.32 | E13: 10135.36 | F13: 180 | G13: 15 | H13: 52 | I13: 4.3 | J13: https://amazon.com/dp/B0D1R935KD | K13: =HYPERLINK(J13) -> https://amazon.com/dp/B0D1R935KD
A14: GOYOJO Thermal Monocular Night Vision, 25mm Focal Lens Thermal Imaging Monoscope 384x288 (50 Hz) Night Vision Goggles Thermal Scopes for Hunting | B14: B0D1RB6PBJ | C14: 759.05 | D14: 121581.96 | E14: 10131.83 | F14: 156 | G14: 13 | H14: 51 | I14: 4.3 | J14: https://amazon.com/dp/B0D1RB6PBJ | K14: =HYPERLINK(J14) -> https://amazon.com/dp/B0D1RB6PBJ
A15: GOYOJO GNG2K Night Vision Monocular - 2K/60Hz Refresh Digital Night Vision Goggles, Helmet Mountable, Stealth Infrared 940nm NVG with 0.0001 Lux Sensor, 4 Color Modes for Tactical/Hunting/Camping | B15: B0FNWHWHMR | C15: 1299 | D15: 119952.48 | E15: 9996.04 | F15: 96 | G15: 8 | H15: 181 | I15: 4.3 | J15: https://amazon.com/dp/B0FNWHWHMR | K15: =HYPERLINK(J15) -> https://amazon.com/dp/B0FNWHWHMR
A16: GOYOJO Helmet-Mounted Night Vision Monocular - 1080P HD, 3X Digital Zoom & 1X Optical, IP66 Waterproof NVG Built-in Digital Compass for Airsoft, Hunting, Camping (Equipped with Fast Helmet) | B16: B0CFH6TPWQ | C16: 249 | D16: 90941.04 | E16: 7578.42 | F16: 360 | G16: 30 | H16: 181 | I16: 4.3 | J16: https://amazon.com/dp/B0CFH6TPWQ | K16: =HYPERLINK(J16) -> https://amazon.com/dp/B0CFH6TPWQ
A17: GOYOJO 2K Digital Night Vision Goggles, NVG Helmet Mounted for Tactical, Hunting, PVS-14 Night Vision Monocular with 4 Color Modes HD Recording & Playback | B17: B0CTH5MH9G | C17: 389 | D17: 82003.8 | E17: 6833.65 | F17: 216 | G17: 18 | H17: 277 | I17: 4.2 | J17: https://amazon.com/dp/B0CTH5MH9G | K17: =HYPERLINK(J17) -> https://amazon.com/dp/B0CTH5MH9G
A18: NVG Night Vision Goggles - Helmet Mounted 2K Night Vision Binoculars Adults with 4 Color Modes 4X Magnification, HD Recording & Playback for Hunting Surveillance (Helmet Not Included) | B18: B0CX1W3986 | C18: 999 | D18: 27400.08 | E18: 2283.34 | F18: 24 | G18: 2 | H18: 23 | I18: 3.7 | J18: https://amazon.com/dp/B0CX1W3986 | K18: =HYPERLINK(J18) -> https://amazon.com/dp/B0CX1W3986
A19: GOYOJO Night Vision Goggles- NVG10 Night Vision Scope with Photo and Video Shooting, NVG Digital Vision Distance 200M for Hunting, Camping | B19: B0BZSBGQTW | C19: 229 | D19: 26399.64 | E19: 2199.97 | F19: 120 | G19: 10 | H19: 277 | I19: 4.2 | J19: https://amazon.com/dp/B0BZSBGQTW | K19: =HYPERLINK(J19) -> https://amazon.com/dp/B0BZSBGQTW
A20: Night Vision Monocular - Digital Night Vision Scope with 1.6" 640x480 HD IPS Display, Audio &Video Recording Camera Function, 850nm IR Illuminator, 4 Imaging Modes, for Hunting, Military Tactical | B20: B0CBV6V43B | C20: 369 | D20: 5705.64 | E20: 475.47 | F20: 12 | G20: 1 | H20: 8 | I20: 4 | J20: https://amazon.com/dp/B0CBV6V43B | K20: =HYPERLINK(J20) -> https://amazon.com/dp/B0CBV6V43B
A21: Head Mounted 4K HD Night Vision, 8X Zoom Night Vision Monocular Digital Infrared Monocular, with Photo and Video Shooting, Built-in 3000mAh Lithium Battery IP54, for Hunting, Camping, Surveillance | B21: B0CW1LVB59 | C21: 149 | D21: 4412.64 | E21: 367.72 | F21: 36 | G21: 3 | H21: 1 | I21: 5 | J21: https://amazon.com/dp/B0CW1LVB59 | K21: =HYPERLINK(J21) -> https://amazon.com/dp/B0CW1LVB59
A22: GOYOJO NVG30 Night Vision Goggles for Adults, PVS-14 Helmet Mounted Night Vision Binoculars with 4 Color Modes 4X Magnification, HD Recording & Playback for Hunting Surveillance | B22: B0CX3YQQQ5 | C22: 1199 | F22: 0 | G22: 0 | H22: 5 | I22: 3.3 | J22: https://amazon.com/dp/B0CX3YQQQ5 | K22: =HYPERLINK(J22) -> https://amazon.com/dp/B0CX3YQQQ5
A23: NVG 2K Night Vision Goggles for Adults, Helmet Mounted Night Vision Monocular with 4 Color Modes 4X Magnification, HD Recording & Playback for Hunting Surveillance | B23: B0CWTPMVRM | C23: 529 | F23: 0 | G23: 0 | H23: 3 | I23: 3 | J23: https://amazon.com/dp/B0CWTPMVRM | K23: =HYPERLINK(J23) -> https://amazon.com/dp/B0CWTPMVRM
A24: GOYOJO Thermal Night Vision Riflescope for Hunting - 25 mm/12um Long-Range Detection, Adjustable Focus, HD Imaging, 6H Battery, and More - Perfect for Hunting, Surveillance, and Wildlife Observation | B24: B0CFV2H85F | C24: 598 | F24: 0 | G24: 0 | H24: 3 | I24: 2.8 | J24: https://amazon.com/dp/B0CFV2H85F | K24: =HYPERLINK(J24) -> https://amazon.com/dp/B0CFV2H85F
A25: GOYOJO Thermal Monocular for Hunting, 25Hz Handheld Infrared Thermal Scope, with High Sensitivity 256x192 Night Vision Telescope, with Photo, Video Record for Night Fishing, Camping, 2X - 4X | B25: B0CP3C49VZ | C25: 399 | F25: 0 | G25: 0 | J25: https://amazon.com/dp/B0CP3C49VZ | K25: =HYPERLINK(J25) -> https://amazon.com/dp/B0CP3C49VZ
A26: TD430 TD Series Handheld Thermal Imaging Monocular Infrared Thermal Imager Scope Monocular (TD430) | B26: B0BV6J7TZZ | C26: 2130 | F26: 0 | G26: 0 | J26: https://amazon.com/dp/B0BV6J7TZZ | K26: =HYPERLINK(J26) -> https://amazon.com/dp/B0BV6J7TZZ
A27: Goyojo Night Vision Monocular Thermal Imager Scope Sight for Hunting | B27: B0CFVKXSS9 | C27: 928 | F27: 0 | G27: 0 | J27: https://amazon.com/dp/B0CFVKXSS9 | K27: =HYPERLINK(J27) -> https://amazon.com/dp/B0CFVKXSS9
A44: Total | D44: =SUM(goyojo!D9:D43) -> 3732365.2 | E44: =SUM(goyojo!E9:E43) -> 311030.43
A45: Rank by Units
A46: Product Name | B46: ASIN | C46: Avg Price | D46: Estimated 12mo Revenue | E46: Monthly Rev | F46: Estimated 12mo Units | G46: Monthly Units | H46: # of Reviews | I46: Tool Rating | J46: Column1 | K46: Link
A47: GOYOJO Thermal Monocular, 256x192 (25 Hz) Thermal Imaging Monoscope Camera for Adults, 10mm Focal Lens Vision Goggles Thermal Scopes for Night Hunting Camping | B47: B0CNXP8JBV | C47: 369 | D47: 1401987.2 | E47: 116832.27 | F47: 3804 | G47: 317 | H47: 251 | I47: 4.3 | J47: https://amazon.com/dp/B0CNXP8JBV | K47: =HYPERLINK(J47) -> https://amazon.com/dp/B0CNXP8JBV
A48: GOYOJO Thermal Imaging Monocular for Hunting, 15mm Focal Lens 256x192 Infrared Night Vision Telescope with Long Battery Life, Thermal Scopes for Outdoor Night Vision Camera Telescope (15mm) | B48: B0CNXPDG7R | C48: 404.1 | D48: 1268646 | E48: 105720.5 | F48: 3144 | G48: 262 | H48: 251 | I48: 4.3 | J48: https://amazon.com/dp/B0CNXPDG7R | K48: =HYPERLINK(J48) -> https://amazon.com/dp/B0CNXPDG7R
A49: GOYOJO Night Vision Goggles Helmet-Mounted Monocular | 1080P HD NVG with 3X Zoom & Adjustable Infrared | IP66 Waterproof for Hunting, Surveillance, Camping | Built-in Compass (100% Darkness) | B49: B0CFH7SGZK | C49: 229 | D49: 174313.32 | E49: 14526.11 | F49: 756 | G49: 63 | H49: 182 | I49: 4.4 | J49: https://amazon.com/dp/B0CFH7SGZK | K49: =HYPERLINK(J49) -> https://amazon.com/dp/B0CFH7SGZK
A50: GOYOJO GNG2K Night Vision Monocular - 2K / 60Hz Refresh Digital Night Vision Goggles, Helmet Mountable, Stealth Infrared 940nm NVG with 0.0001 Lux Sensor, 4 Color Modes for Tactical/Hunting/Camping | B50: B0FNWKSKYK | C50: 519 | D50: 287397 | E50: 23949.75 | F50: 552 | G50: 46 | H50: 181 | I50: 4.3 | J50: https://amazon.com/dp/B0FNWKSKYK | K50: =HYPERLINK(J50) -> https://amazon.com/dp/B0FNWKSKYK
A51: GOYOJO Helmet-Mounted Night Vision Monocular - 1080P HD, 3X Digital Zoom & 1X Optical, IP66 Waterproof NVG Built-in Digital Compass for Airsoft, Hunting, Camping (Equipped with Fast Helmet) | B51: B0CFH6TPWQ | C51: 249 | D51: 90941.04 | E51: 7578.42 | F51: 360 | G51: 30 | H51: 181 | I51: 4.3 | J51: https://amazon.com/dp/B0CFH6TPWQ | K51: =HYPERLINK(J51) -> https://amazon.com/dp/B0CFH6TPWQ
A52: GOYOJO 2K Digital Night Vision Goggles, NVG Helmet Mounted for Tactical, Hunting, PVS-14 Night Vision Monocular with 4 Color Modes HD Recording & Playback | B52: B0CTH5MH9G | C52: 389 | D52: 82003.8 | E52: 6833.65 | F52: 216 | G52: 18 | H52: 277 | I52: 4.2 | J52: https://amazon.com/dp/B0CTH5MH9G | K52: =HYPERLINK(J52) -> https://amazon.com/dp/B0CTH5MH9G
A53: Thermal Imaging Monocular for Hunting, 384x288(50Hz) Infrared Night Vision Telescope with Long Battery Life, 15mm Focal Lens Thermal Scopes for Outdoor Night Vision Camera Telescope | B53: B0D1R935KD | C53: 664.99 | D53: 121624.32 | E53: 10135.36 | F53: 180 | G53: 15 | H53: 52 | I53: 4.3 | J53: https://amazon.com/dp/B0D1R935KD | K53: =HYPERLINK(J53) -> https://amazon.com/dp/B0D1R935KD
A54: GOYOJO Thermal Monocular Night Vision, 25mm Focal Lens Thermal Imaging Monoscope 384x288 (50 Hz) Night Vision Goggles Thermal Scopes for Hunting | B54: B0D1RB6PBJ | C54: 759.05 | D54: 121581.96 | E54: 10131.83 | F54: 156 | G54: 13 | H54: 51 | I54: 4.3 | J54: https://amazon.com/dp/B0D1RB6PBJ | K54: =HYPERLINK(J54) -> https://amazon.com/dp/B0D1RB6PBJ
A55: GOYOJO Night Vision Goggles- NVG10 Night Vision Scope with Photo and Video Shooting, NVG Digital Vision Distance 200M for Hunting, Camping | B55: B0BZSBGQTW | C55: 229 | D55: 26399.64 | E55: 2199.97 | F55: 120 | G55: 10 | H55: 277 | I55: 4.2 | J55: https://amazon.com/dp/B0BZSBGQTW | K55: =HYPERLINK(J55) -> https://amazon.com/dp/B0BZSBGQTW
A56: GOYOJO GNG2K Night Vision Monocular - 2K/60Hz Refresh Digital Night Vision Goggles, Helmet Mountable, Stealth Infrared 940nm NVG with 0.0001 Lux Sensor, 4 Color Modes for Tactical/Hunting/Camping | B56: B0FNWHWHMR | C56: 1299 | D56: 119952.48 | E56: 9996.04 | F56: 96 | G56: 8 | H56: 181 | I56: 4.3 | J56: https://amazon.com/dp/B0FNWHWHMR | K56: =HYPERLINK(J56) -> https://amazon.com/dp/B0FNWHWHMR
A57: Head Mounted 4K HD Night Vision, 8X Zoom Night Vision Monocular Digital Infrared Monocular, with Photo and Video Shooting, Built-in 3000mAh Lithium Battery IP54, for Hunting, Camping, Surveillance | B57: B0CW1LVB59 | C57: 149 | D57: 4412.64 | E57: 367.72 | F57: 36 | G57: 3 | H57: 1 | I57: 5 | J57: https://amazon.com/dp/B0CW1LVB59 | K57: =HYPERLINK(J57) -> https://amazon.com/dp/B0CW1LVB59
A58: NVG Night Vision Goggles - Helmet Mounted 2K Night Vision Binoculars Adults with 4 Color Modes 4X Magnification, HD Recording & Playback for Hunting Surveillance (Helmet Not Included) | B58: B0CX1W3986 | C58: 999 | D58: 27400.08 | E58: 2283.34 | F58: 24 | G58: 2 | H58: 23 | I58: 3.7 | J58: https://amazon.com/dp/B0CX1W3986 | K58: =HYPERLINK(J58) -> https://amazon.com/dp/B0CX1W3986
A59: Night Vision Monocular - Digital Night Vision Scope with 1.6" 640x480 HD IPS Display, Audio &Video Recording Camera Function, 850nm IR Illuminator, 4 Imaging Modes, for Hunting, Military Tactical | B59: B0CBV6V43B | C59: 369 | D59: 5705.64 | E59: 475.47 | F59: 12 | G59: 1 | H59: 8 | I59: 4 | J59: https://amazon.com/dp/B0CBV6V43B | K59: =HYPERLINK(J59) -> https://amazon.com/dp/B0CBV6V43B
A60: NVG 2K Night Vision Goggles for Adults, Helmet Mounted Night Vision Monocular with 4 Color Modes 4X Magnification, HD Recording & Playback for Hunting Surveillance | B60: B0CWTPMVRM | C60: 529 | F60: 0 | G60: 0 | H60: 3 | I60: 3 | J60: https://amazon.com/dp/B0CWTPMVRM | K60: =HYPERLINK(J60) -> https://amazon.com/dp/B0CWTPMVRM
A61: Goyojo Night Vision Monocular Thermal Imager Scope Sight for Hunting | B61: B0CFVKXSS9 | C61: 928 | F61: 0 | G61: 0 | J61: https://amazon.com/dp/B0CFVKXSS9 | K61: =HYPERLINK(J61) -> https://amazon.com/dp/B0CFVKXSS9
...

Sheet agm global vision
A1: #VALUE!
A7: Rank by Revenue
A8: Product Name | B8: ASIN | C8: Avg Price | D8: Estimated 12mo Revenue | E8: Monthly Rev | F8: Estimated 12mo Units | G8: Monthly Units | H8: # of Reviews | I8: Tool Rating | J8: Column1 | K8: Link
A9: AGM Global Vision Taipan TM10-256 Thermal Monocular - 256x192 Resolution, 12μm Pixel Pitch, Video Recording 1-8x Digital Zoom Heat Vision Thermal Optic for Hunting | B9: B0988TDVTW | C9: 549.99 | D9: 303171.12 | E9: 25264.26 | F9: 612 | G9: 51 | H9: 846 | I9: 4.3 | J9: https://amazon.com/dp/B0988TDVTW | K9: =HYPERLINK(J9) -> https://amazon.com/dp/B0988TDVTW
A10: AGM Global Vision Night Vision Monocular PVS-14 NL1 Gen 2 NVG military grade monocular for adults, for hunting. High powered digital tactical survival gear nightvision nv monocular for helmet, headset | B10: B07YCXCTCP | C10: 2609 | D10: 292575.36 | E10: 24381.28 | F10: 108 | G10: 9 | H10: 36 | I10: 4.6 | J10: https://amazon.com/dp/B07YCXCTCP | K10: =HYPERLINK(J10) -> https://amazon.com/dp/B07YCXCTCP
A11: AGM Global Vision Taipan TM15-256 Thermal Imaging Monocular - 256x192 Resolution, 12μm Pixel Pitch, Video Recording 1-8x Digital Zoom Heat Vision Thermal Optic for Hunting | B11: B09897SNLP | C11: 700 | D11: 267027.84 | E11: 22252.32 | F11: 432 | G11: 36 | H11: 846 | I11: 4.3 | J11: https://amazon.com/dp/B09897SNLP | K11: =HYPERLINK(J11) -> https://amazon.com/dp/B09897SNLP
A12: AGM Global Vision Fuzion LRF TM35-384 Fusion Thermal Imaging & CMOS Monocular with Laser Range Finder, 12 Micron 384x288 (50 Hz), 35 mm Lens, Black | B12: B09LWY7717 | C12: 1599 | D12: 149131.44 | E12: 12427.62 | F12: 96 | G12: 8 | H12: 28 | I12: 4.4 | J12: https://amazon.com/dp/B09LWY7717 | K12: =HYPERLINK(J12) -> https://amazon.com/dp/B09LWY7717
A13: AGM Global Vision Sidewinder TM25-384 Thermal Imaging Monocular | B13: B0C4TCBPHX | C13: 1595 | D13: 131300.52 | E13: 10941.71 | F13: 84 | G13: 7 | H13: 2 | I13: 5 | J13: https://amazon.com/dp/B0C4TCBPHX | K13: =HYPERLINK(J13) -> https://amazon.com/dp/B0C4TCBPHX
A14: AGM Global Vision 11P14123483121 Model PVS-14 3AL2 Night Vision Monocular, Black, Gen 3 Auto-Gated Level 2", 64-72 lp/mm Resolution, 1x Magnification, Built-in Infrared Illuminator and Flood Lens | B14: B0B8M93WR8 | C14: 4837.75 | D14: 126685.92 | E14: 10557.16 | F14: 24 | G14: 2 | J14: https://amazon.com/dp/B0B8M93WR8 | K14: =HYPERLINK(J14) -> https://amazon.com/dp/B0B8M93WR8
A15: AGM Global Vision ReachIR LRF 25-384 Thermal Imaging Monocular with Built-in Laser Range Finder, 20mK, 12 Micron, 384x288 (50 Hz) | B15: B0DKTRC16M | C15: 1818.04 | D15: 114649.68 | E15: 9554.14 | F15: 60 | G15: 5 | H15: 4 | I15: 5 | J15: https://amazon.com/dp/B0DKTRC16M | K15: =HYPERLINK(J15) -> https://amazon.com/dp/B0DKTRC16M
A16: AGM Global Vision Fuzion LRF TM35-640 Thermal Monocular with Laser Rangefinder and Bi-Spectrum Image Fusion Hunting Monocular with Thermal Imaging Heat Vision Perfect for Hunting and Outdoor Adventure | B16: B09LX2LTD4 | C16: 1933.72 | D16: 90974.16 | E16: 7581.18 | F16: 48 | G16: 4 | H16: 28 | I16: 4.4 | J16: https://amazon.com/dp/B09LX2LTD4 | K16: =HYPERLINK(J16) -> https://amazon.com/dp/B09LX2LTD4
A17: Total | D17: =SUM('agm global vision'!D9:D16) -> 1475516 | E17: =SUM('agm global vision'!E9:E16) -> 122959.67
A18: Rank by Units
A19: Product Name | B19: ASIN | C19: Avg Price | D19: Estimated 12mo Revenue | E19: Monthly Rev | F19: Estimated 12mo Units | G19: Monthly Units | H19: # of Reviews | I19: Tool Rating | J19: Column1 | K19: Link
A20: AGM Global Vision Taipan TM10-256 Thermal Monocular - 256x192 Resolution, 12μm Pixel Pitch, Video Recording 1-8x Digital Zoom Heat Vision Thermal Optic for Hunting | B20: B0988TDVTW | C20: 549.99 | D20: 303171.12 | E20: 25264.26 | F20: 612 | G20: 51 | H20: 846 | I20: 4.3 | J20: https://amazon.com/dp/B0988TDVTW | K20: =HYPERLINK(J20) -> https://amazon.com/dp/B0988TDVTW
A21: AGM Global Vision Taipan TM15-256 Thermal Imaging Monocular - 256x192 Resolution, 12μm Pixel Pitch, Video Recording 1-8x Digital Zoom Heat Vision Thermal Optic for Hunting | B21: B09897SNLP | C21: 700 | D21: 267027.84 | E21: 22252.32 | F21: 432 | G21: 36 | H21: 846 | I21: 4.3 | J21: https://amazon.com/dp/B09897SNLP | K21: =HYPERLINK(J21) -> https://amazon.com/dp/B09897SNLP
A22: AGM Global Vision Night Vision Monocular PVS-14 NL1 Gen 2 NVG military grade monocular for adults, for hunting. High powered digital tactical survival gear nightvision nv monocular for helmet, headset | B22: B07YCXCTCP | C22: 2609 | D22: 292575.36 | E22: 24381.28 | F22: 108 | G22: 9 | H22: 36 | I22: 4.6 | J22: https://amazon.com/dp/B07YCXCTCP | K22: =HYPERLINK(J22) -> https://amazon.com/dp/B07YCXCTCP
A23: AGM Global Vision Fuzion LRF TM35-384 Fusion Thermal Imaging & CMOS Monocular with Laser Range Finder, 12 Micron 384x288 (50 Hz), 35 mm Lens, Black | B23: B09LWY7717 | C23: 1599 | D23: 149131.44 | E23: 12427.62 | F23: 96 | G23: 8 | H23: 28 | I23: 4.4 | J23: https://amazon.com/dp/B09LWY7717 | K23: =HYPERLINK(J23) -> https://amazon.com/dp/B09LWY7717
A24: AGM Global Vision Neith DC32-4MP 2560 x 1440 Digital Day and Night Vision Clip-On System; Quick Conversion of Daytime Optics Into Night Vision Device; Waterproof and Shockproof | B24: B0CLPCMW88 | C24: 500 | D24: 46857 | E24: 3904.75 | F24: 84 | G24: 7 | H24: 3 | I24: 3.9 | J24: https://amazon.com/dp/B0CLPCMW88 | K24: =HYPERLINK(J24) -> https://amazon.com/dp/B0CLPCMW88
A25: AGM Global Vision Sidewinder TM25-384 Thermal Imaging Monocular | B25: B0C4TCBPHX | C25: 1595 | D25: 131300.52 | E25: 10941.71 | F25: 84 | G25: 7 | H25: 2 | I25: 5 | J25: https://amazon.com/dp/B0C4TCBPHX | K25: =HYPERLINK(J25) -> https://amazon.com/dp/B0C4TCBPHX
A26: Total | F26: =SUM('agm global vision'!F20:F25) -> 1416 | G26: =SUM('agm global vision'!G20:G25) -> 118

Sheet hotpeak
A1: #VALUE!
A7: Rank by Revenue
A8: Product Name | B8: ASIN | C8: Avg Price | D8: Estimated 12mo Revenue | E8: Monthly Rev | F8: Estimated 12mo Units | G8: Monthly Units | H8: # of Reviews | I8: Tool Rating | J8: Column1 | K8: Link
A9: Night Vision Goggles, 112 MP 4K Night Vision Binoculars for Adults, 12X Zoom & 5000mAh Battery, 64GB Card Included, Infrared Night Vision, 1500ft View Range, Perfect for Hunting, Camping & Security | B9: B0F5WCSL4H | C9: 89.99 | D9: 903837.48 | E9: 75319.79 | F9: 9708 | G9: 809 | H9: 242 | I9: 4.4 | J9: https://amazon.com/dp/B0F5WCSL4H | K9: =HYPERLINK(J9) -> https://amazon.com/dp/B0F5WCSL4H
A10: Full Color Night Vision Goggles, 112 MP 4K Night Vision Binoculars 18X Zoom & 5000mAh Battery, 64GB Card Included, Infrared Vision, 1968ft Range, Perfect for Hunting, Camping & Security | B10: B0FRGFKHHG | C10: 139.99 | D10: 395158.2 | E10: 32929.85 | F10: 2448 | G10: 204 | H10: 285 | I10: 4.4 | J10: https://amazon.com/dp/B0FRGFKHHG | K10: =HYPERLINK(J10) -> https://amazon.com/dp/B0FRGFKHHG
A11: 4K Night Vision Goggles, 48 MP Night Vision Binoculars 10X Zoom & 5000mAh Battery, 32GB Card Included, Infrared Vision, 1300ft Range, Perfect for Outdoor, Camping & Security | B11: B0FJM2TBJZ | C11: 59.99 | D11: 195517.92 | E11: 16293.16 | F11: 3036 | G11: 253 | H11: 285 | I11: 4.4 | J11: https://amazon.com/dp/B0FJM2TBJZ | K11: =HYPERLINK(J11) -> https://amazon.com/dp/B0FJM2TBJZ
A17: Total | D17: =SUM(hotpeak!D9:D16) -> 1494513.6 | E17: =SUM(hotpeak!E9:E16) -> 124542.8
A18: Rank by Units
A19: Product Name | B19: ASIN | C19: Avg Price | D19: Estimated 12mo Revenue | E19: Monthly Rev | F19: Estimated 12mo Units | G19: Monthly Units | H19: # of Reviews | I19: Tool Rating | J19: Column1 | K19: Link
A20: Night Vision Goggles, 112 MP 4K Night Vision Binoculars for Adults, 12X Zoom & 5000mAh Battery, 64GB Card Included, Infrared Night Vision, 1500ft View Range, Perfect for Hunting, Camping & Security | B20: B0F5WCSL4H | C20: 89.99 | D20: 903837.48 | E20: 75319.79 | F20: 9708 | G20: 809 | H20: 242 | I20: 4.4 | J20: https://amazon.com/dp/B0F5WCSL4H | K20: =HYPERLINK(J20) -> https://amazon.com/dp/B0F5WCSL4H
A21: 4K Night Vision Goggles, 48 MP Night Vision Binoculars 10X Zoom & 5000mAh Battery, 32GB Card Included, Infrared Vision, 1300ft Range, Perfect for Outdoor, Camping & Security | B21: B0FJM2TBJZ | C21: 59.99 | D21: 195517.92 | E21: 16293.16 | F21: 3036 | G21: 253 | H21: 285 | I21: 4.4 | J21: https://amazon.com/dp/B0FJM2TBJZ | K21: =HYPERLINK(J21) -> https://amazon.com/dp/B0FJM2TBJZ
A22: Full Color Night Vision Goggles, 112 MP 4K Night Vision Binoculars 18X Zoom & 5000mAh Battery, 64GB Card Included, Infrared Vision, 1968ft Range, Perfect for Hunting, Camping & Security | B22: B0FRGFKHHG | C22: 139.99 | D22: 395158.2 | E22: 32929.85 | F22: 2448 | G22: 204 | H22: 285 | I22: 4.4 | J22: https://amazon.com/dp/B0FRGFKHHG | K22: =HYPERLINK(J22) -> https://amazon.com/dp/B0FRGFKHHG
A27: Total | F27: =SUM(hotpeak!F20:F26) -> 15192 | G27: =SUM(hotpeak!G20:G26) -> 1266

Sheet pulsar
A1: #VALUE!
A7: Rank by Revenue
A8: Product Name | B8: ASIN | C8: Avg Price | D8: Estimated 12mo Revenue | E8: Monthly Rev | F8: Estimated 12mo Units | G8: Monthly Units | H8: # of Reviews | I8: Tool Rating | J8: Column1 | K8: Link
A9: Pulsar Axion 2 LRF XQ35 Pro Thermal Monocular with Laser Range Finder | B9: B0C37XZWZJ | C9: 1859.99 | D9: 590961.72 | E9: 49246.81 | F9: 312 | G9: 26 | H9: 39 | I9: 4.3 | J9: https://amazon.com/dp/B0C37XZWZJ | K9: =HYPERLINK(J9) -> https://amazon.com/dp/B0C37XZWZJ
A10: Pulsar Axion 2 XG35 Thermal Monocular | B10: B0B6GJ84TZ | C10: 2379.97 | D10: 427332.12 | E10: 35611.01 | F10: 180 | G10: 15 | H10: 61 | I10: 4.4 | J10: https://amazon.com/dp/B0B6GJ84TZ | K10: =HYPERLINK(J10) -> https://amazon.com/dp/B0B6GJ84TZ
A11: Pulsar Telos XQ35 Thermal Imaging Monocular | B11: B0CTVDMD16 | C11: 1949.99 | D11: 336529.68 | E11: 28044.14 | F11: 168 | G11: 14 | H11: 15 | I11: 4.3 | J11: https://amazon.com/dp/B0CTVDMD16 | K11: =HYPERLINK(J11) -> https://amazon.com/dp/B0CTVDMD16
A12: Pulsar Telos LRF XG50 Thermal Imaging Monocular with Laser Range Finder | B12: B0CTW1RCM1 | C12: 3499.99 | D12: 319761.12 | E12: 26646.76 | F12: 84 | G12: 7 | H12: 6 | I12: 4.8 | J12: https://amazon.com/dp/B0CTW1RCM1 | K12: =HYPERLINK(J12) -> https://amazon.com/dp/B0CTW1RCM1
A13: Pulsar Telos LRF XQ35 Thermal Imaging Monocular with Laser Range Finder | B13: B0CTVD7WNF | C13: 2349 | D13: 311954.16 | E13: 25996.18 | F13: 132 | G13: 11 | H13: 6 | I13: 4.8 | J13: https://amazon.com/dp/B0CTVD7WNF | K13: =HYPERLINK(J13) -> https://amazon.com/dp/B0CTVD7WNF
A14: Pulsar Telos XG50 Thermal Imaging Monocular | B14: B0CTVH53L5 | C14: 2499.97 | D14: 257960.88 | E14: 21496.74 | F14: 96 | G14: 8 | H14: 15 | I14: 4.3 | J14: https://amazon.com/dp/B0CTVH53L5 | K14: =HYPERLINK(J14) -> https://amazon.com/dp/B0CTVH53L5
A15: Pulsar Telos XP50 Thermal Imaging Monocular | B15: B0CKLVYY1J | C15: 3495 | D15: 208113.24 | E15: 17342.77 | F15: 60 | G15: 5 | H15: 15 | I15: 4.3 | J15: https://amazon.com/dp/B0CKLVYY1J | K15: =HYPERLINK(J15) -> https://amazon.com/dp/B0CKLVYY1J
A16: Pulsar Telos LRF XP50 Thermal Imaging Monocular with Laser Range Finder | B16: B003QNIZ14 | C16: 3999.97 | D16: 206632.92 | E16: 17219.41 | F16: 48 | G16: 4 | H16: 6 | I16: 4.8 | J16: https://amazon.com/dp/B003QNIZ14 | K16: =HYPERLINK(J16) -> https://amazon.com/dp/B003QNIZ14
A17: Pulsar Telos XL50 Thermal Imaging Monocular | B17: B0D84HKGHG | C17: 4699 | D17: 173553 | E17: 14462.75 | F17: 36 | G17: 3 | H17: 15 | I17: 4.3 | J17: https://amazon.com/dp/B0D84HKGHG | K17: =HYPERLINK(J17) -> https://amazon.com/dp/B0D84HKGHG
A18: Pulsar Telos LRF XL50 Thermal Imaging Monocular with Laser Range Finder | B18: B0D84GH4GB | C18: 5499.97 | D18: 172290.24 | E18: 14357.52 | F18: 36 | G18: 3 | H18: 6 | I18: 4.8 | J18: https://amazon.com/dp/B0D84GH4GB | K18: =HYPERLINK(J18) -> https://amazon.com/dp/B0D84GH4GB
A19: Total | D19: =SUM(pulsar!D9:D18) -> 3005089.1 | E19: =SUM(pulsar!E9:E18) -> 250424.09
A20: Rank by Units
A21: Product Name | B21: ASIN | C21: Avg Price | D21: Estimated 12mo Revenue | E21: Monthly Rev | F21: Estimated 12mo Units | G21: Monthly Units | H21: # of Reviews | I21: Tool Rating | J21: Column1 | K21: Link
A22: Pulsar Battery Pack LPS 7i | B22: B002Q6UG3W | C22: 129.97 | D22: 67185.36 | E22: 5598.78 | F22: 516 | G22: 43 | H22: 7 | I22: 4.4 | J22: https://amazon.com/dp/B002Q6UG3W | K22: =HYPERLINK(J22) -> https://amazon.com/dp/B002Q6UG3W
A23: Pulsar Axion 2 LRF XQ35 Pro Thermal Monocular with Laser Range Finder | B23: B0C37XZWZJ | C23: 1859.99 | D23: 590961.72 | E23: 49246.81 | F23: 312 | G23: 26 | H23: 39 | I23: 4.3 | J23: https://amazon.com/dp/B0C37XZWZJ | K23: =HYPERLINK(J23) -> https://amazon.com/dp/B0C37XZWZJ
A24: Pulsar Axion 2 XG35 Thermal Monocular | B24: B0B6GJ84TZ | C24: 2379.97 | D24: 427332.12 | E24: 35611.01 | F24: 180 | G24: 15 | H24: 61 | I24: 4.4 | J24: https://amazon.com/dp/B0B6GJ84TZ | K24: =HYPERLINK(J24) -> https://amazon.com/dp/B0B6GJ84TZ
A25: Pulsar Telos XQ35 Thermal Imaging Monocular | B25: B0CTVDMD16 | C25: 1949.99 | D25: 336529.68 | E25: 28044.14 | F25: 168 | G25: 14 | H25: 15 | I25: 4.3 | J25: https://amazon.com/dp/B0CTVDMD16 | K25: =HYPERLINK(J25) -> https://amazon.com/dp/B0CTVDMD16
A26: Pulsar Telos LRF XQ35 Thermal Imaging Monocular with Laser Range Finder | B26: B0CTVD7WNF | C26: 2349 | D26: 311954.16 | E26: 25996.18 | F26: 132 | G26: 11 | H26: 6 | I26: 4.8 | J26: https://amazon.com/dp/B0CTVD7WNF | K26: =HYPERLINK(J26) -> https://amazon.com/dp/B0CTVD7WNF
A27: Pulsar Telos XG50 Thermal Imaging Monocular | B27: B0CTVH53L5 | C27: 2499.97 | D27: 257960.88 | E27: 21496.74 | F27: 96 | G27: 8 | H27: 15 | I27: 4.3 | J27: https://amazon.com/dp/B0CTVH53L5 | K27: =HYPERLINK(J27) -> https://amazon.com/dp/B0CTVH53L5
A28: Pulsar Axion XQ30 Compact Thermal Imaging Monocular | B28: B0DLDYXW27 | C28: 2199.97 | D28: 163979.04 | E28: 13664.92 | F28: 84 | G28: 7 | H28: 14 | I28: 4.6 | J28: https://amazon.com/dp/B0DLDYXW27 | K28: =HYPERLINK(J28) -> https://amazon.com/dp/B0DLDYXW27
A29: Pulsar Telos LRF XG50 Thermal Imaging Monocular with Laser Range Finder | B29: B0CTW1RCM1 | C29: 3499.99 | D29: 319761.12 | E29: 26646.76 | F29: 84 | G29: 7 | H29: 6 | I29: 4.8 | J29: https://amazon.com/dp/B0CTW1RCM1 | K29: =HYPERLINK(J29) -> https://amazon.com/dp/B0CTW1RCM1
A30: Total | F30: =SUM(pulsar!F22:F29) -> 1572 | G30: =SUM(pulsar!G22:G29) -> 131

Sheet armasight
A1: #VALUE!
A7: Rank by Revenue
A8: Product Name | B8: ASIN | C8: Avg Price | D8: Estimated 12mo Revenue | E8: Monthly Rev | F8: Estimated 12mo Units | G8: Monthly Units | H8: # of Reviews | I8: Tool Rating | J8: Column1 | K8: Link
A9: Armasight Sidekick 320 Mini Thermal Monocular with Armacore 320 Thermal Core, 3-Button Control, Compass, and Image Detail Enhancement (Gray) | B9: B0CP8N943X | C9: 1583.12 | D9: 505055.04 | E9: 42087.92 | F9: 324 | G9: 27 | H9: 19 | I9: 3.9 | J9: https://amazon.com/dp/B0CP8N943X | K9: =HYPERLINK(J9) -> https://amazon.com/dp/B0CP8N943X
A10: Armasight Sidekick 640 Mini Thermal Monocular with Armacore 640 Thermal Core, 3-Button Control, Compass, and Image Detail Enhancement (Gray) | B10: B0CPN38V6B | C10: 2723 | D10: 456937.2 | E10: 38078.1 | F10: 168 | G10: 14 | H10: 18 | I10: 4 | J10: https://amazon.com/dp/B0CPN38V6B | K10: =HYPERLINK(J10) -> https://amazon.com/dp/B0CPN38V6B
A11: Armasight PVS-14 Pinnacle Elite Gen 3 IIT, Night Vision Monocular | B11: B0BH1MNCBF | C11: 5445.16 | D11: 69609.96 | E11: 5800.83 | F11: 12 | G11: 1 | H11: 2 | I11: 1 | J11: https://amazon.com/dp/B0BH1MNCBF | K11: =HYPERLINK(J11) -> https://amazon.com/dp/B0BH1MNCBF
A12: Armasight PVS-14 Bravo Tube 1400+ FOM + 3X Magnifier Lens | B12: B0D9STMY3B | C12: 3999 | D12: 45260.16 | E12: 3771.68 | F12: 12 | G12: 1 | H12: 1 | I12: 1 | J12: https://amazon.com/dp/B0D9STMY3B | K12: =HYPERLINK(J12) -> https://amazon.com/dp/B0D9STMY3B
A13: Armasight 3X Lens for PVS-14 with Waterproof Design and Long-Range Observation (Black) | B13: B0BH1M4Y6N | C13: 230.48 | D13: 7293.12 | E13: 607.76 | F13: 36 | G13: 3 | H13: 1 | I13: 5 | J13: https://amazon.com/dp/B0BH1M4Y6N | K13: =HYPERLINK(J13) -> https://amazon.com/dp/B0BH1M4Y6N
A14: Armasight MNVD-51 Pinnacle Gen 3 IIT, Night Vision Monocular | B14: B0BH1J3NBV | C14: 4621.91 | F14: 0 | G14: 0 | H14: 1 | I14: 3 | J14: https://amazon.com/dp/B0BH1J3NBV | K14: =HYPERLINK(J14) -> https://amazon.com/dp/B0BH1J3NBV
A15: Armasight 6X Lens for PVS-14 with Waterproof Design, Lightweight Body, and 8-Degree Field of View (Black) | B15: B0BH1L3G6B | C15: 249 | F15: 0 | G15: 0 | H15: 1 | I15: 5 | J15: https://amazon.com/dp/B0BH1L3G6B | K15: =HYPERLINK(J15) -> https://amazon.com/dp/B0BH1L3G6B
A16: Total | D16: =SUM(armasight!D9:D15) -> 1084155.5 | E16: =SUM(armasight!E9:E15) -> 90346.29
A17: Rank by Units
A18: Product Name | B18: ASIN | C18: Avg Price | D18: Estimated 12mo Revenue | E18: Monthly Rev | F18: Estimated 12mo Units | G18: Monthly Units | H18: # of Reviews | I18: Tool Rating | J18: Column1 | K18: Link
A19: Armasight Sidekick 320 Mini Thermal Monocular with Armacore 320 Thermal Core, 3-Button Control, Compass, and Image Detail Enhancement (Gray) | B19: B0CP8N943X | C19: 1583.12 | D19: 505055.04 | E19: 42087.92 | F19: 324 | G19: 27 | H19: 19 | I19: 3.9 | J19: https://amazon.com/dp/B0CP8N943X | K19: =HYPERLINK(J19) -> https://amazon.com/dp/B0CP8N943X
A20: Armasight Sidekick 640 Mini Thermal Monocular with Armacore 640 Thermal Core, 3-Button Control, Compass, and Image Detail Enhancement (Gray) | B20: B0CPN38V6B | C20: 2723 | D20: 456937.2 | E20: 38078.1 | F20: 168 | G20: 14 | H20: 18 | I20: 4 | J20: https://amazon.com/dp/B0CPN38V6B | K20: =HYPERLINK(J20) -> https://amazon.com/dp/B0CPN38V6B
A21: Armasight 3X Lens for PVS-14 with Waterproof Design and Long-Range Observation (Black) | B21: B0BH1M4Y6N | C21: 230.48 | D21: 7293.12 | E21: 607.76 | F21: 36 | G21: 3 | H21: 1 | I21: 5 | J21: https://amazon.com/dp/B0BH1M4Y6N | K21: =HYPERLINK(J21) -> https://amazon.com/dp/B0BH1M4Y6N
A22: Armasight PVS-14 Pinnacle Elite Gen 3 IIT, Night Vision Monocular | B22: B0BH1MNCBF | C22: 5445.16 | D22: 69609.96 | E22: 5800.83 | F22: 12 | G22: 1 | H22: 2 | I22: 1 | J22: https://amazon.com/dp/B0BH1MNCBF | K22: =HYPERLINK(J22) -> https://amazon.com/dp/B0BH1MNCBF
A23: Armasight PVS-14 Bravo Tube 1400+ FOM + 3X Magnifier Lens | B23: B0D9STMY3B | C23: 3999 | D23: 45260.16 | E23: 3771.68 | F23: 12 | G23: 1 | H23: 1 | I23: 1 | J23: https://amazon.com/dp/B0D9STMY3B | K23: =HYPERLINK(J23) -> https://amazon.com/dp/B0D9STMY3B
A24: Total | F24: =SUM(armasight!F19:F23) -> 552 | G24: =SUM(armasight!G19:G23) -> 46

Sheet RALCAM
A1: #VALUE!
A7: Rank by Revenue
A8: Product Name | B8: ASIN | C8: Avg Price | D8: Estimated 12mo Revenue | E8: Monthly Rev | F8: Estimated 12mo Units | G8: Monthly Units | H8: # of Reviews | I8: Tool Rating | J8: Column1 | K8: Link
A9: Ralcam 360° Articulating Borescope Dual Lens, 5'' Joystick 4 Ways Industrial Endoscope Camera with Light, 6.5mm Slim Probe, 5.0FT Semi-Rigid Snake Inspection Camera for Automotive Mechanics | B9: B0DSW1DKTZ | C9: 299.99 | D9: 324720.48 | E9: 27060.04 | F9: 1140 | G9: 95 | H9: 60 | I9: 4.4 | J9: https://amazon.com/dp/B0DSW1DKTZ | K9: =HYPERLINK(J9) -> https://amazon.com/dp/B0DSW1DKTZ
